Workbook
Name LISTA_ACAO_FUTURA: REGRAS!$B$114:$B$120
Name LISTA_ATIVO_RECEPTIVO: REGRAS!$B$100:$B$101
Name LISTA_CONSULTOR: REGRAS!$A$88:$A$91
Name LISTA_CURVA_ABC: REGRAS!$B$102:$B$104
Name LISTA_FASE: REGRAS!$B$51:$B$59
Name LISTA_GRUPO_DASH: REGRAS!$B$111:$B$113
Name LISTA_MOTIVO: REGRAS!$B$28:$B$37
Name LISTA_RESULTADO: REGRAS!$B$2:$B$13
Name LISTA_SIM_NAO: REGRAS!$B$95:$B$96
Name LISTA_SIM_NAO_NA: REGRAS!$B$97:$B$99
Name LISTA_SINALEIRO: REGRAS!$A$72:$A$75
Name LISTA_SITUACAO: REGRAS!$B$41:$B$47
Name LISTA_TENTATIVA: REGRAS!$B$63:$B$68
Name LISTA_TIPO_CLIENTE: REGRAS!$B$105:$B$110
Name LISTA_TIPO_CONTATO: REGRAS!$B$18:$B$24

Sheet REGRAS
A1: # | B1: RESULTADO | C1: FOLLOW-UP (DIAS) | D1: GRUPO DASH | E1: QUANDO USAR
A2: 1 | B2: EM ATENDIMENTO | C2: 2 | D2: FUNIL | E2: Negociação ativa
A3: 2 | B3: ORÇAMENTO | C3: 1 | D3: FUNIL | E3: Proposta enviada
A4: 3 | B4: CADASTRO | C4: 2 | D4: FUNIL | E4: Cliente novo em cadastro
A5: 4 | B5: VENDA / PEDIDO | C5: 45 | D5: FUNIL | E5: Pedido fechado
A6: 5 | B6: RELACIONAMENTO | C6: 7 | D6: RELAC. | E6: Contato pós-venda/CS
A7: 6 | B7: FOLLOW UP 7 | C7: 7 | D7: RELAC. | E7: Retomar em 1 semana
A8: 7 | B8: FOLLOW UP 15 | C8: 15 | D8: RELAC. | E8: Retomar em 2 semanas
A9: 8 | B9: SUPORTE | C9: 0 | D9: RELAC. | E9: Problema resolvido
A10: 9 | B10: NÃO ATENDE | C10: 1 | D10: NÃO VENDA | E10: Ligou sem resposta
A11: 10 | B11: NÃO RESPONDE | C11: 1 | D11: NÃO VENDA | E11: WhatsApp sem resposta
A12: 11 | B12: RECUSOU LIGAÇÃO | C12: 2 | D12: NÃO VENDA | E12: Rejeitou chamada
A13: 12 | B13: PERDA / FECHOU LOJA | C13: 0 | D13: NÃO VENDA | E13: Cliente perdido
A17: # | B17: TIPO DO CONTATO | C17: QUANDO USAR
A18: 1 | B18: PROSPECÇÃO | C18: Primeiro contato com prospect/lead que nunca comprou
A19: 2 | B19: NEGOCIAÇÃO | C19: Cliente demonstrou interesse, está em fase de proposta/orçamento
A20: 3 | B20: FOLLOW UP | C20: Retomada de contato agendado (follow-up 7d ou 15d)
A21: 4 | B21: ATEND. CLIENTES ATIVOS | C21: Manutenção de clientes ATIVOS (ciclo de recompra, pós-venda)
A22: 5 | B22: ATEND. CLIENTES INATIVOS | C22: Reativação de INAT.REC ou INAT.ANT (não compra há 60+ dias)
A23: 6 | B23: PÓS-VENDA / RELACIONAMENTO | C23: Contato de relacionamento após venda (satisfação, CS, suporte)
A24: 7 | B24: PERDA / NUTRIÇÃO | C24: Cliente perdido ou em nutrição (fechou loja, sem interesse)
A27: # | B27: MOTIVO | C27: DONO DA AÇÃO
A28: 1 | B28: AINDA TEM ESTOQUE | C28: Normal
A29: 2 | B29: PRODUTO NÃO VENDEU / SEM GIRO | C29: DIRETORIA / FÁBRICA
A30: 3 | B30: LOJA ANEXO/PROXIMO - SM | C30: COMERCIAL
A31: 4 | B31: SÓ QUER COMPRAR GRANEL | C31: COMERCIAL / MKT
A32: 5 | B32: PROBLEMA LOGÍSTICO / ENTREGA | C32: LOGÍSTICA
A33: 6 | B33: PROBLEMA FINANCEIRO / CRÉDITO | C33: FINANCEIRO
A34: 7 | B34: PROPRIETARIO / INDISPONÍVEL | C34: Normal
A35: 8 | B35: FECHANDO / FECHOU LOJA | C35: PERDA
A36: 9 | B36: SEM INTERESSE NO MOMENTO | C36: NUTRIÇÃO
A37: 10 | B37: PRIMEIRO CONTATO / SEM RESPOSTA | C37: Normal
A40: DIAS | B40: SITUAÇÃO | C40: COR HEX
A41: ≤ 50 | B41: ATIVO | C41: #00B050
A42: 51-60 | B42: EM RISCO | C42: #FFC000
A43: 61-90 | B43: INAT.REC | C43: #FFC000
A44: > 90 | B44: INAT.ANT | C44: #FF0000
A45: Nunca comprou + cadastro | B45: NOVO | C45: #0070C0
A46: Nunca comprou | B46: PROSPECT | C46: #7B2FF2
A47: Manual (Daiane) | B47: LEAD | C47: #7B2FF2
...

Sheet CARTEIRA
A1: 🟣 MERCOS | AR1: 🔵 FUNIL | BJ1: ⚫ SAP | BU1: 🟢 ACOMPANHAMENTO | BV1: Q1 | BW1: JAN | CC1: 100% | CD1: =SUBTOTAL(109,CD4:CD5000) | CE1: =SUBTOTAL(109,CE4:CE5000) | CL1: FEV | CR1: 100% | CS1: =SUBTOTAL(109,CS4:CS5000) | CT1: =SUBTOTAL(109,CT4:CT5000) | DA1: MAR | DG1: 100% | DH1: =SUBTOTAL(109,DH4:DH5000) | DI1: =SUBTOTAL(109,DI4:DI5000) | DP1: Q2 | DQ1: ABR | DW1: 100% | DX1: =SUBTOTAL(109,DX4:DX5000) | DY1: =SUBTOTAL(109,DY4:DY5000) | EF1: MAI | EL1: 100% | EM1: =SUBTOTAL(109,EM4:EM5000) | EN1: =SUBTOTAL(109,EN4:EN5000) | EU1: JUN | FA1: 100% | FB1: =SUBTOTAL(109,FB4:FB5000) | FC1: =SUBTOTAL(109,FC4:FC5000) | FJ1: Q3 | FK1: JUL | FQ1: 100% | FR1: =SUBTOTAL(109,FR4:FR5000) | FS1: =SUBTOTAL(109,FS4:FS5000) | FZ1: AGO | GF1: 100% | GG1: =SUBTOTAL(109,GG4:GG5000) | GH1: =SUBTOTAL(109,GH4:GH5000) | GO1: SET | GU1: 100% | GV1: =SUBTOTAL(109,GV4:GV5000) | GW1: =SUBTOTAL(109,GW4:GW5000) | HD1: Q4 | HE1: OUT | HK1: 100% | HL1: =SUBTOTAL(109,HL4:HL5000) | HM1: =SUBTOTAL(109,HM4:HM5000) | HT1: NOV | HZ1: 100% | IA1: =SUBTOTAL(109,IA4:IA5000) | IB1: =SUBTOTAL(109,IB4:IB5000) | II1: DEZ | IO1: 100% | IP1: =SUBTOTAL(109,IP4:IP5000) | IQ1: =SUBTOTAL(109,IQ4:IQ5000)
A2: ANCORA | B2: IDENTIDADE | C2: IDENTIDADE | D2: IDENTIDADE | E2: IDENTIDADE | F2: IDENTIDADE | G2: IDENTIDADE | H2: IDENTIDADE | I2: REDE | J2: REDE | K2: REDE | L2: EQUIPE | M2: EQUIPE | N2: STATUS | O2: STATUS | P2: COMPRA | Q2: COMPRA | R2: COMPRA | S2: ECOMMERCE | T2: ECOMMERCE | U2: ECOMMERCE | V2: ECOMMERCE | W2: ECOMMERCE | X2: ECOMMERCE | Y2: VENDAS | Z2: VENDAS | AA2: VENDAS | AB2: VENDAS | AC2: VENDAS | AD2: VENDAS | AE2: VENDAS | AF2: VENDAS | AG2: VENDAS | AH2: VENDAS | AI2: VENDAS | AJ2: VENDAS | AK2: RECORRÊNCIA | AL2: RECORRÊNCIA | AM2: RECORRÊNCIA | AN2: RECORRÊNCIA | AO2: RECORRÊNCIA | AP2: RECORRÊNCIA | AQ2: RECORRÊNCIA | AR2: ANCORA | AS2: PIPELINE | AT2: PIPELINE | AU2: PIPELINE | AV2: PIPELINE | AW2: PERFIL | AX2: PERFIL | AY2: MATURIDADE | AZ2: MATURIDADE | BA2: CONVERSÃO | BB2: CONVERSÃO | BC2: CONVERSÃO | BD2: CONVERSÃO | BE2: CONVERSÃO | BF2: CONVERSÃO | BG2: AÇÃO | BH2: AÇÃO | BI2: SINAL | BJ2: DADOS SAP | BK2: SAP | BL2: SAP | BM2: SAP | BN2: SAP | BO2: SAP | BP2: SAP | BQ2: SAP | BR2: SAP | BS2: SAP | BT2: SAP | BW2: YTD | BZ2: TRI | CC2: MÊS | CL2: YTD | CO2: TRI | CR2: MÊS | DA2: YTD | DD2: TRI | DG2: MÊS | DQ2: YTD | DT2: TRI | DW2: MÊS | EF2: YTD | EI2: TRI | EL2: MÊS | EU2: YTD | EX2: TRI | FA2: MÊS | FK2: YTD | FN2: TRI | FQ2: MÊS | FZ2: YTD | GC2: TRI | GF2: MÊS | GO2: YTD | GR2: TRI | GU2: MÊS | HE2: YTD | HH2: TRI | HK2: MÊS | HT2: YTD | HW2: TRI | HZ2: MÊS | II2: YTD | IL2: TRI | IO2: MÊS
A3: NOME FANTASIA | B3: CNPJ | C3: RAZÃO SOCIAL | D3: UF | E3: CIDADE | F3: EMAIL | G3: TELEFONE | H3: DATA CADASTRO | I3: REDE / REGIONAL | K3: ÚLT. REGISTRO MERCOS | L3: CONSULTOR | M3: VENDEDOR ÚLTIMO PEDIDO | N3: SITUAÇÃO | O3: PRIORIDADE | P3: DIAS SEM COMPRA | Q3: DATA ÚLTIMO PEDIDO | R3: VALOR ÚLTIMO PEDIDO | S3: 📊 ACESSOS SEMANA | T3: ACESSO B2B | U3: ACESSOS PORTAL | V3: ITENS CARRINHO | W3: VALOR B2B | X3: OPORTUNIDADE | Y3: TOTAL PERÍODO | Z3: MAR/25 | AA3: ABR/25 | AB3: MAI/25 | AC3: JUN/25 | AD3: JUL/25 | AE3: AGO/25 | AF3: SET/25 | AG3: OUT/25 | AH3: NOV/25 | AI3: DEZ/25 | AJ3: JAN/26 | AK3: CICLO MÉDIO | AL3: Nº COMPRAS | AM3: CURVA ABC | AN3: MESES POSITIVADO | AO3: MÉDIA MENSAL | AP3: TICKET MÉDIO | AQ3: MESES LISTA | AR3: ESTÁGIO FUNIL | AS3: PRÓX. FOLLOW-UP | AT3: DATA ÚLT.ATENDIMENTO | AU3: ÚLTIMO RESULTADO | AV3: MOTIVO | AW3: TIPO CLIENTE | AX3: TENTATIVA | AY3: FASE | AZ3: ÚLTIMA RECOMPRA | BA3: 🔥 TEMPERATURA | BB3: DIAS ATÉ CONVERSÃO | BC3: DATA 1º CONTATO | BD3: DATA 1º ORÇAMENTO | BE3: DATA 1ª VENDA | BF3: TOTAL TENTATIVAS | BG3: PRÓX. AÇÃO | BH3: AÇÃO DETALHADA | BI3: 🚦 SINALEIRO | BJ3: CÓDIGO DO CLIENTE | BK3: DESCRIÇÃO GRUPO CLIENTE | BL3: ZP NOME GERENTE NACIONAL | BM3: ZR NOME REPRESENTANTE | BN3: ZV NOME VEND. INTERNO | BO3: 01 NOME DO CANAL | BP3: 02 NOME TIPO CLIENTE | BQ3: 03 NOME MACROREGIÃO | BR3: 04 NOME MICROREGIÃO | BS3: 06 NOME GRUPO CHAVE | BT3: VENDA | BU3: % ATING. | BV3: % Q1 | BW3: % YTD | BX3: META | BY3: REALIZADO | BZ3: % TRI | CA3: META | CB3: REALIZADO | CC3: % MÊS | CD3: META | CE3: REALIZADO | CF3: DATA PEDIDO | CG3: JUSTIFICATIVA SEMANA 1 | CH3: JUSTIFICATIVA SEMANA 2 | CI3: JUSTIFICATIVA SEMANA 3 | CJ3: JUSTIFICATIVA SEMANA 4 | CK3: JUSTIFICATIVA MENSAL | CL3: % YTD | CM3: META | CN3: REALIZADO | CO3: % TRI | CP3: META | CQ3: REALIZADO | CR3: % MÊS | CS3: META | CT3: REALIZADO | CU3: DATA PEDIDO | CV3: JUSTIFICATIVA SEMANA 1 | CW3: JUSTIFICATIVA SEMANA 2 | CX3: JUSTIFICATIVA SEMANA 3 | CY3: JUSTIFICATIVA SEMANA 4 | CZ3: JUSTIFICATIVA MENSAL | DA3: % YTD | DB3: META | DC3: REALIZADO | DD3: % TRI | DE3: META | DF3: REALIZADO | DG3: % MÊS | DH3: META | DI3: REALIZADO | DJ3: DATA PEDIDO | DK3: JUSTIFICATIVA SEMANA 1 | DL3: JUSTIFICATIVA SEMANA 2 | DM3: JUSTIFICATIVA SEMANA 3 | DN3: JUSTIFICATIVA SEMANA 4 | DO3: JUSTIFICATIVA MENSAL | DP3: % Q2 | DQ3: % YTD | DR3: META | DS3: REALIZADO | DT3: % TRI | DU3: META | DV3: REALIZADO | DW3: % MÊS | DX3: META | DY3: REALIZADO | DZ3: DATA PEDIDO | EA3: JUSTIFICATIVA SEMANA 1 | EB3: JUSTIFICATIVA SEMANA 2 | EC3: JUSTIFICATIVA SEMANA 3 | ED3: JUSTIFICATIVA SEMANA 4 | EE3: JUSTIFICATIVA MENSAL | EF3: % YTD | EG3: META | EH3: REALIZADO | EI3: % TRI | EJ3: META | EK3: REALIZADO | EL3: % MÊS | EM3: META | EN3: REALIZADO | EO3: DATA PEDIDO | EP3: JUSTIFICATIVA SEMANA 1 | EQ3: JUSTIFICATIVA SEMANA 2 | ER3: JUSTIFICATIVA SEMANA 3 | ES3: JUSTIFICATIVA SEMANA 4 | ET3: JUSTIFICATIVA MENSAL | EU3: % YTD | EV3: META | EW3: REALIZADO | EX3: % TRI | EY3: META | EZ3: REALIZADO | FA3: % MÊS | FB3: META | FC3: REALIZADO | FD3: DATA PEDIDO | FE3: JUSTIFICATIVA SEMANA 1 | FF3: JUSTIFICATIVA SEMANA 2 | FG3: JUSTIFICATIVA SEMANA 3 | FH3: JUSTIFICATIVA SEMANA 4 | FI3: JUSTIFICATIVA MENSAL | FJ3: % Q3 | FK3: % YTD | FL3: META | FM3: REALIZADO | FN3: % TRI | FO3: META | FP3: REALIZADO | FQ3: % MÊS | FR3: META | FS3: REALIZADO | FT3: DATA PEDIDO | FU3: JUSTIFICATIVA SEMANA 1 | FV3: JUSTIFICATIVA SEMANA 2 | FW3: JUSTIFICATIVA SEMANA 3 | FX3: JUSTIFICATIVA SEMANA 4 | FY3: JUSTIFICATIVA MENSAL | FZ3: % YTD | GA3: META | GB3: REALIZADO | GC3: % TRI | GD3: META | GE3: REALIZADO | GF3: % MÊS | GG3: META | GH3: REALIZADO | GI3: DATA PEDIDO | GJ3: JUSTIFICATIVA SEMANA 1 | GK3: JUSTIFICATIVA SEMANA 2 | GL3: JUSTIFICATIVA SEMANA 3 | GM3: JUSTIFICATIVA SEMANA 4 | GN3: JUSTIFICATIVA MENSAL | GO3: % YTD | GP3: META | GQ3: REALIZADO | GR3: % TRI | GS3: META | GT3: REALIZADO | GU3: % MÊS | GV3: META | GW3: REALIZADO | GX3: DATA PEDIDO | GY3: JUSTIFICATIVA SEMANA 1 | GZ3: JUSTIFICATIVA SEMANA 2 | HA3: JUSTIFICATIVA SEMANA 3 | HB3: JUSTIFICATIVA SEMANA 4 | HC3: JUSTIFICATIVA MENSAL | HD3: % Q4 | HE3: % YTD | HF3: META | HG3: REALIZADO | HH3: % TRI | HI3: META | HJ3: REALIZADO | HK3: % MÊS | HL3: META | HM3: REALIZADO | HN3: DATA PEDIDO | HO3: JUSTIFICATIVA SEMANA 1 | HP3: JUSTIFICATIVA SEMANA 2 | HQ3: JUSTIFICATIVA SEMANA 3 | HR3: JUSTIFICATIVA SEMANA 4 | HS3: JUSTIFICATIVA MENSAL | HT3: % YTD | HU3: META | HV3: REALIZADO | HW3: % TRI | HX3: META | HY3: REALIZADO | HZ3: % MÊS | IA3: META | IB3: REALIZADO | IC3: DATA PEDIDO | ID3: JUSTIFICATIVA SEMANA 1 | IE3: JUSTIFICATIVA SEMANA 2 | IF3: JUSTIFICATIVA SEMANA 3 | IG3: JUSTIFICATIVA SEMANA 4 | IH3: JUSTIFICATIVA MENSAL | II3: % YTD | IJ3: META | IK3: REALIZADO | IL3: % TRI | IM3: META | IN3: REALIZADO | IO3: % MÊS | IP3: META | IQ3: REALIZADO | IR3: DATA PEDIDO | IS3: JUSTIFICATIVA SEMANA 1 | IT3: JUSTIFICATIVA SEMANA 2 | IU3: JUSTIFICATIVA SEMANA 3 | IV3: JUSTIFICATIVA SEMANA 4 | IW3: JUSTIFICATIVA MENSAL
A4: =IFERROR(INDEX('DRAFT 1'!$A:$A,MATCH($B4,'DRAFT 1'!$B:$B,0)),"") | B4: 32828171000108 | C4: =IFERROR(INDEX('DRAFT 1'!$C:$C,MATCH($B4,'DRAFT 1'!$B:$B,0)),"") | D4: =IFERROR(INDEX('DRAFT 1'!$D:$D,MATCH($B4,'DRAFT 1'!$B:$B,0)),"") | E4: =IFERROR(INDEX('DRAFT 1'!$E:$E,MATCH($B4,'DRAFT 1'!$B:$B,0)),"") | F4: =IFERROR(INDEX('DRAFT 1'!$F:$F,MATCH($B4,'DRAFT 1'!$B:$B,0)),"") | G4: =IFERROR(INDEX('DRAFT 1'!$G:$G,MATCH($B4,'DRAFT 1'!$B:$B,0)),"") | H4: =IFERROR(INDEX('DRAFT 1'!$H:$H,MATCH($B4,'DRAFT 1'!$B:$B,0)),"") | I4: MUNDO VERDE | K4: =IFERROR(INDEX('DRAFT 1'!$AL:$AL,MATCH($B4,'DRAFT 1'!$B:$B,0)),"") | L4: =IFERROR(INDEX('DRAFT 1'!$J:$J,MATCH($B4,'DRAFT 1'!$B:$B,0)),"") | M4: =IFERROR(INDEX('DRAFT 1'!$K:$K,MATCH($B4,'DRAFT 1'!$B:$B,0)),"") | N4: EM RISCO | O4: =IF(N4="EM RISCO",1,IF(N4="INAT.REC",2,IF(N4="ATIVO",3,IF(N4="INAT.ANT",4,5)))) | P4: =IFERROR(INDEX('DRAFT 1'!$L:$L,MATCH($B4,'DRAFT 1'!$B:$B,0)),"") | Q4: =IFERROR(INDEX('DRAFT 1'!$M:$M,MATCH($B4,'DRAFT 1'!$B:$B,0)),"") | R4: =IFERROR(INDEX('DRAFT 1'!$N:$N,MATCH($B4,'DRAFT 1'!$B:$B,0)),"") | S4: =IFERROR(INDEX('DRAFT 1'!$O:$O,MATCH($B4,'DRAFT 1'!$B:$B,0)),"") | T4: =IFERROR(INDEX('DRAFT 1'!$P:$P,MATCH($B4,'DRAFT 1'!$B:$B,0)),"") | U4: =IFERROR(INDEX('DRAFT 1'!$Q:$Q,MATCH($B4,'DRAFT 1'!$B:$B,0)),"") | V4: =IFERROR(INDEX('DRAFT 1'!$R:$R,MATCH($B4,'DRAFT 1'!$B:$B,0)),"") | W4: =IFERROR(INDEX('DRAFT 1'!$S:$S,MATCH($B4,'DRAFT 1'!$B:$B,0)),"") | X4: =IFERROR(INDEX('DRAFT 1'!$T:$T,MATCH($B4,'DRAFT 1'!$B:$B,0)),"") | Y4: =SUM(Z4:AJ4) | Z4: =IFERROR(INDEX('DRAFT 1'!$U:$U,MATCH($B4,'DRAFT 1'!$B:$B,0)),"") | AA4: =IFERROR(INDEX('DRAFT 1'!$V:$V,MATCH($B4,'DRAFT 1'!$B:$B,0)),"") | AB4: =IFERROR(INDEX('DRAFT 1'!$W:$W,MATCH($B4,'DRAFT 1'!$B:$B,0)),"") | AC4: =IFERROR(INDEX('DRAFT 1'!$X:$X,MATCH($B4,'DRAFT 1'!$B:$B,0)),"") | AD4: =IFERROR(INDEX('DRAFT 1'!$Y:$Y,MATCH($B4,'DRAFT 1'!$B:$B,0)),"") | AE4: =IFERROR(INDEX('DRAFT 1'!$Z:$Z,MATCH($B4,'DRAFT 1'!$B:$B,0)),"") | AF4: =IFERROR(INDEX('DRAFT 1'!$AA:$AA,MATCH($B4,'DRAFT 1'!$B:$B,0)),"") | AG4: =IFERROR(INDEX('DRAFT 1'!$AB:$AB,MATCH($B4,'DRAFT 1'!$B:$B,0)),"") | AH4: =IFERROR(INDEX('DRAFT 1'!$AC:$AC,MATCH($B4,'DRAFT 1'!$B:$B,0)),"") | AI4: =IFERROR(INDEX('DRAFT 1'!$AD:$AD,MATCH($B4,'DRAFT 1'!$B:$B,0)),"") | AJ4: =IFERROR(INDEX('DRAFT 1'!$AE:$AE,MATCH($B4,'DRAFT 1'!$B:$B,0)),"") | AK4: =IFERROR(INDEX('DRAFT 1'!$AG:$AG,MATCH($B4,'DRAFT 1'!$B:$B,0)),"") | AL4: =IFERROR(INDEX('DRAFT 1'!$AH:$AH,MATCH($B4,'DRAFT 1'!$B:$B,0)),"") | AM4: =IFERROR(INDEX('DRAFT 1'!$AI:$AI,MATCH($B4,'DRAFT 1'!$B:$B,0)),"") | AN4: =IFERROR(INDEX('DRAFT 1'!$AJ:$AJ,MATCH($B4,'DRAFT 1'!$B:$B,0)),"") | AO4: =IFERROR(Y4/AN4,0) | AP4: =IFERROR(INDEX('DRAFT 1'!$AK:$AK,MATCH($B4,'DRAFT 1'!$B:$B,0)),"") | AR4: RECOMPRA | AS4: =IFERROR(LOOKUP(2,1/('DRAFT 2'!$D:$D=$B4),'DRAFT 2'!$T:$T),"") | AT4: =IFERROR(LOOKUP(2,1/('DRAFT 2'!$D:$D=$B4),'DRAFT 2'!$A:$A),"") | AU4: =IFERROR(LOOKUP(2,1/('DRAFT 2'!$D:$D=$B4),'DRAFT 2'!$R:$R),"") | AV4: =IFERROR(LOOKUP(2,1/('DRAFT 2'!$D:$D=$B4),'DRAFT 2'!$S:$S),"") | AW4: PROSPECT | AX4: =IFERROR(LOOKUP(2,1/('DRAFT 2'!$D:$D=$B4),'DRAFT 2'!$M:$M),"") | AY4: =IFERROR(LOOKUP(2,1/('DRAFT 2'!$D:$D=$B4),'DRAFT 2'!$K:$K),"") | BA4: =IF(N4="PROSPECT","❄️ FRIO",IF(OR(AR4="ORÇAMENTO",AR4="NEGOCIAÇÃO",AR4="CADASTRO"),"🔥 QUENTE",IF(OR(AR4="FOLLOW UP 7",AR4="FOLLOW UP 15",AR4="ATENDIMENTO"),"⚡ MORNO","❄️ FRIO"))) | BB4: =IF(BE4="","",BE4-BC4) | BG4: =IFERROR(LOOKUP(2,1/('DRAFT 2'!$D:$D=$B4),'DRAFT 2'!$U:$U),"") | BH4: =IFERROR(LOOKUP(2,1/('DRAFT 2'!$D:$D=$B4),'DRAFT 2'!$V:$V),"") | BI4: =IF(Q4="","🟣",IF(P4<=IF(AK4="",45,AK4),"🟢",IF(P4<=IF(AK4="",45,AK4)+30,"🟡","🔴"))) | BJ4: SAP001 | BU4: =CR4 | BV4: =AVERAGE(CC4,CR4,DG4) | BW4: =IF(BX4=0,1,BY4/BX4) | BZ4: =IF(CA4=0,1,CB4/CA4) | CC4: =IF(CD4=0,1,CE4/CD4) | CE4: =IFERROR(AJ4,0) | CF4: =IFERROR(LOOKUP(2,1/('DRAFT 2'!$D:$D=$B4)*('DRAFT 2'!$A:$A>=DATE(2026,1,1))*('DRAFT 2'!$A:$A<DATE(2026,IF(1=12,1+1,1+1),1)),'DRAFT 2'!$A:$A),"") | CG4: =COUNTIFS('DRAFT 2'!$D:$D,$B4,'DRAFT 2'!$A:$A,">="&DATE(2026,1,1),'DRAFT 2'!$A:$A,"<="&DATE(2026,1,7)) | CH4: =COUNTIFS('DRAFT 2'!$D:$D,$B4,'DRAFT 2'!$A:$A,">="&DATE(2026,1,8),'DRAFT 2'!$A:$A,"<="&DATE(2026,1,14)) | CI4: =COUNTIFS('DRAFT 2'!$D:$D,$B4,'DRAFT 2'!$A:$A,">="&DATE(2026,1,15),'DRAFT 2'!$A:$A,"<="&DATE(2026,1,21)) | CJ4: =COUNTIFS('DRAFT 2'!$D:$D,$B4,'DRAFT 2'!$A:$A,">="&DATE(2026,1,22),'DRAFT 2'!$A:$A,"<"&DATE(2026,IF(1=12,1+1,1+1),1)) | CK4: =SUM(CG4:CJ4) | CL4: =IF(CM4=0,1,CN4/CM4) | CO4: =IF(CP4=0,1,CQ4/CP4) | CR4: =IF(CS4=0,1,CT4/CS4) | CT4: 0 | CU4: =IFERROR(LOOKUP(2,1/('DRAFT 2'!$D:$D=$B4)*('DRAFT 2'!$A:$A>=DATE(2026,2,1))*('DRAFT 2'!$A:$A<DATE(2026,IF(2=12,2+1,2+1),1)),'DRAFT 2'!$A:$A),"") | CV4: =COUNTIFS('DRAFT 2'!$D:$D,$B4,'DRAFT 2'!$A:$A,">="&DATE(2026,2,1),'DRAFT 2'!$A:$A,"<="&DATE(2026,2,7)) | CW4: =COUNTIFS('DRAFT 2'!$D:$D,$B4,'DRAFT 2'!$A:$A,">="&DATE(2026,2,8),'DRAFT 2'!$A:$A,"<="&DATE(2026,2,14)) | CX4: =COUNTIFS('DRAFT 2'!$D:$D,$B4,'DRAFT 2'!$A:$A,">="&DATE(2026,2,15),'DRAFT 2'!$A:$A,"<="&DATE(2026,2,21)) | CY4: =COUNTIFS('DRAFT 2'!$D:$D,$B4,'DRAFT 2'!$A:$A,">="&DATE(2026,2,22),'DRAFT 2'!$A:$A,"<"&DATE(2026,IF(2=12,2+1,2+1),1)) | CZ4: =SUM(CV4:CY4) | DA4: =IF(DB4=0,1,DC4/DB4) | DD4: =IF(DE4=0,1,DF4/DE4) | DG4: =IF(DH4=0,1,DI4/DH4) | DJ4: =IFERROR(LOOKUP(2,1/('DRAFT 2'!$D:$D=$B4)*('DRAFT 2'!$A:$A>=DATE(2026,3,1))*('DRAFT 2'!$A:$A<DATE(2026,IF(3=12,3+1,3+1),1)),'DRAFT 2'!$A:$A),"") | DK4: =COUNTIFS('DRAFT 2'!$D:$D,$B4,'DRAFT 2'!$A:$A,">="&DATE(2026,3,1),'DRAFT 2'!$A:$A,"<="&DATE(2026,3,7)) | DL4: =COUNTIFS('DRAFT 2'!$D:$D,$B4,'DRAFT 2'!$A:$A,">="&DATE(2026,3,8),'DRAFT 2'!$A:$A,"<="&DATE(2026,3,14)) | DM4: =COUNTIFS('DRAFT 2'!$D:$D,$B4,'DRAFT 2'!$A:$A,">="&DATE(2026,3,15),'DRAFT 2'!$A:$A,"<="&DATE(2026,3,21)) | DN4: =COUNTIFS('DRAFT 2'!$D:$D,$B4,'DRAFT 2'!$A:$A,">="&DATE(2026,3,22),'DRAFT 2'!$A:$A,"<"&DATE(2026,IF(3=12,3+1,3+1),1)) | DO4: =SUM(DK4:DN4) | DP4: =AVERAGE(DW4,EL4,FA4) | DQ4: =IF(DR4=0,1,DS4/DR4) | DT4: =IF(DU4=0,1,DV4/DU4) | DW4: =IF(DX4=0,1,DY4/DX4) | DZ4: =IFERROR(LOOKUP(2,1/('DRAFT 2'!$D:$D=$B4)*('DRAFT 2'!$A:$A>=DATE(2026,4,1))*('DRAFT 2'!$A:$A<DATE(2026,IF(4=12,4+1,4+1),1)),'DRAFT 2'!$A:$A),"") | EA4: =COUNTIFS('DRAFT 2'!$D:$D,$B4,'DRAFT 2'!$A:$A,">="&DATE(2026,4,1),'DRAFT 2'!$A:$A,"<="&DATE(2026,4,7)) | EB4: =COUNTIFS('DRAFT 2'!$D:$D,$B4,'DRAFT 2'!$A:$A,">="&DATE(2026,4,8),'DRAFT 2'!$A:$A,"<="&DATE(2026,4,14)) | EC4: =COUNTIFS('DRAFT 2'!$D:$D,$B4,'DRAFT 2'!$A:$A,">="&DATE(2026,4,15),'DRAFT 2'!$A:$A,"<="&DATE(2026,4,21)) | ED4: =COUNTIFS('DRAFT 2'!$D:$D,$B4,'DRAFT 2'!$A:$A,">="&DATE(2026,4,22),'DRAFT 2'!$A:$A,"<"&DATE(2026,IF(4=12,4+1,4+1),1)) | EE4: =SUM(EA4:ED4) | EF4: =IF(EG4=0,1,EH4/EG4) | EI4: =IF(EJ4=0,1,EK4/EJ4) | EL4: =IF(EM4=0,1,EN4/EM4) | EO4: =IFERROR(LOOKUP(2,1/('DRAFT 2'!$D:$D=$B4)*('DRAFT 2'!$A:$A>=DATE(2026,5,1))*('DRAFT 2'!$A:$A<DATE(2026,IF(5=12,5+1,5+1),1)),'DRAFT 2'!$A:$A),"") | EP4: =COUNTIFS('DRAFT 2'!$D:$D,$B4,'DRAFT 2'!$A:$A,">="&DATE(2026,5,1),'DRAFT 2'!$A:$A,"<="&DATE(2026,5,7)) | EQ4: =COUNTIFS('DRAFT 2'!$D:$D,$B4,'DRAFT 2'!$A:$A,">="&DATE(2026,5,8),'DRAFT 2'!$A:$A,"<="&DATE(2026,5,14)) | ER4: =COUNTIFS('DRAFT 2'!$D:$D,$B4,'DRAFT 2'!$A:$A,">="&DATE(2026,5,15),'DRAFT 2'!$A:$A,"<="&DATE(2026,5,21)) | ES4: =COUNTIFS('DRAFT 2'!$D:$D,$B4,'DRAFT 2'!$A:$A,">="&DATE(2026,5,22),'DRAFT 2'!$A:$A,"<"&DATE(2026,IF(5=12,5+1,5+1),1)) | ET4: =SUM(EP4:ES4) | EU4: =IF(EV4=0,1,EW4/EV4) | EX4: =IF(EY4=0,1,EZ4/EY4) | FA4: =IF(FB4=0,1,FC4/FB4) | FD4: =IFERROR(LOOKUP(2,1/('DRAFT 2'!$D:$D=$B4)*('DRAFT 2'!$A:$A>=DATE(2026,6,1))*('DRAFT 2'!$A:$A<DATE(2026,IF(6=12,6+1,6+1),1)),'DRAFT 2'!$A:$A),"") | FE4: =COUNTIFS('DRAFT 2'!$D:$D,$B4,'DRAFT 2'!$A:$A,">="&DATE(2026,6,1),'DRAFT 2'!$A:$A,"<="&DATE(2026,6,7)) | FF4: =COUNTIFS('DRAFT 2'!$D:$D,$B4,'DRAFT 2'!$A:$A,">="&DATE(2026,6,8),'DRAFT 2'!$A:$A,"<="&DATE(2026,6,14)) | FG4: =COUNTIFS('DRAFT 2'!$D:$D,$B4,'DRAFT 2'!$A:$A,">="&DATE(2026,6,15),'DRAFT 2'!$A:$A,"<="&DATE(2026,6,21)) | FH4: =COUNTIFS('DRAFT 2'!$D:$D,$B4,'DRAFT 2'!$A:$A,">="&DATE(2026,6,22),'DRAFT 2'!$A:$A,"<"&DATE(2026,IF(6=12,6+1,6+1),1)) | FI4: =SUM(FE4:FH4) | FJ4: =AVERAGE(FQ4,GF4,GU4) | FK4: =IF(FL4=0,1,FM4/FL4) | FN4: =IF(FO4=0,1,FP4/FO4) | FQ4: =IF(FR4=0,1,FS4/FR4) | FT4: =IFERROR(LOOKUP(2,1/('DRAFT 2'!$D:$D=$B4)*('DRAFT 2'!$A:$A>=DATE(2026,7,1))*('DRAFT 2'!$A:$A<DATE(2026,IF(7=12,7+1,7+1),1)),'DRAFT 2'!$A:$A),"") | FU4: =COUNTIFS('DRAFT 2'!$D:$D,$B4,'DRAFT 2'!$A:$A,">="&DATE(2026,7,1),'DRAFT 2'!$A:$A,"<="&DATE(2026,7,7)) | FV4: =COUNTIFS('DRAFT 2'!$D:$D,$B4,'DRAFT 2'!$A:$A,">="&DATE(2026,7,8),'DRAFT 2'!$A:$A,"<="&DATE(2026,7,14)) | FW4: =COUNTIFS('DRAFT 2'!$D:$D,$B4,'DRAFT 2'!$A:$A,">="&DATE(2026,7,15),'DRAFT 2'!$A:$A,"<="&DATE(2026,7,21)) | FX4: =COUNTIFS('DRAFT 2'!$D:$D,$B4,'DRAFT 2'!$A:$A,">="&DATE(2026,7,22),'DRAFT 2'!$A:$A,"<"&DATE(2026,IF(7=12,7+1,7+1),1)) | FY4: =SUM(FU4:FX4) | FZ4: =IF(GA4=0,1,GB4/GA4) | GC4: =IF(GD4=0,1,GE4/GD4) | GF4: =IF(GG4=0,1,GH4/GG4) | GI4: =IFERROR(LOOKUP(2,1/('DRAFT 2'!$D:$D=$B4)*('DRAFT 2'!$A:$A>=DATE(2026,8,1))*('DRAFT 2'!$A:$A<DATE(2026,IF(8=12,8+1,8+1),1)),'DRAFT 2'!$A:$A),"") | GJ4: =COUNTIFS('DRAFT 2'!$D:$D,$B4,'DRAFT 2'!$A:$A,">="&DATE(2026,8,1),'DRAFT 2'!$A:$A,"<="&DATE(2026,8,7)) | GK4: =COUNTIFS('DRAFT 2'!$D:$D,$B4,'DRAFT 2'!$A:$A,">="&DATE(2026,8,8),'DRAFT 2'!$A:$A,"<="&DATE(2026,8,14)) | GL4: =COUNTIFS('DRAFT 2'!$D:$D,$B4,'DRAFT 2'!$A:$A,">="&DATE(2026,8,15),'DRAFT 2'!$A:$A,"<="&DATE(2026,8,21)) | GM4: =COUNTIFS('DRAFT 2'!$D:$D,$B4,'DRAFT 2'!$A:$A,">="&DATE(2026,8,22),'DRAFT 2'!$A:$A,"<"&DATE(2026,IF(8=12,8+1,8+1),1)) | GN4: =SUM(GJ4:GM4) | GO4: =IF(GP4=0,1,GQ4/GP4) | GR4: =IF(GS4=0,1,GT4/GS4) | GU4: =IF(GV4=0,1,GW4/GV4) | GX4: =IFERROR(LOOKUP(2,1/('DRAFT 2'!$D:$D=$B4)*('DRAFT 2'!$A:$A>=DATE(2026,9,1))*('DRAFT 2'!$A:$A<DATE(2026,IF(9=12,9+1,9+1),1)),'DRAFT 2'!$A:$A),"") | GY4: =COUNTIFS('DRAFT 2'!$D:$D,$B4,'DRAFT 2'!$A:$A,">="&DATE(2026,9,1),'DRAFT 2'!$A:$A,"<="&DATE(2026,9,7)) | GZ4: =COUNTIFS('DRAFT 2'!$D:$D,$B4,'DRAFT 2'!$A:$A,">="&DATE(2026,9,8),'DRAFT 2'!$A:$A,"<="&DATE(2026,9,14)) | HA4: =COUNTIFS('DRAFT 2'!$D:$D,$B4,'DRAFT 2'!$A:$A,">="&DATE(2026,9,15),'DRAFT 2'!$A:$A,"<="&DATE(2026,9,21)) | HB4: =COUNTIFS('DRAFT 2'!$D:$D,$B4,'DRAFT 2'!$A:$A,">="&DATE(2026,9,22),'DRAFT 2'!$A:$A,"<"&DATE(2026,IF(9=12,9+1,9+1),1)) | HC4: =SUM(GY4:HB4) | HD4: =AVERAGE(HK4,HZ4,IO4) | HE4: =IF(HF4=0,1,HG4/HF4) | HH4: =IF(HI4=0,1,HJ4/HI4) | HK4: =IF(HL4=0,1,HM4/HL4) | HN4: =IFERROR(LOOKUP(2,1/('DRAFT 2'!$D:$D=$B4)*('DRAFT 2'!$A:$A>=DATE(2026,10,1))*('DRAFT 2'!$A:$A<DATE(2026,IF(10=12,10+1,10+1),1)),'DRAFT 2'!$A:$A),"") | HO4: =COUNTIFS('DRAFT 2'!$D:$D,$B4,'DRAFT 2'!$A:$A,">="&DATE(2026,10,1),'DRAFT 2'!$A:$A,"<="&DATE(2026,10,7)) | HP4: =COUNTIFS('DRAFT 2'!$D:$D,$B4,'DRAFT 2'!$A:$A,">="&DATE(2026,10,8),'DRAFT 2'!$A:$A,"<="&DATE(2026,10,14)) | HQ4: =COUNTIFS('DRAFT 2'!$D:$D,$B4,'DRAFT 2'!$A:$A,">="&DATE(2026,10,15),'DRAFT 2'!$A:$A,"<="&DATE(2026,10,21)) | HR4: =COUNTIFS('DRAFT 2'!$D:$D,$B4,'DRAFT 2'!$A:$A,">="&DATE(2026,10,22),'DRAFT 2'!$A:$A,"<"&DATE(2026,IF(10=12,10+1,10+1),1)) | HS4: =SUM(HO4:HR4) | HT4: =IF(HU4=0,1,HV4/HU4) | HW4: =IF(HX4=0,1,HY4/HX4) | HZ4: =IF(IA4=0,1,IB4/IA4) | IC4: =IFERROR(LOOKUP(2,1/('DRAFT 2'!$D:$D=$B4)*('DRAFT 2'!$A:$A>=DATE(2026,11,1))*('DRAFT 2'!$A:$A<DATE(2026,IF(11=12,11+1,11+1),1)),'DRAFT 2'!$A:$A),"") | ID4: =COUNTIFS('DRAFT 2'!$D:$D,$B4,'DRAFT 2'!$A:$A,">="&DATE(2026,11,1),'DRAFT 2'!$A:$A,"<="&DATE(2026,11,7)) | IE4: =COUNTIFS('DRAFT 2'!$D:$D,$B4,'DRAFT 2'!$A:$A,">="&DATE(2026,11,8),'DRAFT 2'!$A:$A,"<="&DATE(2026,11,14)) | IF4: =COUNTIFS('DRAFT 2'!$D:$D,$B4,'DRAFT 2'!$A:$A,">="&DATE(2026,11,15),'DRAFT 2'!$A:$A,"<="&DATE(2026,11,21)) | IG4: =COUNTIFS('DRAFT 2'!$D:$D,$B4,'DRAFT 2'!$A:$A,">="&DATE(2026,11,22),'DRAFT 2'!$A:$A,"<"&DATE(2026,IF(11=12,11+1,11+1),1)) | IH4: =SUM(ID4:IG4) | II4: =IF(IJ4=0,1,IK4/IJ4) | IL4: =IF(IM4=0,1,IN4/IM4) | IO4: =IF(IP4=0,1,IQ4/IP4) | IR4: =IFERROR(LOOKUP(2,1/('DRAFT 2'!$D:$D=$B4)*('DRAFT 2'!$A:$A>=DATE(2026,12,1))*('DRAFT 2'!$A:$A<DATE(2026,IF(12=12,12+1,12+1),1)),'DRAFT 2'!$A:$A),"") | IS4: =COUNTIFS('DRAFT 2'!$D:$D,$B4,'DRAFT 2'!$A:$A,">="&DATE(2026,12,1),'DRAFT 2'!$A:$A,"<="&DATE(2026,12,7)) | IT4: =COUNTIFS('DRAFT 2'!$D:$D,$B4,'DRAFT 2'!$A:$A,">="&DATE(2026,12,8),'DRAFT 2'!$A:$A,"<="&DATE(2026,12,14)) | IU4: =COUNTIFS('DRAFT 2'!$D:$D,$B4,'DRAFT 2'!$A:$A,">="&DATE(2026,12,15),'DRAFT 2'!$A:$A,"<="&DATE(2026,12,21)) | IV4: =COUNTIFS('DRAFT 2'!$D:$D,$B4,'DRAFT 2'!$A:$A,">="&DATE(2026,12,22),'DRAFT 2'!$A:$A,"<"&DATE(2026,IF(12=12,12+1,12+1),1)) | IW4: =SUM(IS4:IV4)
A5: =IFERROR(INDEX('DRAFT 1'!$A:$A,MATCH($B5,'DRAFT 1'!$B:$B,0)),"") | B5: 41626544000140 | C5: =IFERROR(INDEX('DRAFT 1'!$C:$C,MATCH($B5,'DRAFT 1'!$B:$B,0)),"") | D5: =IFERROR(INDEX('DRAFT 1'!$D:$D,MATCH($B5,'DRAFT 1'!$B:$B,0)),"") | E5: =IFERROR(INDEX('DRAFT 1'!$E:$E,MATCH($B5,'DRAFT 1'!$B:$B,0)),"") | F5: =IFERROR(INDEX('DRAFT 1'!$F:$F,MATCH($B5,'DRAFT 1'!$B:$B,0)),"") | G5: =IFERROR(INDEX('DRAFT 1'!$G:$G,MATCH($B5,'DRAFT 1'!$B:$B,0)),"") | H5: =IFERROR(INDEX('DRAFT 1'!$H:$H,MATCH($B5,'DRAFT 1'!$B:$B,0)),"") | I5: FIT LAND | K5: =IFERROR(INDEX('DRAFT 1'!$AL:$AL,MATCH($B5,'DRAFT 1'!$B:$B,0)),"") | L5: =IFERROR(INDEX('DRAFT 1'!$J:$J,MATCH($B5,'DRAFT 1'!$B:$B,0)),"") | M5: =IFERROR(INDEX('DRAFT 1'!$K:$K,MATCH($B5,'DRAFT 1'!$B:$B,0)),"") | N5: EM RISCO | O5: =IF(N5="EM RISCO",1,IF(N5="INAT.REC",2,IF(N5="ATIVO",3,IF(N5="INAT.ANT",4,5)))) | P5: =IFERROR(INDEX('DRAFT 1'!$L:$L,MATCH($B5,'DRAFT 1'!$B:$B,0)),"") | Q5: =IFERROR(INDEX('DRAFT 1'!$M:$M,MATCH($B5,'DRAFT 1'!$B:$B,0)),"") | R5: =IFERROR(INDEX('DRAFT 1'!$N:$N,MATCH($B5,'DRAFT 1'!$B:$B,0)),"") | S5: =IFERROR(INDEX('DRAFT 1'!$O:$O,MATCH($B5,'DRAFT 1'!$B:$B,0)),"") | T5: =IFERROR(INDEX('DRAFT 1'!$P:$P,MATCH($B5,'DRAFT 1'!$B:$B,0)),"") | U5: =IFERROR(INDEX('DRAFT 1'!$Q:$Q,MATCH($B5,'DRAFT 1'!$B:$B,0)),"") | V5: =IFERROR(INDEX('DRAFT 1'!$R:$R,MATCH($B5,'DRAFT 1'!$B:$B,0)),"") | W5: =IFERROR(INDEX('DRAFT 1'!$S:$S,MATCH($B5,'DRAFT 1'!$B:$B,0)),"") | X5: =IFERROR(INDEX('DRAFT 1'!$T:$T,MATCH($B5,'DRAFT 1'!$B:$B,0)),"") | Y5: =SUM(Z5:AJ5) | Z5: =IFERROR(INDEX('DRAFT 1'!$U:$U,MATCH($B5,'DRAFT 1'!$B:$B,0)),"") | AA5: =IFERROR(INDEX('DRAFT 1'!$V:$V,MATCH($B5,'DRAFT 1'!$B:$B,0)),"") | AB5: =IFERROR(INDEX('DRAFT 1'!$W:$W,MATCH($B5,'DRAFT 1'!$B:$B,0)),"") | AC5: =IFERROR(INDEX('DRAFT 1'!$X:$X,MATCH($B5,'DRAFT 1'!$B:$B,0)),"") | AD5: =IFERROR(INDEX('DRAFT 1'!$Y:$Y,MATCH($B5,'DRAFT 1'!$B:$B,0)),"") | AE5: =IFERROR(INDEX('DRAFT 1'!$Z:$Z,MATCH($B5,'DRAFT 1'!$B:$B,0)),"") | AF5: =IFERROR(INDEX('DRAFT 1'!$AA:$AA,MATCH($B5,'DRAFT 1'!$B:$B,0)),"") | AG5: =IFERROR(INDEX('DRAFT 1'!$AB:$AB,MATCH($B5,'DRAFT 1'!$B:$B,0)),"") | AH5: =IFERROR(INDEX('DRAFT 1'!$AC:$AC,MATCH($B5,'DRAFT 1'!$B:$B,0)),"") | AI5: =IFERROR(INDEX('DRAFT 1'!$AD:$AD,MATCH($B5,'DRAFT 1'!$B:$B,0)),"") | AJ5: =IFERROR(INDEX('DRAFT 1'!$AE:$AE,MATCH($B5,'DRAFT 1'!$B:$B,0)),"") | AK5: =IFERROR(INDEX('DRAFT 1'!$AG:$AG,MATCH($B5,'DRAFT 1'!$B:$B,0)),"") | AL5: =IFERROR(INDEX('DRAFT 1'!$AH:$AH,MATCH($B5,'DRAFT 1'!$B:$B,0)),"") | AM5: =IFERROR(INDEX('DRAFT 1'!$AI:$AI,MATCH($B5,'DRAFT 1'!$B:$B,0)),"") | AN5: =IFERROR(INDEX('DRAFT 1'!$AJ:$AJ,MATCH($B5,'DRAFT 1'!$B:$B,0)),"") | AO5: =IFERROR(Y5/AN5,0) | AP5: =IFERROR(INDEX('DRAFT 1'!$AK:$AK,MATCH($B5,'DRAFT 1'!$B:$B,0)),"") | AR5: PÓS-VENDA | AS5: =IFERROR(LOOKUP(2,1/('DRAFT 2'!$D:$D=$B5),'DRAFT 2'!$T:$T),"") | AT5: =IFERROR(LOOKUP(2,1/('DRAFT 2'!$D:$D=$B5),'DRAFT 2'!$A:$A),"") | AU5: =IFERROR(LOOKUP(2,1/('DRAFT 2'!$D:$D=$B5),'DRAFT 2'!$R:$R),"") | AV5: =IFERROR(LOOKUP(2,1/('DRAFT 2'!$D:$D=$B5),'DRAFT 2'!$S:$S),"") | AW5: LEAD | AX5: =IFERROR(LOOKUP(2,1/('DRAFT 2'!$D:$D=$B5),'DRAFT 2'!$M:$M),"") | AY5: =IFERROR(LOOKUP(2,1/('DRAFT 2'!$D:$D=$B5),'DRAFT 2'!$K:$K),"") | BA5: =IF(N5="PROSPECT","❄️ FRIO",IF(OR(AR5="ORÇAMENTO",AR5="NEGOCIAÇÃO",AR5="CADASTRO"),"🔥 QUENTE",IF(OR(AR5="FOLLOW UP 7",AR5="FOLLOW UP 15",AR5="ATENDIMENTO"),"⚡ MORNO","❄️ FRIO"))) | BB5: =IF(BE5="","",BE5-BC5) | BG5: =IFERROR(LOOKUP(2,1/('DRAFT 2'!$D:$D=$B5),'DRAFT 2'!$U:$U),"") | BH5: =IFERROR(LOOKUP(2,1/('DRAFT 2'!$D:$D=$B5),'DRAFT 2'!$V:$V),"") | BI5: =IF(Q5="","🟣",IF(P5<=IF(AK5="",45,AK5),"🟢",IF(P5<=IF(AK5="",45,AK5)+30,"🟡","🔴"))) | BJ5: SAP002 | BU5: =CR5 | BV5: =AVERAGE(CC5,CR5,DG5) | BW5: =IF(BX5=0,1,BY5/BX5) | BZ5: =IF(CA5=0,1,CB5/CA5) | CC5: =IF(CD5=0,1,CE5/CD5) | CE5: =IFERROR(AJ5,0) | CF5: =IFERROR(LOOKUP(2,1/('DRAFT 2'!$D:$D=$B5)*('DRAFT 2'!$A:$A>=DATE(2026,1,1))*('DRAFT 2'!$A:$A<DATE(2026,IF(1=12,1+1,1+1),1)),'DRAFT 2'!$A:$A),"") | CG5: =COUNTIFS('DRAFT 2'!$D:$D,$B5,'DRAFT 2'!$A:$A,">="&DATE(2026,1,1),'DRAFT 2'!$A:$A,"<="&DATE(2026,1,7)) | CH5: =COUNTIFS('DRAFT 2'!$D:$D,$B5,'DRAFT 2'!$A:$A,">="&DATE(2026,1,8),'DRAFT 2'!$A:$A,"<="&DATE(2026,1,14)) | CI5: =COUNTIFS('DRAFT 2'!$D:$D,$B5,'DRAFT 2'!$A:$A,">="&DATE(2026,1,15),'DRAFT 2'!$A:$A,"<="&DATE(2026,1,21)) | CJ5: =COUNTIFS('DRAFT 2'!$D:$D,$B5,'DRAFT 2'!$A:$A,">="&DATE(2026,1,22),'DRAFT 2'!$A:$A,"<"&DATE(2026,IF(1=12,1+1,1+1),1)) | CK5: =SUM(CG5:CJ5) | CL5: =IF(CM5=0,1,CN5/CM5) | CO5: =IF(CP5=0,1,CQ5/CP5) | CR5: =IF(CS5=0,1,CT5/CS5) | CT5: 0 | CU5: =IFERROR(LOOKUP(2,1/('DRAFT 2'!$D:$D=$B5)*('DRAFT 2'!$A:$A>=DATE(2026,2,1))*('DRAFT 2'!$A:$A<DATE(2026,IF(2=12,2+1,2+1),1)),'DRAFT 2'!$A:$A),"") | CV5: =COUNTIFS('DRAFT 2'!$D:$D,$B5,'DRAFT 2'!$A:$A,">="&DATE(2026,2,1),'DRAFT 2'!$A:$A,"<="&DATE(2026,2,7)) | CW5: =COUNTIFS('DRAFT 2'!$D:$D,$B5,'DRAFT 2'!$A:$A,">="&DATE(2026,2,8),'DRAFT 2'!$A:$A,"<="&DATE(2026,2,14)) | CX5: =COUNTIFS('DRAFT 2'!$D:$D,$B5,'DRAFT 2'!$A:$A,">="&DATE(2026,2,15),'DRAFT 2'!$A:$A,"<="&DATE(2026,2,21)) | CY5: =COUNTIFS('DRAFT 2'!$D:$D,$B5,'DRAFT 2'!$A:$A,">="&DATE(2026,2,22),'DRAFT 2'!$A:$A,"<"&DATE(2026,IF(2=12,2+1,2+1),1)) | CZ5: =SUM(CV5:CY5) | DA5: =IF(DB5=0,1,DC5/DB5) | DD5: =IF(DE5=0,1,DF5/DE5) | DG5: =IF(DH5=0,1,DI5/DH5) | DJ5: =IFERROR(LOOKUP(2,1/('DRAFT 2'!$D:$D=$B5)*('DRAFT 2'!$A:$A>=DATE(2026,3,1))*('DRAFT 2'!$A:$A<DATE(2026,IF(3=12,3+1,3+1),1)),'DRAFT 2'!$A:$A),"") | DK5: =COUNTIFS('DRAFT 2'!$D:$D,$B5,'DRAFT 2'!$A:$A,">="&DATE(2026,3,1),'DRAFT 2'!$A:$A,"<="&DATE(2026,3,7)) | DL5: =COUNTIFS('DRAFT 2'!$D:$D,$B5,'DRAFT 2'!$A:$A,">="&DATE(2026,3,8),'DRAFT 2'!$A:$A,"<="&DATE(2026,3,14)) | DM5: =COUNTIFS('DRAFT 2'!$D:$D,$B5,'DRAFT 2'!$A:$A,">="&DATE(2026,3,15),'DRAFT 2'!$A:$A,"<="&DATE(2026,3,21)) | DN5: =COUNTIFS('DRAFT 2'!$D:$D,$B5,'DRAFT 2'!$A:$A,">="&DATE(2026,3,22),'DRAFT 2'!$A:$A,"<"&DATE(2026,IF(3=12,3+1,3+1),1)) | DO5: =SUM(DK5:DN5) | DP5: =AVERAGE(DW5,EL5,FA5) | DQ5: =IF(DR5=0,1,DS5/DR5) | DT5: =IF(DU5=0,1,DV5/DU5) | DW5: =IF(DX5=0,1,DY5/DX5) | DZ5: =IFERROR(LOOKUP(2,1/('DRAFT 2'!$D:$D=$B5)*('DRAFT 2'!$A:$A>=DATE(2026,4,1))*('DRAFT 2'!$A:$A<DATE(2026,IF(4=12,4+1,4+1),1)),'DRAFT 2'!$A:$A),"") | EA5: =COUNTIFS('DRAFT 2'!$D:$D,$B5,'DRAFT 2'!$A:$A,">="&DATE(2026,4,1),'DRAFT 2'!$A:$A,"<="&DATE(2026,4,7)) | EB5: =COUNTIFS('DRAFT 2'!$D:$D,$B5,'DRAFT 2'!$A:$A,">="&DATE(2026,4,8),'DRAFT 2'!$A:$A,"<="&DATE(2026,4,14)) | EC5: =COUNTIFS('DRAFT 2'!$D:$D,$B5,'DRAFT 2'!$A:$A,">="&DATE(2026,4,15),'DRAFT 2'!$A:$A,"<="&DATE(2026,4,21)) | ED5: =COUNTIFS('DRAFT 2'!$D:$D,$B5,'DRAFT 2'!$A:$A,">="&DATE(2026,4,22),'DRAFT 2'!$A:$A,"<"&DATE(2026,IF(4=12,4+1,4+1),1)) | EE5: =SUM(EA5:ED5) | EF5: =IF(EG5=0,1,EH5/EG5) | EI5: =IF(EJ5=0,1,EK5/EJ5) | EL5: =IF(EM5=0,1,EN5/EM5) | EO5: =IFERROR(LOOKUP(2,1/('DRAFT 2'!$D:$D=$B5)*('DRAFT 2'!$A:$A>=DATE(2026,5,1))*('DRAFT 2'!$A:$A<DATE(2026,IF(5=12,5+1,5+1),1)),'DRAFT 2'!$A:$A),"") | EP5: =COUNTIFS('DRAFT 2'!$D:$D,$B5,'DRAFT 2'!$A:$A,">="&DATE(2026,5,1),'DRAFT 2'!$A:$A,"<="&DATE(2026,5,7)) | EQ5: =COUNTIFS('DRAFT 2'!$D:$D,$B5,'DRAFT 2'!$A:$A,">="&DATE(2026,5,8),'DRAFT 2'!$A:$A,"<="&DATE(2026,5,14)) | ER5: =COUNTIFS('DRAFT 2'!$D:$D,$B5,'DRAFT 2'!$A:$A,">="&DATE(2026,5,15),'DRAFT 2'!$A:$A,"<="&DATE(2026,5,21)) | ES5: =COUNTIFS('DRAFT 2'!$D:$D,$B5,'DRAFT 2'!$A:$A,">="&DATE(2026,5,22),'DRAFT 2'!$A:$A,"<"&DATE(2026,IF(5=12,5+1,5+1),1)) | ET5: =SUM(EP5:ES5) | EU5: =IF(EV5=0,1,EW5/EV5) | EX5: =IF(EY5=0,1,EZ5/EY5) | FA5: =IF(FB5=0,1,FC5/FB5) | FD5: =IFERROR(LOOKUP(2,1/('DRAFT 2'!$D:$D=$B5)*('DRAFT 2'!$A:$A>=DATE(2026,6,1))*('DRAFT 2'!$A:$A<DATE(2026,IF(6=12,6+1,6+1),1)),'DRAFT 2'!$A:$A),"") | FE5: =COUNTIFS('DRAFT 2'!$D:$D,$B5,'DRAFT 2'!$A:$A,">="&DATE(2026,6,1),'DRAFT 2'!$A:$A,"<="&DATE(2026,6,7)) | FF5: =COUNTIFS('DRAFT 2'!$D:$D,$B5,'DRAFT 2'!$A:$A,">="&DATE(2026,6,8),'DRAFT 2'!$A:$A,"<="&DATE(2026,6,14)) | FG5: =COUNTIFS('DRAFT 2'!$D:$D,$B5,'DRAFT 2'!$A:$A,">="&DATE(2026,6,15),'DRAFT 2'!$A:$A,"<="&DATE(2026,6,21)) | FH5: =COUNTIFS('DRAFT 2'!$D:$D,$B5,'DRAFT 2'!$A:$A,">="&DATE(2026,6,22),'DRAFT 2'!$A:$A,"<"&DATE(2026,IF(6=12,6+1,6+1),1)) | FI5: =SUM(FE5:FH5) | FJ5: =AVERAGE(FQ5,GF5,GU5) | FK5: =IF(FL5=0,1,FM5/FL5) | FN5: =IF(FO5=0,1,FP5/FO5) | FQ5: =IF(FR5=0,1,FS5/FR5) | FT5: =IFERROR(LOOKUP(2,1/('DRAFT 2'!$D:$D=$B5)*('DRAFT 2'!$A:$A>=DATE(2026,7,1))*('DRAFT 2'!$A:$A<DATE(2026,IF(7=12,7+1,7+1),1)),'DRAFT 2'!$A:$A),"") | FU5: =COUNTIFS('DRAFT 2'!$D:$D,$B5,'DRAFT 2'!$A:$A,">="&DATE(2026,7,1),'DRAFT 2'!$A:$A,"<="&DATE(2026,7,7)) | FV5: =COUNTIFS('DRAFT 2'!$D:$D,$B5,'DRAFT 2'!$A:$A,">="&DATE(2026,7,8),'DRAFT 2'!$A:$A,"<="&DATE(2026,7,14)) | FW5: =COUNTIFS('DRAFT 2'!$D:$D,$B5,'DRAFT 2'!$A:$A,">="&DATE(2026,7,15),'DRAFT 2'!$A:$A,"<="&DATE(2026,7,21)) | FX5: =COUNTIFS('DRAFT 2'!$D:$D,$B5,'DRAFT 2'!$A:$A,">="&DATE(2026,7,22),'DRAFT 2'!$A:$A,"<"&DATE(2026,IF(7=12,7+1,7+1),1)) | FY5: =SUM(FU5:FX5) | FZ5: =IF(GA5=0,1,GB5/GA5) | GC5: =IF(GD5=0,1,GE5/GD5) | GF5: =IF(GG5=0,1,GH5/GG5) | GI5: =IFERROR(LOOKUP(2,1/('DRAFT 2'!$D:$D=$B5)*('DRAFT 2'!$A:$A>=DATE(2026,8,1))*('DRAFT 2'!$A:$A<DATE(2026,IF(8=12,8+1,8+1),1)),'DRAFT 2'!$A:$A),"") | GJ5: =COUNTIFS('DRAFT 2'!$D:$D,$B5,'DRAFT 2'!$A:$A,">="&DATE(2026,8,1),'DRAFT 2'!$A:$A,"<="&DATE(2026,8,7)) | GK5: =COUNTIFS('DRAFT 2'!$D:$D,$B5,'DRAFT 2'!$A:$A,">="&DATE(2026,8,8),'DRAFT 2'!$A:$A,"<="&DATE(2026,8,14)) | GL5: =COUNTIFS('DRAFT 2'!$D:$D,$B5,'DRAFT 2'!$A:$A,">="&DATE(2026,8,15),'DRAFT 2'!$A:$A,"<="&DATE(2026,8,21)) | GM5: =COUNTIFS('DRAFT 2'!$D:$D,$B5,'DRAFT 2'!$A:$A,">="&DATE(2026,8,22),'DRAFT 2'!$A:$A,"<"&DATE(2026,IF(8=12,8+1,8+1),1)) | GN5: =SUM(GJ5:GM5) | GO5: =IF(GP5=0,1,GQ5/GP5) | GR5: =IF(GS5=0,1,GT5/GS5) | GU5: =IF(GV5=0,1,GW5/GV5) | GX5: =IFERROR(LOOKUP(2,1/('DRAFT 2'!$D:$D=$B5)*('DRAFT 2'!$A:$A>=DATE(2026,9,1))*('DRAFT 2'!$A:$A<DATE(2026,IF(9=12,9+1,9+1),1)),'DRAFT 2'!$A:$A),"") | GY5: =COUNTIFS('DRAFT 2'!$D:$D,$B5,'DRAFT 2'!$A:$A,">="&DATE(2026,9,1),'DRAFT 2'!$A:$A,"<="&DATE(2026,9,7)) | GZ5: =COUNTIFS('DRAFT 2'!$D:$D,$B5,'DRAFT 2'!$A:$A,">="&DATE(2026,9,8),'DRAFT 2'!$A:$A,"<="&DATE(2026,9,14)) | HA5: =COUNTIFS('DRAFT 2'!$D:$D,$B5,'DRAFT 2'!$A:$A,">="&DATE(2026,9,15),'DRAFT 2'!$A:$A,"<="&DATE(2026,9,21)) | HB5: =COUNTIFS('DRAFT 2'!$D:$D,$B5,'DRAFT 2'!$A:$A,">="&DATE(2026,9,22),'DRAFT 2'!$A:$A,"<"&DATE(2026,IF(9=12,9+1,9+1),1)) | HC5: =SUM(GY5:HB5) | HD5: =AVERAGE(HK5,HZ5,IO5) | HE5: =IF(HF5=0,1,HG5/HF5) | HH5: =IF(HI5=0,1,HJ5/HI5) | HK5: =IF(HL5=0,1,HM5/HL5) | HN5: =IFERROR(LOOKUP(2,1/('DRAFT 2'!$D:$D=$B5)*('DRAFT 2'!$A:$A>=DATE(2026,10,1))*('DRAFT 2'!$A:$A<DATE(2026,IF(10=12,10+1,10+1),1)),'DRAFT 2'!$A:$A),"") | HO5: =COUNTIFS('DRAFT 2'!$D:$D,$B5,'DRAFT 2'!$A:$A,">="&DATE(2026,10,1),'DRAFT 2'!$A:$A,"<="&DATE(2026,10,7)) | HP5: =COUNTIFS('DRAFT 2'!$D:$D,$B5,'DRAFT 2'!$A:$A,">="&DATE(2026,10,8),'DRAFT 2'!$A:$A,"<="&DATE(2026,10,14)) | HQ5: =COUNTIFS('DRAFT 2'!$D:$D,$B5,'DRAFT 2'!$A:$A,">="&DATE(2026,10,15),'DRAFT 2'!$A:$A,"<="&DATE(2026,10,21)) | HR5: =COUNTIFS('DRAFT 2'!$D:$D,$B5,'DRAFT 2'!$A:$A,">="&DATE(2026,10,22),'DRAFT 2'!$A:$A,"<"&DATE(2026,IF(10=12,10+1,10+1),1)) | HS5: =SUM(HO5:HR5) | HT5: =IF(HU5=0,1,HV5/HU5) | HW5: =IF(HX5=0,1,HY5/HX5) | HZ5: =IF(IA5=0,1,IB5/IA5) | IC5: =IFERROR(LOOKUP(2,1/('DRAFT 2'!$D:$D=$B5)*('DRAFT 2'!$A:$A>=DATE(2026,11,1))*('DRAFT 2'!$A:$A<DATE(2026,IF(11=12,11+1,11+1),1)),'DRAFT 2'!$A:$A),"") | ID5: =COUNTIFS('DRAFT 2'!$D:$D,$B5,'DRAFT 2'!$A:$A,">="&DATE(2026,11,1),'DRAFT 2'!$A:$A,"<="&DATE(2026,11,7)) | IE5: =COUNTIFS('DRAFT 2'!$D:$D,$B5,'DRAFT 2'!$A:$A,">="&DATE(2026,11,8),'DRAFT 2'!$A:$A,"<="&DATE(2026,11,14)) | IF5: =COUNTIFS('DRAFT 2'!$D:$D,$B5,'DRAFT 2'!$A:$A,">="&DATE(2026,11,15),'DRAFT 2'!$A:$A,"<="&DATE(2026,11,21)) | IG5: =COUNTIFS('DRAFT 2'!$D:$D,$B5,'DRAFT 2'!$A:$A,">="&DATE(2026,11,22),'DRAFT 2'!$A:$A,"<"&DATE(2026,IF(11=12,11+1,11+1),1)) | IH5: =SUM(ID5:IG5) | II5: =IF(IJ5=0,1,IK5/IJ5) | IL5: =IF(IM5=0,1,IN5/IM5) | IO5: =IF(IP5=0,1,IQ5/IP5) | IR5: =IFERROR(LOOKUP(2,1/('DRAFT 2'!$D:$D=$B5)*('DRAFT 2'!$A:$A>=DATE(2026,12,1))*('DRAFT 2'!$A:$A<DATE(2026,IF(12=12,12+1,12+1),1)),'DRAFT 2'!$A:$A),"") | IS5: =COUNTIFS('DRAFT 2'!$D:$D,$B5,'DRAFT 2'!$A:$A,">="&DATE(2026,12,1),'DRAFT 2'!$A:$A,"<="&DATE(2026,12,7)) | IT5: =COUNTIFS('DRAFT 2'!$D:$D,$B5,'DRAFT 2'!$A:$A,">="&DATE(2026,12,8),'DRAFT 2'!$A:$A,"<="&DATE(2026,12,14)) | IU5: =COUNTIFS('DRAFT 2'!$D:$D,$B5,'DRAFT 2'!$A:$A,">="&DATE(2026,12,15),'DRAFT 2'!$A:$A,"<="&DATE(2026,12,21)) | IV5: =COUNTIFS('DRAFT 2'!$D:$D,$B5,'DRAFT 2'!$A:$A,">="&DATE(2026,12,22),'DRAFT 2'!$A:$A,"<"&DATE(2026,IF(12=12,12+1,12+1),1)) | IW5: =SUM(IS5:IV5)
A6: =IFERROR(INDEX('DRAFT 1'!$A:$A,MATCH($B6,'DRAFT 1'!$B:$B,0)),"") | B6: 12345678000199 | C6: =IFERROR(INDEX('DRAFT 1'!$C:$C,MATCH($B6,'DRAFT 1'!$B:$B,0)),"") | D6: =IFERROR(INDEX('DRAFT 1'!$D:$D,MATCH($B6,'DRAFT 1'!$B:$B,0)),"") | E6: =IFERROR(INDEX('DRAFT 1'!$E:$E,MATCH($B6,'DRAFT 1'!$B:$B,0)),"") | F6: =IFERROR(INDEX('DRAFT 1'!$F:$F,MATCH($B6,'DRAFT 1'!$B:$B,0)),"") | G6: =IFERROR(INDEX('DRAFT 1'!$G:$G,MATCH($B6,'DRAFT 1'!$B:$B,0)),"") | H6: =IFERROR(INDEX('DRAFT 1'!$H:$H,MATCH($B6,'DRAFT 1'!$B:$B,0)),"") | I6: BIOMUNDO | K6: =IFERROR(INDEX('DRAFT 1'!$AL:$AL,MATCH($B6,'DRAFT 1'!$B:$B,0)),"") | L6: =IFERROR(INDEX('DRAFT 1'!$J:$J,MATCH($B6,'DRAFT 1'!$B:$B,0)),"") | M6: =IFERROR(INDEX('DRAFT 1'!$K:$K,MATCH($B6,'DRAFT 1'!$B:$B,0)),"") | N6: INAT.ANT | O6: =IF(N6="EM RISCO",1,IF(N6="INAT.REC",2,IF(N6="ATIVO",3,IF(N6="INAT.ANT",4,5)))) | P6: =IFERROR(INDEX('DRAFT 1'!$L:$L,MATCH($B6,'DRAFT 1'!$B:$B,0)),"") | Q6: =IFERROR(INDEX('DRAFT 1'!$M:$M,MATCH($B6,'DRAFT 1'!$B:$B,0)),"") | R6: =IFERROR(INDEX('DRAFT 1'!$N:$N,MATCH($B6,'DRAFT 1'!$B:$B,0)),"") | S6: =IFERROR(INDEX('DRAFT 1'!$O:$O,MATCH($B6,'DRAFT 1'!$B:$B,0)),"") | T6: =IFERROR(INDEX('DRAFT 1'!$P:$P,MATCH($B6,'DRAFT 1'!$B:$B,0)),"") | U6: =IFERROR(INDEX('DRAFT 1'!$Q:$Q,MATCH($B6,'DRAFT 1'!$B:$B,0)),"") | V6: =IFERROR(INDEX('DRAFT 1'!$R:$R,MATCH($B6,'DRAFT 1'!$B:$B,0)),"") | W6: =IFERROR(INDEX('DRAFT 1'!$S:$S,MATCH($B6,'DRAFT 1'!$B:$B,0)),"") | X6: =IFERROR(INDEX('DRAFT 1'!$T:$T,MATCH($B6,'DRAFT 1'!$B:$B,0)),"") | Y6: =SUM(Z6:AJ6) | Z6: =IFERROR(INDEX('DRAFT 1'!$U:$U,MATCH($B6,'DRAFT 1'!$B:$B,0)),"") | AA6: =IFERROR(INDEX('DRAFT 1'!$V:$V,MATCH($B6,'DRAFT 1'!$B:$B,0)),"") | AB6: =IFERROR(INDEX('DRAFT 1'!$W:$W,MATCH($B6,'DRAFT 1'!$B:$B,0)),"") | AC6: =IFERROR(INDEX('DRAFT 1'!$X:$X,MATCH($B6,'DRAFT 1'!$B:$B,0)),"") | AD6: =IFERROR(INDEX('DRAFT 1'!$Y:$Y,MATCH($B6,'DRAFT 1'!$B:$B,0)),"") | AE6: =IFERROR(INDEX('DRAFT 1'!$Z:$Z,MATCH($B6,'DRAFT 1'!$B:$B,0)),"") | AF6: =IFERROR(INDEX('DRAFT 1'!$AA:$AA,MATCH($B6,'DRAFT 1'!$B:$B,0)),"") | AG6: =IFERROR(INDEX('DRAFT 1'!$AB:$AB,MATCH($B6,'DRAFT 1'!$B:$B,0)),"") | AH6: =IFERROR(INDEX('DRAFT 1'!$AC:$AC,MATCH($B6,'DRAFT 1'!$B:$B,0)),"") | AI6: =IFERROR(INDEX('DRAFT 1'!$AD:$AD,MATCH($B6,'DRAFT 1'!$B:$B,0)),"") | AJ6: =IFERROR(INDEX('DRAFT 1'!$AE:$AE,MATCH($B6,'DRAFT 1'!$B:$B,0)),"") | AK6: =IFERROR(INDEX('DRAFT 1'!$AG:$AG,MATCH($B6,'DRAFT 1'!$B:$B,0)),"") | AL6: =IFERROR(INDEX('DRAFT 1'!$AH:$AH,MATCH($B6,'DRAFT 1'!$B:$B,0)),"") | AM6: =IFERROR(INDEX('DRAFT 1'!$AI:$AI,MATCH($B6,'DRAFT 1'!$B:$B,0)),"") | AN6: =IFERROR(INDEX('DRAFT 1'!$AJ:$AJ,MATCH($B6,'DRAFT 1'!$B:$B,0)),"") | AO6: =IFERROR(Y6/AN6,0) | AP6: =IFERROR(INDEX('DRAFT 1'!$AK:$AK,MATCH($B6,'DRAFT 1'!$B:$B,0)),"") | AR6: EM ATENDIMENTO | AS6: =IFERROR(LOOKUP(2,1/('DRAFT 2'!$D:$D=$B6),'DRAFT 2'!$T:$T),"") | AT6: =IFERROR(LOOKUP(2,1/('DRAFT 2'!$D:$D=$B6),'DRAFT 2'!$A:$A),"") | AU6: =IFERROR(LOOKUP(2,1/('DRAFT 2'!$D:$D=$B6),'DRAFT 2'!$R:$R),"") | AV6: =IFERROR(LOOKUP(2,1/('DRAFT 2'!$D:$D=$B6),'DRAFT 2'!$S:$S),"") | AW6: LEAD | AX6: =IFERROR(LOOKUP(2,1/('DRAFT 2'!$D:$D=$B6),'DRAFT 2'!$M:$M),"") | AY6: =IFERROR(LOOKUP(2,1/('DRAFT 2'!$D:$D=$B6),'DRAFT 2'!$K:$K),"") | BA6: =IF(N6="PROSPECT","❄️ FRIO",IF(OR(AR6="ORÇAMENTO",AR6="NEGOCIAÇÃO",AR6="CADASTRO"),"🔥 QUENTE",IF(OR(AR6="FOLLOW UP 7",AR6="FOLLOW UP 15",AR6="ATENDIMENTO"),"⚡ MORNO","❄️ FRIO"))) | BB6: =IF(BE6="","",BE6-BC6) | BG6: =IFERROR(LOOKUP(2,1/('DRAFT 2'!$D:$D=$B6),'DRAFT 2'!$U:$U),"") | BH6: =IFERROR(LOOKUP(2,1/('DRAFT 2'!$D:$D=$B6),'DRAFT 2'!$V:$V),"") | BI6: =IF(Q6="","🟣",IF(P6<=IF(AK6="",45,AK6),"🟢",IF(P6<=IF(AK6="",45,AK6)+30,"🟡","🔴"))) | BJ6: SAP003 | BU6: =CR6 | BV6: =AVERAGE(CC6,CR6,DG6) | BW6: =IF(BX6=0,1,BY6/BX6) | BZ6: =IF(CA6=0,1,CB6/CA6) | CC6: =IF(CD6=0,1,CE6/CD6) | CE6: =IFERROR(AJ6,0) | CF6: =IFERROR(LOOKUP(2,1/('DRAFT 2'!$D:$D=$B6)*('DRAFT 2'!$A:$A>=DATE(2026,1,1))*('DRAFT 2'!$A:$A<DATE(2026,IF(1=12,1+1,1+1),1)),'DRAFT 2'!$A:$A),"") | CG6: =COUNTIFS('DRAFT 2'!$D:$D,$B6,'DRAFT 2'!$A:$A,">="&DATE(2026,1,1),'DRAFT 2'!$A:$A,"<="&DATE(2026,1,7)) | CH6: =COUNTIFS('DRAFT 2'!$D:$D,$B6,'DRAFT 2'!$A:$A,">="&DATE(2026,1,8),'DRAFT 2'!$A:$A,"<="&DATE(2026,1,14)) | CI6: =COUNTIFS('DRAFT 2'!$D:$D,$B6,'DRAFT 2'!$A:$A,">="&DATE(2026,1,15),'DRAFT 2'!$A:$A,"<="&DATE(2026,1,21)) | CJ6: =COUNTIFS('DRAFT 2'!$D:$D,$B6,'DRAFT 2'!$A:$A,">="&DATE(2026,1,22),'DRAFT 2'!$A:$A,"<"&DATE(2026,IF(1=12,1+1,1+1),1)) | CK6: =SUM(CG6:CJ6) | CL6: =IF(CM6=0,1,CN6/CM6) | CO6: =IF(CP6=0,1,CQ6/CP6) | CR6: =IF(CS6=0,1,CT6/CS6) | CT6: 0 | CU6: =IFERROR(LOOKUP(2,1/('DRAFT 2'!$D:$D=$B6)*('DRAFT 2'!$A:$A>=DATE(2026,2,1))*('DRAFT 2'!$A:$A<DATE(2026,IF(2=12,2+1,2+1),1)),'DRAFT 2'!$A:$A),"") | CV6: =COUNTIFS('DRAFT 2'!$D:$D,$B6,'DRAFT 2'!$A:$A,">="&DATE(2026,2,1),'DRAFT 2'!$A:$A,"<="&DATE(2026,2,7)) | CW6: =COUNTIFS('DRAFT 2'!$D:$D,$B6,'DRAFT 2'!$A:$A,">="&DATE(2026,2,8),'DRAFT 2'!$A:$A,"<="&DATE(2026,2,14)) | CX6: =COUNTIFS('DRAFT 2'!$D:$D,$B6,'DRAFT 2'!$A:$A,">="&DATE(2026,2,15),'DRAFT 2'!$A:$A,"<="&DATE(2026,2,21)) | CY6: =COUNTIFS('DRAFT 2'!$D:$D,$B6,'DRAFT 2'!$A:$A,">="&DATE(2026,2,22),'DRAFT 2'!$A:$A,"<"&DATE(2026,IF(2=12,2+1,2+1),1)) | CZ6: =SUM(CV6:CY6) | DA6: =IF(DB6=0,1,DC6/DB6) | DD6: =IF(DE6=0,1,DF6/DE6) | DG6: =IF(DH6=0,1,DI6/DH6) | DJ6: =IFERROR(LOOKUP(2,1/('DRAFT 2'!$D:$D=$B6)*('DRAFT 2'!$A:$A>=DATE(2026,3,1))*('DRAFT 2'!$A:$A<DATE(2026,IF(3=12,3+1,3+1),1)),'DRAFT 2'!$A:$A),"") | DK6: =COUNTIFS('DRAFT 2'!$D:$D,$B6,'DRAFT 2'!$A:$A,">="&DATE(2026,3,1),'DRAFT 2'!$A:$A,"<="&DATE(2026,3,7)) | DL6: =COUNTIFS('DRAFT 2'!$D:$D,$B6,'DRAFT 2'!$A:$A,">="&DATE(2026,3,8),'DRAFT 2'!$A:$A,"<="&DATE(2026,3,14)) | DM6: =COUNTIFS('DRAFT 2'!$D:$D,$B6,'DRAFT 2'!$A:$A,">="&DATE(2026,3,15),'DRAFT 2'!$A:$A,"<="&DATE(2026,3,21)) | DN6: =COUNTIFS('DRAFT 2'!$D:$D,$B6,'DRAFT 2'!$A:$A,">="&DATE(2026,3,22),'DRAFT 2'!$A:$A,"<"&DATE(2026,IF(3=12,3+1,3+1),1)) | DO6: =SUM(DK6:DN6) | DP6: =AVERAGE(DW6,EL6,FA6) | DQ6: =IF(DR6=0,1,DS6/DR6) | DT6: =IF(DU6=0,1,DV6/DU6) | DW6: =IF(DX6=0,1,DY6/DX6) | DZ6: =IFERROR(LOOKUP(2,1/('DRAFT 2'!$D:$D=$B6)*('DRAFT 2'!$A:$A>=DATE(2026,4,1))*('DRAFT 2'!$A:$A<DATE(2026,IF(4=12,4+1,4+1),1)),'DRAFT 2'!$A:$A),"") | EA6: =COUNTIFS('DRAFT 2'!$D:$D,$B6,'DRAFT 2'!$A:$A,">="&DATE(2026,4,1),'DRAFT 2'!$A:$A,"<="&DATE(2026,4,7)) | EB6: =COUNTIFS('DRAFT 2'!$D:$D,$B6,'DRAFT 2'!$A:$A,">="&DATE(2026,4,8),'DRAFT 2'!$A:$A,"<="&DATE(2026,4,14)) | EC6: =COUNTIFS('DRAFT 2'!$D:$D,$B6,'DRAFT 2'!$A:$A,">="&DATE(2026,4,15),'DRAFT 2'!$A:$A,"<="&DATE(2026,4,21)) | ED6: =COUNTIFS('DRAFT 2'!$D:$D,$B6,'DRAFT 2'!$A:$A,">="&DATE(2026,4,22),'DRAFT 2'!$A:$A,"<"&DATE(2026,IF(4=12,4+1,4+1),1)) | EE6: =SUM(EA6:ED6) | EF6: =IF(EG6=0,1,EH6/EG6) | EI6: =IF(EJ6=0,1,EK6/EJ6) | EL6: =IF(EM6=0,1,EN6/EM6) | EO6: =IFERROR(LOOKUP(2,1/('DRAFT 2'!$D:$D=$B6)*('DRAFT 2'!$A:$A>=DATE(2026,5,1))*('DRAFT 2'!$A:$A<DATE(2026,IF(5=12,5+1,5+1),1)),'DRAFT 2'!$A:$A),"") | EP6: =COUNTIFS('DRAFT 2'!$D:$D,$B6,'DRAFT 2'!$A:$A,">="&DATE(2026,5,1),'DRAFT 2'!$A:$A,"<="&DATE(2026,5,7)) | EQ6: =COUNTIFS('DRAFT 2'!$D:$D,$B6,'DRAFT 2'!$A:$A,">="&DATE(2026,5,8),'DRAFT 2'!$A:$A,"<="&DATE(2026,5,14)) | ER6: =COUNTIFS('DRAFT 2'!$D:$D,$B6,'DRAFT 2'!$A:$A,">="&DATE(2026,5,15),'DRAFT 2'!$A:$A,"<="&DATE(2026,5,21)) | ES6: =COUNTIFS('DRAFT 2'!$D:$D,$B6,'DRAFT 2'!$A:$A,">="&DATE(2026,5,22),'DRAFT 2'!$A:$A,"<"&DATE(2026,IF(5=12,5+1,5+1),1)) | ET6: =SUM(EP6:ES6) | EU6: =IF(EV6=0,1,EW6/EV6) | EX6: =IF(EY6=0,1,EZ6/EY6) | FA6: =IF(FB6=0,1,FC6/FB6) | FD6: =IFERROR(LOOKUP(2,1/('DRAFT 2'!$D:$D=$B6)*('DRAFT 2'!$A:$A>=DATE(2026,6,1))*('DRAFT 2'!$A:$A<DATE(2026,IF(6=12,6+1,6+1),1)),'DRAFT 2'!$A:$A),"") | FE6: =COUNTIFS('DRAFT 2'!$D:$D,$B6,'DRAFT 2'!$A:$A,">="&DATE(2026,6,1),'DRAFT 2'!$A:$A,"<="&DATE(2026,6,7)) | FF6: =COUNTIFS('DRAFT 2'!$D:$D,$B6,'DRAFT 2'!$A:$A,">="&DATE(2026,6,8),'DRAFT 2'!$A:$A,"<="&DATE(2026,6,14)) | FG6: =COUNTIFS('DRAFT 2'!$D:$D,$B6,'DRAFT 2'!$A:$A,">="&DATE(2026,6,15),'DRAFT 2'!$A:$A,"<="&DATE(2026,6,21)) | FH6: =COUNTIFS('DRAFT 2'!$D:$D,$B6,'DRAFT 2'!$A:$A,">="&DATE(2026,6,22),'DRAFT 2'!$A:$A,"<"&DATE(2026,IF(6=12,6+1,6+1),1)) | FI6: =SUM(FE6:FH6) | FJ6: =AVERAGE(FQ6,GF6,GU6) | FK6: =IF(FL6=0,1,FM6/FL6) | FN6: =IF(FO6=0,1,FP6/FO6) | FQ6: =IF(FR6=0,1,FS6/FR6) | FT6: =IFERROR(LOOKUP(2,1/('DRAFT 2'!$D:$D=$B6)*('DRAFT 2'!$A:$A>=DATE(2026,7,1))*('DRAFT 2'!$A:$A<DATE(2026,IF(7=12,7+1,7+1),1)),'DRAFT 2'!$A:$A),"") | FU6: =COUNTIFS('DRAFT 2'!$D:$D,$B6,'DRAFT 2'!$A:$A,">="&DATE(2026,7,1),'DRAFT 2'!$A:$A,"<="&DATE(2026,7,7)) | FV6: =COUNTIFS('DRAFT 2'!$D:$D,$B6,'DRAFT 2'!$A:$A,">="&DATE(2026,7,8),'DRAFT 2'!$A:$A,"<="&DATE(2026,7,14)) | FW6: =COUNTIFS('DRAFT 2'!$D:$D,$B6,'DRAFT 2'!$A:$A,">="&DATE(2026,7,15),'DRAFT 2'!$A:$A,"<="&DATE(2026,7,21)) | FX6: =COUNTIFS('DRAFT 2'!$D:$D,$B6,'DRAFT 2'!$A:$A,">="&DATE(2026,7,22),'DRAFT 2'!$A:$A,"<"&DATE(2026,IF(7=12,7+1,7+1),1)) | FY6: =SUM(FU6:FX6) | FZ6: =IF(GA6=0,1,GB6/GA6) | GC6: =IF(GD6=0,1,GE6/GD6) | GF6: =IF(GG6=0,1,GH6/GG6) | GI6: =IFERROR(LOOKUP(2,1/('DRAFT 2'!$D:$D=$B6)*('DRAFT 2'!$A:$A>=DATE(2026,8,1))*('DRAFT 2'!$A:$A<DATE(2026,IF(8=12,8+1,8+1),1)),'DRAFT 2'!$A:$A),"") | GJ6: =COUNTIFS('DRAFT 2'!$D:$D,$B6,'DRAFT 2'!$A:$A,">="&DATE(2026,8,1),'DRAFT 2'!$A:$A,"<="&DATE(2026,8,7)) | GK6: =COUNTIFS('DRAFT 2'!$D:$D,$B6,'DRAFT 2'!$A:$A,">="&DATE(2026,8,8),'DRAFT 2'!$A:$A,"<="&DATE(2026,8,14)) | GL6: =COUNTIFS('DRAFT 2'!$D:$D,$B6,'DRAFT 2'!$A:$A,">="&DATE(2026,8,15),'DRAFT 2'!$A:$A,"<="&DATE(2026,8,21)) | GM6: =COUNTIFS('DRAFT 2'!$D:$D,$B6,'DRAFT 2'!$A:$A,">="&DATE(2026,8,22),'DRAFT 2'!$A:$A,"<"&DATE(2026,IF(8=12,8+1,8+1),1)) | GN6: =SUM(GJ6:GM6) | GO6: =IF(GP6=0,1,GQ6/GP6) | GR6: =IF(GS6=0,1,GT6/GS6) | GU6: =IF(GV6=0,1,GW6/GV6) | GX6: =IFERROR(LOOKUP(2,1/('DRAFT 2'!$D:$D=$B6)*('DRAFT 2'!$A:$A>=DATE(2026,9,1))*('DRAFT 2'!$A:$A<DATE(2026,IF(9=12,9+1,9+1),1)),'DRAFT 2'!$A:$A),"") | GY6: =COUNTIFS('DRAFT 2'!$D:$D,$B6,'DRAFT 2'!$A:$A,">="&DATE(2026,9,1),'DRAFT 2'!$A:$A,"<="&DATE(2026,9,7)) | GZ6: =COUNTIFS('DRAFT 2'!$D:$D,$B6,'DRAFT 2'!$A:$A,">="&DATE(2026,9,8),'DRAFT 2'!$A:$A,"<="&DATE(2026,9,14)) | HA6: =COUNTIFS('DRAFT 2'!$D:$D,$B6,'DRAFT 2'!$A:$A,">="&DATE(2026,9,15),'DRAFT 2'!$A:$A,"<="&DATE(2026,9,21)) | HB6: =COUNTIFS('DRAFT 2'!$D:$D,$B6,'DRAFT 2'!$A:$A,">="&DATE(2026,9,22),'DRAFT 2'!$A:$A,"<"&DATE(2026,IF(9=12,9+1,9+1),1)) | HC6: =SUM(GY6:HB6) | HD6: =AVERAGE(HK6,HZ6,IO6) | HE6: =IF(HF6=0,1,HG6/HF6) | HH6: =IF(HI6=0,1,HJ6/HI6) | HK6: =IF(HL6=0,1,HM6/HL6) | HN6: =IFERROR(LOOKUP(2,1/('DRAFT 2'!$D:$D=$B6)*('DRAFT 2'!$A:$A>=DATE(2026,10,1))*('DRAFT 2'!$A:$A<DATE(2026,IF(10=12,10+1,10+1),1)),'DRAFT 2'!$A:$A),"") | HO6: =COUNTIFS('DRAFT 2'!$D:$D,$B6,'DRAFT 2'!$A:$A,">="&DATE(2026,10,1),'DRAFT 2'!$A:$A,"<="&DATE(2026,10,7)) | HP6: =COUNTIFS('DRAFT 2'!$D:$D,$B6,'DRAFT 2'!$A:$A,">="&DATE(2026,10,8),'DRAFT 2'!$A:$A,"<="&DATE(2026,10,14)) | HQ6: =COUNTIFS('DRAFT 2'!$D:$D,$B6,'DRAFT 2'!$A:$A,">="&DATE(2026,10,15),'DRAFT 2'!$A:$A,"<="&DATE(2026,10,21)) | HR6: =COUNTIFS('DRAFT 2'!$D:$D,$B6,'DRAFT 2'!$A:$A,">="&DATE(2026,10,22),'DRAFT 2'!$A:$A,"<"&DATE(2026,IF(10=12,10+1,10+1),1)) | HS6: =SUM(HO6:HR6) | HT6: =IF(HU6=0,1,HV6/HU6) | HW6: =IF(HX6=0,1,HY6/HX6) | HZ6: =IF(IA6=0,1,IB6/IA6) | IC6: =IFERROR(LOOKUP(2,1/('DRAFT 2'!$D:$D=$B6)*('DRAFT 2'!$A:$A>=DATE(2026,11,1))*('DRAFT 2'!$A:$A<DATE(2026,IF(11=12,11+1,11+1),1)),'DRAFT 2'!$A:$A),"") | ID6: =COUNTIFS('DRAFT 2'!$D:$D,$B6,'DRAFT 2'!$A:$A,">="&DATE(2026,11,1),'DRAFT 2'!$A:$A,"<="&DATE(2026,11,7)) | IE6: =COUNTIFS('DRAFT 2'!$D:$D,$B6,'DRAFT 2'!$A:$A,">="&DATE(2026,11,8),'DRAFT 2'!$A:$A,"<="&DATE(2026,11,14)) | IF6: =COUNTIFS('DRAFT 2'!$D:$D,$B6,'DRAFT 2'!$A:$A,">="&DATE(2026,11,15),'DRAFT 2'!$A:$A,"<="&DATE(2026,11,21)) | IG6: =COUNTIFS('DRAFT 2'!$D:$D,$B6,'DRAFT 2'!$A:$A,">="&DATE(2026,11,22),'DRAFT 2'!$A:$A,"<"&DATE(2026,IF(11=12,11+1,11+1),1)) | IH6: =SUM(ID6:IG6) | II6: =IF(IJ6=0,1,IK6/IJ6) | IL6: =IF(IM6=0,1,IN6/IM6) | IO6: =IF(IP6=0,1,IQ6/IP6) | IR6: =IFERROR(LOOKUP(2,1/('DRAFT 2'!$D:$D=$B6)*('DRAFT 2'!$A:$A>=DATE(2026,12,1))*('DRAFT 2'!$A:$A<DATE(2026,IF(12=12,12+1,12+1),1)),'DRAFT 2'!$A:$A),"") | IS6: =COUNTIFS('DRAFT 2'!$D:$D,$B6,'DRAFT 2'!$A:$A,">="&DATE(2026,12,1),'DRAFT 2'!$A:$A,"<="&DATE(2026,12,7)) | IT6: =COUNTIFS('DRAFT 2'!$D:$D,$B6,'DRAFT 2'!$A:$A,">="&DATE(2026,12,8),'DRAFT 2'!$A:$A,"<="&DATE(2026,12,14)) | IU6: =COUNTIFS('DRAFT 2'!$D:$D,$B6,'DRAFT 2'!$A:$A,">="&DATE(2026,12,15),'DRAFT 2'!$A:$A,"<="&DATE(2026,12,21)) | IV6: =COUNTIFS('DRAFT 2'!$D:$D,$B6,'DRAFT 2'!$A:$A,">="&DATE(2026,12,22),'DRAFT 2'!$A:$A,"<"&DATE(2026,IF(12=12,12+1,12+1),1)) | IW6: =SUM(IS6:IV6)
