Workbook
Name LISTA_RESULTADO: REGRAS!$A$2:$A$13
Name LISTA_TIPO_CONTATO: REGRAS!$A$17:$A$23
Name LISTA_MOTIVO: REGRAS!$A$27:$A$36
Name LISTA_SITUACAO: REGRAS!$B$40:$B$44
Name LISTA_FASE: REGRAS!$B$48:$B$56
Name LISTA_TENTATIVA: REGRAS!$A$60:$A$65
Name LISTA_SINALEIRO: REGRAS!$A$69:$A$72
Name LISTA_CONSULTOR: REGRAS!$A$90:$A$93
Name LISTA_SIM_NAO: REGRAS!$F$97:$F$98
Name LISTA_SIM_NAO_NA: REGRAS!$G$97:$G$99
Name LISTA_ATIVO_RECEPTIVO: REGRAS!$H$97:$H$98
Name LISTA_CURVA_ABC: REGRAS!$I$97:$I$99
Name LISTA_TIPO_CLIENTE: REGRAS!$J$97:$J$102
Name LISTA_BLOCO: REGRAS!$K$97:$K$98
Name LISTA_UF: REGRAS!$L$97:$L$123
Name LISTA_ACAO_FUTURA: REGRAS!$M$97:$M$104
Name TABELA_RESULTADO: REGRAS!$A$2:$B$13

Sheet REGRAS
A1: RESULTADO | B1: FOLLOW-UP (DIAS) | C1: GRUPO DASH | D1: QUANDO USAR
A2: EM ATENDIMENTO | B2: 2 | C2: FUNIL | D2: Negociação ativa
A3: ORÇAMENTO | B3: 1 | C3: FUNIL | D3: Proposta enviada
A4: CADASTRO | B4: 2 | C4: FUNIL | D4: Em processo de cadastro
A5: VENDA / PEDIDO | B5: 45 | C5: FUNIL | D5: Pedido fechado
A6: RELACIONAMENTO | B6: 7 | C6: RELAC. | D6: Pós-venda CS
A7: FOLLOW UP 7 | B7: 7 | C7: RELAC. | D7: Retomar em 1 semana
A8: FOLLOW UP 15 | B8: 15 | C8: RELAC. | D8: Retomar em 2 semanas
A9: SUPORTE | B9: 0 | C9: RELAC. | D9: Problema resolvido
A10: NÃO ATENDE | B10: 1 | C10: NÃO VENDA | D10: Escalona T+1
A11: NÃO RESPONDE | B11: 1 | C11: NÃO VENDA | D11: WhatsApp sem resposta
A12: RECUSOU LIGAÇÃO | B12: 2 | C12: NÃO VENDA | D12: Mudança de canal
A13: PERDA / FECHOU LOJA | B13: 0 | C13: NÃO VENDA | D13: Perdido definitivamente
A16: TIPO DO CONTATO | B16: QUANDO USAR
A17: PROSPECÇÃO | B17: 1º contato com prospect/lead
A18: NEGOCIAÇÃO | B18: Em negociação ativa
A19: FOLLOW UP | B19: Retorno agendado
A20: ATEND. CLIENTES ATIVOS | B20: Dentro do ciclo de compra
A21: ATEND. CLIENTES INATIVOS | B21: Ultrapassou ciclo
A22: PÓS-VENDA / RELACIONAMENTO | B22: CS verificar PDV
A23: MOTIVO / PAROU DE COMPRAR | B23: Investigar feedback fábrica
A26: MOTIVO | B26: DONO DA AÇÃO | C26: INSIGHT
A27: PRODUTO NÃO VENDEU / SEM GIRO | B27: DIRETORIA / FÁBRICA | C27: Produto sem fit no PDV
A28: PREÇO ALTO / MARGEM | B28: COMERCIAL | C28: Revisar tabela
A29: PREFERIU CONCORRENTE | B29: COMERCIAL / MKT | C29: Qual concorrente
A30: PROBLEMA LOGÍSTICO | B30: LOGÍSTICA | C30: Atraso avaria falta
A31: PROBLEMA FINANCEIRO | B31: FINANCEIRO | C31: Bloqueado sem crédito
A32: AINDA TEM ESTOQUE | B32: NORMAL | C32: Ajustar ciclo
A33: FECHOU LOJA | B33: PERDA | C33: Atualizar status
A34: SEM INTERESSE | B34: NUTRIÇÃO | C34: Ir pra nutrição
A35: VIAJANDO / INDISPONÍVEL | B35: NORMAL | C35: Reagendar
A36: 1º CONTATO / SEM MOTIVO | B36: NORMAL | C36: Prospecção inicial
A39: DIAS SEM COMPRA | B39: SITUAÇÃO | C39: COR HEX
... A56: Com orçamento aberto | B56: ORÇAMENTO | C56: Máxima
A59: TENTATIVA | B59: CANAL | C59: INTERVALO | D59: COMPORTAMENTO
A60: T1 | B60: WhatsApp | C60: Dia 0 | D60: Primeira abordagem
A61: T2 | B61: Ligação | C61: +1 dia útil | D61: Se não respondeu T1
A62: T3 | B62: WhatsApp | C62: +2 dias | D62: Mudança de abordagem
A63: T4 | B63: Ligação final | C63: +2 dias | D63: Última tentativa ativa
A64: NUTRIÇÃO | B64: Email + WhatsApp | C64: Ciclo 15 dias | D64: Após T4 sem resposta
...

Sheet CARTEIRA
A1: NOME FANTASIA | B1: REDE / REGIONAL | C1: UF | D1: CONSULTOR | E1: SITUAÇÃO | F1: DIAS SEM COMPRA | G1: 🚦 SINALEIRO | H1: TIPO CLIENTE | I1: FASE | J1: TENTATIVA | K1: CNPJ | L1: RAZÃO SOCIAL | M1: CIDADE | N1: EMAIL | O1: TELEFONE | P1: COD_FONTE | Q1: DATA CADASTRO | R1: CICLO MÉDIO | S1: DATA ÚLTIMO PEDIDO | T1: VALOR ÚLTIMO PEDIDO | U1: VENDEDOR ÚLTIMO PEDIDO | V1: Nº DE COMPRAS | W1: CURVA ABC | X1: TICKET MÉDIO | Y1: MESES POSITIVADO | Z1: MÉDIA MENSAL | AA1: TOTAL PERÍODO R$ | AB1: MAR/25 | AC1: ABR/25 | AD1: MAI/25 | AE1: JUN/25 | AF1: JUL/25 | AG1: AGO/25 | AH1: SET/25 | AI1: OUT/25 | AJ1: NOV/25 | AK1: DEZ/25 | AL1: JAN/26 | AM1: MESES LISTA | AN1: DIAS ATÉ CONVERSÃO | AO1: DATA 1º CONTATO | AP1: DATA 1º ORÇAMENTO | AQ1: DATA 1ª VENDA | AR1: TOTAL TENTATIVAS ATÉ VENDA | AS1: DATA ÚLTIMA RECOMPRA | AT1: ACESSO B2B | AU1: ACESSOS PORTAL | AV1: ITENS CARRINHO | AW1: VALOR PORTAL B2B | AX1: OPORTUNIDADE ECOM | AY1: COD_SAP | AZ1: STATUS PARCEIRO | BA1: ENDEREÇO | BB1: CEP | BC1: CONDIÇÃO PAGAMENTO | BD1: LISTA PREÇOS | BE1: GRUPO CLIENTE | BF1: BLOQUEIO VENDAS | BG1: BLOQUEIO GERAL | BH1: DESC. COMERCIAL | BI1: MACRORREGIÃO | BJ1: PRÓX. FOLLOW-UP | BK1: BLOCO | BL1: ESTÁGIO FUNIL | BM1: AÇÃO DETALHADA | BN1: DATA ÚLT. ATENDIMENTO | BO1: ÚLTIMO RESULTADO | BP1: MOTIVO | BQ1: PRIORIDADE | BR1: OBSERVAÇÃO | BS1: % ATING. MÊS | BT1: META MÊS R$ | BU1: REALIZADO MÊS R$ | BV1: % ATING. TRI | BW1: META TRI R$ | BX1: REALIZADO TRI R$ | BY1: % ATING. YTD | BZ1: META YTD R$ | CA1: REALIZADO YTD R$ | CB1: DATA ÚLTIMO PEDIDO | CC1: JUSTIFICATIVA SEMANAL
A2: DIVINA TERRA CWB | B2: DIVINA TERRA | C2: PR | D2: DAIANE | E2: =IF(S2="",IF(H2="LEAD","LEAD",IF(H2="NOVO","NOVO","PROSPECT")),IF(F2<=50,"ATIVO",IF(F2<=60,"EM RISCO",IF(F2<=90,"INATIVO RECENTE","INATIVO ANTIGO")))) | F2: =IF(S2="","",INT(TODAY()-S2)) | G2: =IF(S2="","🟣",IF(F2<=R2,"🟢",IF(F2<=R2+30,"🟡","🔴"))) | H2: EM DESENVOLVIMENTO | I2: =IF(BO2="ORÇAMENTO","ORÇAMENTO",IF(BO2="EM ATENDIMENTO","EM ATENDIMENTO",IF(S2="","PROSPECÇÃO",IF(F2<=10,"PÓS-VENDA",IF(F2<=25,"CS",IF(F2<=R2,"RECOMPRA",IF(F2<=90,"SALVAMENTO","RECUPERAÇÃO"))))))) | J2: T1 | K2: 32828171000108 | L2: DIVINA TERRA LTDA | M2: CURITIBA | N2: divina@email.com | O2: 5541999990001 | P2: SAP_ATIVO | Q2: 45717 | R2: 45 | S2: 46049 | T2: 1850 | U2: MANU | V2: 8 | W2: A | X2: =IF(V2>0,AA2/V2,0) | Y2: 10 | Z2: =IF(Y2>0,AA2/Y2,0) | AA2: =SUM(AB2:AL2) | AB2: 0 | AC2: 500 | AD2: 0 | AE2: 1200 | AF2: 0 | AG2: 2500 | AH2: 3000 | AI2: 1500 | AJ2: 2800 | AK2: 1500 | AL2: 0 | AM2: JAN/26,DEZ/25,NOV/25 | AN2: =IF(AND(AO2<>"",AQ2<>""),AQ2-AO2,"") | AO2: 45809 | AQ2: 45853 | AR2: 5 | AT2: SIM | AU2: 12 | AV2: 3 | AW2: 850 | AX2: QUENTE | AY2: 1000105451 | AZ2: ATIVO | BA2: Rua das Flores 100 | BB2: 80000100 | BC2: 30DDL | BD2: LISTA1 | BE2: VAREJO | BJ2: =IF(BN2="","",BN2+IFERROR(VLOOKUP(BO2,TABELA_RESULTADO,2,FALSE),7)) | BK2: MANHÃ | BL2: CS/RECOMPRA | BM2: Ligar oferecer mix | BN2: 46058 | BO2: RELACIONAMENTO | BQ2: =IF(W2="A",30,IF(W2="B",15,5))+IF(G2="🔴",40,IF(G2="🟡",25,IF(G2="🟢",10,5)))+IF(OR(I2="RECOMPRA",I2="SALVAMENTO"),25,IF(I2="CS",20,IF(I2="PROSPECÇÃO",10,5))) | BR2: Em dia | BS2: =IF(BT2>0,BU2/BT2,0) | BT2: 15000 | BU2: 12500 | BV2: =IF(BW2>0,BX2/BW2,0) | BW2: 45000 | BX2: 38000 | BY2: =IF(BZ2>0,CA2/BZ2,0) | BZ2: 135000 | CA2: 98000 | CB2: =S2 | CC2: Em dia
A3: ALICE GRAOS | B3: TUDO EM GRAOS | C3: RS | D3: MANU | E3: =IF(S3="",IF(H3="LEAD","LEAD",IF(H3="NOVO","NOVO","PROSPECT")),IF(F3<=50,"ATIVO",IF(F3<=60,"EM RISCO",IF(F3<=90,"INATIVO RECENTE","INATIVO ANTIGO")))) | F3: =IF(S3="","",INT(TODAY()-S3)) | G3: =IF(S3="","🟣",IF(F3<=R3,"🟢",IF(F3<=R3+30,"🟡","🔴"))) | H3: RECORRENTE | I3: =IF(BO3="ORÇAMENTO","ORÇAMENTO",IF(BO3="EM ATENDIMENTO","EM ATENDIMENTO",IF(S3="","PROSPECÇÃO",IF(F3<=10,"PÓS-VENDA",IF(F3<=25,"CS",IF(F3<=R3,"RECOMPRA",IF(F3<=90,"SALVAMENTO","RECUPERAÇÃO"))))))) | J3: T1 | K3: 41626544000140 | L3: ALICE GRAOS LTDA | M3: PORTO ALEGRE | N3: alice@email.com | O3: 5551999990002 | P3: SAP_ATIVO | Q3: 45672 | R3: 31 | S3: 46008 | T3: 920 | U3: LARISSA | V3: 5 | W3: B | X3: =IF(V3>0,AA3/V3,0) | Y3: 6 | Z3: =IF(Y3>0,AA3/Y3,0) | AA3: =SUM(AB3:AL3) | AB3: 0 | AC3: 0 | AD3: 0 | AE3: 800 | AF3: 1200 | AG3: 1500 | AH3: 1800 | AI3: 1200 | AJ3: 1500 | AK3: 1808 | AL3: 0 | AM3: DEZ/25,NOV/25,OUT/25 | AN3: =IF(AND(AO3<>"",AQ3<>""),AQ3-AO3,"") | AO3: 45726 | AQ3: 45767 | AR3: 3 | AT3: NÃO | AU3: 0 | AV3: 0 | AW3: 0 | AY3: 1000105678 | AZ3: ATIVO | BA3: Rua Principal 50 | BB3: 90000200 | BC3: 28DDL | BD3: LISTA2 | BE3: VAREJO | BJ3: =IF(BN3="","",BN3+IFERROR(VLOOKUP(BO3,TABELA_RESULTADO,2,FALSE),7)) | BK3: MANHÃ | BL3: ATENÇÃO/SALVAR | BM3: WhatsApp recompra | BN3: 46056 | BO3: NÃO RESPONDE | BP3: AINDA TEM ESTOQUE | BQ3: =IF(W3="A",30,IF(W3="B",15,5))+IF(G3="🔴",40,IF(G3="🟡",25,IF(G3="🟢",10,5)))+IF(OR(I3="RECOMPRA",I3="SALVAMENTO"),25,IF(I3="CS",20,IF(I3="PROSPECÇÃO",10,5))) | BR3: Estoque parado | BS3: =IF(BT3>0,BU3/BT3,0) | BT3: 8000 | BU3: 4500 | BV3: =IF(BW3>0,BX3/BW3,0) | BW3: 24000 | BX3: 18000 | BY3: =IF(BZ3>0,CA3/BZ3,0) | BZ3: 72000 | CA3: 45000 | CB3: =S3 | CC3: Estoque parado
A4: BIO SC FLORIPA | B4: BIOMUNDO | C4: SC | D4: DAIANE | E4: =IF(S4="",IF(H4="LEAD","LEAD",IF(H4="NOVO","NOVO","PROSPECT")),IF(F4<=50,"ATIVO",IF(F4<=60,"EM RISCO",IF(F4<=90,"INATIVO RECENTE","INATIVO ANTIGO")))) | F4: =IF(S4="","",INT(TODAY()-S4)) | G4: =IF(S4="","🟣",IF(F4<=R4,"🟢",IF(F4<=R4+30,"🟡","🔴"))) | H4: RECORRENTE | I4: =IF(BO4="ORÇAMENTO","ORÇAMENTO",IF(BO4="EM ATENDIMENTO","EM ATENDIMENTO",IF(S4="","PROSPECÇÃO",IF(F4<=10,"PÓS-VENDA",IF(F4<=25,"CS",IF(F4<=R4,"RECOMPRA",IF(F4<=90,"SALVAMENTO","RECUPERAÇÃO"))))))) | J4: T2 | K4: 46945954000178 | L4: BIO SC LTDA | M4: FLORIANOPOLIS | N4: biosc@email.com | O4: 5548999990003 | P4: SAP_INATIVO | Q4: 45463 | R4: 60 | S4: 45962 | T4: 680 | U4: MANU | V4: 3 | W4: C | X4: =IF(V4>0,AA4/V4,0) | Y4: 5 | Z4: =IF(Y4>0,AA4/Y4,0) | AA4: =SUM(AB4:AL4) | AB4: 0 | AC4: 0 | AD4: 0 | AE4: 0 | AF4: 0 | AG4: 0 | AH4: 2500 | AI4: 1800 | AJ4: 1500 | AK4: 1029 | AL4: 0 | AM4: JAN/26,DEZ/25 | AN4: =IF(AND(AO4<>"",AQ4<>""),AQ4-AO4,"") | AO4: 45884 | AQ4: 45910 | AR4: 6 | AT4: NÃO | AU4: 0 | AV4: 0 | AW4: 0 | AY4: 1000101541 | AZ4: ATIVO | BA4: Rua do Sol 200 | BB4: 88000300 | BC4: 30DDL | BD4: LISTA1 | BE4: VAREJO | BJ4: =IF(BN4="","",BN4+IFERROR(VLOOKUP(BO4,TABELA_RESULTADO,2,FALSE),7)) | BK4: TARDE | BL4: PERDA/NUTRIÇÃO | BM4: Ligar investigar motivo | BN4: 46054 | BO4: RECUSOU LIGAÇÃO | BP4: PREÇO ALTO / MARGEM | BQ4: =IF(W4="A",30,IF(W4="B",15,5))+IF(G4="🔴",40,IF(G4="🟡",25,IF(G4="🟢",10,5)))+IF(OR(I4="RECOMPRA",I4="SALVAMENTO"),25,IF(I4="CS",20,IF(I4="PROSPECÇÃO",10,5))) | BR4: Reclamou preço | BS4: =IF(BT4>0,BU4/BT4,0) | BT4: 5000 | BU4: 2000 | BV4: =IF(BW4>0,BX4/BW4,0) | BW4: 15000 | BX4: 8000 | BY4: =IF(BZ4>0,CA4/BZ4,0) | BZ4: 45000 | CA4: 20000 | CB4: =S4 | CC4: Reclamou preço
A5: AFS ALDEIA | B5: ARMAZEM FITSTORE | C5: SP | D5: DAIANE | E5: =IF(S5="",IF(H5="LEAD","LEAD",IF(H5="NOVO","NOVO","PROSPECT")),IF(F5<=50,"ATIVO",IF(F5<=60,"EM RISCO",IF(F5<=90,"INATIVO RECENTE","INATIVO ANTIGO")))) | F5: =IF(S5="","",INT(TODAY()-S5)) | G5: =IF(S5="","🟣",IF(F5<=R5,"🟢",IF(F5<=R5+30,"🟡","🔴"))) | H5: PROSPECT | I5: =IF(BO5="ORÇAMENTO","ORÇAMENTO",IF(BO5="EM ATENDIMENTO","EM ATENDIMENTO",IF(S5="","PROSPECÇÃO",IF(F5<=10,"PÓS-VENDA",IF(F5<=25,"CS",IF(F5<=R5,"RECOMPRA",IF(F5<=90,"SALVAMENTO","RECUPERAÇÃO"))))))) | J5: T1 | K5: 39915172000120 | L5: AFS ALDEIA LTDA | M5: SAO PAULO | N5: afs@email.com | O5: 5511999990004 | P5: PROSPECT | Q5: 46032 | V5: 0 | X5: =IF(V5>0,AA5/V5,0) | Y5: 0 | Z5: =IF(Y5>0,AA5/Y5,0) | AA5: =SUM(AB5:AL5) | AB5: 0 | AC5: 0 | AD5: 0 | AE5: 0 | AF5: 0 | AG5: 0 | AH5: 0 | AI5: 0 | AJ5: 0 | AK5: 0 | AL5: 0 | AN5: =IF(AND(AO5<>"",AQ5<>""),AQ5-AO5,"") | AO5: 46032 | AT5: NÃO | AU5: 0 | AV5: 0 | AW5: 0 | BJ5: =IF(BN5="","",BN5+IFERROR(VLOOKUP(BO5,TABELA_RESULTADO,2,FALSE),7)) | BK5: TARDE | BL5: ABERTURA/ATIVAÇÃO | BM5: 1º contato WhatsApp | BN5: 46058 | BO5: NÃO RESPONDE | BP5: 1º CONTATO / SEM MOTIVO | BQ5: =IF(W5="A",30,IF(W5="B",15,5))+IF(G5="🔴",40,IF(G5="🟡",25,IF(G5="🟢",10,5)))+IF(OR(I5="RECOMPRA",I5="SALVAMENTO"),25,IF(I5="CS",20,IF(I5="PROSPECÇÃO",10,5))) | BR5: Aguardando retorno | BS5: =IF(BT5>0,BU5/BT5,0) | BT5: 0 | BU5: 0 | BV5: =IF(BW5>0,BX5/BW5,0) | BW5: 0 | BX5: 0 | BY5: =IF(BZ5>0,CA5/BZ5,0) | BZ5: 0 | CA5: 0 | CB5: =S5 | CC5: Aguardando retorno
A6: CIA SAUDE SP | B6: CIA DA SAUDE | C6: SP | D6: JULIO | E6: =IF(S6="",IF(H6="LEAD","LEAD",IF(H6="NOVO","NOVO","PROSPECT")),IF(F6<=50,"ATIVO",IF(F6<=60,"EM RISCO",IF(F6<=90,"INATIVO RECENTE","INATIVO ANTIGO")))) | F6: =IF(S6="","",INT(TODAY()-S6)) | G6: =IF(S6="","🟣",IF(F6<=R6,"🟢",IF(F6<=R6+30,"🟡","🔴"))) | H6: EM DESENVOLVIMENTO | I6: =IF(BO6="ORÇAMENTO","ORÇAMENTO",IF(BO6="EM ATENDIMENTO","EM ATENDIMENTO",IF(S6="","PROSPECÇÃO",IF(F6<=10,"PÓS-VENDA",IF(F6<=25,"CS",IF(F6<=R6,"RECOMPRA",IF(F6<=90,"SALVAMENTO","RECUPERAÇÃO"))))))) | J6: T1 | K6: 12345678000199 | L6: CIA SAUDE SP LTDA | M6: SAO PAULO | N6: ciasaude@email.com | O6: 5511999990005 | P6: SAP_ATIVO | Q6: 45689 | R6: 30 | S6: 46052 | T6: 2200 | U6: JULIO | V6: 12 | W6: A | X6: =IF(V6>0,AA6/V6,0) | Y6: 11 | Z6: =IF(Y6>0,AA6/Y6,0) | AA6: =SUM(AB6:AL6) | AB6: 1500 | AC6: 2000 | AD6: 2500 | AE6: 2000 | AF6: 2500 | AG6: 2800 | AH6: 3000 | AI6: 2500 | AJ6: 3200 | AK6: 3500 | AL6: 0 | AM6: JAN/26,DEZ/25,NOV/25 | AN6: =IF(AND(AO6<>"",AQ6<>""),AQ6-AO6,"") | AO6: 45731 | AP6: 45736 | AQ6: 45757 | AR6: 4 | AS6: 46037 | AT6: SIM | AU6: 25 | AV6: 8 | AW6: 1500 | AX6: CONVERTIDO | AY6: 1000106000 | AZ6: ATIVO | BA6: Av Paulista 500 | BB6: 01000100 | BC6: 30DDL | BD6: LISTA1 | BE6: REDE | BJ6: =IF(BN6="","",BN6+IFERROR(VLOOKUP(BO6,TABELA_RESULTADO,2,FALSE),7)) | BK6: MANHÃ | BL6: CS/RECOMPRA | BM6: Ligar confirmar pedido | BN6: 46059 | BO6: VENDA / PEDIDO | BQ6: =IF(W6="A",30,IF(W6="B",15,5))+IF(G6="🔴",40,IF(G6="🟡",25,IF(G6="🟢",10,5)))+IF(OR(I6="RECOMPRA",I6="SALVAMENTO"),25,IF(I6="CS",20,IF(I6="PROSPECÇÃO",10,5))) | BR6: Cliente top | BS6: =IF(BT6>0,BU6/BT6,0) | BT6: 20000 | BU6: 18500 | BV6: =IF(BW6>0,BX6/BW6,0) | BW6: 60000 | BX6: 52000 | BY6: =IF(BZ6>0,CA6/BZ6,0) | BZ6: 180000 | CA6: 155000 | CB6: =S6 | CC6: Cliente top

Sheet LOG
A1: DATA | B1: CONSULTOR | C1: NOME FANTASIA | D1: CNPJ | E1: UF | F1: REDE / REGIONAL | G1: SITUAÇÃO | H1: WHATSAPP | I1: LIGAÇÃO | J1: LIGAÇÃO ATENDIDA | K1: TIPO AÇÃO | L1: TIPO DO CONTATO | M1: RESULTADO | N1: MOTIVO | O1: FOLLOW-UP | P1: AÇÃO | Q1: MERCOS ATUALIZADO | R1: FASE | S1: TENTATIVA | T1: NOTA DO DIA
A2: 46058 | B2: DAIANE | C2: DIVINA TERRA CWB | D2: 32828171000108 | E2: PR | F2: DIVINA TERRA | G2: ATIVO | H2: SIM | I2: NÃO | J2: N/A | K2: ATIVO | L2: PÓS-VENDA / RELACIONAMENTO | M2: RELACIONAMENTO | N2: AINDA TEM ESTOQUE | O2: =IF(M2="","",IF(OR(M2="SUPORTE",M2="PERDA / FECHOU LOJA"),"SEM",IFERROR(A2+VLOOKUP(M2,TABELA_RESULTADO,2,FALSE),""))) | P2: Verificar estoque | Q2: SIM | R2: CS | S2: T1 | T2: Cliente satisfeito
A3: 46058 | B3: MANU | C3: ALICE GRAOS | D3: 41626544000140 | E3: RS | F3: TUDO EM GRAOS | G3: EM RISCO | H3: SIM | I3: NÃO | J3: N/A | K3: ATIVO | L3: ATEND. CLIENTES ATIVOS | M3: NÃO RESPONDE | N3: 1º CONTATO / SEM MOTIVO | O3: =IF(M3="","",IF(OR(M3="SUPORTE",M3="PERDA / FECHOU LOJA"),"SEM",IFERROR(A3+VLOOKUP(M3,TABELA_RESULTADO,2,FALSE),""))) | P3: Tentar ligar amanhã | Q3: NÃO | R3: RECOMPRA | S3: T1 | T3: Sem resposta WhatsApp
A4: 46058 | B4: DAIANE | C4: BIO SC FLORIPA | D4: 46945954000178 | E4: SC | F4: BIOMUNDO | G4: INATIVO RECENTE | H4: SIM | I4: SIM | J4: NÃO | K4: ATIVO | L4: ATEND. CLIENTES INATIVOS | M4: RECUSOU LIGAÇÃO | N4: PREÇO ALTO / MARGEM | O4: =IF(M4="","",IF(OR(M4="SUPORTE",M4="PERDA / FECHOU LOJA"),"SEM",IFERROR(A4+VLOOKUP(M4,TABELA_RESULTADO,2,FALSE),""))) | P4: Enviar tabela nova | Q4: SIM | R4: SALVAMENTO | S4: T2 | T4: Reclamou preço
A5: 46058 | B5: DAIANE | C5: AFS ALDEIA | D5: 39915172000120 | E5: SP | F5: ARMAZEM FITSTORE | G5: PROSPECT | H5: SIM | I5: NÃO | J5: N/A | K5: ATIVO | L5: PROSPECÇÃO | M5: NÃO RESPONDE | N5: 1º CONTATO / SEM MOTIVO | O5: =IF(M5="","",IF(OR(M5="SUPORTE",M5="PERDA / FECHOU LOJA"),"SEM",IFERROR(A5+VLOOKUP(M5,TABELA_RESULTADO,2,FALSE),""))) | P5: 1º contato feito | Q5: NÃO | R5: PROSPECÇÃO | S5: T1 | T5: WhatsApp enviado
A6: 46059 | B6: JULIO | C6: CIA SAUDE SP | D6: 12345678000199 | E6: SP | F6: CIA DA SAUDE | G6: ATIVO | H6: NÃO | I6: SIM | J6: SIM | K6: ATIVO | L6: ATEND. CLIENTES ATIVOS | M6: VENDA / PEDIDO | O6: =IF(M6="","",IF(OR(M6="SUPORTE",M6="PERDA / FECHOU LOJA"),"SEM",IFERROR(A6+VLOOKUP(M6,TABELA_RESULTADO,2,FALSE),""))) | P6: Pedido confirmado | Q6: SIM | R6: CS | S6: T1 | T6: Pedido R$ 2.200
A7: 46059 | B7: MANU | C7: ALICE GRAOS | D7: 41626544000140 | E7: RS | F7: TUDO EM GRAOS | G7: EM RISCO | H7: NÃO | I7: SIM | J7: NÃO | K7: ATIVO | L7: FOLLOW UP | M7: NÃO ATENDE | N7: AINDA TEM ESTOQUE | O7: =IF(M7="","",IF(OR(M7="SUPORTE",M7="PERDA / FECHOU LOJA"),"SEM",IFERROR(A7+VLOOKUP(M7,TABELA_RESULTADO,2,FALSE),""))) | P7: Tentar WhatsApp | Q7: SIM | R7: RECOMPRA | S7: T2 | T7: Não atendeu
A8: 46059 | B8: DAIANE | C8: AFS ALDEIA | D8: 39915172000120 | E8: SP | F8: ARMAZEM FITSTORE | G8: PROSPECT | H8: SIM | I8: NÃO | J8: N/A | K8: ATIVO | L8: PROSPECÇÃO | M8: EM ATENDIMENTO | N8: 1º CONTATO / SEM MOTIVO | O8: =IF(M8="","",IF(OR(M8="SUPORTE",M8="PERDA / FECHOU LOJA"),"SEM",IFERROR(A8+VLOOKUP(M8,TABELA_RESULTADO,2,FALSE),""))) | P8: Respondeu interesse | Q8: SIM | R8: PROSPECÇÃO | S8: T1 | T8: Pediu catálogo
A9: 46060 | B9: DAIANE | C9: DIVINA TERRA CWB | D9: 32828171000108 | E9: PR | F9: DIVINA TERRA | G9: ATIVO | H9: NÃO | I9: SIM | J9: SIM | K9: RECEPTIVO | L9: NEGOCIAÇÃO | M9: ORÇAMENTO | O9: =IF(M9="","",IF(OR(M9="SUPORTE",M9="PERDA / FECHOU LOJA"),"SEM",IFERROR(A9+VLOOKUP(M9,TABELA_RESULTADO,2,FALSE),""))) | P9: Enviar orçamento mix | Q9: SIM | R9: CS | S9: T1 | T9: Pediu orçamento novo mix

Sheet DRAFT 1
A1: DATA | B1: CNPJ | C1: NOME FANTASIA | D1: VALOR PEDIDO | E1: STATUS PEDIDO | F1: VENDEDOR | G1: MIGRADO
A2: 46059 | B2: 12345678000199 | C2: CIA SAUDE SP | D2: 2200 | E2: CONFIRMADO | F2: JULIO | G2: NÃO
A3: 46060 | B3: 32828171000108 | C3: DIVINA TERRA CWB | D3: 1850 | E3: PENDENTE | F3: MANU | G3: NÃO

Sheet DRAFT 2
A1: NOME FANTASIA | B1: CNPJ | C1: UF | D1: REDE/REGIONAL | E1: TELEFONE | F1: EMAIL | G1: SITUAÇÃO | H1: DIAS SEM COMPRA | I1: SINALEIRO | J1: FASE | K1: TENTATIVA | L1: AÇÃO SUGERIDA | M1: BLOCO | N1: ÚLTIMO RESULTADO | O1: WHATSAPP | P1: LIGAÇÃO | Q1: LIGAÇÃO ATENDIDA | R1: TIPO AÇÃO | S1: TIPO DO CONTATO | T1: RESULTADO | U1: MOTIVO | V1: AÇÃO FUTURA | W1: MERCOS ATUALIZADO | X1: NOTA DO DIA | Y1: ✅ VÁLIDO | Z1: ⚠ ERRO | AA1: 📝 MIGRADO
A2: DIVINA TERRA CWB | B2: 32828171000108 | C2: PR | D2: DIVINA TERRA | E2: 5541999990001 | F2: divina@email.com | G2: ATIVO | H2: 12 | I2: 🟢 | J2: CS | K2: T1 | L2: Ligar oferecer mix | M2: MANHÃ | N2: RELACIONAMENTO | O2: SIM | P2: NÃO | Q2: N/A | R2: ATIVO | S2: PÓS-VENDA / RELACIONAMENTO | T2: RELACIONAMENTO | U2: AINDA TEM ESTOQUE | V2: Verificar estoque | W2: SIM | X2: Cliente satisfeito | Y2: =IF(AND(B2<>"",T2<>"",S2<>""),"OK","ERRO") | Z2: =IF(Y2="OK","",IF(B2="","CNPJ VAZIO",IF(T2="","SEM RESULTADO","SEM TIPO CONTATO")))
A3: CIA SAUDE SP | B3: 12345678000199 | C3: SP | D3: CIA DA SAUDE | E3: 5511999990005 | F3: ciasaude@email.com | G3: ATIVO | H3: 9 | I3: 🟢 | J3: PÓS-VENDA | K3: T1 | L3: Ligar confirmar pedido | M3: MANHÃ | N3: VENDA / PEDIDO | O3: NÃO | P3: SIM | Q3: SIM | R3: ATIVO | S3: ATEND. CLIENTES ATIVOS | T3: VENDA / PEDIDO | V3: Pedido confirmado | W3: SIM | X3: Pedido R$ 2.200 | Y3: =IF(AND(B3<>"",T3<>"",S3<>""),"OK","ERRO") | Z3: =IF(Y3="OK","",IF(B3="","CNPJ VAZIO",IF(T3="","SEM RESULTADO","SEM TIPO CONTATO")))
A4: AFS ALDEIA | C4: SP | D4: ARMAZEM FITSTORE | E4: 5511999990004 | F4: afs@email.com | G4: PROSPECT | I4: 🟣 | J4: PROSPECÇÃO | K4: T1 | L4: 1º contato WhatsApp | M4: TARDE | N4: NÃO RESPONDE | O4: SIM | P4: NÃO | Q4: N/A | R4: ATIVO | U4: 1º CONTATO / SEM MOTIVO | V4: 1º contato feito | W4: NÃO | X4: WhatsApp enviado | Y4: =IF(AND(B4<>"",T4<>"",S4<>""),"OK","ERRO") | Z4: =IF(Y4="OK","",IF(B4="","CNPJ VAZIO",IF(T4="","SEM RESULTADO","SEM TIPO CONTATO")))

Sheet DASH
A1: 📊 DASHBOARD JARVIS CRM
A2: CONSULTOR: | B2: TODOS
A3: PERÍODO: | B3: 46023 | C3: a | D3: 46061
A5: CONTATOS | B5: VENDAS | C5: ORÇAMENTOS | D5: NÃO ATENDE | E5: % CONVERSÃO | F5: MERCOS OK
A6: =IF($B$2="TODOS",COUNTIFS(LOG!A:A,">="&B3,LOG!A:A,"<="&D3),COUNTIFS(LOG!A:A,">="&B3,LOG!A:A,"<="&D3,LOG!B:B,$B$2)) | B6: =IF($B$2="TODOS",COUNTIFS(LOG!A:A,">="&B3,LOG!A:A,"<="&D3,LOG!M:M,"VENDA / PEDIDO"),COUNTIFS(LOG!A:A,">="&B3,LOG!A:A,"<="&D3,LOG!M:M,"VENDA / PEDIDO",LOG!B:B,$B$2)) | C6: =IF($B$2="TODOS",COUNTIFS(LOG!A:A,">="&B3,LOG!A:A,"<="&D3,LOG!M:M,"ORÇAMENTO"),COUNTIFS(LOG!A:A,">="&B3,LOG!A:A,"<="&D3,LOG!M:M,"ORÇAMENTO",LOG!B:B,$B$2)) | D6: =IF($B$2="TODOS",COUNTIFS(LOG!A:A,">="&B3,LOG!A:A,"<="&D3,LOG!M:M,"NÃO ATENDE"),COUNTIFS(LOG!A:A,">="&B3,LOG!A:A,"<="&D3,LOG!M:M,"NÃO ATENDE",LOG!B:B,$B$2)) | E6: =IFERROR(B6/A6,0) | F6: =IF($B$2="TODOS",IFERROR(COUNTIFS(LOG!A:A,">="&B3,LOG!A:A,"<="&D3,LOG!Q:Q,"SIM")/COUNTIFS(LOG!A:A,">="&B3,LOG!A:A,"<="&D3),0),IFERROR(COUNTIFS(LOG!A:A,">="&B3,LOG!A:A,"<="&D3,LOG!Q:Q,"SIM",LOG!B:B,$B$2)/COUNTIFS(LOG!A:A,">="&B3,LOG!A:A,"<="&D3,LOG!B:B,$B$2),0))
A10: CONTATOS POR TIPO & FUNIL
A11: TIPO DO CONTATO | B11: TOTAL | C11: FUNIL | D11: RELAC. | E11: NÃO VENDA
A12: PROSPECÇÃO | B12: =IF($B$2="TODOS",COUNTIFS(LOG!L:L,A12,LOG!A:A,">="&$B$3,LOG!A:A,"<="&$D$3),COUNTIFS(LOG!L:L,A12,LOG!A:A,">="&$B$3,LOG!A:A,"<="&$D$3,LOG!B:B,$B$2)) | C12: =IF($B$2="TODOS",COUNTIFS(LOG!L:L,A12,LOG!A:A,">="&$B$3,LOG!A:A,"<="&$D$3,LOG!M:M,"EM ATENDIMENTO")+COUNTIFS(LOG!L:L,A12,LOG!A:A,">="&$B$3,LOG!A:A,"<="&$D$3,LOG!M:M,"ORÇAMENTO")+COUNTIFS(LOG!L:L,A12,LOG!A:A,">="&$B$3,LOG!A:A,"<="&$D$3,LOG!M:M,"CADASTRO")+COUNTIFS(LOG!L:L,A12,LOG!A:A,">="&$B$3,LOG!A:A,"<="&$D$3,LOG!M:M,"VENDA / PEDIDO"),COUNTIFS(LOG!L:L,A12,LOG!A:A,">="&$B$3,LOG!A:A,"<="&$D$3,LOG!M:M,"EM ATENDIMENTO",LOG!B:B,$B$2)+COUNTIFS(LOG!L:L,A12,LOG!A:A,">="&$B$3,LOG!A:A,"<="&$D$3,LOG!M:M,"ORÇAMENTO",LOG!B:B,$B$2)+COUNTIFS(LOG!L:L,A12,LOG!A:A,">="&$B$3,LOG!A:A,"<="&$D$3,LOG!M:M,"CADASTRO",LOG!B:B,$B$2)+COUNTIFS(LOG!L:L,A12,LOG!A:A,">="&$B$3,LOG!A:A,"<="&$D$3,LOG!M:M,"VENDA / PEDIDO",LOG!B:B,$B$2)) | D12: =IF($B$2="TODOS",COUNTIFS(LOG!L:L,A12,LOG!A:A,">="&$B$3,LOG!A:A,"<="&$D$3,LOG!M:M,"RELACIONAMENTO")+COUNTIFS(LOG!L:L,A12,LOG!A:A,">="&$B$3,LOG!A:A,"<="&$D$3,LOG!M:M,"FOLLOW UP 7")+COUNTIFS(LOG!L:L,A12,LOG!A:A,">="&$B$3,LOG!A:A,"<="&$D$3,LOG!M:M,"FOLLOW UP 15")+COUNTIFS(LOG!L:L,A12,LOG!A:A,">="&$B$3,LOG!A:A,"<="&$D$3,LOG!M:M,"SUPORTE"),COUNTIFS(LOG!L:L,A12,LOG!A:A,">="&$B$3,LOG!A:A,"<="&$D$3,LOG!M:M,"RELACIONAMENTO",LOG!B:B,$B$2)+COUNTIFS(LOG!L:L,A12,LOG!A:A,">="&$B$3,LOG!A:A,"<="&$D$3,LOG!M:M,"FOLLOW UP 7",LOG!B:B,$B$2)+COUNTIFS(LOG!L:L,A12,LOG!A:A,">="&$B$3,LOG!A:A,"<="&$D$3,LOG!M:M,"FOLLOW UP 15",LOG!B:B,$B$2)+COUNTIFS(LOG!L:L,A12,LOG!A:A,">="&$B$3,LOG!A:A,"<="&$D$3,LOG!M:M,"SUPORTE",LOG!B:B,$B$2)) | E12: =IF($B$2="TODOS",COUNTIFS(LOG!L:L,A12,LOG!A:A,">="&$B$3,LOG!A:A,"<="&$D$3,LOG!M:M,"NÃO ATENDE")+COUNTIFS(LOG!L:L,A12,LOG!A:A,">="&$B$3,LOG!A:A,"<="&$D$3,LOG!M:M,"NÃO RESPONDE")+COUNTIFS(LOG!L:L,A12,LOG!A:A,">="&$B$3,LOG!A:A,"<="&$D$3,LOG!M:M,"RECUSOU LIGAÇÃO")+COUNTIFS(LOG!L:L,A12,LOG!A:A,">="&$B$3,LOG!A:A,"<="&$D$3,LOG!M:M,"PERDA / FECHOU LOJA"),COUNTIFS(LOG!L:L,A12,LOG!A:A,">="&$B$3,LOG!A:A,"<="&$D$3,LOG!M:M,"NÃO ATENDE",LOG!B:B,$B$2)+COUNTIFS(LOG!L:L,A12,LOG!A:A,">="&$B$3,LOG!A:A,"<="&$D$3,LOG!M:M,"NÃO RESPONDE",LOG!B:B,$B$2)+COUNTIFS(LOG!L:L,A12,LOG!A:A,">="&$B$3,LOG!A:A,"<="&$D$3,LOG!M:M,"RECUSOU LIGAÇÃO",LOG!B:B,$B$2)+COUNTIFS(LOG!L:L,A12,LOG!A:A,">="&$B$3,LOG!A:A,"<="&$D$3,LOG!M:M,"PERDA / FECHOU LOJA",LOG!B:B,$B$2))
A13: NEGOCIAÇÃO | B13: =IF($B$2="TODOS",COUNTIFS(LOG!L:L,A13,LOG!A:A,">="&$B$3,LOG!A:A,"<="&$D$3),COUNTIFS(LOG!L:L,A13,LOG!A:A,">="&$B$3,LOG!A:A,"<="&$D$3,LOG!B:B,$B$2)) | C13: =IF($B$2="TODOS",COUNTIFS(LOG!L:L,A13,LOG!A:A,">="&$B$3,LOG!A:A,"<="&$D$3,LOG!M:M,"EM ATENDIMENTO")+COUNTIFS(LOG!L:L,A13,LOG!A:A,">="&$B$3,LOG!A:A,"<="&$D$3,LOG!M:M,"ORÇAMENTO")+COUNTIFS(LOG!L:L,A13,LOG!A:A,">="&$B$3,LOG!A:A,"<="&$D$3,LOG!M:M,"CADASTRO")+COUNTIFS(LOG!L:L,A13,LOG!A:A,">="&$B$3,LOG!A:A,"<="&$D$3,LOG!M:M,"VENDA / PEDIDO"),COUNTIFS(LOG!L:L,A13,LOG!A:A,">="&$B$3,LOG!A:A,"<="&$D$3,LOG!M:M,"EM ATENDIMENTO",LOG!B:B,$B$2)+COUNTIFS(LOG!L:L,A13,LOG!A:A,">="&$B$3,LOG!A:A,"<="&$D$3,LOG!M:M,"ORÇAMENTO",LOG!B:B,$B$2)+COUNTIFS(LOG!L:L,A13,LOG!A:A,">="&$B$3,LOG!A:A,"<="&$D$3,LOG!M:M,"CADASTRO",LOG!B:B,$B$2)+COUNTIFS(LOG!L:L,A13,LOG!A:A,">="&$B$3,LOG!A:A,"<="&$D$3,LOG!M:M,"VENDA / PEDIDO",LOG!B:B,$B$2)) | D13: =IF($B$2="TODOS",COUNTIFS(LOG!L:L,A13,LOG!A:A,">="&$B$3,LOG!A:A,"<="&$D$3,LOG!M:M,"RELACIONAMENTO")+COUNTIFS(LOG!L:L,A13,LOG!A:A,">="&$B$3,LOG!A:A,"<="&$D$3,LOG!M:M,"FOLLOW UP 7")+COUNTIFS(LOG!L:L,A13,LOG!A:A,">="&$B$3,LOG!A:A,"<="&$D$3,LOG!M:M,"FOLLOW UP 15")+COUNTIFS(LOG!L:L,A13,LOG!A:A,">="&$B$3,LOG!A:A,"<="&$D$3,LOG!M:M,"SUPORTE"),COUNTIFS(LOG!L:L,A13,LOG!A:A,">="&$B$3,LOG!A:A,"<="&$D$3,LOG!M:M,"RELACIONAMENTO",LOG!B:B,$B$2)+COUNTIFS(LOG!L:L,A13,LOG!A:A,">="&$B$3,LOG!A:A,"<="&$D$3,LOG!M:M,"FOLLOW UP 7",LOG!B:B,$B$2)+COUNTIFS(LOG!L:L,A13,LOG!A:A,">="&$B$3,LOG!A:A,"<="&$D$3,LOG!M:M,"FOLLOW UP 15",LOG!B:B,$B$2)+COUNTIFS(LOG!L:L,A13,LOG!A:A,">="&$B$3,LOG!A:A,"<="&$D$3,LOG!M:M,"SUPORTE",LOG!B:B,$B$2)) | E13: =IF($B$2="TODOS",COUNTIFS(LOG!L:L,A13,LOG!A:A,">="&$B$3,LOG!A:A,"<="&$D$3,LOG!M:M,"NÃO ATENDE")+COUNTIFS(LOG!L:L,A13,LOG!A:A,">="&$B$3,LOG!A:A,"<="&$D$3,LOG!M:M,"NÃO RESPONDE")+COUNTIFS(LOG!L:L,A13,LOG!A:A,">="&$B$3,LOG!A:A,"<="&$D$3,LOG!M:M,"RECUSOU LIGAÇÃO")+COUNTIFS(LOG!L:L,A13,LOG!A:A,">="&$B$3,LOG!A:A,"<="&$D$3,LOG!M:M,"PERDA / FECHOU LOJA"),COUNTIFS(LOG!L:L,A13,LOG!A:A,">="&$B$3,LOG!A:A,"<="&$D$3,LOG!M:M,"NÃO ATENDE",LOG!B:B,$B$2)+COUNTIFS(LOG!L:L,A13,LOG!A:A,">="&$B$3,LOG!A:A,"<="&$D$3,LOG!M:M,"NÃO RESPONDE",LOG!B:B,$B$2)+COUNTIFS(LOG!L:L,A13,LOG!A:A,">="&$B$3,LOG!A:A,"<="&$D$3,LOG!M:M,"RECUSOU LIGAÇÃO",LOG!B:B,$B$2)+COUNTIFS(LOG!L:L,A13,LOG!A:A,">="&$B$3,LOG!A:A,"<="&$D$3,LOG!M:M,"PERDA / FECHOU LOJA",LOG!B:B,$B$2))
A14: FOLLOW UP | B14: =IF($B$2="TODOS",COUNTIFS(LOG!L:L,A14,LOG!A:A,">="&$B$3,LOG!A:A,"<="&$D$3),COUNTIFS(LOG!L:L,A14,LOG!A:A,">="&$B$3,LOG!A:A,"<="&$D$3,LOG!B:B,$B$2)) | C14: =IF($B$2="TODOS",COUNTIFS(LOG!L:L,A14,LOG!A:A,">="&$B$3,LOG!A:A,"<="&$D$3,LOG!M:M,"EM ATENDIMENTO")+COUNTIFS(LOG!L:L,A14,LOG!A:A,">="&$B$3,LOG!A:A,"<="&$D$3,LOG!M:M,"ORÇAMENTO")+COUNTIFS(LOG!L:L,A14,LOG!A:A,">="&$B$3,LOG!A:A,"<="&$D$3,LOG!M:M,"CADASTRO")+COUNTIFS(LOG!L:L,A14,LOG!A:A,">="&$B$3,LOG!A:A,"<="&$D$3,LOG!M:M,"VENDA / PEDIDO"),COUNTIFS(LOG!L:L,A14,LOG!A:A,">="&$B$3,LOG!A:A,"<="&$D$3,LOG!M:M,"EM ATENDIMENTO",LOG!B:B,$B$2)+COUNTIFS(LOG!L:L,A14,LOG!A:A,">="&$B$3,LOG!A:A,"<="&$D$3,LOG!M:M,"ORÇAMENTO",LOG!B:B,$B$2)+COUNTIFS(LOG!L:L,A14,LOG!A:A,">="&$B$3,LOG!A:A,"<="&$D$3,LOG!M:M,"CADASTRO",LOG!B:B,$B$2)+COUNTIFS(LOG!L:L,A14,LOG!A:A,">="&$B$3,LOG!A:A,"<="&$D$3,LOG!M:M,"VENDA / PEDIDO",LOG!B:B,$B$2)) | D14: =IF($B$2="TODOS",COUNTIFS(LOG!L:L,A14,LOG!A:A,">="&$B$3,LOG!A:A,"<="&$D$3,LOG!M:M,"RELACIONAMENTO")+COUNTIFS(LOG!L:L,A14,LOG!A:A,">="&$B$3,LOG!A:A,"<="&$D$3,LOG!M:M,"FOLLOW UP 7")+COUNTIFS(LOG!L:L,A14,LOG!A:A,">="&$B$3,LOG!A:A,"<="&$D$3,LOG!M:M,"FOLLOW UP 15")+COUNTIFS(LOG!L:L,A14,LOG!A:A,">="&$B$3,LOG!A:A,"<="&$D$3,LOG!M:M,"SUPORTE"),COUNTIFS(LOG!L:L,A14,LOG!A:A,">="&$B$3,LOG!A:A,"<="&$D$3,LOG!M:M,"RELACIONAMENTO",LOG!B:B,$B$2)+COUNTIFS(LOG!L:L,A14,LOG!A:A,">="&$B$3,LOG!A:A,"<="&$D$3,LOG!M:M,"FOLLOW UP 7",LOG!B:B,$B$2)+COUNTIFS(LOG!L:L,A14,LOG!A:A,">="&$B$3,LOG!A:A,"<="&$D$3,LOG!M:M,"FOLLOW UP 15",LOG!B:B,$B$2)+COUNTIFS(LOG!L:L,A14,LOG!A:A,">="&$B$3,LOG!A:A,"<="&$D$3,LOG!M:M,"SUPORTE",LOG!B:B,$B$2)) | E14: =IF($B$2="TODOS",COUNTIFS(LOG!L:L,A14,LOG!A:A,">="&$B$3,LOG!A:A,"<="&$D$3,LOG!M:M,"NÃO ATENDE")+COUNTIFS(LOG!L:L,A14,LOG!A:A,">="&$B$3,LOG!A:A,"<="&$D$3,LOG!M:M,"NÃO RESPONDE")+COUNTIFS(LOG!L:L,A14,LOG!A:A,">="&$B$3,LOG!A:A,"<="&$D$3,LOG!M:M,"RECUSOU LIGAÇÃO")+COUNTIFS(LOG!L:L,A14,LOG!A:A,">="&$B$3,LOG!A:A,"<="&$D$3,LOG!M:M,"PERDA / FECHOU LOJA"),COUNTIFS(LOG!L:L,A14,LOG!A:A,">="&$B$3,LOG!A:A,"<="&$D$3,LOG!M:M,"NÃO ATENDE",LOG!B:B,$B$2)+COUNTIFS(LOG!L:L,A14,LOG!A:A,">="&$B$3,LOG!A:A,"<="&$D$3,LOG!M:M,"NÃO RESPONDE",LOG!B:B,$B$2)+COUNTIFS(LOG!L:L,A14,LOG!A:A,">="&$B$3,LOG!A:A,"<="&$D$3,LOG!M:M,"RECUSOU LIGAÇÃO",LOG!B:B,$B$2)+COUNTIFS(LOG!L:L,A14,LOG!A:A,">="&$B$3,LOG!A:A,"<="&$D$3,LOG!M:M,"PERDA / FECHOU LOJA",LOG!B:B,$B$2))
A15: ATEND. CLIENTES ATIVOS | B15: =IF($B$2="TODOS",COUNTIFS(LOG!L:L,A15,LOG!A:A,">="&$B$3,LOG!A:A,"<="&$D$3),COUNTIFS(LOG!L:L,A15,LOG!A:A,">="&$B$3,LOG!A:A,"<="&$D$3,LOG!B:B,$B$2)) | C15: =IF($B$2="TODOS",COUNTIFS(LOG!L:L,A15,LOG!A:A,">="&$B$3,LOG!A:A,"<="&$D$3,LOG!M:M,"EM ATENDIMENTO")+COUNTIFS(LOG!L:L,A15,LOG!A:A,">="&$B$3,LOG!A:A,"<="&$D$3,LOG!M:M,"ORÇAMENTO")+COUNTIFS(LOG!L:L,A15,LOG!A:A,">="&$B$3,LOG!A:A,"<="&$D$3,LOG!M:M,"CADASTRO")+COUNTIFS(LOG!L:L,A15,LOG!A:A,">="&$B$3,LOG!A:A,"<="&$D$3,LOG!M:M,"VENDA / PEDIDO"),COUNTIFS(LOG!L:L,A15,LOG!A:A,">="&$B$3,LOG!A:A,"<="&$D$3,LOG!M:M,"EM ATENDIMENTO",LOG!B:B,$B$2)+COUNTIFS(LOG!L:L,A15,LOG!A:A,">="&$B$3,LOG!A:A,"<="&$D$3,LOG!M:M,"ORÇAMENTO",LOG!B:B,$B$2)+COUNTIFS(LOG!L:L,A15,LOG!A:A,">="&$B$3,LOG!A:A,"<="&$D$3,LOG!M:M,"CADASTRO",LOG!B:B,$B$2)+COUNTIFS(LOG!L:L,A15,LOG!A:A,">="&$B$3,LOG!A:A,"<="&$D$3,LOG!M:M,"VENDA / PEDIDO",LOG!B:B,$B$2)) | D15: =IF($B$2="TODOS",COUNTIFS(LOG!L:L,A15,LOG!A:A,">="&$B$3,LOG!A:A,"<="&$D$3,LOG!M:M,"RELACIONAMENTO")+COUNTIFS(LOG!L:L,A15,LOG!A:A,">="&$B$3,LOG!A:A,"<="&$D$3,LOG!M:M,"FOLLOW UP 7")+COUNTIFS(LOG!L:L,A15,LOG!A:A,">="&$B$3,LOG!A:A,"<="&$D$3,LOG!M:M,"FOLLOW UP 15")+COUNTIFS(LOG!L:L,A15,LOG!A:A,">="&$B$3,LOG!A:A,"<="&$D$3,LOG!M:M,"SUPORTE"),COUNTIFS(LOG!L:L,A15,LOG!A:A,">="&$B$3,LOG!A:A,"<="&$D$3,LOG!M:M,"RELACIONAMENTO",LOG!B:B,$B$2)+COUNTIFS(LOG!L:L,A15,LOG!A:A,">="&$B$3,LOG!A:A,"<="&$D$3,LOG!M:M,"FOLLOW UP 7",LOG!B:B,$B$2)+COUNTIFS(LOG!L:L,A15,LOG!A:A,">="&$B$3,LOG!A:A,"<="&$D$3,LOG!M:M,"FOLLOW UP 15",LOG!B:B,$B$2)+COUNTIFS(LOG!L:L,A15,LOG!A:A,">="&$B$3,LOG!A:A,"<="&$D$3,LOG!M:M,"SUPORTE",LOG!B:B,$B$2)) | E15: =IF($B$2="TODOS",COUNTIFS(LOG!L:L,A15,LOG!A:A,">="&$B$3,LOG!A:A,"<="&$D$3,LOG!M:M,"NÃO ATENDE")+COUNTIFS(LOG!L:L,A15,LOG!A:A,">="&$B$3,LOG!A:A,"<="&$D$3,LOG!M:M,"NÃO RESPONDE")+COUNTIFS(LOG!L:L,A15,LOG!A:A,">="&$B$3,LOG!A:A,"<="&$D$3,LOG!M:M,"RECUSOU LIGAÇÃO")+COUNTIFS(LOG!L:L,A15,LOG!A:A,">="&$B$3,LOG!A:A,"<="&$D$3,LOG!M:M,"PERDA / FECHOU LOJA"),COUNTIFS(LOG!L:L,A15,LOG!A:A,">="&$B$3,LOG!A:A,"<="&$D$3,LOG!M:M,"NÃO ATENDE",LOG!B:B,$B$2)+COUNTIFS(LOG!L:L,A15,LOG!A:A,">="&$B$3,LOG!A:A,"<="&$D$3,LOG!M:M,"NÃO RESPONDE",LOG!B:B,$B$2)+COUNTIFS(LOG!L:L,A15,LOG!A:A,">="&$B$3,LOG!A:A,"<="&$D$3,LOG!M:M,"RECUSOU LIGAÇÃO",LOG!B:B,$B$2)+COUNTIFS(LOG!L:L,A15,LOG!A:A,">="&$B$3,LOG!A:A,"<="&$D$3,LOG!M:M,"PERDA / FECHOU LOJA",LOG!B:B,$B$2))
A16: ATEND. CLIENTES INATIVOS | B16: =IF($B$2="TODOS",COUNTIFS(LOG!L:L,A16,LOG!A:A,">="&$B$3,LOG!A:A,"<="&$D$3),COUNTIFS(LOG!L:L,A16,LOG!A:A,">="&$B$3,LOG!A:A,"<="&$D$3,LOG!B:B,$B$2)) | C16: =IF($B$2="TODOS",COUNTIFS(LOG!L:L,A16,LOG!A:A,">="&$B$3,LOG!A:A,"<="&$D$3,LOG!M:M,"EM ATENDIMENTO")+COUNTIFS(LOG!L:L,A16,LOG!A:A,">="&$B$3,LOG!A:A,"<="&$D$3,LOG!M:M,"ORÇAMENTO")+COUNTIFS(LOG!L:L,A16,LOG!A:A,">="&$B$3,LOG!A:A,"<="&$D$3,LOG!M:M,"CADASTRO")+COUNTIFS(LOG!L:L,A16,LOG!A:A,">="&$B$3,LOG!A:A,"<="&$D$3,LOG!M:M,"VENDA / PEDIDO"),COUNTIFS(LOG!L:L,A16,LOG!A:A,">="&$B$3,LOG!A:A,"<="&$D$3,LOG!M:M,"EM ATENDIMENTO",LOG!B:B,$B$2)+COUNTIFS(LOG!L:L,A16,LOG!A:A,">="&$B$3,LOG!A:A,"<="&$D$3,LOG!M:M,"ORÇAMENTO",LOG!B:B,$B$2)+COUNTIFS(LOG!L:L,A16,LOG!A:A,">="&$B$3,LOG!A:A,"<="&$D$3,LOG!M:M,"CADASTRO",LOG!B:B,$B$2)+COUNTIFS(LOG!L:L,A16,LOG!A:A,">="&$B$3,LOG!A:A,"<="&$D$3,LOG!M:M,"VENDA / PEDIDO",LOG!B:B,$B$2)) | D16: =IF($B$2="TODOS",COUNTIFS(LOG!L:L,A16,LOG!A:A,">="&$B$3,LOG!A:A,"<="&$D$3,LOG!M:M,"RELACIONAMENTO")+COUNTIFS(LOG!L:L,A16,LOG!A:A,">="&$B$3,LOG!A:A,"<="&$D$3,LOG!M:M,"FOLLOW UP 7")+COUNTIFS(LOG!L:L,A16,LOG!A:A,">="&$B$3,LOG!A:A,"<="&$D$3,LOG!M:M,"FOLLOW UP 15")+COUNTIFS(LOG!L:L,A16,LOG!A:A,">="&$B$3,LOG!A:A,"<="&$D$3,LOG!M:M,"SUPORTE"),COUNTIFS(LOG!L:L,A16,LOG!A:A,">="&$B$3,LOG!A:A,"<="&$D$3,LOG!M:M,"RELACIONAMENTO",LOG!B:B,$B$2)+COUNTIFS(LOG!L:L,A16,LOG!A:A,">="&$B$3,LOG!A:A,"<="&$D$3,LOG!M:M,"FOLLOW UP 7",LOG!B:B,$B$2)+COUNTIFS(LOG!L:L,A16,LOG!A:A,">="&$B$3,LOG!A:A,"<="&$D$3,LOG!M:M,"FOLLOW UP 15",LOG!B:B,$B$2)+COUNTIFS(LOG!L:L,A16,LOG!A:A,">="&$B$3,LOG!A:A,"<="&$D$3,LOG!M:M,"SUPORTE",LOG!B:B,$B$2)) | E16: =IF($B$2="TODOS",COUNTIFS(LOG!L:L,A16,LOG!A:A,">="&$B$3,LOG!A:A,"<="&$D$3,LOG!M:M,"NÃO ATENDE")+COUNTIFS(LOG!L:L,A16,LOG!A:A,">="&$B$3,LOG!A:A,"<="&$D$3,LOG!M:M,"NÃO RESPONDE")+COUNTIFS(LOG!L:L,A16,LOG!A:A,">="&$B$3,LOG!A:A,"<="&$D$3,LOG!M:M,"RECUSOU LIGAÇÃO")+COUNTIFS(LOG!L:L,A16,LOG!A:A,">="&$B$3,LOG!A:A,"<="&$D$3,LOG!M:M,"PERDA / FECHOU LOJA"),COUNTIFS(LOG!L:L,A16,LOG!A:A,">="&$B$3,LOG!A:A,"<="&$D$3,LOG!M:M,"NÃO ATENDE",LOG!B:B,$B$2)+COUNTIFS(LOG!L:L,A16,LOG!A:A,">="&$B$3,LOG!A:A,"<="&$D$3,LOG!M:M,"NÃO RESPONDE",LOG!B:B,$B$2)+COUNTIFS(LOG!L:L,A16,LOG!A:A,">="&$B$3,LOG!A:A,"<="&$D$3,LOG!M:M,"RECUSOU LIGAÇÃO",LOG!B:B,$B$2)+COUNTIFS(LOG!L:L,A16,LOG!A:A,">="&$B$3,LOG!A:A,"<="&$D$3,LOG!M:M,"PERDA / FECHOU LOJA",LOG!B:B,$B$2))
A17: PÓS-VENDA / RELACIONAMENTO | B17: =IF($B$2="TODOS",COUNTIFS(LOG!L:L,A17,LOG!A:A,">="&$B$3,LOG!A:A,"<="&$D$3),COUNTIFS(LOG!L:L,A17,LOG!A:A,">="&$B$3,LOG!A:A,"<="&$D$3,LOG!B:B,$B$2)) | C17: =IF($B$2="TODOS",COUNTIFS(LOG!L:L,A17,LOG!A:A,">="&$B$3,LOG!A:A,"<="&$D$3,LOG!M:M,"EM ATENDIMENTO")+COUNTIFS(LOG!L:L,A17,LOG!A:A,">="&$B$3,LOG!A:A,"<="&$D$3,LOG!M:M,"ORÇAMENTO")+COUNTIFS(LOG!L:L,A17,LOG!A:A,">="&$B$3,LOG!A:A,"<="&$D$3,LOG!M:M,"CADASTRO")+COUNTIFS(LOG!L:L,A17,LOG!A:A,">="&$B$3,LOG!A:A,"<="&$D$3,LOG!M:M,"VENDA / PEDIDO"),COUNTIFS(LOG!L:L,A17,LOG!A:A,">="&$B$3,LOG!A:A,"<="&$D$3,LOG!M:M,"EM ATENDIMENTO",LOG!B:B,$B$2)+COUNTIFS(LOG!L:L,A17,LOG!A:A,">="&$B$3,LOG!A:A,"<="&$D$3,LOG!M:M,"ORÇAMENTO",LOG!B:B,$B$2)+COUNTIFS(LOG!L:L,A17,LOG!A:A,">="&$B$3,LOG!A:A,"<="&$D$3,LOG!M:M,"CADASTRO",LOG!B:B,$B$2)+COUNTIFS(LOG!L:L,A17,LOG!A:A,">="&$B$3,LOG!A:A,"<="&$D$3,LOG!M:M,"VENDA / PEDIDO",LOG!B:B,$B$2)) | D17: =IF($B$2="TODOS",COUNTIFS(LOG!L:L,A17,LOG!A:A,">="&$B$3,LOG!A:A,"<="&$D$3,LOG!M:M,"RELACIONAMENTO")+COUNTIFS(LOG!L:L,A17,LOG!A:A,">="&$B$3,LOG!A:A,"<="&$D$3,LOG!M:M,"FOLLOW UP 7")+COUNTIFS(LOG!L:L,A17,LOG!A:A,">="&$B$3,LOG!A:A,"<="&$D$3,LOG!M:M,"FOLLOW UP 15")+COUNTIFS(LOG!L:L,A17,LOG!A:A,">="&$B$3,LOG!A:A,"<="&$D$3,LOG!M:M,"SUPORTE"),COUNTIFS(LOG!L:L,A17,LOG!A:A,">="&$B$3,LOG!A:A,"<="&$D$3,LOG!M:M,"RELACIONAMENTO",LOG!B:B,$B$2)+COUNTIFS(LOG!L:L,A17,LOG!A:A,">="&$B$3,LOG!A:A,"<="&$D$3,LOG!M:M,"FOLLOW UP 7",LOG!B:B,$B$2)+COUNTIFS(LOG!L:L,A17,LOG!A:A,">="&$B$3,LOG!A:A,"<="&$D$3,LOG!M:M,"FOLLOW UP 15",LOG!B:B,$B$2)+COUNTIFS(LOG!L:L,A17,LOG!A:A,">="&$B$3,LOG!A:A,"<="&$D$3,LOG!M:M,"SUPORTE",LOG!B:B,$B$2)) | E17: =IF($B$2="TODOS",COUNTIFS(LOG!L:L,A17,LOG!A:A,">="&$B$3,LOG!A:A,"<="&$D$3,LOG!M:M,"NÃO ATENDE")+COUNTIFS(LOG!L:L,A17,LOG!A:A,">="&$B$3,LOG!A:A,"<="&$D$3,LOG!M:M,"NÃO RESPONDE")+COUNTIFS(LOG!L:L,A17,LOG!A:A,">="&$B$3,LOG!A:A,"<="&$D$3,LOG!M:M,"RECUSOU LIGAÇÃO")+COUNTIFS(LOG!L:L,A17,LOG!A:A,">="&$B$3,LOG!A:A,"<="&$D$3,LOG!M:M,"PERDA / FECHOU LOJA"),COUNTIFS(LOG!L:L,A17,LOG!A:A,">="&$B$3,LOG!A:A,"<="&$D$3,LOG!M:M,"NÃO ATENDE",LOG!B:B,$B$2)+COUNTIFS(LOG!L:L,A17,LOG!A:A,">="&$B$3,LOG!A:A,"<="&$D$3,LOG!M:M,"NÃO RESPONDE",LOG!B:B,$B$2)+COUNTIFS(LOG!L:L,A17,LOG!A:A,">="&$B$3,LOG!A:A,"<="&$D$3,LOG!M:M,"RECUSOU LIGAÇÃO",LOG!B:B,$B$2)+COUNTIFS(LOG!L:L,A17,LOG!A:A,">="&$B$3,LOG!A:A,"<="&$D$3,LOG!M:M,"PERDA / FECHOU LOJA",LOG!B:B,$B$2))
A18: MOTIVO / PAROU DE COMPRAR | B18: =IF($B$2="TODOS",COUNTIFS(LOG!L:L,A18,LOG!A:A,">="&$B$3,LOG!A:A,"<="&$D$3),COUNTIFS(LOG!L:L,A18,LOG!A:A,">="&$B$3,LOG!A:A,"<="&$D$3,LOG!B:B,$B$2)) | C18: =IF($B$2="TODOS",COUNTIFS(LOG!L:L,A18,LOG!A:A,">="&$B$3,LOG!A:A,"<="&$D$3,LOG!M:M,"EM ATENDIMENTO")+COUNTIFS(LOG!L:L,A18,LOG!A:A,">="&$B$3,LOG!A:A,"<="&$D$3,LOG!M:M,"ORÇAMENTO")+COUNTIFS(LOG!L:L,A18,LOG!A:A,">="&$B$3,LOG!A:A,"<="&$D$3,LOG!M:M,"CADASTRO")+COUNTIFS(LOG!L:L,A18,LOG!A:A,">="&$B$3,LOG!A:A,"<="&$D$3,LOG!M:M,"VENDA / PEDIDO"),COUNTIFS(LOG!L:L,A18,LOG!A:A,">="&$B$3,LOG!A:A,"<="&$D$3,LOG!M:M,"EM ATENDIMENTO",LOG!B:B,$B$2)+COUNTIFS(LOG!L:L,A18,LOG!A:A,">="&$B$3,LOG!A:A,"<="&$D$3,LOG!M:M,"ORÇAMENTO",LOG!B:B,$B$2)+COUNTIFS(LOG!L:L,A18,LOG!A:A,">="&$B$3,LOG!A:A,"<="&$D$3,LOG!M:M,"CADASTRO",LOG!B:B,$B$2)+COUNTIFS(LOG!L:L,A18,LOG!A:A,">="&$B$3,LOG!A:A,"<="&$D$3,LOG!M:M,"VENDA / PEDIDO",LOG!B:B,$B$2)) | D18: =IF($B$2="TODOS",COUNTIFS(LOG!L:L,A18,LOG!A:A,">="&$B$3,LOG!A:A,"<="&$D$3,LOG!M:M,"RELACIONAMENTO")+COUNTIFS(LOG!L:L,A18,LOG!A:A,">="&$B$3,LOG!A:A,"<="&$D$3,LOG!M:M,"FOLLOW UP 7")+COUNTIFS(LOG!L:L,A18,LOG!A:A,">="&$B$3,LOG!A:A,"<="&$D$3,LOG!M:M,"FOLLOW UP 15")+COUNTIFS(LOG!L:L,A18,LOG!A:A,">="&$B$3,LOG!A:A,"<="&$D$3,LOG!M:M,"SUPORTE"),COUNTIFS(LOG!L:L,A18,LOG!A:A,">="&$B$3,LOG!A:A,"<="&$D$3,LOG!M:M,"RELACIONAMENTO",LOG!B:B,$B$2)+COUNTIFS(LOG!L:L,A18,LOG!A:A,">="&$B$3,LOG!A:A,"<="&$D$3,LOG!M:M,"FOLLOW UP 7",LOG!B:B,$B$2)+COUNTIFS(LOG!L:L,A18,LOG!A:A,">="&$B$3,LOG!A:A,"<="&$D$3,LOG!M:M,"FOLLOW UP 15",LOG!B:B,$B$2)+COUNTIFS(LOG!L:L,A18,LOG!A:A,">="&$B$3,LOG!A:A,"<="&$D$3,LOG!M:M,"SUPORTE",LOG!B:B,$B$2)) | E18: =IF($B$2="TODOS",COUNTIFS(LOG!L:L,A18,LOG!A:A,">="&$B$3,LOG!A:A,"<="&$D$3,LOG!M:M,"NÃO ATENDE")+COUNTIFS(LOG!L:L,A18,LOG!A:A,">="&$B$3,LOG!A:A,"<="&$D$3,LOG!M:M,"NÃO RESPONDE")+COUNTIFS(LOG!L:L,A18,LOG!A:A,">="&$B$3,LOG!A:A,"<="&$D$3,LOG!M:M,"RECUSOU LIGAÇÃO")+COUNTIFS(LOG!L:L,A18,LOG!A:A,">="&$B$3,LOG!A:A,"<="&$D$3,LOG!M:M,"PERDA / FECHOU LOJA"),COUNTIFS(LOG!L:L,A18,LOG!A:A,">="&$B$3,LOG!A:A,"<="&$D$3,LOG!M:M,"NÃO ATENDE",LOG!B:B,$B$2)+COUNTIFS(LOG!L:L,A18,LOG!A:A,">="&$B$3,LOG!A:A,"<="&$D$3,LOG!M:M,"NÃO RESPONDE",LOG!B:B,$B$2)+COUNTIFS(LOG!L:L,A18,LOG!A:A,">="&$B$3,LOG!A:A,"<="&$D$3,LOG!M:M,"RECUSOU LIGAÇÃO",LOG!B:B,$B$2)+COUNTIFS(LOG!L:L,A18,LOG!A:A,">="&$B$3,LOG!A:A,"<="&$D$3,LOG!M:M,"PERDA / FECHOU LOJA",LOG!B:B,$B$2))
A19: TOTAL | B19: =SUM(B12:B18) | C19: =SUM(C12:C18) | D19: =SUM(D12:D18) | E19: =SUM(E12:E18)
A22: CRUZAMENTO TIPO × RESULTADO
A23: TIPO \ RESULTADO | B23: EM ATENDIMENTO | C23: ORÇAMENTO | D23: CADASTRO | E23: VENDA / PEDIDO | F23: RELACIONAMENTO | G23: FOLLOW UP 7 | H23: FOLLOW UP 15 | I23: SUPORTE | J23: NÃO ATENDE | K23: NÃO RESPONDE | L23: RECUSOU LIGAÇÃO | M23: PERDA / FECHOU LOJA
A24: PROSPECÇÃO | B24: =IF($B$2="TODOS",COUNTIFS(LOG!L:L,$A24,LOG!M:M,B$23,LOG!A:A,">="&$B$3,LOG!A:A,"<="&$D$3),COUNTIFS(LOG!L:L,$A24,LOG!M:M,B$23,LOG!A:A,">="&$B$3,LOG!A:A,"<="&$D$3,LOG!B:B,$B$2)) | C24: =IF($B$2="TODOS",COUNTIFS(LOG!L:L,$A24,LOG!M:M,C$23,LOG!A:A,">="&$B$3,LOG!A:A,"<="&$D$3),COUNTIFS(LOG!L:L,$A24,LOG!M:M,C$23,LOG!A:A,">="&$B$3,LOG!A:A,"<="&$D$3,LOG!B:B,$B$2)) | D24: =IF($B$2="TODOS",COUNTIFS(LOG!L:L,$A24,LOG!M:M,D$23,LOG!A:A,">="&$B$3,LOG!A:A,"<="&$D$3),COUNTIFS(LOG!L:L,$A24,LOG!M:M,D$23,LOG!A:A,">="&$B$3,LOG!A:A,"<="&$D$3,LOG!B:B,$B$2)) | E24: =IF($B$2="TODOS",COUNTIFS(LOG!L:L,$A24,LOG!M:M,E$23,LOG!A:A,">="&$B$3,LOG!A:A,"<="&$D$3),COUNTIFS(LOG!L:L,$A24,LOG!M:M,E$23,LOG!A:A,">="&$B$3,LOG!A:A,"<="&$D$3,LOG!B:B,$B$2)) | F24: =IF($B$2="TODOS",COUNTIFS(LOG!L:L,$A24,LOG!M:M,F$23,LOG!A:A,">="&$B$3,LOG!A:A,"<="&$D$3),COUNTIFS(LOG!L:L,$A24,LOG!M:M,F$23,LOG!A:A,">="&$B$3,LOG!A:A,"<="&$D$3,LOG!B:B,$B$2)) | G24: =IF($B$2="TODOS",COUNTIFS(LOG!L:L,$A24,LOG!M:M,G$23,LOG!A:A,">="&$B$3,LOG!A:A,"<="&$D$3),COUNTIFS(LOG!L:L,$A24,LOG!M:M,G$23,LOG!A:A,">="&$B$3,LOG!A:A,"<="&$D$3,LOG!B:B,$B$2)) | H24: =IF($B$2="TODOS",COUNTIFS(LOG!L:L,$A24,LOG!M:M,H$23,LOG!A:A,">="&$B$3,LOG!A:A,"<="&$D$3),COUNTIFS(LOG!L:L,$A24,LOG!M:M,H$23,LOG!A:A,">="&$B$3,LOG!A:A,"<="&$D$3,LOG!B:B,$B$2)) | I24: =IF($B$2="TODOS",COUNTIFS(LOG!L:L,$A24,LOG!M:M,I$23,LOG!A:A,">="&$B$3,LOG!A:A,"<="&$D$3),COUNTIFS(LOG!L:L,$A24,LOG!M:M,I$23,LOG!A:A,">="&$B$3,LOG!A:A,"<="&$D$3,LOG!B:B,$B$2)) | ... M24: =IF($B$2="TODOS",COUNTIFS(LOG!L:L,$A24,LOG!M:M,M$23,LOG!A:A,">="&$B$3,LOG!A:A,"<="&$D$3),COUNTIFS(LOG!L:L,$A24,LOG!M:M,M$23,LOG!A:A,">="&$B$3,LOG!A:A,"<="&$D$3,LOG!B:B,$B$2))
A25: NEGOCIAÇÃO | B25: =IF($B$2="TODOS",COUNTIFS(LOG!L:L,$A25,LOG!M:M,B$23,LOG!A:A,">="&$B$3,LOG!A:A,"<="&$D$3),COUNTIFS(LOG!L:L,$A25,LOG!M:M,B$23,LOG!A:A,">="&$B$3,LOG!A:A,"<="&$D$3,LOG!B:B,$B$2)) | C25: =IF($B$2="TODOS",COUNTIFS(LOG!L:L,$A25,LOG!M:M,C$23,LOG!A:A,">="&$B$3,LOG!A:A,"<="&$D$3),COUNTIFS(LOG!L:L,$A25,LOG!M:M,C$23,LOG!A:A,">="&$B$3,LOG!A:A,"<="&$D$3,LOG!B:B,$B$2)) | D25: =IF($B$2="TODOS",COUNTIFS(LOG!L:L,$A25,LOG!M:M,D$23,LOG!A:A,">="&$B$3,LOG!A:A,"<="&$D$3),COUNTIFS(LOG!L:L,$A25,LOG!M:M,D$23,LOG!A:A,">="&$B$3,LOG!A:A,"<="&$D$3,LOG!B:B,$B$2)) | E25: =IF($B$2="TODOS",COUNTIFS(LOG!L:L,$A25,LOG!M:M,E$23,LOG!A:A,">="&$B$3,LOG!A:A,"<="&$D$3),COUNTIFS(LOG!L:L,$A25,LOG!M:M,E$23,LOG!A:A,">="&$B$3,LOG!A:A,"<="&$D$3,LOG!B:B,$B$2)) | F25: =IF($B$2="TODOS",COUNTIFS(LOG!L:L,$A25,LOG!M:M,F$23,LOG!A:A,">="&$B$3,LOG!A:A,"<="&$D$3),COUNTIFS(LOG!L:L,$A25,LOG!M:M,F$23,LOG!A:A,">="&$B$3,LOG!A:A,"<="&$D$3,LOG!B:B,$B$2)) | G25: =IF($B$2="TODOS",COUNTIFS(LOG!L:L,$A25,LOG!M:M,G$23,LOG!A:A,">="&$B$3,LOG!A:A,"<="&$D$3),COUNTIFS(LOG!L:L,$A25,LOG!M:M,G$23,LOG!A:A,">="&$B$3,LOG!A:A,"<="&$D$3,LOG!B:B,$B$2)) | H25: =IF($B$2="TODOS",COUNTIFS(LOG!L:L,$A25,LOG!M:M,H$23,LOG!A:A,">="&$B$3,LOG!A:A,"<="&$D$3),COUNTIFS(LOG!L:L,$A25,LOG!M:M,H$23,LOG!A:A,">="&$B$3,LOG!A:A,"<="&$D$3,LOG!B:B,$B$2)) | I25: =IF($B$2="TODOS",COUNTIFS(LOG!L:L,$A25,LOG!M:M,I$23,LOG!A:A,">="&$B$3,LOG!A:A,"<="&$D$3),COUNTIFS(LOG!L:L,$A25,LOG!M:M,I$23,LOG!A:A,">="&$B$3,LOG!A:A,"<="&$D$3,LOG!B:B,$B$2)) | ... M25: =IF($B$2="TODOS",COUNTIFS(LOG!L:L,$A25,LOG!M:M,M$23,LOG!A:A,">="&$B$3,LOG!A:A,"<="&$D$3),COUNTIFS(LOG!L:L,$A25,LOG!M:M,M$23,LOG!A:A,">="&$B$3,LOG!A:A,"<="&$D$3,LOG!B:B,$B$2))
A26: FOLLOW UP | B26: =IF($B$2="TODOS",COUNTIFS(LOG!L:L,$A26,LOG!M:M,B$23,LOG!A:A,">="&$B$3,LOG!A:A,"<="&$D$3),COUNTIFS(LOG!L:L,$A26,LOG!M:M,B$23,LOG!A:A,">="&$B$3,LOG!A:A,"<="&$D$3,LOG!B:B,$B$2)) | C26: =IF($B$2="TODOS",COUNTIFS(LOG!L:L,$A26,LOG!M:M,C$23,LOG!A:A,">="&$B$3,LOG!A:A,"<="&$D$3),COUNTIFS(LOG!L:L,$A26,LOG!M:M,C$23,LOG!A:A,">="&$B$3,LOG!A:A,"<="&$D$3,LOG!B:B,$B$2)) | D26: =IF($B$2="TODOS",COUNTIFS(LOG!L:L,$A26,LOG!M:M,D$23,LOG!A:A,">="&$B$3,LOG!A:A,"<="&$D$3),COUNTIFS(LOG!L:L,$A26,LOG!M:M,D$23,LOG!A:A,">="&$B$3,LOG!A:A,"<="&$D$3,LOG!B:B,$B$2)) | E26: =IF($B$2="TODOS",COUNTIFS(LOG!L:L,$A26,LOG!M:M,E$23,LOG!A:A,">="&$B$3,LOG!A:A,"<="&$D$3),COUNTIFS(LOG!L:L,$A26,LOG!M:M,E$23,LOG!A:A,">="&$B$3,LOG!A:A,"<="&$D$3,LOG!B:B,$B$2)) | F26: =IF($B$2="TODOS",COUNTIFS(LOG!L:L,$A26,LOG!M:M,F$23,LOG!A:A,">="&$B$3,LOG!A:A,"<="&$D$3),COUNTIFS(LOG!L:L,$A26,LOG!M:M,F$23,LOG!A:A,">="&$B$3,LOG!A:A,"<="&$D$3,LOG!B:B,$B$2)) | G26: =IF($B$2="TODOS",COUNTIFS(LOG!L:L,$A26,LOG!M:M,G$23,LOG!A:A,">="&$B$3,LOG!A:A,"<="&$D$3),COUNTIFS(LOG!L:L,$A26,LOG!M:M,G$23,LOG!A:A,">="&$B$3,LOG!A:A,"<="&$D$3,LOG!B:B,$B$2)) | H26: =IF($B$2="TODOS",COUNTIFS(LOG!L:L,$A26,LOG!M:M,H$23,LOG!A:A,">="&$B$3,LOG!A:A,"<="&$D$3),COUNTIFS(LOG!L:L,$A26,LOG!M:M,H$23,LOG!A:A,">="&$B$3,LOG!A:A,"<="&$D$3,LOG!B:B,$B$2)) | I26: =IF($B$2="TODOS",COUNTIFS(LOG!L:L,$A26,LOG!M:M,I$23,LOG!A:A,">="&$B$3,LOG!A:A,"<="&$D$3),COUNTIFS(LOG!L:L,$A26,LOG!M:M,I$23,LOG!A:A,">="&$B$3,LOG!A:A,"<="&$D$3,LOG!B:B,$B$2)) | ... M26: =IF($B$2="TODOS",COUNTIFS(LOG!L:L,$A26,LOG!M:M,M$23,LOG!A:A,">="&$B$3,LOG!A:A,"<="&$D$3),COUNTIFS(LOG!L:L,$A26,LOG!M:M,M$23,LOG!A:A,">="&$B$3,LOG!A:A,"<="&$D$3,LOG!B:B,$B$2))
A27: ATEND. CLIENTES ATIVOS | B27: =IF($B$2="TODOS",COUNTIFS(LOG!L:L,$A27,LOG!M:M,B$23,LOG!A:A,">="&$B$3,LOG!A:A,"<="&$D$3),COUNTIFS(LOG!L:L,$A27,LOG!M:M,B$23,LOG!A:A,">="&$B$3,LOG!A:A,"<="&$D$3,LOG!B:B,$B$2)) | C27: =IF($B$2="TODOS",COUNTIFS(LOG!L:L,$A27,LOG!M:M,C$23,LOG!A:A,">="&$B$3,LOG!A:A,"<="&$D$3),COUNTIFS(LOG!L:L,$A27,LOG!M:M,C$23,LOG!A:A,">="&$B$3,LOG!A:A,"<="&$D$3,LOG!B:B,$B$2)) | D27: =IF($B$2="TODOS",COUNTIFS(LOG!L:L,$A27,LOG!M:M,D$23,LOG!A:A,">="&$B$3,LOG!A:A,"<="&$D$3),COUNTIFS(LOG!L:L,$A27,LOG!M:M,D$23,LOG!A:A,">="&$B$3,LOG!A:A,"<="&$D$3,LOG!B:B,$B$2)) | E27: =IF($B$2="TODOS",COUNTIFS(LOG!L:L,$A27,LOG!M:M,E$23,LOG!A:A,">="&$B$3,LOG!A:A,"<="&$D$3),COUNTIFS(LOG!L:L,$A27,LOG!M:M,E$23,LOG!A:A,">="&$B$3,LOG!A:A,"<="&$D$3,LOG!B:B,$B$2)) | F27: =IF($B$2="TODOS",COUNTIFS(LOG!L:L,$A27,LOG!M:M,F$23,LOG!A:A,">="&$B$3,LOG!A:A,"<="&$D$3),COUNTIFS(LOG!L:L,$A27,LOG!M:M,F$23,LOG!A:A,">="&$B$3,LOG!A:A,"<="&$D$3,LOG!B:B,$B$2)) | G27: =IF($B$2="TODOS",COUNTIFS(LOG!L:L,$A27,LOG!M:M,G$23,LOG!A:A,">="&$B$3,LOG!A:A,"<="&$D$3),COUNTIFS(LOG!L:L,$A27,LOG!M:M,G$23,LOG!A:A,">="&$B$3,LOG!A:A,"<="&$D$3,LOG!B:B,$B$2)) | H27: =IF($B$2="TODOS",COUNTIFS(LOG!L:L,$A27,LOG!M:M,H$23,LOG!A:A,">="&$B$3,LOG!A:A,"<="&$D$3),COUNTIFS(LOG!L:L,$A27,LOG!M:M,H$23,LOG!A:A,">="&$B$3,LOG!A:A,"<="&$D$3,LOG!B:B,$B$2)) | I27: =IF($B$2="TODOS",COUNTIFS(LOG!L:L,$A27,LOG!M:M,I$23,LOG!A:A,">="&$B$3,LOG!A:A,"<="&$D$3),COUNTIFS(LOG!L:L,$A27,LOG!M:M,I$23,LOG!A:A,">="&$B$3,LOG!A:A,"<="&$D$3,LOG!B:B,$B$2)) | ... M27: =IF($B$2="TODOS",COUNTIFS(LOG!L:L,$A27,LOG!M:M,M$23,LOG!A:A,">="&$B$3,LOG!A:A,"<="&$D$3),COUNTIFS(LOG!L:L,$A27,LOG!M:M,M$23,LOG!A:A,">="&$B$3,LOG!A:A,"<="&$D$3,LOG!B:B,$B$2))
A28: ATEND. CLIENTES INATIVOS | B28: =IF($B$2="TODOS",COUNTIFS(LOG!L:L,$A28,LOG!M:M,B$23,LOG!A:A,">="&$B$3,LOG!A:A,"<="&$D$3),COUNTIFS(LOG!L:L,$A28,LOG!M:M,B$23,LOG!A:A,">="&$B$3,LOG!A:A,"<="&$D$3,LOG!B:B,$B$2)) | C28: =IF($B$2="TODOS",COUNTIFS(LOG!L:L,$A28,LOG!M:M,C$23,LOG!A:A,">="&$B$3,LOG!A:A,"<="&$D$3),COUNTIFS(LOG!L:L,$A28,LOG!M:M,C$23,LOG!A:A,">="&$B$3,LOG!A:A,"<="&$D$3,LOG!B:B,$B$2)) | D28: =IF($B$2="TODOS",COUNTIFS(LOG!L:L,$A28,LOG!M:M,D$23,LOG!A:A,">="&$B$3,LOG!A:A,"<="&$D$3),COUNTIFS(LOG!L:L,$A28,LOG!M:M,D$23,LOG!A:A,">="&$B$3,LOG!A:A,"<="&$D$3,LOG!B:B,$B$2)) | E28: =IF($B$2="TODOS",COUNTIFS(LOG!L:L,$A28,LOG!M:M,E$23,LOG!A:A,">="&$B$3,LOG!A:A,"<="&$D$3),COUNTIFS(LOG!L:L,$A28,LOG!M:M,E$23,LOG!A:A,">="&$B$3,LOG!A:A,"<="&$D$3,LOG!B:B,$B$2)) | F28: =IF($B$2="TODOS",COUNTIFS(LOG!L:L,$A28,LOG!M:M,F$23,LOG!A:A,">="&$B$3,LOG!A:A,"<="&$D$3),COUNTIFS(LOG!L:L,$A28,LOG!M:M,F$23,LOG!A:A,">="&$B$3,LOG!A:A,"<="&$D$3,LOG!B:B,$B$2)) | G28: =IF($B$2="TODOS",COUNTIFS(LOG!L:L,$A28,LOG!M:M,G$23,LOG!A:A,">="&$B$3,LOG!A:A,"<="&$D$3),COUNTIFS(LOG!L:L,$A28,LOG!M:M,G$23,LOG!A:A,">="&$B$3,LOG!A:A,"<="&$D$3,LOG!B:B,$B$2)) | H28: =IF($B$2="TODOS",COUNTIFS(LOG!L:L,$A28,LOG!M:M,H$23,LOG!A:A,">="&$B$3,LOG!A:A,"<="&$D$3),COUNTIFS(LOG!L:L,$A28,LOG!M:M,H$23,LOG!A:A,">="&$B$3,LOG!A:A,"<="&$D$3,LOG!B:B,$B$2)) | I28: =IF($B$2="TODOS",COUNTIFS(LOG!L:L,$A28,LOG!M:M,I$23,LOG!A:A,">="&$B$3,LOG!A:A,"<="&$D$3),COUNTIFS(LOG!L:L,$A28,LOG!M:M,I$23,LOG!A:A,">="&$B$3,LOG!A:A,"<="&$D$3,LOG!B:B,$B$2)) | ... M28: =IF($B$2="TODOS",COUNTIFS(LOG!L:L,$A28,LOG!M:M,M$23,LOG!A:A,">="&$B$3,LOG!A:A,"<="&$D$3),COUNTIFS(LOG!L:L,$A28,LOG!M:M,M$23,LOG!A:A,">="&$B$3,LOG!A:A,"<="&$D$3,LOG!B:B,$B$2))
A29: PÓS-VENDA / RELACIONAMENTO | B29: =IF($B$2="TODOS",COUNTIFS(LOG!L:L,$A29,LOG!M:M,B$23,LOG!A:A,">="&$B$3,LOG!A:A,"<="&$D$3),COUNTIFS(LOG!L:L,$A29,LOG!M:M,B$23,LOG!A:A,">="&$B$3,LOG!A:A,"<="&$D$3,LOG!B:B,$B$2)) | C29: =IF($B$2="TODOS",COUNTIFS(LOG!L:L,$A29,LOG!M:M,C$23,LOG!A:A,">="&$B$3,LOG!A:A,"<="&$D$3),COUNTIFS(LOG!L:L,$A29,LOG!M:M,C$23,LOG!A:A,">="&$B$3,LOG!A:A,"<="&$D$3,LOG!B:B,$B$2)) | D29: =IF($B$2="TODOS",COUNTIFS(LOG!L:L,$A29,LOG!M:M,D$23,LOG!A:A,">="&$B$3,LOG!A:A,"<="&$D$3),COUNTIFS(LOG!L:L,$A29,LOG!M:M,D$23,LOG!A:A,">="&$B$3,LOG!A:A,"<="&$D$3,LOG!B:B,$B$2)) | E29: =IF($B$2="TODOS",COUNTIFS(LOG!L:L,$A29,LOG!M:M,E$23,LOG!A:A,">="&$B$3,LOG!A:A,"<="&$D$3),COUNTIFS(LOG!L:L,$A29,LOG!M:M,E$23,LOG!A:A,">="&$B$3,LOG!A:A,"<="&$D$3,LOG!B:B,$B$2)) | F29: =IF($B$2="TODOS",COUNTIFS(LOG!L:L,$A29,LOG!M:M,F$23,LOG!A:A,">="&$B$3,LOG!A:A,"<="&$D$3),COUNTIFS(LOG!L:L,$A29,LOG!M:M,F$23,LOG!A:A,">="&$B$3,LOG!A:A,"<="&$D$3,LOG!B:B,$B$2)) | G29: =IF($B$2="TODOS",COUNTIFS(LOG!L:L,$A29,LOG!M:M,G$23,LOG!A:A,">="&$B$3,LOG!A:A,"<="&$D$3),COUNTIFS(LOG!L:L,$A29,LOG!M:M,G$23,LOG!A:A,">="&$B$3,LOG!A:A,"<="&$D$3,LOG!B:B,$B$2)) | H29: =IF($B$2="TODOS",COUNTIFS(LOG!L:L,$A29,LOG!M:M,H$23,LOG!A:A,">="&$B$3,LOG!A:A,"<="&$D$3),COUNTIFS(LOG!L:L,$A29,LOG!M:M,H$23,LOG!A:A,">="&$B$3,LOG!A:A,"<="&$D$3,LOG!B:B,$B$2)) | I29: =IF($B$2="TODOS",COUNTIFS(LOG!L:L,$A29,LOG!M:M,I$23,LOG!A:A,">="&$B$3,LOG!A:A,"<="&$D$3),COUNTIFS(LOG!L:L,$A29,LOG!M:M,I$23,LOG!A:A,">="&$B$3,LOG!A:A,"<="&$D$3,LOG!B:B,$B$2)) | ... M29: =IF($B$2="TODOS",COUNTIFS(LOG!L:L,$A29,LOG!M:M,M$23,LOG!A:A,">="&$B$3,LOG!A:A,"<="&$D$3),COUNTIFS(LOG!L:L,$A29,LOG!M:M,M$23,LOG!A:A,">="&$B$3,LOG!A:A,"<="&$D$3,LOG!B:B,$B$2))
A30: MOTIVO / PAROU DE COMPRAR | B30: =IF($B$2="TODOS",COUNTIFS(LOG!L:L,$A30,LOG!M:M,B$23,LOG!A:A,">="&$B$3,LOG!A:A,"<="&$D$3),COUNTIFS(LOG!L:L,$A30,LOG!M:M,B$23,LOG!A:A,">="&$B$3,LOG!A:A,"<="&$D$3,LOG!B:B,$B$2)) | C30: =IF($B$2="TODOS",COUNTIFS(LOG!L:L,$A30,LOG!M:M,C$23,LOG!A:A,">="&$B$3,LOG!A:A,"<="&$D$3),COUNTIFS(LOG!L:L,$A30,LOG!M:M,C$23,LOG!A:A,">="&$B$3,LOG!A:A,"<="&$D$3,LOG!B:B,$B$2)) | D30: =IF($B$2="TODOS",COUNTIFS(LOG!L:L,$A30,LOG!M:M,D$23,LOG!A:A,">="&$B$3,LOG!A:A,"<="&$D$3),COUNTIFS(LOG!L:L,$A30,LOG!M:M,D$23,LOG!A:A,">="&$B$3,LOG!A:A,"<="&$D$3,LOG!B:B,$B$2)) | E30: =IF($B$2="TODOS",COUNTIFS(LOG!L:L,$A30,LOG!M:M,E$23,LOG!A:A,">="&$B$3,LOG!A:A,"<="&$D$3),COUNTIFS(LOG!L:L,$A30,LOG!M:M,E$23,LOG!A:A,">="&$B$3,LOG!A:A,"<="&$D$3,LOG!B:B,$B$2)) | F30: =IF($B$2="TODOS",COUNTIFS(LOG!L:L,$A30,LOG!M:M,F$23,LOG!A:A,">="&$B$3,LOG!A:A,"<="&$D$3),COUNTIFS(LOG!L:L,$A30,LOG!M:M,F$23,LOG!A:A,">="&$B$3,LOG!A:A,"<="&$D$3,LOG!B:B,$B$2)) | G30: =IF($B$2="TODOS",COUNTIFS(LOG!L:L,$A30,LOG!M:M,G$23,LOG!A:A,">="&$B$3,LOG!A:A,"<="&$D$3),COUNTIFS(LOG!L:L,$A30,LOG!M:M,G$23,LOG!A:A,">="&$B$3,LOG!A:A,"<="&$D$3,LOG!B:B,$B$2)) | H30: =IF($B$2="TODOS",COUNTIFS(LOG!L:L,$A30,LOG!M:M,H$23,LOG!A:A,">="&$B$3,LOG!A:A,"<="&$D$3),COUNTIFS(LOG!L:L,$A30,LOG!M:M,H$23,LOG!A:A,">="&$B$3,LOG!A:A,"<="&$D$3,LOG!B:B,$B$2)) | I30: =IF($B$2="TODOS",COUNTIFS(LOG!L:L,$A30,LOG!M:M,I$23,LOG!A:A,">="&$B$3,LOG!A:A,"<="&$D$3),COUNTIFS(LOG!L:L,$A30,LOG!M:M,I$23,LOG!A:A,">="&$B$3,LOG!A:A,"<="&$D$3,LOG!B:B,$B$2)) | ... M30: =IF($B$2="TODOS",COUNTIFS(LOG!L:L,$A30,LOG!M:M,M$23,LOG!A:A,">="&$B$3,LOG!A:A,"<="&$D$3),COUNTIFS(LOG!L:L,$A30,LOG!M:M,M$23,LOG!A:A,">="&$B$3,LOG!A:A,"<="&$D$3,LOG!B:B,$B$2))
A34: 📋 POR QUE NÃO COMPRAM — INTELIGÊNCIA DIRETORIA
A35: MOTIVO | B35: QTD | C35: % | D35: DONO DA AÇÃO
A36: PRODUTO NÃO VENDEU / SEM GIRO | B36: =IF($B$2="TODOS",COUNTIFS(LOG!N:N,A36,LOG!A:A,">="&$B$3,LOG!A:A,"<="&$D$3),COUNTIFS(LOG!N:N,A36,LOG!A:A,">="&$B$3,LOG!A:A,"<="&$D$3,LOG!B:B,$B$2)) | C36: =IFERROR(B36/SUM($B$36:$B$45),0) | D36: DIRETORIA / FÁBRICA
A37: PREÇO ALTO / MARGEM | B37: =IF($B$2="TODOS",COUNTIFS(LOG!N:N,A37,LOG!A:A,">="&$B$3,LOG!A:A,"<="&$D$3),COUNTIFS(LOG!N:N,A37,LOG!A:A,">="&$B$3,LOG!A:A,"<="&$D$3,LOG!B:B,$B$2)) | C37: =IFERROR(B37/SUM($B$36:$B$45),0) | D37: COMERCIAL
A38: PREFERIU CONCORRENTE | B38: =IF($B$2="TODOS",COUNTIFS(LOG!N:N,A38,LOG!A:A,">="&$B$3,LOG!A:A,"<="&$D$3),COUNTIFS(LOG!N:N,A38,LOG!A:A,">="&$B$3,LOG!A:A,"<="&$D$3,LOG!B:B,$B$2)) | C38: =IFERROR(B38/SUM($B$36:$B$45),0) | D38: COMERCIAL / MKT
A39: PROBLEMA LOGÍSTICO | B39: =IF($B$2="TODOS",COUNTIFS(LOG!N:N,A39,LOG!A:A,">="&$B$3,LOG!A:A,"<="&$D$3),COUNTIFS(LOG!N:N,A39,LOG!A:A,">="&$B$3,LOG!A:A,"<="&$D$3,LOG!B:B,$B$2)) | C39: =IFERROR(B39/SUM($B$36:$B$45),0) | D39: LOGÍSTICA
A40: PROBLEMA FINANCEIRO | B40: =IF($B$2="TODOS",COUNTIFS(LOG!N:N,A40,LOG!A:A,">="&$B$3,LOG!A:A,"<="&$D$3),COUNTIFS(LOG!N:N,A40,LOG!A:A,">="&$B$3,LOG!A:A,"<="&$D$3,LOG!B:B,$B$2)) | C40: =IFERROR(B40/SUM($B$36:$B$45),0) | D40: FINANCEIRO
A41: AINDA TEM ESTOQUE | B41: =IF($B$2="TODOS",COUNTIFS(LOG!N:N,A41,LOG!A:A,">="&$B$3,LOG!A:A,"<="&$D$3),COUNTIFS(LOG!N:N,A41,LOG!A:A,">="&$B$3,LOG!A:A,"<="&$D$3,LOG!B:B,$B$2)) | C41: =IFERROR(B41/SUM($B$36:$B$45),0) | D41: NORMAL
A42: FECHOU LOJA | B42: =IF($B$2="TODOS",COUNTIFS(LOG!N:N,A42,LOG!A:A,">="&$B$3,LOG!A:A,"<="&$D$3),COUNTIFS(LOG!N:N,A42,LOG!A:A,">="&$B$3,LOG!A:A,"<="&$D$3,LOG!B:B,$B$2)) | C42: =IFERROR(B42/SUM($B$36:$B$45),0) | D42: PERDA
A43: SEM INTERESSE | B43: =IF($B$2="TODOS",COUNTIFS(LOG!N:N,A43,LOG!A:A,">="&$B$3,LOG!A:A,"<="&$D$3),COUNTIFS(LOG!N:N,A43,LOG!A:A,">="&$B$3,LOG!A:A,"<="&$D$3,LOG!B:B,$B$2)) | C43: =IFERROR(B43/SUM($B$36:$B$45),0) | D43: NUTRIÇÃO
A44: VIAJANDO / INDISPONÍVEL | B44: =IF($B$2="TODOS",COUNTIFS(LOG!N:N,A44,LOG!A:A,">="&$B$3,LOG!A:A,"<="&$D$3),COUNTIFS(LOG!N:N,A44,LOG!A:A,">="&$B$3,LOG!A:A,"<="&$D$3,LOG!B:B,$B$2)) | C44: =IFERROR(B44/SUM($B$36:$B$45),0) | D44: NORMAL
A45: 1º CONTATO / SEM MOTIVO | B45: =IF($B$2="TODOS",COUNTIFS(LOG!N:N,A45,LOG!A:A,">="&$B$3,LOG!A:A,"<="&$D$3),COUNTIFS(LOG!N:N,A45,LOG!A:A,">="&$B$3,LOG!A:A,"<="&$D$3,LOG!B:B,$B$2)) | C45: =IFERROR(B45/SUM($B$36:$B$45),0) | D45: NORMAL
A46: TOTAL | B46: =SUM(B36:B45) | C46: 1
A49: FORMA DO CONTATO
A50: FORMA | B50: QTD | C50: %
A51: Só WhatsApp | B51: =IF($B$2="TODOS",COUNTIFS(LOG!H:H,"SIM",LOG!I:I,"NÃO",LOG!A:A,">="&$B$3,LOG!A:A,"<="&$D$3),COUNTIFS(LOG!H:H,"SIM",LOG!I:I,"NÃO",LOG!A:A,">="&$B$3,LOG!A:A,"<="&$D$3,LOG!B:B,$B$2)) | C51: =IFERROR(B51/SUM($B$51:$B$53),0)
...

Sheet AGENDA
A1: 📋 AGENDA DD/MM/AAAA — [CONSULTOR]
A2: Cart:XX | Prosp:XX | Follow-ups:XX | Novos:XX
A3: ⏰ 8:00 Reunião | ☀ 9-12 CARTEIRA | 🌙 13-17 PROSPECÇÃO
A4: ⚠ REGISTRAR TUDO: Mercos + Kanban WhatsApp + Esta planilha
A6: NOME FANTASIA | B6: CNPJ | C6: UF | D6: REDE/REGIONAL | E6: TELEFONE | F6: EMAIL | G6: SITUAÇÃO | H6: DIAS SEM COMPRA | I6: SINALEIRO | J6: FASE | K6: TENTATIVA | L6: AÇÃO SUGERIDA | M6: BLOCO | N6: ÚLTIMO RESULTADO | O6: WHATSAPP | P6: LIGAÇÃO | Q6: LIGAÇÃO ATENDIDA | R6: TIPO AÇÃO | S6: TIPO DO CONTATO | T6: RESULTADO | U6: MOTIVO | V6: AÇÃO FUTURA | W6: MERCOS ATUALIZADO | X6: NOTA DO DIA
A7: DIVINA TERRA CWB | B7: 32828171000108 | C7: PR | D7: DIVINA TERRA | E7: 5541999990001 | F7: divina@email.com | G7: ATIVO | H7: 12 | I7: 🟢 | J7: CS | K7: T1 | L7: Ligar oferecer mix | M7: MANHÃ | N7: RELACIONAMENTO | O7: SIM | P7: NÃO | Q7: N/A | R7: ATIVO | S7: PÓS-VENDA / RELACIONAMENTO | T7: RELACIONAMENTO | U7: AINDA TEM ESTOQUE | V7: Verificar estoque | W7: SIM | X7: Cliente satisfeito
A8: ALICE GRAOS | B8: 41626544000140 | C8: RS | D8: TUDO EM GRAOS | E8: 5551999990002 | F8: alice@email.com | G8: EM RISCO | H8: 53 | I8: 🟡 | J8: RECOMPRA | K8: T1 | L8: WhatsApp recompra | M8: MANHÃ | N8: NÃO RESPONDE
A9: CIA SAUDE SP | B9: 12345678000199 | C9: SP | D9: CIA DA SAUDE | E9: 5511999990005 | F9: ciasaude@email.com | G9: ATIVO | H9: 9 | I9: 🟢 | J9: PÓS-VENDA | K9: T1 | L9: Ligar confirmar pedido | M9: MANHÃ | N9: VENDA / PEDIDO | O9: NÃO | P9: SIM | Q9: SIM | R9: ATIVO | S9: ATEND. CLIENTES ATIVOS | T9: VENDA / PEDIDO | V9: Pedido confirmado | W9: SIM | X9: Pedido R$ 2.200
