Workbook

Sheet PROJEÇÃO
A1: PROJEÇÃO — META SAP + SINALEIRO DE ATINGIMENTO | AS1: 🏪 SINALEIRO REDES DE FRANQUIAS | BB1: META CLIENTE IGUALITÁRIA | BH1: ⚡ ATIVAR SLICERS: Inserir > Segmentação de Dados > marcar: UF, CONSULTOR, SEMÁFORO, TIPO CARTEIRA, REDE | BP1: META COMPENSADA DINÂMICA
A2: IDENTIFICAÇÃO | E2: LOCALIZAÇÃO | F2: SINALEIRO REDE | L2: META MENSAL (SAP) | Z2: REALIZADO MENSAL | AN2: INDICADORES | AS2: GRUPO | AT2: CLIENTES | AU2: C/ VENDA | AV2: META R$ | AW2: FAT. REAL R$ | AX2: SINALEIRO % | AY2: COR | AZ2: AÇÃO | BB2: META POR CLIENTE (Ticket Médio) | BO2: . | BP2: ⚡ META COMPENSADA (Dinâmica) | CC2: FILTROS SLICER
A3: CNPJ | B3: NOME FANTASIA | C3: REDE / GRUPO CHAVE | D3: CONSULTOR | E3: UF | F3: TOTAL LOJAS | G3: SINALEIRO % | H3: COR SINALEIRO | I3: AÇÃO GRUPO | J3: _sep_10 | K3: REGIÃO | L3: META ANUAL | M3: META JAN | N3: META FEV | O3: META MAR | P3: META ABR | Q3: META MAI | R3: META JUN | S3: META JUL | T3: META AGO | U3: META SET | V3: META OUT | W3: META NOV | X3: META DEZ | Y3: _sep_25 | Z3: REAL ANUAL | AA3: REAL JAN | AB3: REAL FEV | AC3: REAL MAR | AD3: REAL ABR | AE3: REAL MAI | AF3: REAL JUN | AG3: REAL JUL | AH3: REAL AGO | AI3: REAL SET | AJ3: REAL OUT | AK3: REAL NOV | AL3: REAL DEZ | AM3: _sep_39 | AN3: % YTD | AO3: 🚦 SINAL META | AP3: GAP | AQ3: RANKING | AR3: _sep_44 | AS3: FITLAND | AT3: =COUNTIF(C$4:C$503,AS3) -> 44 | AU3: =COUNTIFS(C$4:C$503,AS3,Z$4:Z$503,">0") -> 44 | AV3: =SUMIF(C$4:C$503,AS3,L$4:L$503) -> 321337.45 | AW3: =SUMIF(C$4:C$503,AS3,Z$4:Z$503) -> 159653.14 | AX3: =IF(AV3=0,0,AW3/AV3) -> 0.49683951 | AY3: =IF(AX3>=0.6,"🟢 VERDE",IF(AX3>=0.4,"🟡 AMARELO",IF(AX3>=0.01,"🔴 VERMELHO","🟣 ROXO"))) -> 🟡 AMARELO | AZ3: =IF(AX3>=0.6,"JBP",IF(AX3>=0.4,"Sell Out",IF(AX3>=0.1,"Positivação + Expandir",IF(AX3>=0.01,"Ativar + Prospectar","Mapear + Prospectar")))) -> Sell Out | BA3: . | BB3: DIST ANUAL | BC3: DIST JAN | BD3: DIST FEV | BE3: DIST MAR | BF3: DIST ABR | BG3: DIST MAI | BH3: DIST JUN | BI3: DIST JUL | BJ3: DIST AGO | BK3: DIST SET | BL3: DIST OUT | BM3: DIST NOV | BN3: DIST DEZ | BO3: ._67 | BP3: COMP ANUAL | BQ3: COMP JAN | BR3: COMP FEV | BS3: COMP MAR | BT3: COMP ABR | BU3: COMP MAI | BV3: COMP JUN | BW3: COMP JUL | BX3: COMP AGO | BY3: COMP SET | BZ3: COMP OUT | CA3: COMP NOV | CB3: COMP DEZ | CC3: SEMÁFORO | CD3: TIPO CARTEIRA | CE3: REDE
A4: 23014826000105 | B4: TROPICAL SUPERMERCADOS LTDA | C4: CENTRO OESTE | D4: LARISSA PADILHA | E4: MT | F4: =IFERROR(VLOOKUP(C4,$AS$3:$AT$10,2,FALSE()),IFERROR(VLOOKUP(C4,$AS$15:$AT$22,2,FALSE()),"")) -> 33 | G4: =IFERROR(VLOOKUP(C4,$AS$3:$AX$10,6,FALSE()),IFERROR(VLOOKUP(C4,$AS$15:$AX$22,6,FALSE()),"")) -> 0.34149404 | H4: =IFERROR(VLOOKUP(C4,$AS$3:$AY$10,7,FALSE()),IFERROR(VLOOKUP(C4,$AS$15:$AY$22,7,FALSE()),"")) -> 🔴 VERMELHO | I4: =IFERROR(VLOOKUP(C4,$AS$3:$AZ$10,8,FALSE()),IFERROR(VLOOKUP(C4,$AS$15:$AZ$22,8,FALSE()),"")) -> Positivação + Expandir | K4: CENTRO OESTE | L4: 249796.02 | M4: 17553.92 | N4: 18343.21 | O4: 18785.22 | P4: 19274.58 | Q4: 19906.01 | R4: 20426.95 | S4: 21216.24 | T4: 21737.18 | U4: 22226.54 | V4: 22779.05 | W4: 23378.91 | X4: 24168.21 | Y4: . | Z4: =SUM(AA4:AL4) -> 52292.36 | AF4: 6442.21 | AG4: 4099.98 | AH4: 8406.63 | AI4: 5299.97 | AK4: 14998.98 | AL4: 13044.59 | AM4: . | AN4: =IF(L4=0,0,Z4/L4) -> 0.20934024 | AO4: =IF(AN4="","",IF(AN4>=0.9,"🟢",IF(AN4>=0.7,"🟡",IF(AN4>=0.5,"🟠","🔴")))) -> 🔴 | AP4: =IF(L4=0,0,L4-Z4) -> 197503.66 | AQ4: =IF(AP4=0,"",RANK(AP4,AP$4:AP$503,0)) -> 1 | AR4: . | AS4: CIA DA SAUDE | AT4: =COUNTIF(C$4:C$503,AS4) -> 21 | AU4: =COUNTIFS(C$4:C$503,AS4,Z$4:Z$503,">0") -> 19 | AV4: =SUMIF(C$4:C$503,AS4,L$4:L$503) -> 90676.46 | AW4: =SUMIF(C$4:C$503,AS4,Z$4:Z$503) -> 44568.8 | AX4: =IF(AV4=0,0,AW4/AV4) -> 0.49151456 | AY4: =IF(AX4>=0.6,"🟢 VERDE",IF(AX4>=0.4,"🟡 AMARELO",IF(AX4>=0.01,"🔴 VERMELHO","🟣 ROXO"))) -> 🟡 AMARELO | AZ4: =IF(AX4>=0.6,"JBP",IF(AX4>=0.4,"Sell Out",IF(AX4>=0.1,"Positivação + Expandir",IF(AX4>=0.01,"Ativar + Prospectar","Mapear + Prospectar")))) -> Sell Out | BA4: . | BB4: =SUM(L$4:L$503)/COUNTA(A$4:A$503) -> 9494.3999 | BC4: =SUM(M$4:M$503)/COUNTA(A$4:A$503) -> 667.20008 | BD4: =SUM(N$4:N$503)/COUNTA(A$4:A$503) -> 697.19996 | BE4: =SUM(O$4:O$503)/COUNTA(A$4:A$503) -> 713.9999 | BF4: =SUM(P$4:P$503)/COUNTA(A$4:A$503) -> 732.59984 | BG4: =SUM(Q$4:Q$503)/COUNTA(A$4:A$503) -> 756.59992 | BH4: =SUM(R$4:R$503)/COUNTA(A$4:A$503) -> 776.40004 | BI4: =SUM(S$4:S$503)/COUNTA(A$4:A$503) -> 806.40012 | BJ4: =SUM(T$4:T$503)/COUNTA(A$4:A$503) -> 826.1999 | BK4: =SUM(U$4:U$503)/COUNTA(A$4:A$503) -> 844.8002 | BL4: =SUM(V$4:V$503)/COUNTA(A$4:A$503) -> 865.7998 | BM4: =SUM(W$4:W$503)/COUNTA(A$4:A$503) -> 888.59982 | BN4: =SUM(X$4:X$503)/COUNTA(A$4:A$503) -> 918.60034 | BO4: . | BP4: =IF(Z4>=BB4,0,IFERROR(BB4+(SUMPRODUCT((Z$4:Z$503>=BB$4:BB$503)*(Z$4:Z$503-BB$4:BB$503))/MAX(1,COUNTIF(Z$4:Z$503,"<"&BB4+0.01))),BB4)) -> 0 | BQ4: =IF(AA4>=BC4,0,IFERROR(BC4+SUMPRODUCT((AA$4:AA$503>=BC$4:BC$503)*(AA$4:AA$503-BC$4:BC$503))/MAX(1,COUNTIF(AA$4:AA$503,"<"&BC4+0.01)),BC4)) -> 2238.4659 | BR4: =IF(AB4>=BD4,0,IFERROR(BD4+SUMPRODUCT((AB$4:AB$503>=BD$4:BD$503)*(AB$4:AB$503-BD$4:BD$503))/MAX(1,COUNTIF(AB$4:AB$503,"<"&BD4+0.01)),BD4)) -> 3335.2938 | BS4: =IF(AC4>=BE4,0,IFERROR(BE4+SUMPRODUCT((AC$4:AC$503>=BE$4:BE$503)*(AC$4:AC$503-BE$4:BE$503))/MAX(1,COUNTIF(AC$4:AC$503,"<"&BE4+0.01)),BE4)) -> 6188.7335 | BT4: =IF(AD4>=BF4,0,IFERROR(BF4+SUMPRODUCT((AD$4:AD$503>=BF$4:BF$503)*(AD$4:AD$503-BF$4:BF$503))/MAX(1,COUNTIF(AD$4:AD$503,"<"&BF4+0.01)),BF4)) -> 11354.354 | BU4: =IF(AE4>=BG4,0,IFERROR(BG4+SUMPRODUCT((AE$4:AE$503>=BG$4:BG$503)*(AE$4:AE$503-BG$4:BG$503))/MAX(1,COUNTIF(AE$4:AE$503,"<"&BG4+0.01)),BG4)) -> 7704.8592 | BV4: =IF(AF4>=BH4,0,IFERROR(BH4+SUMPRODUCT((AF$4:AF$503>=BH$4:BH$503)*(AF$4:AF$503-BH$4:BH$503))/MAX(1,COUNTIF(AF$4:AF$503,"<"&BH4+0.01)),BH4)) -> 0 | BW4: =IF(AG4>=BI4,0,IFERROR(BI4+SUMPRODUCT((AG$4:AG$503>=BI$4:BI$503)*(AG$4:AG$503-BI$4:BI$503))/MAX(1,COUNTIF(AG$4:AG$503,"<"&BI4+0.01)),BI4)) -> 0 | BX4: =IF(AH4>=BJ4,0,IFERROR(BJ4+SUMPRODUCT((AH$4:AH$503>=BJ$4:BJ$503)*(AH$4:AH$503-BJ$4:BJ$503))/MAX(1,COUNTIF(AH$4:AH$503,"<"&BJ4+0.01)),BJ4)) -> 0 | ... CB4: =IF(AL4>=BN4,0,IFERROR(BN4+SUMPRODUCT((AL$4:AL$503>=BN$4:BN$503)*(AL$4:AL$503-BN$4:BN$503))/MAX(1,COUNTIF(AL$4:AL$503,"<"&BN4+0.01)),BN4)) -> 0 | CC4: =IF(AO4="🟢","VERDE",IF(AO4="🟡","AMARELO",IF(AO4="🟠","VERMELHO",IF(AO4="🔴","VERMELHO","ROXO")))) -> VERMELHO | CD4: 🌎 REGIÕES | CE4: SEM REDE
A5: 59673556000191 | B5: SHS IMPORTACAO E EXPORTACAO DE ARTIGOS D | C5: SUL | D5: HEMANUELE DITZEL (MANU) | E5: PR | F5: =IFERROR(VLOOKUP(C5,$AS$3:$AT$10,2,FALSE()),IFERROR(VLOOKUP(C5,$AS$15:$AT$22,2,FALSE()),"")) -> 132 | G5: =IFERROR(VLOOKUP(C5,$AS$3:$AX$10,6,FALSE()),IFERROR(VLOOKUP(C5,$AS$15:$AX$22,6,FALSE()),"")) -> 0.46819018 | H5: =IFERROR(VLOOKUP(C5,$AS$3:$AY$10,7,FALSE()),IFERROR(VLOOKUP(C5,$AS$15:$AY$22,7,FALSE()),"")) -> 🟡 AMARELO | I5: =IFERROR(VLOOKUP(C5,$AS$3:$AZ$10,8,FALSE()),IFERROR(VLOOKUP(C5,$AS$15:$AZ$22,8,FALSE()),"")) -> Sell Out | K5: SUL | L5: 162422.58 | M5: 11413.92 | N5: 11927.14 | O5: 12214.54 | P5: 12532.73 | Q5: 12943.31 | R5: 13282.03 | S5: 13795.24 | T5: 14133.97 | U5: 14452.16 | V5: 14811.41 | W5: 15201.46 | X5: 15714.67 | Y5: . | Z5: =SUM(AA5:AL5) -> 65318.4 | AC5: 10611.2 | AD5: 54707.2 | AM5: . | AN5: =IF(L5=0,0,Z5/L5) -> 0.40215098 | AO5: =IF(AN5="","",IF(AN5>=0.9,"🟢",IF(AN5>=0.7,"🟡",IF(AN5>=0.5,"🟠","🔴")))) -> 🔴 | AP5: =IF(L5=0,0,L5-Z5) -> 97104.18 | AQ5: =IF(AP5=0,"",RANK(AP5,AP$4:AP$503,0)) -> 2 | AR5: . | AS5: DIVINA TERRA | AT5: =COUNTIF(C$4:C$503,AS5) -> 15 | AU5: =COUNTIFS(C$4:C$503,AS5,Z$4:Z$503,">0") -> 12 | AV5: =SUMIF(C$4:C$503,AS5,L$4:L$503) -> 54466.5 | AW5: =SUMIF(C$4:C$503,AS5,Z$4:Z$503) -> 33829.79 | AX5: =IF(AV5=0,0,AW5/AV5) -> 0.62111188 | AY5: =IF(AX5>=0.6,"🟢 VERDE",IF(AX5>=0.4,"🟡 AMARELO",IF(AX5>=0.01,"🔴 VERMELHO","🟣 ROXO"))) -> 🟢 VERDE | AZ5: =IF(AX5>=0.6,"JBP",IF(AX5>=0.4,"Sell Out",IF(AX5>=0.1,"Positivação + Expandir",IF(AX5>=0.01,"Ativar + Prospectar","Mapear + Prospectar")))) -> JBP | BA5: . | BB5: =SUM(L$4:L$503)/COUNTA(A$4:A$503) -> 9494.3999 | BC5: =SUM(M$4:M$503)/COUNTA(A$4:A$503) -> 667.20008 | BD5: =SUM(N$4:N$503)/COUNTA(A$4:A$503) -> 697.19996 | BE5: =SUM(O$4:O$503)/COUNTA(A$4:A$503) -> 713.9999 | BF5: =SUM(P$4:P$503)/COUNTA(A$4:A$503) -> 732.59984 | BG5: =SUM(Q$4:Q$503)/COUNTA(A$4:A$503) -> 756.59992 | BH5: =SUM(R$4:R$503)/COUNTA(A$4:A$503) -> 776.40004 | BI5: =SUM(S$4:S$503)/COUNTA(A$4:A$503) -> 806.40012 | BJ5: =SUM(T$4:T$503)/COUNTA(A$4:A$503) -> 826.1999 | BK5: =SUM(U$4:U$503)/COUNTA(A$4:A$503) -> 844.8002 | BL5: =SUM(V$4:V$503)/COUNTA(A$4:A$503) -> 865.7998 | BM5: =SUM(W$4:W$503)/COUNTA(A$4:A$503) -> 888.59982 | BN5: =SUM(X$4:X$503)/COUNTA(A$4:A$503) -> 918.60034 | BO5: . | BP5: =IF(Z5>=BB5,0,IFERROR(BB5+(SUMPRODUCT((Z$4:Z$503>=BB$4:BB$503)*(Z$4:Z$503-BB$4:BB$503))/MAX(1,COUNTIF(Z$4:Z$503,"<"&BB5+0.01))),BB5)) -> 0 | BQ5: =IF(AA5>=BC5,0,IFERROR(BC5+SUMPRODUCT((AA$4:AA$503>=BC$4:BC$503)*(AA$4:AA$503-BC$4:BC$503))/MAX(1,COUNTIF(AA$4:AA$503,"<"&BC5+0.01)),BC5)) -> 2238.4659 | BR5: =IF(AB5>=BD5,0,IFERROR(BD5+SUMPRODUCT((AB$4:AB$503>=BD$4:BD$503)*(AB$4:AB$503-BD$4:BD$503))/MAX(1,COUNTIF(AB$4:AB$503,"<"&BD5+0.01)),BD5)) -> 3335.2938 | BS5: =IF(AC5>=BE5,0,IFERROR(BE5+SUMPRODUCT((AC$4:AC$503>=BE$4:BE$503)*(AC$4:AC$503-BE$4:BE$503))/MAX(1,COUNTIF(AC$4:AC$503,"<"&BE5+0.01)),BE5)) -> 0 | BT5: =IF(AD5>=BF5,0,IFERROR(BF5+SUMPRODUCT((AD$4:AD$503>=BF$4:BF$503)*(AD$4:AD$503-BF$4:BF$503))/MAX(1,COUNTIF(AD$4:AD$503,"<"&BF5+0.01)),BF5)) -> 0 | BU5: =IF(AE5>=BG5,0,IFERROR(BG5+SUMPRODUCT((AE$4:AE$503>=BG$4:BG$503)*(AE$4:AE$503-BG$4:BG$503))/MAX(1,COUNTIF(AE$4:AE$503,"<"&BG5+0.01)),BG5)) -> 7704.8592 | BV5: =IF(AF5>=BH5,0,IFERROR(BH5+SUMPRODUCT((AF$4:AF$503>=BH$4:BH$503)*(AF$4:AF$503-BH$4:BH$503))/MAX(1,COUNTIF(AF$4:AF$503,"<"&BH5+0.01)),BH5)) -> 9942.6504 | BW5: =IF(AG5>=BI5,0,IFERROR(BI5+SUMPRODUCT((AG$4:AG$503>=BI$4:BI$503)*(AG$4:AG$503-BI$4:BI$503))/MAX(1,COUNTIF(AG$4:AG$503,"<"&BI5+0.01)),BI5)) -> 9142.1587 | BX5: =IF(AH5>=BJ5,0,IFERROR(BJ5+SUMPRODUCT((AH$4:AH$503>=BJ$4:BJ$503)*(AH$4:AH$503-BJ$4:BJ$503))/MAX(1,COUNTIF(AH$4:AH$503,"<"&BJ5+0.01)),BJ5)) -> 5621.5026 | ... CB5: =IF(AL5>=BN5,0,IFERROR(BN5+SUMPRODUCT((AL$4:AL$503>=BN$4:BN$503)*(AL$4:AL$503-BN$4:BN$503))/MAX(1,COUNTIF(AL$4:AL$503,"<"&BN5+0.01)),BN5)) -> 3597.2615 | CC5: =IF(AO5="🟢","VERDE",IF(AO5="🟡","AMARELO",IF(AO5="🟠","VERMELHO",IF(AO5="🔴","VERMELHO","ROXO")))) -> VERMELHO | CD5: 🌎 REGIÕES | CE5: SEM REDE
A6: 42535786000191 | B6: BEVILACQUA CEREAIS LTDA - EPP | C6: RJ + ES + MG | D6: LARISSA PADILHA | E6: MG | F6: =IFERROR(VLOOKUP(C6,$AS$3:$AT$10,2,FALSE()),IFERROR(VLOOKUP(C6,$AS$15:$AT$22,2,FALSE()),"")) -> 49 | G6: =IFERROR(VLOOKUP(C6,$AS$3:$AX$10,6,FALSE()),IFERROR(VLOOKUP(C6,$AS$15:$AX$22,6,FALSE()),"")) -> 0.46396509 | H6: =IFERROR(VLOOKUP(C6,$AS$3:$AY$10,7,FALSE()),IFERROR(VLOOKUP(C6,$AS$15:$AY$22,7,FALSE()),"")) -> 🟡 AMARELO | I6: =IFERROR(VLOOKUP(C6,$AS$3:$AZ$10,8,FALSE()),IFERROR(VLOOKUP(C6,$AS$15:$AZ$22,8,FALSE()),"")) -> Sell Out | K6: RJ + ES + MG | L6: 125085.15 | M6: 8790.11 | N6: 9185.35 | O6: 9406.68 | P6: 9651.73 | Q6: 9967.92 | R6: 10228.78 | S6: 10624.02 | T6: 10884.87 | U6: 11129.92 | V6: 11406.59 | W6: 11706.97 | X6: 12102.21 | Y6: . | Z6: =SUM(AA6:AL6) -> 61002.61 | AD6: 10984.56 | AE6: 40838.05 | AH6: 9180 | AM6: . | AN6: =IF(L6=0,0,Z6/L6) -> 0.48768867 | AO6: =IF(AN6="","",IF(AN6>=0.9,"🟢",IF(AN6>=0.7,"🟡",IF(AN6>=0.5,"🟠","🔴")))) -> 🔴 | AP6: =IF(L6=0,0,L6-Z6) -> 64082.54 | AQ6: =IF(AP6=0,"",RANK(AP6,AP$4:AP$503,0)) -> 3 | AR6: . | AS6: VIDA LEVE | AT6: =COUNTIF(C$4:C$503,AS6) -> 25 | AU6: =COUNTIFS(C$4:C$503,AS6,Z$4:Z$503,">0") -> 24 | AV6: =SUMIF(C$4:C$503,AS6,L$4:L$503) -> 108083.15 | AW6: =SUMIF(C$4:C$503,AS6,Z$4:Z$503) -> 58013.82 | AX6: =IF(AV6=0,0,AW6/AV6) -> 0.53675175 | AY6: =IF(AX6>=0.6,"🟢 VERDE",IF(AX6>=0.4,"🟡 AMARELO",IF(AX6>=0.01,"🔴 VERMELHO","🟣 ROXO"))) -> 🟡 AMARELO | AZ6: =IF(AX6>=0.6,"JBP",IF(AX6>=0.4,"Sell Out",IF(AX6>=0.1,"Positivação + Expandir",IF(AX6>=0.01,"Ativar + Prospectar","Mapear + Prospectar")))) -> Sell Out | BA6: . | BB6: =SUM(L$4:L$503)/COUNTA(A$4:A$503) -> 9494.3999 | BC6: =SUM(M$4:M$503)/COUNTA(A$4:A$503) -> 667.20008 | BD6: =SUM(N$4:N$503)/COUNTA(A$4:A$503) -> 697.19996 | BE6: =SUM(O$4:O$503)/COUNTA(A$4:A$503) -> 713.9999 | BF6: =SUM(P$4:P$503)/COUNTA(A$4:A$503) -> 732.59984 | BG6: =SUM(Q$4:Q$503)/COUNTA(A$4:A$503) -> 756.59992 | BH6: =SUM(R$4:R$503)/COUNTA(A$4:A$503) -> 776.40004 | BI6: =SUM(S$4:S$503)/COUNTA(A$4:A$503) -> 806.40012 | BJ6: =SUM(T$4:T$503)/COUNTA(A$4:A$503) -> 826.1999 | BK6: =SUM(U$4:U$503)/COUNTA(A$4:A$503) -> 844.8002 | BL6: =SUM(V$4:V$503)/COUNTA(A$4:A$503) -> 865.7998 | BM6: =SUM(W$4:W$503)/COUNTA(A$4:A$503) -> 888.59982 | BN6: =SUM(X$4:X$503)/COUNTA(A$4:A$503) -> 918.60034 | BO6: . | BP6: =IF(Z6>=BB6,0,IFERROR(BB6+(SUMPRODUCT((Z$4:Z$503>=BB$4:BB$503)*(Z$4:Z$503-BB$4:BB$503))/MAX(1,COUNTIF(Z$4:Z$503,"<"&BB6+0.01))),BB6)) -> 0 | BQ6: =IF(AA6>=BC6,0,IFERROR(BC6+SUMPRODUCT((AA$4:AA$503>=BC$4:BC$503)*(AA$4:AA$503-BC$4:BC$503))/MAX(1,COUNTIF(AA$4:AA$503,"<"&BC6+0.01)),BC6)) -> 2238.4659 | BR6: =IF(AB6>=BD6,0,IFERROR(BD6+SUMPRODUCT((AB$4:AB$503>=BD$4:BD$503)*(AB$4:AB$503-BD$4:BD$503))/MAX(1,COUNTIF(AB$4:AB$503,"<"&BD6+0.01)),BD6)) -> 3335.2938 | BS6: =IF(AC6>=BE6,0,IFERROR(BE6+SUMPRODUCT((AC$4:AC$503>=BE$4:BE$503)*(AC$4:AC$503-BE$4:BE$503))/MAX(1,COUNTIF(AC$4:AC$503,"<"&BE6+0.01)),BE6)) -> 6188.7335 | BT6: =IF(AD6>=BF6,0,IFERROR(BF6+SUMPRODUCT((AD$4:AD$503>=BF$4:BF$503)*(AD$4:AD$503-BF$4:BF$503))/MAX(1,COUNTIF(AD$4:AD$503,"<"&BF6+0.01)),BF6)) -> 0 | BU6: =IF(AE6>=BG6,0,IFERROR(BG6+SUMPRODUCT((AE$4:AE$503>=BG$4:BG$503)*(AE$4:AE$503-BG$4:BG$503))/MAX(1,COUNTIF(AE$4:AE$503,"<"&BG6+0.01)),BG6)) -> 0 | BV6: =IF(AF6>=BH6,0,IFERROR(BH6+SUMPRODUCT((AF$4:AF$503>=BH$4:BH$503)*(AF$4:AF$503-BH$4:BH$503))/MAX(1,COUNTIF(AF$4:AF$503,"<"&BH6+0.01)),BH6)) -> 9942.6504 | BW6: =IF(AG6>=BI6,0,IFERROR(BI6+SUMPRODUCT((AG$4:AG$503>=BI$4:BI$503)*(AG$4:AG$503-BI$4:BI$503))/MAX(1,COUNTIF(AG$4:AG$503,"<"&BI6+0.01)),BI6)) -> 9142.1587 | BX6: =IF(AH6>=BJ6,0,IFERROR(BJ6+SUMPRODUCT((AH$4:AH$503>=BJ$4:BJ$503)*(AH$4:AH$503-BJ$4:BJ$503))/MAX(1,COUNTIF(AH$4:AH$503,"<"&BJ6+0.01)),BJ6)) -> 0 | ... CB6: =IF(AL6>=BN6,0,IFERROR(BN6+SUMPRODUCT((AL$4:AL$503>=BN$4:BN$503)*(AL$4:AL$503-BN$4:BN$503))/MAX(1,COUNTIF(AL$4:AL$503,"<"&BN6+0.01)),BN6)) -> 3597.2615 | CC6: =IF(AO6="🟢","VERDE",IF(AO6="🟡","AMARELO",IF(AO6="🟠","VERMELHO",IF(AO6="🔴","VERMELHO","ROXO")))) -> VERMELHO | CD6: 🌎 REGIÕES | CE6: SEM REDE
A7: 41418074000120 | B7: SIMPLES E SAUDAVEL COMERCIO PRODUTOS NAT | C7: SP INTERIOR | D7: LARISSA PADILHA | E7: SP | F7: =IFERROR(VLOOKUP(C7,$AS$3:$AT$10,2,FALSE()),IFERROR(VLOOKUP(C7,$AS$15:$AT$22,2,FALSE()),"")) -> 42 | G7: =IFERROR(VLOOKUP(C7,$AS$3:$AX$10,6,FALSE()),IFERROR(VLOOKUP(C7,$AS$15:$AX$22,6,FALSE()),"")) -> 0.42487208 | H7: =IFERROR(VLOOKUP(C7,$AS$3:$AY$10,7,FALSE()),IFERROR(VLOOKUP(C7,$AS$15:$AY$22,7,FALSE()),"")) -> 🟡 AMARELO | I7: =IFERROR(VLOOKUP(C7,$AS$3:$AZ$10,8,FALSE()),IFERROR(VLOOKUP(C7,$AS$15:$AZ$22,8,FALSE()),"")) -> Sell Out | K7: SP INTERIOR | L7: 103481.47 | M7: 7271.95 | N7: 7598.93 | O7: 7782.04 | P7: 7984.76 | Q7: 8246.34 | R7: 8462.15 | S7: 8789.12 | T7: 9004.93 | U7: 9207.65 | V7: 9436.54 | W7: 9685.04 | X7: 10012.02 | Y7: . | Z7: =SUM(AA7:AL7) -> 43134.58 | AA7: 3845.66 | AB7: 3430.8 | AC7: 4796.88 | AD7: 3290.88 | AE7: 4094.88 | AG7: 4541.91 | AH7: 5337.2 | AI7: 6672 | AJ7: 7124.37 | AM7: . | AN7: =IF(L7=0,0,Z7/L7) -> 0.41683385 | AO7: =IF(AN7="","",IF(AN7>=0.9,"🟢",IF(AN7>=0.7,"🟡",IF(AN7>=0.5,"🟠","🔴")))) -> 🔴 | AP7: =IF(L7=0,0,L7-Z7) -> 60346.89 | AQ7: =IF(AP7=0,"",RANK(AP7,AP$4:AP$503,0)) -> 4 | AR7: . | AS7: MUNDO VERDE | AT7: =COUNTIF(C$4:C$503,AS7) -> 4 | AU7: =COUNTIFS(C$4:C$503,AS7,Z$4:Z$503,">0") -> 4 | AV7: =SUMIF(C$4:C$503,AS7,L$4:L$503) -> 36754.96 | AW7: =SUMIF(C$4:C$503,AS7,Z$4:Z$503) -> 19117.46 | AX7: =IF(AV7=0,0,AW7/AV7) -> 0.52013279 | AY7: =IF(AX7>=0.6,"🟢 VERDE",IF(AX7>=0.4,"🟡 AMARELO",IF(AX7>=0.01,"🔴 VERMELHO","🟣 ROXO"))) -> 🟡 AMARELO | AZ7: =IF(AX7>=0.6,"JBP",IF(AX7>=0.4,"Sell Out",IF(AX7>=0.1,"Positivação + Expandir",IF(AX7>=0.01,"Ativar + Prospectar","Mapear + Prospectar")))) -> Sell Out | BA7: . | BB7: =SUM(L$4:L$503)/COUNTA(A$4:A$503) -> 9494.3999 | BC7: =SUM(M$4:M$503)/COUNTA(A$4:A$503) -> 667.20008 | BD7: =SUM(N$4:N$503)/COUNTA(A$4:A$503) -> 697.19996 | BE7: =SUM(O$4:O$503)/COUNTA(A$4:A$503) -> 713.9999 | BF7: =SUM(P$4:P$503)/COUNTA(A$4:A$503) -> 732.59984 | BG7: =SUM(Q$4:Q$503)/COUNTA(A$4:A$503) -> 756.59992 | BH7: =SUM(R$4:R$503)/COUNTA(A$4:A$503) -> 776.40004 | BI7: =SUM(S$4:S$503)/COUNTA(A$4:A$503) -> 806.40012 | BJ7: =SUM(T$4:T$503)/COUNTA(A$4:A$503) -> 826.1999 | BK7: =SUM(U$4:U$503)/COUNTA(A$4:A$503) -> 844.8002 | BL7: =SUM(V$4:V$503)/COUNTA(A$4:A$503) -> 865.7998 | BM7: =SUM(W$4:W$503)/COUNTA(A$4:A$503) -> 888.59982 | BN7: =SUM(X$4:X$503)/COUNTA(A$4:A$503) -> 918.60034 | BO7: . | BP7: =IF(Z7>=BB7,0,IFERROR(BB7+(SUMPRODUCT((Z$4:Z$503>=BB$4:BB$503)*(Z$4:Z$503-BB$4:BB$503))/MAX(1,COUNTIF(Z$4:Z$503,"<"&BB7+0.01))),BB7)) -> 0 | BQ7: =IF(AA7>=BC7,0,IFERROR(BC7+SUMPRODUCT((AA$4:AA$503>=BC$4:BC$503)*(AA$4:AA$503-BC$4:BC$503))/MAX(1,COUNTIF(AA$4:AA$503,"<"&BC7+0.01)),BC7)) -> 0 | BR7: =IF(AB7>=BD7,0,IFERROR(BD7+SUMPRODUCT((AB$4:AB$503>=BD$4:BD$503)*(AB$4:AB$503-BD$4:BD$503))/MAX(1,COUNTIF(AB$4:AB$503,"<"&BD7+0.01)),BD7)) -> 0 | BS7: =IF(AC7>=BE7,0,IFERROR(BE7+SUMPRODUCT((AC$4:AC$503>=BE$4:BE$503)*(AC$4:AC$503-BE$4:BE$503))/MAX(1,COUNTIF(AC$4:AC$503,"<"&BE7+0.01)),BE7)) -> 0 | BT7: =IF(AD7>=BF7,0,IFERROR(BF7+SUMPRODUCT((AD$4:AD$503>=BF$4:BF$503)*(AD$4:AD$503-BF$4:BF$503))/MAX(1,COUNTIF(AD$4:AD$503,"<"&BF7+0.01)),BF7)) -> 0 | BU7: =IF(AE7>=BG7,0,IFERROR(BG7+SUMPRODUCT((AE$4:AE$503>=BG$4:BG$503)*(AE$4:AE$503-BG$4:BG$503))/MAX(1,COUNTIF(AE$4:AE$503,"<"&BG7+0.01)),BG7)) -> 0 | BV7: =IF(AF7>=BH7,0,IFERROR(BH7+SUMPRODUCT((AF$4:AF$503>=BH$4:BH$503)*(AF$4:AF$503-BH$4:BH$503))/MAX(1,COUNTIF(AF$4:AF$503,"<"&BH7+0.01)),BH7)) -> 9942.6504 | BW7: =IF(AG7>=BI7,0,IFERROR(BI7+SUMPRODUCT((AG$4:AG$503>=BI$4:BI$503)*(AG$4:AG$503-BI$4:BI$503))/MAX(1,COUNTIF(AG$4:AG$503,"<"&BI7+0.01)),BI7)) -> 0 | BX7: =IF(AH7>=BJ7,0,IFERROR(BJ7+SUMPRODUCT((AH$4:AH$503>=BJ$4:BJ$503)*(AH$4:AH$503-BJ$4:BJ$503))/MAX(1,COUNTIF(AH$4:AH$503,"<"&BJ7+0.01)),BJ7)) -> 0 | ... CB7: =IF(AL7>=BN7,0,IFERROR(BN7+SUMPRODUCT((AL$4:AL$503>=BN$4:BN$503)*(AL$4:AL$503-BN$4:BN$503))/MAX(1,COUNTIF(AL$4:AL$503,"<"&BN7+0.01)),BN7)) -> 3597.2615 | CC7: =IF(AO7="🟢","VERDE",IF(AO7="🟡","AMARELO",IF(AO7="🟠","VERMELHO",IF(AO7="🔴","VERMELHO","ROXO")))) -> VERMELHO | CD7: 🌎 REGIÕES | CE7: SEM REDE
A8: 00939085000178 | B8: PORT-GALI HOTELARIA E TURISMO LTDA | C8: SEM GRUPO | D8: LARISSA PADILHA | E8: . | F8: =IFERROR(VLOOKUP(C8,$AS$3:$AT$10,2,FALSE()),IFERROR(VLOOKUP(C8,$AS$15:$AT$22,2,FALSE()),"")) -> 49 | G8: =IFERROR(VLOOKUP(C8,$AS$3:$AX$10,6,FALSE()),IFERROR(VLOOKUP(C8,$AS$15:$AX$22,6,FALSE()),"")) -> 0.43639135 | H8: =IFERROR(VLOOKUP(C8,$AS$3:$AY$10,7,FALSE()),IFERROR(VLOOKUP(C8,$AS$15:$AY$22,7,FALSE()),"")) -> 🟡 AMARELO | I8: =IFERROR(VLOOKUP(C8,$AS$3:$AZ$10,8,FALSE()),IFERROR(VLOOKUP(C8,$AS$15:$AZ$22,8,FALSE()),"")) -> Sell Out | K8: . | L8: 96766.44 | M8: 6800.07 | N8: 7105.83 | O8: 7277.05 | P8: 7466.62 | Q8: 7711.23 | R8: 7913.03 | S8: 8218.79 | T8: 8420.59 | U8: 8610.16 | V8: 8824.19 | W8: 9056.56 | X8: 9362.32 | Y8: . | Z8: =SUM(AA8:AL8) -> 40115.33 | AD8: 5026.2 | AF8: 5040 | AI8: 5260.84 | AJ8: 10920 | AK8: 5490.9 | AL8: 8377.39 | AM8: . | AN8: =IF(L8=0,0,Z8/L8) -> 0.41455829 | AO8: =IF(AN8="","",IF(AN8>=0.9,"🟢",IF(AN8>=0.7,"🟡",IF(AN8>=0.5,"🟠","🔴")))) -> 🔴 | AP8: =IF(L8=0,0,L8-Z8) -> 56651.11 | AQ8: =IF(AP8=0,"",RANK(AP8,AP$4:AP$503,0)) -> 5 | AR8: . | AS8: BIO MUNDO | AT8: =COUNTIF(C$4:C$503,AS8) -> 7 | AU8: =COUNTIFS(C$4:C$503,AS8,Z$4:Z$503,">0") -> 4 | AV8: =SUMIF(C$4:C$503,AS8,L$4:L$503) -> 29621.13 | AW8: =SUMIF(C$4:C$503,AS8,Z$4:Z$503) -> 12480.52 | AX8: =IF(AV8=0,0,AW8/AV8) -> 0.42133842 | AY8: =IF(AX8>=0.6,"🟢 VERDE",IF(AX8>=0.4,"🟡 AMARELO",IF(AX8>=0.01,"🔴 VERMELHO","🟣 ROXO"))) -> 🟡 AMARELO | AZ8: =IF(AX8>=0.6,"JBP",IF(AX8>=0.4,"Sell Out",IF(AX8>=0.1,"Positivação + Expandir",IF(AX8>=0.01,"Ativar + Prospectar","Mapear + Prospectar")))) -> Sell Out | BA8: . | BB8: =SUM(L$4:L$503)/COUNTA(A$4:A$503) -> 9494.3999 | BC8: =SUM(M$4:M$503)/COUNTA(A$4:A$503) -> 667.20008 | BD8: =SUM(N$4:N$503)/COUNTA(A$4:A$503) -> 697.19996 | BE8: =SUM(O$4:O$503)/COUNTA(A$4:A$503) -> 713.9999 | BF8: =SUM(P$4:P$503)/COUNTA(A$4:A$503) -> 732.59984 | BG8: =SUM(Q$4:Q$503)/COUNTA(A$4:A$503) -> 756.59992 | BH8: =SUM(R$4:R$503)/COUNTA(A$4:A$503) -> 776.40004 | BI8: =SUM(S$4:S$503)/COUNTA(A$4:A$503) -> 806.40012 | BJ8: =SUM(T$4:T$503)/COUNTA(A$4:A$503) -> 826.1999 | BK8: =SUM(U$4:U$503)/COUNTA(A$4:A$503) -> 844.8002 | BL8: =SUM(V$4:V$503)/COUNTA(A$4:A$503) -> 865.7998 | BM8: =SUM(W$4:W$503)/COUNTA(A$4:A$503) -> 888.59982 | BN8: =SUM(X$4:X$503)/COUNTA(A$4:A$503) -> 918.60034 | BO8: . | BP8: =IF(Z8>=BB8,0,IFERROR(BB8+(SUMPRODUCT((Z$4:Z$503>=BB$4:BB$503)*(Z$4:Z$503-BB$4:BB$503))/MAX(1,COUNTIF(Z$4:Z$503,"<"&BB8+0.01))),BB8)) -> 0 | BQ8: =IF(AA8>=BC8,0,IFERROR(BC8+SUMPRODUCT((AA$4:AA$503>=BC$4:BC$503)*(AA$4:AA$503-BC$4:BC$503))/MAX(1,COUNTIF(AA$4:AA$503,"<"&BC8+0.01)),BC8)) -> 2238.4659 | BR8: =IF(AB8>=BD8,0,IFERROR(BD8+SUMPRODUCT((AB$4:AB$503>=BD$4:BD$503)*(AB$4:AB$503-BD$4:BD$503))/MAX(1,COUNTIF(AB$4:AB$503,"<"&BD8+0.01)),BD8)) -> 3335.2938 | BS8: =IF(AC8>=BE8,0,IFERROR(BE8+SUMPRODUCT((AC$4:AC$503>=BE$4:BE$503)*(AC$4:AC$503-BE$4:BE$503))/MAX(1,COUNTIF(AC$4:AC$503,"<"&BE8+0.01)),BE8)) -> 6188.7335 | BT8: =IF(AD8>=BF8,0,IFERROR(BF8+SUMPRODUCT((AD$4:AD$503>=BF$4:BF$503)*(AD$4:AD$503-BF$4:BF$503))/MAX(1,COUNTIF(AD$4:AD$503,"<"&BF8+0.01)),BF8)) -> 0 | BU8: =IF(AE8>=BG8,0,IFERROR(BG8+SUMPRODUCT((AE$4:AE$503>=BG$4:BG$503)*(AE$4:AE$503-BG$4:BG$503))/MAX(1,COUNTIF(AE$4:AE$503,"<"&BG8+0.01)),BG8)) -> 7704.8592 | BV8: =IF(AF8>=BH8,0,IFERROR(BH8+SUMPRODUCT((AF$4:AF$503>=BH$4:BH$503)*(AF$4:AF$503-BH$4:BH$503))/MAX(1,COUNTIF(AF$4:AF$503,"<"&BH8+0.01)),BH8)) -> 0 | BW8: =IF(AG8>=BI8,0,IFERROR(BI8+SUMPRODUCT((AG$4:AG$503>=BI$4:BI$503)*(AG$4:AG$503-BI$4:BI$503))/MAX(1,COUNTIF(AG$4:AG$503,"<"&BI8+0.01)),BI8)) -> 9142.1587 | BX8: =IF(AH8>=BJ8,0,IFERROR(BJ8+SUMPRODUCT((AH$4:AH$503>=BJ$4:BJ$503)*(AH$4:AH$503-BJ$4:BJ$503))/MAX(1,COUNTIF(AH$4:AH$503,"<"&BJ8+0.01)),BJ8)) -> 5621.5026 | ... CB8: =IF(AL8>=BN8,0,IFERROR(BN8+SUMPRODUCT((AL$4:AL$503>=BN$4:BN$503)*(AL$4:AL$503-BN$4:BN$503))/MAX(1,COUNTIF(AL$4:AL$503,"<"&BN8+0.01)),BN8)) -> 0 | CC8: =IF(AO8="🟢","VERDE",IF(AO8="🟡","AMARELO",IF(AO8="🟠","VERMELHO",IF(AO8="🔴","VERMELHO","ROXO")))) -> VERMELHO | CD8: 🌎 REGIÕES | CE8: SEM REDE
A9: 15265760000106 | B9: A CEREALISSIMA COMERCIO DE PRODUTOS NATU | C9: CENTRO OESTE | D9: LARISSA PADILHA | E9: GO | F9: =IFERROR(VLOOKUP(C9,$AS$3:$AT$10,2,FALSE()),IFERROR(VLOOKUP(C9,$AS$15:$AT$22,2,FALSE()),"")) -> 33 | G9: =IFERROR(VLOOKUP(C9,$AS$3:$AX$10,6,FALSE()),IFERROR(VLOOKUP(C9,$AS$15:$AX$22,6,FALSE()),"")) -> 0.34149404 | H9: =IFERROR(VLOOKUP(C9,$AS$3:$AY$10,7,FALSE()),IFERROR(VLOOKUP(C9,$AS$15:$AY$22,7,FALSE()),"")) -> 🔴 VERMELHO | I9: =IFERROR(VLOOKUP(C9,$AS$3:$AZ$10,8,FALSE()),IFERROR(VLOOKUP(C9,$AS$15:$AZ$22,8,FALSE()),"")) -> Positivação + Expandir | K9: CENTRO OESTE | L9: 83332.29 | M9: 5856.01 | N9: 6119.32 | O9: 6266.77 | P9: 6430.03 | Q9: 6640.67 | R9: 6814.46 | S9: 7077.77 | T9: 7251.55 | U9: 7414.8 | V9: 7599.12 | W9: 7799.24 | X9: 8062.55 | Y9: . | Z9: =SUM(AA9:AL9) -> 33079.94 | AC9: 2991.96 | AF9: 3054.38 | AG9: 3778.78 | AH9: 5097.2 | AI9: 5983.46 | AJ9: 3773.16 | AK9: 8401 | AM9: . | AN9: =IF(L9=0,0,Z9/L9) -> 0.39696425 | AO9: =IF(AN9="","",IF(AN9>=0.9,"🟢",IF(AN9>=0.7,"🟡",IF(AN9>=0.5,"🟠","🔴")))) -> 🔴 | AP9: =IF(L9=0,0,L9-Z9) -> 50252.35 | AQ9: =IF(AP9=0,"",RANK(AP9,AP$4:AP$503,0)) -> 6 | AR9: . | AS9: TUDO EM GRAOS | AT9: =COUNTIF(C$4:C$503,AS9) -> 3 | AU9: =COUNTIFS(C$4:C$503,AS9,Z$4:Z$503,">0") -> 2 | AV9: =SUMIF(C$4:C$503,AS9,L$4:L$503) -> 20677.87 | AW9: =SUMIF(C$4:C$503,AS9,Z$4:Z$503) -> 8579.2 | AX9: =IF(AV9=0,0,AW9/AV9) -> 0.41489767 | AY9: =IF(AX9>=0.6,"🟢 VERDE",IF(AX9>=0.4,"🟡 AMARELO",IF(AX9>=0.01,"🔴 VERMELHO","🟣 ROXO"))) -> 🟡 AMARELO | AZ9: =IF(AX9>=0.6,"JBP",IF(AX9>=0.4,"Sell Out",IF(AX9>=0.1,"Positivação + Expandir",IF(AX9>=0.01,"Ativar + Prospectar","Mapear + Prospectar")))) -> Sell Out | BA9: . | BB9: =SUM(L$4:L$503)/COUNTA(A$4:A$503) -> 9494.3999 | BC9: =SUM(M$4:M$503)/COUNTA(A$4:A$503) -> 667.20008 | BD9: =SUM(N$4:N$503)/COUNTA(A$4:A$503) -> 697.19996 | BE9: =SUM(O$4:O$503)/COUNTA(A$4:A$503) -> 713.9999 | BF9: =SUM(P$4:P$503)/COUNTA(A$4:A$503) -> 732.59984 | BG9: =SUM(Q$4:Q$503)/COUNTA(A$4:A$503) -> 756.59992 | BH9: =SUM(R$4:R$503)/COUNTA(A$4:A$503) -> 776.40004 | BI9: =SUM(S$4:S$503)/COUNTA(A$4:A$503) -> 806.40012 | BJ9: =SUM(T$4:T$503)/COUNTA(A$4:A$503) -> 826.1999 | BK9: =SUM(U$4:U$503)/COUNTA(A$4:A$503) -> 844.8002 | BL9: =SUM(V$4:V$503)/COUNTA(A$4:A$503) -> 865.7998 | BM9: =SUM(W$4:W$503)/COUNTA(A$4:A$503) -> 888.59982 | BN9: =SUM(X$4:X$503)/COUNTA(A$4:A$503) -> 918.60034 | BO9: . | BP9: =IF(Z9>=BB9,0,IFERROR(BB9+(SUMPRODUCT((Z$4:Z$503>=BB$4:BB$503)*(Z$4:Z$503-BB$4:BB$503))/MAX(1,COUNTIF(Z$4:Z$503,"<"&BB9+0.01))),BB9)) -> 0 | BQ9: =IF(AA9>=BC9,0,IFERROR(BC9+SUMPRODUCT((AA$4:AA$503>=BC$4:BC$503)*(AA$4:AA$503-BC$4:BC$503))/MAX(1,COUNTIF(AA$4:AA$503,"<"&BC9+0.01)),BC9)) -> 2238.4659 | BR9: =IF(AB9>=BD9,0,IFERROR(BD9+SUMPRODUCT((AB$4:AB$503>=BD$4:BD$503)*(AB$4:AB$503-BD$4:BD$503))/MAX(1,COUNTIF(AB$4:AB$503,"<"&BD9+0.01)),BD9)) -> 3335.2938 | BS9: =IF(AC9>=BE9,0,IFERROR(BE9+SUMPRODUCT((AC$4:AC$503>=BE$4:BE$503)*(AC$4:AC$503-BE$4:BE$503))/MAX(1,COUNTIF(AC$4:AC$503,"<"&BE9+0.01)),BE9)) -> 0 | BT9: =IF(AD9>=BF9,0,IFERROR(BF9+SUMPRODUCT((AD$4:AD$503>=BF$4:BF$503)*(AD$4:AD$503-BF$4:BF$503))/MAX(1,COUNTIF(AD$4:AD$503,"<"&BF9+0.01)),BF9)) -> 11354.354 | BU9: =IF(AE9>=BG9,0,IFERROR(BG9+SUMPRODUCT((AE$4:AE$503>=BG$4:BG$503)*(AE$4:AE$503-BG$4:BG$503))/MAX(1,COUNTIF(AE$4:AE$503,"<"&BG9+0.01)),BG9)) -> 7704.8592 | BV9: =IF(AF9>=BH9,0,IFERROR(BH9+SUMPRODUCT((AF$4:AF$503>=BH$4:BH$503)*(AF$4:AF$503-BH$4:BH$503))/MAX(1,COUNTIF(AF$4:AF$503,"<"&BH9+0.01)),BH9)) -> 0 | BW9: =IF(AG9>=BI9,0,IFERROR(BI9+SUMPRODUCT((AG$4:AG$503>=BI$4:BI$503)*(AG$4:AG$503-BI$4:BI$503))/MAX(1,COUNTIF(AG$4:AG$503,"<"&BI9+0.01)),BI9)) -> 0 | BX9: =IF(AH9>=BJ9,0,IFERROR(BJ9+SUMPRODUCT((AH$4:AH$503>=BJ$4:BJ$503)*(AH$4:AH$503-BJ$4:BJ$503))/MAX(1,COUNTIF(AH$4:AH$503,"<"&BJ9+0.01)),BJ9)) -> 0 | ... CB9: =IF(AL9>=BN9,0,IFERROR(BN9+SUMPRODUCT((AL$4:AL$503>=BN$4:BN$503)*(AL$4:AL$503-BN$4:BN$503))/MAX(1,COUNTIF(AL$4:AL$503,"<"&BN9+0.01)),BN9)) -> 3597.2615 | CC9: =IF(AO9="🟢","VERDE",IF(AO9="🟡","AMARELO",IF(AO9="🟠","VERMELHO",IF(AO9="🔴","VERMELHO","ROXO")))) -> VERMELHO | CD9: 🌎 REGIÕES | CE9: SEM REDE
A10: 08895369000111 | B10: ROTTA DO SOL HOTELARIA E TURISMO LTDA | C10: SEM GRUPO | D10: LARISSA PADILHA | E10: . | F10: =IFERROR(VLOOKUP(C10,$AS$3:$AT$10,2,FALSE()),IFERROR(VLOOKUP(C10,$AS$15:$AT$22,2,FALSE()),"")) -> 49 | G10: =IFERROR(VLOOKUP(C10,$AS$3:$AX$10,6,FALSE()),IFERROR(VLOOKUP(C10,$AS$15:$AX$22,6,FALSE()),"")) -> 0.43639135 | H10: =IFERROR(VLOOKUP(C10,$AS$3:$AY$10,7,FALSE()),IFERROR(VLOOKUP(C10,$AS$15:$AY$22,7,FALSE()),"")) -> 🟡 AMARELO | I10: =IFERROR(VLOOKUP(C10,$AS$3:$AZ$10,8,FALSE()),IFERROR(VLOOKUP(C10,$AS$15:$AZ$22,8,FALSE()),"")) -> Sell Out | K10: . | L10: 75249.03 | M10: 5287.98 | N10: 5525.74 | O10: 5658.89 | P10: 5806.31 | Q10: 5996.53 | R10: 6153.45 | S10: 6391.22 | T10: 6548.15 | U10: 6695.57 | V10: 6862 | W10: 7042.71 | X10: 7280.48 | Y10: . | Z10: =SUM(AA10:AL10) -> 30618.45 | AD10: 6846 | AE10: 3780 | AG10: 7118.85 | AI10: 5970 | AK10: 6903.6 | AM10: . | AN10: =IF(L10=0,0,Z10/L10) -> 0.40689495 | AO10: =IF(AN10="","",IF(AN10>=0.9,"🟢",IF(AN10>=0.7,"🟡",IF(AN10>=0.5,"🟠","🔴")))) -> 🔴 | AP10: =IF(L10=0,0,L10-Z10) -> 44630.58 | AQ10: =IF(AP10=0,"",RANK(AP10,AP$4:AP$503,0)) -> 7 | AR10: . | AS10: ARMAZEM FITSTORE | AT10: =COUNTIF(C$4:C$503,AS10) -> 0 | AU10: =COUNTIFS(C$4:C$503,AS10,Z$4:Z$503,">0") -> 0 | AV10: =SUMIF(C$4:C$503,AS10,L$4:L$503) -> 0 | AW10: =SUMIF(C$4:C$503,AS10,Z$4:Z$503) -> 0 | AX10: =IF(AV10=0,0,AW10/AV10) -> 0 | AY10: =IF(AX10>=0.6,"🟢 VERDE",IF(AX10>=0.4,"🟡 AMARELO",IF(AX10>=0.01,"🔴 VERMELHO","🟣 ROXO"))) -> 🟣 ROXO | AZ10: =IF(AX10>=0.6,"JBP",IF(AX10>=0.4,"Sell Out",IF(AX10>=0.1,"Positivação + Expandir",IF(AX10>=0.01,"Ativar + Prospectar","Mapear + Prospectar")))) -> Mapear + Prospectar | BA10: . | BB10: =SUM(L$4:L$503)/COUNTA(A$4:A$503) -> 9494.3999 | BC10: =SUM(M$4:M$503)/COUNTA(A$4:A$503) -> 667.20008 | BD10: =SUM(N$4:N$503)/COUNTA(A$4:A$503) -> 697.19996 | BE10: =SUM(O$4:O$503)/COUNTA(A$4:A$503) -> 713.9999 | BF10: =SUM(P$4:P$503)/COUNTA(A$4:A$503) -> 732.59984 | BG10: =SUM(Q$4:Q$503)/COUNTA(A$4:A$503) -> 756.59992 | BH10: =SUM(R$4:R$503)/COUNTA(A$4:A$503) -> 776.40004 | BI10: =SUM(S$4:S$503)/COUNTA(A$4:A$503) -> 806.40012 | BJ10: =SUM(T$4:T$503)/COUNTA(A$4:A$503) -> 826.1999 | BK10: =SUM(U$4:U$503)/COUNTA(A$4:A$503) -> 844.8002 | BL10: =SUM(V$4:V$503)/COUNTA(A$4:A$503) -> 865.7998 | BM10: =SUM(W$4:W$503)/COUNTA(A$4:A$503) -> 888.59982 | BN10: =SUM(X$4:X$503)/COUNTA(A$4:A$503) -> 918.60034 | BO10: . | BP10: =IF(Z10>=BB10,0,IFERROR(BB10+(SUMPRODUCT((Z$4:Z$503>=BB$4:BB$503)*(Z$4:Z$503-BB$4:BB$503))/MAX(1,COUNTIF(Z$4:Z$503,"<"&BB10+0.01))),BB10)) -> 0 | BQ10: =IF(AA10>=BC10,0,IFERROR(BC10+SUMPRODUCT((AA$4:AA$503>=BC$4:BC$503)*(AA$4:AA$503-BC$4:BC$503))/MAX(1,COUNTIF(AA$4:AA$503,"<"&BC10+0.01)),BC10)) -> 2238.4659 | BR10: =IF(AB10>=BD10,0,IFERROR(BD10+SUMPRODUCT((AB$4:AB$503>=BD$4:BD$503)*(AB$4:AB$503-BD$4:BD$503))/MAX(1,COUNTIF(AB$4:AB$503,"<"&BD10+0.01)),BD10)) -> 3335.2938 | BS10: =IF(AC10>=BE10,0,IFERROR(BE10+SUMPRODUCT((AC$4:AC$503>=BE$4:BE$503)*(AC$4:AC$503-BE$4:BE$503))/MAX(1,COUNTIF(AC$4:AC$503,"<"&BE10+0.01)),BE10)) -> 6188.7335 | BT10: =IF(AD10>=BF10,0,IFERROR(BF10+SUMPRODUCT((AD$4:AD$503>=BF$4:BF$503)*(AD$4:AD$503-BF$4:BF$503))/MAX(1,COUNTIF(AD$4:AD$503,"<"&BF10+0.01)),BF10)) -> 0 | BU10: =IF(AE10>=BG10,0,IFERROR(BG10+SUMPRODUCT((AE$4:AE$503>=BG$4:BG$503)*(AE$4:AE$503-BG$4:BG$503))/MAX(1,COUNTIF(AE$4:AE$503,"<"&BG10+0.01)),BG10)) -> 0 | BV10: =IF(AF10>=BH10,0,IFERROR(BH10+SUMPRODUCT((AF$4:AF$503>=BH$4:BH$503)*(AF$4:AF$503-BH$4:BH$503))/MAX(1,COUNTIF(AF$4:AF$503,"<"&BH10+0.01)),BH10)) -> 9942.6504 | BW10: =IF(AG10>=BI10,0,IFERROR(BI10+SUMPRODUCT((AG$4:AG$503>=BI$4:BI$503)*(AG$4:AG$503-BI$4:BI$503))/MAX(1,COUNTIF(AG$4:AG$503,"<"&BI10+0.01)),BI10)) -> 0 | BX10: =IF(AH10>=BJ10,0,IFERROR(BJ10+SUMPRODUCT((AH$4:AH$503>=BJ$4:BJ$503)*(AH$4:AH$503-BJ$4:BJ$503))/MAX(1,COUNTIF(AH$4:AH$503,"<"&BJ10+0.01)),BJ10)) -> 5621.5026 | ... CB10: =IF(AL10>=BN10,0,IFERROR(BN10+SUMPRODUCT((AL$4:AL$503>=BN$4:BN$503)*(AL$4:AL$503-BN$4:BN$503))/MAX(1,COUNTIF(AL$4:AL$503,"<"&BN10+0.01)),BN10)) -> 3597.2615 | CC10: =IF(AO10="🟢","VERDE",IF(AO10="🟡","AMARELO",IF(AO10="🟠","VERMELHO",IF(AO10="🔴","VERMELHO","ROXO")))) -> VERMELHO | CD10: 🌎 REGIÕES | CE10: SEM REDE
A11: 55615538000283 | B11: COMERCIAL TICAZO HIRATA SA | C11: SP INTERIOR | D11: LARISSA PADILHA | E11: SP | F11: =IFERROR(VLOOKUP(C11,$AS$3:$AT$10,2,FALSE()),IFERROR(VLOOKUP(C11,$AS$15:$AT$22,2,FALSE()),"")) -> 42 | G11: =IFERROR(VLOOKUP(C11,$AS$3:$AX$10,6,FALSE()),IFERROR(VLOOKUP(C11,$AS$15:$AX$22,6,FALSE()),"")) -> 0.42487208 | H11: =IFERROR(VLOOKUP(C11,$AS$3:$AY$10,7,FALSE()),IFERROR(VLOOKUP(C11,$AS$15:$AY$22,7,FALSE()),"")) -> 🟡 AMARELO | I11: =IFERROR(VLOOKUP(C11,$AS$3:$AZ$10,8,FALSE()),IFERROR(VLOOKUP(C11,$AS$15:$AZ$22,8,FALSE()),"")) -> Sell Out | K11: SP INTERIOR | L11: 64642.76 | M11: 4542.64 | N11: 4746.9 | O11: 4861.28 | P11: 4987.92 | Q11: 5151.32 | R11: 5286.13 | S11: 5490.39 | T11: 5625.19 | U11: 5751.83 | V11: 5894.81 | W11: 6050.05 | X11: 6254.3 | Y11: . | Z11: =SUM(AA11:AL11) -> 27305.35 | AC11: 4155.84 | AD11: 3082.89 | AE11: 5621.77 | AG11: 4988.89 | AH11: 2571.82 | AJ11: 4770.31 | AK11: 2113.83 | AM11: . | AN11: =IF(L11=0,0,Z11/L11) -> 0.42240384 | AO11: =IF(AN11="","",IF(AN11>=0.9,"🟢",IF(AN11>=0.7,"🟡",IF(AN11>=0.5,"🟠","🔴")))) -> 🔴 | AP11: =IF(L11=0,0,L11-Z11) -> 37337.41 | AQ11: =IF(AP11=0,"",RANK(AP11,AP$4:AP$503,0)) -> 8 | AR11: . | AS11: TOTAL REDES | AU11: =SUM(AU3:AU10) -> 109 | AV11: =SUM(AV3:AV10) -> 661617.52 | AW11: =SUM(AW3:AW10) -> 336242.73 | AX11: =IF(AV11=0,0,AW11/AV11) -> 0.50821316 | BA11: . | BB11: =SUM(L$4:L$503)/COUNTA(A$4:A$503) -> 9494.3999 | BC11: =SUM(M$4:M$503)/COUNTA(A$4:A$503) -> 667.20008 | BD11: =SUM(N$4:N$503)/COUNTA(A$4:A$503) -> 697.19996 | BE11: =SUM(O$4:O$503)/COUNTA(A$4:A$503) -> 713.9999 | BF11: =SUM(P$4:P$503)/COUNTA(A$4:A$503) -> 732.59984 | BG11: =SUM(Q$4:Q$503)/COUNTA(A$4:A$503) -> 756.59992 | BH11: =SUM(R$4:R$503)/COUNTA(A$4:A$503) -> 776.40004 | BI11: =SUM(S$4:S$503)/COUNTA(A$4:A$503) -> 806.40012 | BJ11: =SUM(T$4:T$503)/COUNTA(A$4:A$503) -> 826.1999 | BK11: =SUM(U$4:U$503)/COUNTA(A$4:A$503) -> 844.8002 | BL11: =SUM(V$4:V$503)/COUNTA(A$4:A$503) -> 865.7998 | BM11: =SUM(W$4:W$503)/COUNTA(A$4:A$503) -> 888.59982 | BN11: =SUM(X$4:X$503)/COUNTA(A$4:A$503) -> 918.60034 | BO11: . | BP11: =IF(Z11>=BB11,0,IFERROR(BB11+(SUMPRODUCT((Z$4:Z$503>=BB$4:BB$503)*(Z$4:Z$503-BB$4:BB$503))/MAX(1,COUNTIF(Z$4:Z$503,"<"&BB11+0.01))),BB11)) -> 0 | BQ11: =IF(AA11>=BC11,0,IFERROR(BC11+SUMPRODUCT((AA$4:AA$503>=BC$4:BC$503)*(AA$4:AA$503-BC$4:BC$503))/MAX(1,COUNTIF(AA$4:AA$503,"<"&BC11+0.01)),BC11)) -> 2238.4659 | BR11: =IF(AB11>=BD11,0,IFERROR(BD11+SUMPRODUCT((AB$4:AB$503>=BD$4:BD$503)*(AB$4:AB$503-BD$4:BD$503))/MAX(1,COUNTIF(AB$4:AB$503,"<"&BD11+0.01)),BD11)) -> 3335.2938 | BS11: =IF(AC11>=BE11,0,IFERROR(BE11+SUMPRODUCT((AC$4:AC$503>=BE$4:BE$503)*(AC$4:AC$503-BE$4:BE$503))/MAX(1,COUNTIF(AC$4:AC$503,"<"&BE11+0.01)),BE11)) -> 0 | BT11: =IF(AD11>=BF11,0,IFERROR(BF11+SUMPRODUCT((AD$4:AD$503>=BF$4:BF$503)*(AD$4:AD$503-BF$4:BF$503))/MAX(1,COUNTIF(AD$4:AD$503,"<"&BF11+0.01)),BF11)) -> 0 | BU11: =IF(AE11>=BG11,0,IFERROR(BG11+SUMPRODUCT((AE$4:AE$503>=BG$4:BG$503)*(AE$4:AE$503-BG$4:BG$503))/MAX(1,COUNTIF(AE$4:AE$503,"<"&BG11+0.01)),BG11)) -> 0 | BV11: =IF(AF11>=BH11,0,IFERROR(BH11+SUMPRODUCT((AF$4:AF$503>=BH$4:BH$503)*(AF$4:AF$503-BH$4:BH$503))/MAX(1,COUNTIF(AF$4:AF$503,"<"&BH11+0.01)),BH11)) -> 9942.6504 | BW11: =IF(AG11>=BI11,0,IFERROR(BI11+SUMPRODUCT((AG$4:AG$503>=BI$4:BI$503)*(AG$4:AG$503-BI$4:BI$503))/MAX(1,COUNTIF(AG$4:AG$503,"<"&BI11+0.01)),BI11)) -> 0 | BX11: =IF(AH11>=BJ11,0,IFERROR(BJ11+SUMPRODUCT((AH$4:AH$503>=BJ$4:BJ$503)*(AH$4:AH$503-BJ$4:BJ$503))/MAX(1,COUNTIF(AH$4:AH$503,"<"&BJ11+0.01)),BJ11)) -> 0 | ... CB11: =IF(AL11>=BN11,0,IFERROR(BN11+SUMPRODUCT((AL$4:AL$503>=BN$4:BN$503)*(AL$4:AL$503-BN$4:BN$503))/MAX(1,COUNTIF(AL$4:AL$503,"<"&BN11+0.01)),BN11)) -> 3597.2615 | CC11: =IF(AO11="🟢","VERDE",IF(AO11="🟡","AMARELO",IF(AO11="🟠","VERMELHO",IF(AO11="🔴","VERMELHO","ROXO")))) -> VERMELHO | CD11: 🌎 REGIÕES | CE11: SEM REDE
A12: 34924371000181 | B12: SOARES DISTRIBUIDORA DE PRODUTOS EM GERA | C12: SUL | D12: HEMANUELE DITZEL (MANU) | E12: PR | F12: =IFERROR(VLOOKUP(C12,$AS$3:$AT$10,2,FALSE()),IFERROR(VLOOKUP(C12,$AS$15:$AT$22,2,FALSE()),"")) -> 132 | G12: =IFERROR(VLOOKUP(C12,$AS$3:$AX$10,6,FALSE()),IFERROR(VLOOKUP(C12,$AS$15:$AX$22,6,FALSE()),"")) -> 0.46819018 | H12: =IFERROR(VLOOKUP(C12,$AS$3:$AY$10,7,FALSE()),IFERROR(VLOOKUP(C12,$AS$15:$AY$22,7,FALSE()),"")) -> 🟡 AMARELO | I12: =IFERROR(VLOOKUP(C12,$AS$3:$AZ$10,8,FALSE()),IFERROR(VLOOKUP(C12,$AS$15:$AZ$22,8,FALSE()),"")) -> Sell Out | K12: SUL | L12: 64453.39 | M12: 4529.33 | N12: 4732.99 | O12: 4847.04 | P12: 4973.31 | Q12: 5136.23 | R12: 5270.65 | S12: 5474.3 | T12: 5608.72 | U12: 5734.98 | V12: 5877.54 | W12: 6032.32 | X12: 6235.98 | Y12: . | Z12: =SUM(AA12:AL12) -> 27788.43 | AF12: 27788.43 | AM12: . | AN12: =IF(L12=0,0,Z12/L12) -> 0.43113993 | AO12: =IF(AN12="","",IF(AN12>=0.9,"🟢",IF(AN12>=0.7,"🟡",IF(AN12>=0.5,"🟠","🔴")))) -> 🔴 | AP12: =IF(L12=0,0,L12-Z12) -> 36664.96 | AQ12: =IF(AP12=0,"",RANK(AP12,AP$4:AP$503,0)) -> 9 | AR12: . | BA12: . | BB12: =SUM(L$4:L$503)/COUNTA(A$4:A$503) -> 9494.3999 | BC12: =SUM(M$4:M$503)/COUNTA(A$4:A$503) -> 667.20008 | BD12: =SUM(N$4:N$503)/COUNTA(A$4:A$503) -> 697.19996 | BE12: =SUM(O$4:O$503)/COUNTA(A$4:A$503) -> 713.9999 | BF12: =SUM(P$4:P$503)/COUNTA(A$4:A$503) -> 732.59984 | BG12: =SUM(Q$4:Q$503)/COUNTA(A$4:A$503) -> 756.59992 | BH12: =SUM(R$4:R$503)/COUNTA(A$4:A$503) -> 776.40004 | BI12: =SUM(S$4:S$503)/COUNTA(A$4:A$503) -> 806.40012 | BJ12: =SUM(T$4:T$503)/COUNTA(A$4:A$503) -> 826.1999 | BK12: =SUM(U$4:U$503)/COUNTA(A$4:A$503) -> 844.8002 | BL12: =SUM(V$4:V$503)/COUNTA(A$4:A$503) -> 865.7998 | BM12: =SUM(W$4:W$503)/COUNTA(A$4:A$503) -> 888.59982 | BN12: =SUM(X$4:X$503)/COUNTA(A$4:A$503) -> 918.60034 | BO12: . | BP12: =IF(Z12>=BB12,0,IFERROR(BB12+(SUMPRODUCT((Z$4:Z$503>=BB$4:BB$503)*(Z$4:Z$503-BB$4:BB$503))/MAX(1,COUNTIF(Z$4:Z$503,"<"&BB12+0.01))),BB12)) -> 0 | BQ12: =IF(AA12>=BC12,0,IFERROR(BC12+SUMPRODUCT((AA$4:AA$503>=BC$4:BC$503)*(AA$4:AA$503-BC$4:BC$503))/MAX(1,COUNTIF(AA$4:AA$503,"<"&BC12+0.01)),BC12)) -> 2238.4659 | BR12: =IF(AB12>=BD12,0,IFERROR(BD12+SUMPRODUCT((AB$4:AB$503>=BD$4:BD$503)*(AB$4:AB$503-BD$4:BD$503))/MAX(1,COUNTIF(AB$4:AB$503,"<"&BD12+0.01)),BD12)) -> 3335.2938 | BS12: =IF(AC12>=BE12,0,IFERROR(BE12+SUMPRODUCT((AC$4:AC$503>=BE$4:BE$503)*(AC$4:AC$503-BE$4:BE$503))/MAX(1,COUNTIF(AC$4:AC$503,"<"&BE12+0.01)),BE12)) -> 6188.7335 | BT12: =IF(AD12>=BF12,0,IFERROR(BF12+SUMPRODUCT((AD$4:AD$503>=BF$4:BF$503)*(AD$4:AD$503-BF$4:BF$503))/MAX(1,COUNTIF(AD$4:AD$503,"<"&BF12+0.01)),BF12)) -> 11354.354 | BU12: =IF(AE12>=BG12,0,IFERROR(BG12+SUMPRODUCT((AE$4:AE$503>=BG$4:BG$503)*(AE$4:AE$503-BG$4:BG$503))/MAX(1,COUNTIF(AE$4:AE$503,"<"&BG12+0.01)),BG12)) -> 7704.8592 | BV12: =IF(AF12>=BH12,0,IFERROR(BH12+SUMPRODUCT((AF$4:AF$503>=BH$4:BH$503)*(AF$4:AF$503-BH$4:BH$503))/MAX(1,COUNTIF(AF$4:AF$503,"<"&BH12+0.01)),BH12)) -> 0 | BW12: =IF(AG12>=BI12,0,IFERROR(BI12+SUMPRODUCT((AG$4:AG$503>=BI$4:BI$503)*(AG$4:AG$503-BI$4:BI$503))/MAX(1,COUNTIF(AG$4:AG$503,"<"&BI12+0.01)),BI12)) -> 9142.1587 | BX12: =IF(AH12>=BJ12,0,IFERROR(BJ12+SUMPRODUCT((AH$4:AH$503>=BJ$4:BJ$503)*(AH$4:AH$503-BJ$4:BJ$503))/MAX(1,COUNTIF(AH$4:AH$503,"<"&BJ12+0.01)),BJ12)) -> 5621.5026 | ... CB12: =IF(AL12>=BN12,0,IFERROR(BN12+SUMPRODUCT((AL$4:AL$503>=BN$4:BN$503)*(AL$4:AL$503-BN$4:BN$503))/MAX(1,COUNTIF(AL$4:AL$503,"<"&BN12+0.01)),BN12)) -> 3597.2615 | CC12: =IF(AO12="🟢","VERDE",IF(AO12="🟡","AMARELO",IF(AO12="🟠","VERMELHO",IF(AO12="🔴","VERMELHO","ROXO")))) -> VERMELHO | CD12: 🌎 REGIÕES | CE12: SEM REDE
A13: 41887017000190 | B13: CHOKOLATEN ALIMENTOS INDUSTRIA E COMERCI | C13: SUL | D13: HEMANUELE DITZEL (MANU) | E13: SC | F13: =IFERROR(VLOOKUP(C13,$AS$3:$AT$10,2,FALSE()),IFERROR(VLOOKUP(C13,$AS$15:$AT$22,2,FALSE()),"")) -> 132 | G13: =IFERROR(VLOOKUP(C13,$AS$3:$AX$10,6,FALSE()),IFERROR(VLOOKUP(C13,$AS$15:$AX$22,6,FALSE()),"")) -> 0.46819018 | H13: =IFERROR(VLOOKUP(C13,$AS$3:$AY$10,7,FALSE()),IFERROR(VLOOKUP(C13,$AS$15:$AY$22,7,FALSE()),"")) -> 🟡 AMARELO | I13: =IFERROR(VLOOKUP(C13,$AS$3:$AZ$10,8,FALSE()),IFERROR(VLOOKUP(C13,$AS$15:$AZ$22,8,FALSE()),"")) -> Sell Out | K13: SUL | L13: 57545.51 | M13: 4043.9 | N13: 4225.72 | O13: 4327.55 | P13: 4440.28 | Q13: 4585.75 | R13: 4705.76 | S13: 4887.59 | T13: 5007.59 | U13: 5120.33 | V13: 5247.61 | W13: 5385.8 | X13: 5567.63 | Y13: . | Z13: =SUM(AA13:AL13) -> 35439.82 | AG13: 3467.83 | AI13: 12654.14 | AJ13: 9729.07 | AK13: 9588.78 | AM13: . | AN13: =IF(L13=0,0,Z13/L13) -> 0.61585726 | AO13: =IF(AN13="","",IF(AN13>=0.9,"🟢",IF(AN13>=0.7,"🟡",IF(AN13>=0.5,"🟠","🔴")))) -> 🟠 | AP13: =IF(L13=0,0,L13-Z13) -> 22105.69 | AQ13: =IF(AP13=0,"",RANK(AP13,AP$4:AP$503,0)) -> 17 | AR13: . | AS13: 🌎 SINALEIRO REGIÕES | BA13: . | BB13: =SUM(L$4:L$503)/COUNTA(A$4:A$503) -> 9494.3999 | BC13: =SUM(M$4:M$503)/COUNTA(A$4:A$503) -> 667.20008 | BD13: =SUM(N$4:N$503)/COUNTA(A$4:A$503) -> 697.19996 | BE13: =SUM(O$4:O$503)/COUNTA(A$4:A$503) -> 713.9999 | BF13: =SUM(P$4:P$503)/COUNTA(A$4:A$503) -> 732.59984 | BG13: =SUM(Q$4:Q$503)/COUNTA(A$4:A$503) -> 756.59992 | BH13: =SUM(R$4:R$503)/COUNTA(A$4:A$503) -> 776.40004 | BI13: =SUM(S$4:S$503)/COUNTA(A$4:A$503) -> 806.40012 | BJ13: =SUM(T$4:T$503)/COUNTA(A$4:A$503) -> 826.1999 | BK13: =SUM(U$4:U$503)/COUNTA(A$4:A$503) -> 844.8002 | BL13: =SUM(V$4:V$503)/COUNTA(A$4:A$503) -> 865.7998 | BM13: =SUM(W$4:W$503)/COUNTA(A$4:A$503) -> 888.59982 | BN13: =SUM(X$4:X$503)/COUNTA(A$4:A$503) -> 918.60034 | BO13: . | BP13: =IF(Z13>=BB13,0,IFERROR(BB13+(SUMPRODUCT((Z$4:Z$503>=BB$4:BB$503)*(Z$4:Z$503-BB$4:BB$503))/MAX(1,COUNTIF(Z$4:Z$503,"<"&BB13+0.01))),BB13)) -> 0 | BQ13: =IF(AA13>=BC13,0,IFERROR(BC13+SUMPRODUCT((AA$4:AA$503>=BC$4:BC$503)*(AA$4:AA$503-BC$4:BC$503))/MAX(1,COUNTIF(AA$4:AA$503,"<"&BC13+0.01)),BC13)) -> 2238.4659 | BR13: =IF(AB13>=BD13,0,IFERROR(BD13+SUMPRODUCT((AB$4:AB$503>=BD$4:BD$503)*(AB$4:AB$503-BD$4:BD$503))/MAX(1,COUNTIF(AB$4:AB$503,"<"&BD13+0.01)),BD13)) -> 3335.2938 | BS13: =IF(AC13>=BE13,0,IFERROR(BE13+SUMPRODUCT((AC$4:AC$503>=BE$4:BE$503)*(AC$4:AC$503-BE$4:BE$503))/MAX(1,COUNTIF(AC$4:AC$503,"<"&BE13+0.01)),BE13)) -> 6188.7335 | BT13: =IF(AD13>=BF13,0,IFERROR(BF13+SUMPRODUCT((AD$4:AD$503>=BF$4:BF$503)*(AD$4:AD$503-BF$4:BF$503))/MAX(1,COUNTIF(AD$4:AD$503,"<"&BF13+0.01)),BF13)) -> 11354.354 | BU13: =IF(AE13>=BG13,0,IFERROR(BG13+SUMPRODUCT((AE$4:AE$503>=BG$4:BG$503)*(AE$4:AE$503-BG$4:BG$503))/MAX(1,COUNTIF(AE$4:AE$503,"<"&BG13+0.01)),BG13)) -> 7704.8592 | BV13: =IF(AF13>=BH13,0,IFERROR(BH13+SUMPRODUCT((AF$4:AF$503>=BH$4:BH$503)*(AF$4:AF$503-BH$4:BH$503))/MAX(1,COUNTIF(AF$4:AF$503,"<"&BH13+0.01)),BH13)) -> 9942.6504 | BW13: =IF(AG13>=BI13,0,IFERROR(BI13+SUMPRODUCT((AG$4:AG$503>=BI$4:BI$503)*(AG$4:AG$503-BI$4:BI$503))/MAX(1,COUNTIF(AG$4:AG$503,"<"&BI13+0.01)),BI13)) -> 0 | BX13: =IF(AH13>=BJ13,0,IFERROR(BJ13+SUMPRODUCT((AH$4:AH$503>=BJ$4:BJ$503)*(AH$4:AH$503-BJ$4:BJ$503))/MAX(1,COUNTIF(AH$4:AH$503,"<"&BJ13+0.01)),BJ13)) -> 5621.5026 | ... CB13: =IF(AL13>=BN13,0,IFERROR(BN13+SUMPRODUCT((AL$4:AL$503>=BN$4:BN$503)*(AL$4:AL$503-BN$4:BN$503))/MAX(1,COUNTIF(AL$4:AL$503,"<"&BN13+0.01)),BN13)) -> 3597.2615 | CC13: =IF(AO13="🟢","VERDE",IF(AO13="🟡","AMARELO",IF(AO13="🟠","VERMELHO",IF(AO13="🔴","VERMELHO","ROXO")))) -> VERMELHO | CD13: 🌎 REGIÕES | CE13: SEM REDE
A14: 31545180000110 | B14: NATURALIS PRODUTOS NATURAIS LTDA - EPP | C14: SUL | D14: HEMANUELE DITZEL (MANU) | E14: SC | F14: =IFERROR(VLOOKUP(C14,$AS$3:$AT$10,2,FALSE()),IFERROR(VLOOKUP(C14,$AS$15:$AT$22,2,FALSE()),"")) -> 132 | G14: =IFERROR(VLOOKUP(C14,$AS$3:$AX$10,6,FALSE()),IFERROR(VLOOKUP(C14,$AS$15:$AX$22,6,FALSE()),"")) -> 0.46819018 | H14: =IFERROR(VLOOKUP(C14,$AS$3:$AY$10,7,FALSE()),IFERROR(VLOOKUP(C14,$AS$15:$AY$22,7,FALSE()),"")) -> 🟡 AMARELO | I14: =IFERROR(VLOOKUP(C14,$AS$3:$AZ$10,8,FALSE()),IFERROR(VLOOKUP(C14,$AS$15:$AZ$22,8,FALSE()),"")) -> Sell Out | K14: SUL | L14: 55925.26 | M14: 3930.04 | N14: 4106.75 | O14: 4205.7 | P14: 4315.26 | Q14: 4456.63 | R14: 4573.26 | S14: 4749.97 | T14: 4866.6 | U14: 4976.16 | V14: 5099.86 | W14: 5234.16 | X14: 5410.87 | Y14: . | Z14: =SUM(AA14:AL14) -> 22963.56 | AB14: 1512 | AD14: 4899.73 | AE14: 2635.53 | AH14: 5094 | AI14: 1188.55 | AJ14: 3502.75 | AL14: 4131 | AM14: . | AN14: =IF(L14=0,0,Z14/L14) -> 0.41061159 | AO14: =IF(AN14="","",IF(AN14>=0.9,"🟢",IF(AN14>=0.7,"🟡",IF(AN14>=0.5,"🟠","🔴")))) -> 🔴 | AP14: =IF(L14=0,0,L14-Z14) -> 32961.7 | AQ14: =IF(AP14=0,"",RANK(AP14,AP$4:AP$503,0)) -> 10 | AR14: . | AS14: GRUPO | AT14: CLIENTES | AU14: C/ VENDA | AV14: META R$ | AW14: FAT. REAL R$ | AX14: SINALEIRO % | AY14: COR | AZ14: AÇÃO | BA14: . | BB14: =SUM(L$4:L$503)/COUNTA(A$4:A$503) -> 9494.3999 | BC14: =SUM(M$4:M$503)/COUNTA(A$4:A$503) -> 667.20008 | BD14: =SUM(N$4:N$503)/COUNTA(A$4:A$503) -> 697.19996 | BE14: =SUM(O$4:O$503)/COUNTA(A$4:A$503) -> 713.9999 | BF14: =SUM(P$4:P$503)/COUNTA(A$4:A$503) -> 732.59984 | BG14: =SUM(Q$4:Q$503)/COUNTA(A$4:A$503) -> 756.59992 | BH14: =SUM(R$4:R$503)/COUNTA(A$4:A$503) -> 776.40004 | BI14: =SUM(S$4:S$503)/COUNTA(A$4:A$503) -> 806.40012 | BJ14: =SUM(T$4:T$503)/COUNTA(A$4:A$503) -> 826.1999 | BK14: =SUM(U$4:U$503)/COUNTA(A$4:A$503) -> 844.8002 | BL14: =SUM(V$4:V$503)/COUNTA(A$4:A$503) -> 865.7998 | BM14: =SUM(W$4:W$503)/COUNTA(A$4:A$503) -> 888.59982 | BN14: =SUM(X$4:X$503)/COUNTA(A$4:A$503) -> 918.60034 | BO14: . | BP14: =IF(Z14>=BB14,0,IFERROR(BB14+(SUMPRODUCT((Z$4:Z$503>=BB$4:BB$503)*(Z$4:Z$503-BB$4:BB$503))/MAX(1,COUNTIF(Z$4:Z$503,"<"&BB14+0.01))),BB14)) -> 0 | BQ14: =IF(AA14>=BC14,0,IFERROR(BC14+SUMPRODUCT((AA$4:AA$503>=BC$4:BC$503)*(AA$4:AA$503-BC$4:BC$503))/MAX(1,COUNTIF(AA$4:AA$503,"<"&BC14+0.01)),BC14)) -> 2238.4659 | BR14: =IF(AB14>=BD14,0,IFERROR(BD14+SUMPRODUCT((AB$4:AB$503>=BD$4:BD$503)*(AB$4:AB$503-BD$4:BD$503))/MAX(1,COUNTIF(AB$4:AB$503,"<"&BD14+0.01)),BD14)) -> 0 | BS14: =IF(AC14>=BE14,0,IFERROR(BE14+SUMPRODUCT((AC$4:AC$503>=BE$4:BE$503)*(AC$4:AC$503-BE$4:BE$503))/MAX(1,COUNTIF(AC$4:AC$503,"<"&BE14+0.01)),BE14)) -> 6188.7335 | BT14: =IF(AD14>=BF14,0,IFERROR(BF14+SUMPRODUCT((AD$4:AD$503>=BF$4:BF$503)*(AD$4:AD$503-BF$4:BF$503))/MAX(1,COUNTIF(AD$4:AD$503,"<"&BF14+0.01)),BF14)) -> 0 | BU14: =IF(AE14>=BG14,0,IFERROR(BG14+SUMPRODUCT((AE$4:AE$503>=BG$4:BG$503)*(AE$4:AE$503-BG$4:BG$503))/MAX(1,COUNTIF(AE$4:AE$503,"<"&BG14+0.01)),BG14)) -> 0 | BV14: =IF(AF14>=BH14,0,IFERROR(BH14+SUMPRODUCT((AF$4:AF$503>=BH$4:BH$503)*(AF$4:AF$503-BH$4:BH$503))/MAX(1,COUNTIF(AF$4:AF$503,"<"&BH14+0.01)),BH14)) -> 9942.6504 | BW14: =IF(AG14>=BI14,0,IFERROR(BI14+SUMPRODUCT((AG$4:AG$503>=BI$4:BI$503)*(AG$4:AG$503-BI$4:BI$503))/MAX(1,COUNTIF(AG$4:AG$503,"<"&BI14+0.01)),BI14)) -> 9142.1587 | BX14: =IF(AH14>=BJ14,0,IFERROR(BJ14+SUMPRODUCT((AH$4:AH$503>=BJ$4:BJ$503)*(AH$4:AH$503-BJ$4:BJ$503))/MAX(1,COUNTIF(AH$4:AH$503,"<"&BJ14+0.01)),BJ14)) -> 0 | ... CB14: =IF(AL14>=BN14,0,IFERROR(BN14+SUMPRODUCT((AL$4:AL$503>=BN$4:BN$503)*(AL$4:AL$503-BN$4:BN$503))/MAX(1,COUNTIF(AL$4:AL$503,"<"&BN14+0.01)),BN14)) -> 0 | CC14: =IF(AO14="🟢","VERDE",IF(AO14="🟡","AMARELO",IF(AO14="🟠","VERMELHO",IF(AO14="🔴","VERMELHO","ROXO")))) -> VERMELHO | CD14: 🌎 REGIÕES | CE14: SEM REDE
A15: 34901637000170 | B15: MERCANTIL SALES LTDA - ME | C15: NORTE + MA | D15: LARISSA PADILHA | E15: PA | F15: =IFERROR(VLOOKUP(C15,$AS$3:$AT$10,2,FALSE()),IFERROR(VLOOKUP(C15,$AS$15:$AT$22,2,FALSE()),"")) -> 10 | G15: =IFERROR(VLOOKUP(C15,$AS$3:$AX$10,6,FALSE()),IFERROR(VLOOKUP(C15,$AS$15:$AX$22,6,FALSE()),"")) -> 0.45643525 | H15: =IFERROR(VLOOKUP(C15,$AS$3:$AY$10,7,FALSE()),IFERROR(VLOOKUP(C15,$AS$15:$AY$22,7,FALSE()),"")) -> 🟡 AMARELO | I15: =IFERROR(VLOOKUP(C15,$AS$3:$AZ$10,8,FALSE()),IFERROR(VLOOKUP(C15,$AS$15:$AZ$22,8,FALSE()),"")) -> Sell Out | K15: NORTE + MA | L15: 54236.21 | M15: 3811.34 | N15: 3982.72 | O15: 4078.68 | P15: 4184.94 | Q15: 4322.03 | R15: 4435.14 | S15: 4606.51 | T15: 4719.62 | U15: 4825.87 | V15: 4945.83 | W15: 5076.08 | X15: 5247.45 | Y15: . | Z15: =SUM(AA15:AL15) -> 26817.41 | AA15: 5364.79 | AC15: 4625.46 | AE15: 2713 | AF15: 4506.85 | AH15: 3280.39 | AI15: 3792.14 | AK15: 2534.78 | AM15: . | AN15: =IF(L15=0,0,Z15/L15) -> 0.49445583 | AO15: =IF(AN15="","",IF(AN15>=0.9,"🟢",IF(AN15>=0.7,"🟡",IF(AN15>=0.5,"🟠","🔴")))) -> 🔴 | AP15: =IF(L15=0,0,L15-Z15) -> 27418.8 | AQ15: =IF(AP15=0,"",RANK(AP15,AP$4:AP$503,0)) -> 11 | AR15: . | AS15: SUL | AT15: =COUNTIF(C$4:C$503,AS15) -> 132 | AU15: =COUNTIFS(C$4:C$503,AS15,Z$4:Z$503,">0") -> 131 | AV15: =SUMIF(C$4:C$503,AS15,L$4:L$503) -> 1152066.6 | AW15: =SUMIF(C$4:C$503,AS15,Z$4:Z$503) -> 539386.25 | AX15: =IF(AV15=0,0,AW15/AV15) -> 0.46819018 | AY15: =IF(AX15>=0.6,"🟢 VERDE",IF(AX15>=0.4,"🟡 AMARELO",IF(AX15>=0.01,"🔴 VERMELHO","🟣 ROXO"))) -> 🟡 AMARELO | AZ15: =IF(AX15>=0.6,"JBP",IF(AX15>=0.4,"Sell Out",IF(AX15>=0.1,"Positivação + Expandir",IF(AX15>=0.01,"Ativar + Prospectar","Mapear + Prospectar")))) -> Sell Out | BA15: . | BB15: =SUM(L$4:L$503)/COUNTA(A$4:A$503) -> 9494.3999 | BC15: =SUM(M$4:M$503)/COUNTA(A$4:A$503) -> 667.20008 | BD15: =SUM(N$4:N$503)/COUNTA(A$4:A$503) -> 697.19996 | BE15: =SUM(O$4:O$503)/COUNTA(A$4:A$503) -> 713.9999 | BF15: =SUM(P$4:P$503)/COUNTA(A$4:A$503) -> 732.59984 | BG15: =SUM(Q$4:Q$503)/COUNTA(A$4:A$503) -> 756.59992 | BH15: =SUM(R$4:R$503)/COUNTA(A$4:A$503) -> 776.40004 | BI15: =SUM(S$4:S$503)/COUNTA(A$4:A$503) -> 806.40012 | BJ15: =SUM(T$4:T$503)/COUNTA(A$4:A$503) -> 826.1999 | BK15: =SUM(U$4:U$503)/COUNTA(A$4:A$503) -> 844.8002 | BL15: =SUM(V$4:V$503)/COUNTA(A$4:A$503) -> 865.7998 | BM15: =SUM(W$4:W$503)/COUNTA(A$4:A$503) -> 888.59982 | BN15: =SUM(X$4:X$503)/COUNTA(A$4:A$503) -> 918.60034 | BO15: . | BP15: =IF(Z15>=BB15,0,IFERROR(BB15+(SUMPRODUCT((Z$4:Z$503>=BB$4:BB$503)*(Z$4:Z$503-BB$4:BB$503))/MAX(1,COUNTIF(Z$4:Z$503,"<"&BB15+0.01))),BB15)) -> 0 | BQ15: =IF(AA15>=BC15,0,IFERROR(BC15+SUMPRODUCT((AA$4:AA$503>=BC$4:BC$503)*(AA$4:AA$503-BC$4:BC$503))/MAX(1,COUNTIF(AA$4:AA$503,"<"&BC15+0.01)),BC15)) -> 0 | BR15: =IF(AB15>=BD15,0,IFERROR(BD15+SUMPRODUCT((AB$4:AB$503>=BD$4:BD$503)*(AB$4:AB$503-BD$4:BD$503))/MAX(1,COUNTIF(AB$4:AB$503,"<"&BD15+0.01)),BD15)) -> 3335.2938 | BS15: =IF(AC15>=BE15,0,IFERROR(BE15+SUMPRODUCT((AC$4:AC$503>=BE$4:BE$503)*(AC$4:AC$503-BE$4:BE$503))/MAX(1,COUNTIF(AC$4:AC$503,"<"&BE15+0.01)),BE15)) -> 0 | BT15: =IF(AD15>=BF15,0,IFERROR(BF15+SUMPRODUCT((AD$4:AD$503>=BF$4:BF$503)*(AD$4:AD$503-BF$4:BF$503))/MAX(1,COUNTIF(AD$4:AD$503,"<"&BF15+0.01)),BF15)) -> 11354.354 | BU15: =IF(AE15>=BG15,0,IFERROR(BG15+SUMPRODUCT((AE$4:AE$503>=BG$4:BG$503)*(AE$4:AE$503-BG$4:BG$503))/MAX(1,COUNTIF(AE$4:AE$503,"<"&BG15+0.01)),BG15)) -> 0 | BV15: =IF(AF15>=BH15,0,IFERROR(BH15+SUMPRODUCT((AF$4:AF$503>=BH$4:BH$503)*(AF$4:AF$503-BH$4:BH$503))/MAX(1,COUNTIF(AF$4:AF$503,"<"&BH15+0.01)),BH15)) -> 0 | BW15: =IF(AG15>=BI15,0,IFERROR(BI15+SUMPRODUCT((AG$4:AG$503>=BI$4:BI$503)*(AG$4:AG$503-BI$4:BI$503))/MAX(1,COUNTIF(AG$4:AG$503,"<"&BI15+0.01)),BI15)) -> 9142.1587 | BX15: =IF(AH15>=BJ15,0,IFERROR(BJ15+SUMPRODUCT((AH$4:AH$503>=BJ$4:BJ$503)*(AH$4:AH$503-BJ$4:BJ$503))/MAX(1,COUNTIF(AH$4:AH$503,"<"&BJ15+0.01)),BJ15)) -> 0 | ... CB15: =IF(AL15>=BN15,0,IFERROR(BN15+SUMPRODUCT((AL$4:AL$503>=BN$4:BN$503)*(AL$4:AL$503-BN$4:BN$503))/MAX(1,COUNTIF(AL$4:AL$503,"<"&BN15+0.01)),BN15)) -> 3597.2615 | CC15: =IF(AO15="🟢","VERDE",IF(AO15="🟡","AMARELO",IF(AO15="🟠","VERMELHO",IF(AO15="🔴","VERMELHO","ROXO")))) -> VERMELHO | CD15: 🌎 REGIÕES | CE15: SEM REDE
A16: 14133092000192 | B16: BESCO INDUSTRIAL DE ALIMENTOS LTDA - ME | C16: SUL | D16: HEMANUELE DITZEL (MANU) | E16: SC | F16: =IFERROR(VLOOKUP(C16,$AS$3:$AT$10,2,FALSE()),IFERROR(VLOOKUP(C16,$AS$15:$AT$22,2,FALSE()),"")) -> 132 | G16: =IFERROR(VLOOKUP(C16,$AS$3:$AX$10,6,FALSE()),IFERROR(VLOOKUP(C16,$AS$15:$AX$22,6,FALSE()),"")) -> 0.46819018 | H16: =IFERROR(VLOOKUP(C16,$AS$3:$AY$10,7,FALSE()),IFERROR(VLOOKUP(C16,$AS$15:$AY$22,7,FALSE()),"")) -> 🟡 AMARELO | I16: =IFERROR(VLOOKUP(C16,$AS$3:$AZ$10,8,FALSE()),IFERROR(VLOOKUP(C16,$AS$15:$AZ$22,8,FALSE()),"")) -> Sell Out | K16: SUL | L16: 53677.08 | M16: 3772.05 | N16: 3941.66 | O16: 4036.64 | P16: 4141.79 | Q16: 4277.48 | R16: 4389.42 | S16: 4559.02 | T16: 4670.96 | U16: 4776.12 | V16: 4894.84 | W16: 5023.75 | X16: 5193.35 | Y16: . | Z16: =SUM(AA16:AL16) -> 26818.32 | AE16: 8607.14 | AF16: 12740.35 | AG16: 5470.83 | AM16: . | AN16: =IF(L16=0,0,Z16/L16) -> 0.4996233 | AO16: =IF(AN16="","",IF(AN16>=0.9,"🟢",IF(AN16>=0.7,"🟡",IF(AN16>=0.5,"🟠","🔴")))) -> 🔴 | AP16: =IF(L16=0,0,L16-Z16) -> 26858.76 | AQ16: =IF(AP16=0,"",RANK(AP16,AP$4:AP$503,0)) -> 13 | AR16: . | AS16: SP CAPITAL | AT16: =COUNTIF(C$4:C$503,AS16) -> 29 | AU16: =COUNTIFS(C$4:C$503,AS16,Z$4:Z$503,">0") -> 29 | AV16: =SUMIF(C$4:C$503,AS16,L$4:L$503) -> 239355.48 | AW16: =SUMIF(C$4:C$503,AS16,Z$4:Z$503) -> 101928.35 | AX16: =IF(AV16=0,0,AW16/AV16) -> 0.42584507 | AY16: =IF(AX16>=0.6,"🟢 VERDE",IF(AX16>=0.4,"🟡 AMARELO",IF(AX16>=0.01,"🔴 VERMELHO","🟣 ROXO"))) -> 🟡 AMARELO | AZ16: =IF(AX16>=0.6,"JBP",IF(AX16>=0.4,"Sell Out",IF(AX16>=0.1,"Positivação + Expandir",IF(AX16>=0.01,"Ativar + Prospectar","Mapear + Prospectar")))) -> Sell Out | BA16: . | BB16: =SUM(L$4:L$503)/COUNTA(A$4:A$503) -> 9494.3999 | BC16: =SUM(M$4:M$503)/COUNTA(A$4:A$503) -> 667.20008 | BD16: =SUM(N$4:N$503)/COUNTA(A$4:A$503) -> 697.19996 | BE16: =SUM(O$4:O$503)/COUNTA(A$4:A$503) -> 713.9999 | BF16: =SUM(P$4:P$503)/COUNTA(A$4:A$503) -> 732.59984 | BG16: =SUM(Q$4:Q$503)/COUNTA(A$4:A$503) -> 756.59992 | BH16: =SUM(R$4:R$503)/COUNTA(A$4:A$503) -> 776.40004 | BI16: =SUM(S$4:S$503)/COUNTA(A$4:A$503) -> 806.40012 | BJ16: =SUM(T$4:T$503)/COUNTA(A$4:A$503) -> 826.1999 | BK16: =SUM(U$4:U$503)/COUNTA(A$4:A$503) -> 844.8002 | BL16: =SUM(V$4:V$503)/COUNTA(A$4:A$503) -> 865.7998 | BM16: =SUM(W$4:W$503)/COUNTA(A$4:A$503) -> 888.59982 | BN16: =SUM(X$4:X$503)/COUNTA(A$4:A$503) -> 918.60034 | BO16: . | BP16: =IF(Z16>=BB16,0,IFERROR(BB16+(SUMPRODUCT((Z$4:Z$503>=BB$4:BB$503)*(Z$4:Z$503-BB$4:BB$503))/MAX(1,COUNTIF(Z$4:Z$503,"<"&BB16+0.01))),BB16)) -> 0 | BQ16: =IF(AA16>=BC16,0,IFERROR(BC16+SUMPRODUCT((AA$4:AA$503>=BC$4:BC$503)*(AA$4:AA$503-BC$4:BC$503))/MAX(1,COUNTIF(AA$4:AA$503,"<"&BC16+0.01)),BC16)) -> 2238.4659 | BR16: =IF(AB16>=BD16,0,IFERROR(BD16+SUMPRODUCT((AB$4:AB$503>=BD$4:BD$503)*(AB$4:AB$503-BD$4:BD$503))/MAX(1,COUNTIF(AB$4:AB$503,"<"&BD16+0.01)),BD16)) -> 3335.2938 | BS16: =IF(AC16>=BE16,0,IFERROR(BE16+SUMPRODUCT((AC$4:AC$503>=BE$4:BE$503)*(AC$4:AC$503-BE$4:BE$503))/MAX(1,COUNTIF(AC$4:AC$503,"<"&BE16+0.01)),BE16)) -> 6188.7335 | BT16: =IF(AD16>=BF16,0,IFERROR(BF16+SUMPRODUCT((AD$4:AD$503>=BF$4:BF$503)*(AD$4:AD$503-BF$4:BF$503))/MAX(1,COUNTIF(AD$4:AD$503,"<"&BF16+0.01)),BF16)) -> 11354.354 | BU16: =IF(AE16>=BG16,0,IFERROR(BG16+SUMPRODUCT((AE$4:AE$503>=BG$4:BG$503)*(AE$4:AE$503-BG$4:BG$503))/MAX(1,COUNTIF(AE$4:AE$503,"<"&BG16+0.01)),BG16)) -> 0 | BV16: =IF(AF16>=BH16,0,IFERROR(BH16+SUMPRODUCT((AF$4:AF$503>=BH$4:BH$503)*(AF$4:AF$503-BH$4:BH$503))/MAX(1,COUNTIF(AF$4:AF$503,"<"&BH16+0.01)),BH16)) -> 0 | BW16: =IF(AG16>=BI16,0,IFERROR(BI16+SUMPRODUCT((AG$4:AG$503>=BI$4:BI$503)*(AG$4:AG$503-BI$4:BI$503))/MAX(1,COUNTIF(AG$4:AG$503,"<"&BI16+0.01)),BI16)) -> 0 | BX16: =IF(AH16>=BJ16,0,IFERROR(BJ16+SUMPRODUCT((AH$4:AH$503>=BJ$4:BJ$503)*(AH$4:AH$503-BJ$4:BJ$503))/MAX(1,COUNTIF(AH$4:AH$503,"<"&BJ16+0.01)),BJ16)) -> 5621.5026 | ... CB16: =IF(AL16>=BN16,0,IFERROR(BN16+SUMPRODUCT((AL$4:AL$503>=BN$4:BN$503)*(AL$4:AL$503-BN$4:BN$503))/MAX(1,COUNTIF(AL$4:AL$503,"<"&BN16+0.01)),BN16)) -> 3597.2615 | CC16: =IF(AO16="🟢","VERDE",IF(AO16="🟡","AMARELO",IF(AO16="🟠","VERMELHO",IF(AO16="🔴","VERMELHO","ROXO")))) -> VERMELHO | CD16: 🌎 REGIÕES | CE16: SEM REDE
A17: 80230774000148 | B17: COOP. CENTRAL CREDITO, POUPANCA E INVEST | C17: SUL | D17: HEMANUELE DITZEL (MANU) | E17: PR | F17: =IFERROR(VLOOKUP(C17,$AS$3:$AT$10,2,FALSE()),IFERROR(VLOOKUP(C17,$AS$15:$AT$22,2,FALSE()),"")) -> 132 | G17: =IFERROR(VLOOKUP(C17,$AS$3:$AX$10,6,FALSE()),IFERROR(VLOOKUP(C17,$AS$15:$AX$22,6,FALSE()),"")) -> 0.46819018 | H17: =IFERROR(VLOOKUP(C17,$AS$3:$AY$10,7,FALSE()),IFERROR(VLOOKUP(C17,$AS$15:$AY$22,7,FALSE()),"")) -> 🟡 AMARELO | I17: =IFERROR(VLOOKUP(C17,$AS$3:$AZ$10,8,FALSE()),IFERROR(VLOOKUP(C17,$AS$15:$AZ$22,8,FALSE()),"")) -> Sell Out | K17: SUL | L17: 45011.85 | M17: 3163.12 | N17: 3305.34 | O17: 3384.99 | P17: 3473.17 | Q17: 3586.95 | R17: 3680.82 | S17: 3823.05 | T17: 3916.92 | U17: 4005.1 | V17: 4104.66 | W17: 4212.75 | X17: 4354.98 | Y17: . | Z17: =SUM(AA17:AL17) -> 18101.56 | AB17: 2831.96 | AD17: 2297.2 | AE17: 2297.2 | AG17: 2001.6 | AH17: 2001.6 | AI17: 3336 | AJ17: 3336 | AM17: . | AN17: =IF(L17=0,0,Z17/L17) -> 0.40215099 | AO17: =IF(AN17="","",IF(AN17>=0.9,"🟢",IF(AN17>=0.7,"🟡",IF(AN17>=0.5,"🟠","🔴")))) -> 🔴 | AP17: =IF(L17=0,0,L17-Z17) -> 26910.29 | AQ17: =IF(AP17=0,"",RANK(AP17,AP$4:AP$503,0)) -> 12 | AR17: . | AS17: SP INTERIOR | AT17: =COUNTIF(C$4:C$503,AS17) -> 42 | AU17: =COUNTIFS(C$4:C$503,AS17,Z$4:Z$503,">0") -> 42 | AV17: =SUMIF(C$4:C$503,AS17,L$4:L$503) -> 438148.58 | AW17: =SUMIF(C$4:C$503,AS17,Z$4:Z$503) -> 186157.1 | AX17: =IF(AV17=0,0,AW17/AV17) -> 0.42487208 | AY17: =IF(AX17>=0.6,"🟢 VERDE",IF(AX17>=0.4,"🟡 AMARELO",IF(AX17>=0.01,"🔴 VERMELHO","🟣 ROXO"))) -> 🟡 AMARELO | AZ17: =IF(AX17>=0.6,"JBP",IF(AX17>=0.4,"Sell Out",IF(AX17>=0.1,"Positivação + Expandir",IF(AX17>=0.01,"Ativar + Prospectar","Mapear + Prospectar")))) -> Sell Out | BA17: . | BB17: =SUM(L$4:L$503)/COUNTA(A$4:A$503) -> 9494.3999 | BC17: =SUM(M$4:M$503)/COUNTA(A$4:A$503) -> 667.20008 | BD17: =SUM(N$4:N$503)/COUNTA(A$4:A$503) -> 697.19996 | BE17: =SUM(O$4:O$503)/COUNTA(A$4:A$503) -> 713.9999 | BF17: =SUM(P$4:P$503)/COUNTA(A$4:A$503) -> 732.59984 | BG17: =SUM(Q$4:Q$503)/COUNTA(A$4:A$503) -> 756.59992 | BH17: =SUM(R$4:R$503)/COUNTA(A$4:A$503) -> 776.40004 | BI17: =SUM(S$4:S$503)/COUNTA(A$4:A$503) -> 806.40012 | BJ17: =SUM(T$4:T$503)/COUNTA(A$4:A$503) -> 826.1999 | BK17: =SUM(U$4:U$503)/COUNTA(A$4:A$503) -> 844.8002 | BL17: =SUM(V$4:V$503)/COUNTA(A$4:A$503) -> 865.7998 | BM17: =SUM(W$4:W$503)/COUNTA(A$4:A$503) -> 888.59982 | BN17: =SUM(X$4:X$503)/COUNTA(A$4:A$503) -> 918.60034 | BO17: . | BP17: =IF(Z17>=BB17,0,IFERROR(BB17+(SUMPRODUCT((Z$4:Z$503>=BB$4:BB$503)*(Z$4:Z$503-BB$4:BB$503))/MAX(1,COUNTIF(Z$4:Z$503,"<"&BB17+0.01))),BB17)) -> 0 | BQ17: =IF(AA17>=BC17,0,IFERROR(BC17+SUMPRODUCT((AA$4:AA$503>=BC$4:BC$503)*(AA$4:AA$503-BC$4:BC$503))/MAX(1,COUNTIF(AA$4:AA$503,"<"&BC17+0.01)),BC17)) -> 2238.4659 | BR17: =IF(AB17>=BD17,0,IFERROR(BD17+SUMPRODUCT((AB$4:AB$503>=BD$4:BD$503)*(AB$4:AB$503-BD$4:BD$503))/MAX(1,COUNTIF(AB$4:AB$503,"<"&BD17+0.01)),BD17)) -> 0 | BS17: =IF(AC17>=BE17,0,IFERROR(BE17+SUMPRODUCT((AC$4:AC$503>=BE$4:BE$503)*(AC$4:AC$503-BE$4:BE$503))/MAX(1,COUNTIF(AC$4:AC$503,"<"&BE17+0.01)),BE17)) -> 6188.7335 | BT17: =IF(AD17>=BF17,0,IFERROR(BF17+SUMPRODUCT((AD$4:AD$503>=BF$4:BF$503)*(AD$4:AD$503-BF$4:BF$503))/MAX(1,COUNTIF(AD$4:AD$503,"<"&BF17+0.01)),BF17)) -> 0 | BU17: =IF(AE17>=BG17,0,IFERROR(BG17+SUMPRODUCT((AE$4:AE$503>=BG$4:BG$503)*(AE$4:AE$503-BG$4:BG$503))/MAX(1,COUNTIF(AE$4:AE$503,"<"&BG17+0.01)),BG17)) -> 0 | BV17: =IF(AF17>=BH17,0,IFERROR(BH17+SUMPRODUCT((AF$4:AF$503>=BH$4:BH$503)*(AF$4:AF$503-BH$4:BH$503))/MAX(1,COUNTIF(AF$4:AF$503,"<"&BH17+0.01)),BH17)) -> 9942.6504 | BW17: =IF(AG17>=BI17,0,IFERROR(BI17+SUMPRODUCT((AG$4:AG$503>=BI$4:BI$503)*(AG$4:AG$503-BI$4:BI$503))/MAX(1,COUNTIF(AG$4:AG$503,"<"&BI17+0.01)),BI17)) -> 0 | BX17: =IF(AH17>=BJ17,0,IFERROR(BJ17+SUMPRODUCT((AH$4:AH$503>=BJ$4:BJ$503)*(AH$4:AH$503-BJ$4:BJ$503))/MAX(1,COUNTIF(AH$4:AH$503,"<"&BJ17+0.01)),BJ17)) -> 0 | ... CB17: =IF(AL17>=BN17,0,IFERROR(BN17+SUMPRODUCT((AL$4:AL$503>=BN$4:BN$503)*(AL$4:AL$503-BN$4:BN$503))/MAX(1,COUNTIF(AL$4:AL$503,"<"&BN17+0.01)),BN17)) -> 3597.2615 | CC17: =IF(AO17="🟢","VERDE",IF(AO17="🟡","AMARELO",IF(AO17="🟠","VERMELHO",IF(AO17="🔴","VERMELHO","ROXO")))) -> VERMELHO | CD17: 🌎 REGIÕES | CE17: SEM REDE
