Workbook

Sheet Resumo
A1: FATURAMENTO PROJETADO ABR-DEZ | G1: =Faturamento!AC1 -> 3157000 | N1: TOTAIS | O1: NÃO
N3: Rótulos de Linha | O3: Soma de ABR | P3: Soma de MAI | Q3: Soma de JUN | R3: Soma de JUL | S3: Soma de AGO | T3: Soma de SET | U3: Soma de OUT | V3: Soma de NOV | W3: Soma de DEZ | X3: Soma de TOTAL META
N4: HELDER DA SILVA BRUNKOW | O4: 66000 | P4: 75000 | Q4: 95000 | R4: 113000 | S4: 135300 | T4: 169400 | U4: 185900 | V4: 207900 | W4: 141900 | X4: 1189400
N5: REGIONAL VENDA INTERNA - KEY ACCOUNT | O5: 30000 | P5: 33000 | Q5: 40000 | R5: 48000 | S5: 61600 | T5: 75900 | U5: 79200 | V5: 91300 | W5: 62700 | X5: 521700
N6: HEMANUELE ROSA DITZEL | O6: 63000 | P6: 77000 | Q6: 96000 | R6: 115000 | S6: 143000 | T6: 181500 | U6: 198000 | V6: 222200 | W6: 151800 | X6: 1247500
N7: REGIONAL VENDA INTERNA - CONVENIENCIA | O7: 10400 | P7: 11200 | Q7: 15200 | R7: 18400 | S7: 22400 | T7: 25600 | U7: 28800 | V7: 32800 | W7: 33600 | X7: 198400
N8: Total Geral | O8: 169400 | P8: 196200 | Q8: 246200 | R8: 294400 | S8: 362300 | T8: 452400 | U8: 491900 | V8: 554200 | W8: 390000 | X8: 3157000
A21: TOTAIS | B21: (Tudo)
A23: Rótulos de Linha | B23: Soma de JUL | C23: Soma de AGO
A24: 1324 | B24: 2000 | C24: 2200
A25: 1325 | B25: 10000 | C25: 11000
A26: 1326 | B26: 8000 | C26: 8800
A27: 1327 | B27: 4000 | C27: 4400
A28: 1328 | B28: 6000 | C28: 6600
A29: 1329 | B29: 4000 | C29: 4400
A30: 1330 | B30: 2000 | C30: 2200
A31: 1331 | B31: 22000 | C31: 26400
A32: 1332 | B32: 6000 | C32: 6600
A33: 1346 | B33: 4000 | C33: 4400
A34: 1347 | B34: 4000 | C34: 4400
A35: 1348 | B35: 2000 | C35: 2200
... A89: 1533 | B89: 2000 | C89: 2200
A90: Total Geral | B90: 588800 | C90: 724600
O95: Atual | P95: proposto | Q95: gap | R95: ações
N96: meta faturamento | O96: 250 | P96: 450000 | Q96: =P96-O96 -> 449750
N97: meta / vendedor /3 | O97: =O96/2 -> 125 | P97: =P96/3 -> 150000 | Q97: =P97-O97 -> 149875
E98: 240 | N98: ticket medio | O98: 1200 | P98: 2000 | Q98: =P98-O98 -> 800
E99: 294 | N99: positivações mês / vendedor | O99: =O97/O98 -> 0.10416667 | P99: =P97/P98 -> 75 | Q99: =P99-O99 -> 74.895833
E100: 150 | N100: positivação dia / vendedor | O100: =O99/24 -> 0.0043402778 | P100: =P99/24 -> 3.125 | Q100: =P100-O100 -> 3.1206597
N101: taxa conversão | P101: 0.1 | Q101: =P101-O101 -> 0.1
N102: leads abordados por dia | P102: =P100/P101 -> 31.25 | Q102: =P102-O102 -> 31.25

Sheet Planilha1

Sheet Faturamento
K1: ; | Q1: =SUM(Q3:Q1190)/2 -> 0 | R1: =SUM(R3:R1190)/2 -> 170446.27 | S1: =SUM(S3:S1190)/2 -> 193433.64 | T1: =SUM(T3:T1190)/2 -> 169400 | U1: =SUM(U3:U1190)/2 -> 196200 | V1: =SUM(V3:V1190)/2 -> 246200 | W1: =SUM(W3:W1190)/2 -> 294400 | X1: =SUM(X3:X1190)/2 -> 362300 | ... AB1: =SUM(AB3:AB1190)/2 -> 390000 | AC1: =SUM(T1:AB1) -> 3157000
A2: TOTAIS | B2: CÓD. ZP | C2: ZP Gerente Nacional | D2: CÓD. ZP | E2: ZY Gerente Regional | F2: CÓD. ZS | G2: ZS Supervisor | H2: CÓD. ZQ | I2: ZQ Coordenador | J2: CÓD. ZX / ZR | K2: ZR Representante | L2: Titulo | M2: UF | N2: Nº Grupo | O2: Grupo Cliente | P2: Grupo Produto | Q2: JAN | R2: FEV | S2: MAR | T2: ABR | U2: MAI | V2: JUN | W2: JUL | X2: AGO | Y2: SET | Z2: OUT | AA2: NOV | AB2: DEZ | AC2: TOTAL META | AD2: FALTA VENDER | AE2: VENDIDO EM 2024 | AF2: META ANO PROPOSTA | AG2: VENDIDO 1º TRI MAIS GRANEL | AH2: META 1º TRI | AI2: FALTOU 1º TRI | AJ2: % REALIZADO 1º TRI | AK2: STATUS | AL2: BALIZADOR DA META | AM2: Ação
A3: =IF(L3=1,"SIM","NÃO") -> SIM | B3: =_xlfn.XLOOKUP($N3,'Base de Grupos'!$A:$A,'Base de Grupos'!$D:$D) -> 1000065763 | C3: =_xlfn.XLOOKUP($N3,'Base de Grupos'!$A:$A,'Base de Grupos'!$E:$E) -> CANAL VENDA INTERNA | D3: =_xlfn.XLOOKUP($N3,'Base de Grupos'!$A:$A,'Base de Grupos'!$F:$F) -> 1000065763 | E3: =_xlfn.XLOOKUP($N3,'Base de Grupos'!$A:$A,'Base de Grupos'!$G:$G) -> CANAL VENDA INTERNA | F3: =_xlfn.XLOOKUP($N3,'Base de Grupos'!$A:$A,'Base de Grupos'!$H:$H) -> 1000105900 | G3: =_xlfn.XLOOKUP($N3,'Base de Grupos'!$A:$A,'Base de Grupos'!$I:$I) -> REGIONAL VENDA DIRETA CO + NE + NO | H3: =_xlfn.XLOOKUP($N3,'Base de Grupos'!$A:$A,'Base de Grupos'!$J:$J) -> 1000105900 | I3: =_xlfn.XLOOKUP($N3,'Base de Grupos'!$A:$A,'Base de Grupos'!$K:$K) -> REGIONAL VENDA DIRETA CO + NE + NO | J3: =_xlfn.XLOOKUP($N3,'Base de Grupos'!$A:$A,'Base de Grupos'!$L:$L) -> 1000150135 | K3: =_xlfn.XLOOKUP($N3,'Base de Grupos'!$A:$A,'Base de Grupos'!$M:$M) -> HELDER DA SILVA BRUNKOW | L3: =IF(N3<>N2,1,"") -> 1 | M3: =_xlfn.XLOOKUP($N3,'Base de Grupos'!$A:$A,'Base de Grupos'!$C:$C) -> AP | N3: 1324 | O3: VENDA INTERNA AP | P3: 1. TOTAL - VENDA INTERNA AP | Q3: =SUM(Q4:Q20) -> 0 | R3: =SUM(R4:R20) -> 10568.294 | S3: =SUM(S4:S20) -> 12029.079 | T3: =SUM(T4:T20) -> 1000 | U3: =SUM(U4:U20) -> 1000 | V3: =SUM(V4:V20) -> 1000 | W3: =SUM(W4:W20) -> 1000 | X3: =SUM(X4:X20) -> 1100 | ... AE3: =SUM(AE4:AE20) -> 0 | AF3: =IFERROR((AC3-AE3)/AE3,"") | AG3: =SUM(AG4:AG20) -> 0 | AH3: =SUM(AH4:AH20) -> 22597.373 | AI3: =SUM(AI4:AI20) -> 22597.373 | AJ3: =IFERROR(AG3/AH3,"") -> 0
A4: =IF(L4=1,"SIM","NÃO") -> NÃO | B4: =_xlfn.XLOOKUP($N4,'Base de Grupos'!$A:$A,'Base de Grupos'!$D:$D) -> 1000065763 | C4: =_xlfn.XLOOKUP($N4,'Base de Grupos'!$A:$A,'Base de Grupos'!$E:$E) -> CANAL VENDA INTERNA | D4: =_xlfn.XLOOKUP($N4,'Base de Grupos'!$A:$A,'Base de Grupos'!$F:$F) -> 1000065763 | E4: =_xlfn.XLOOKUP($N4,'Base de Grupos'!$A:$A,'Base de Grupos'!$G:$G) -> CANAL VENDA INTERNA | F4: =_xlfn.XLOOKUP($N4,'Base de Grupos'!$A:$A,'Base de Grupos'!$H:$H) -> 1000105900 | G4: =_xlfn.XLOOKUP($N4,'Base de Grupos'!$A:$A,'Base de Grupos'!$I:$I) -> REGIONAL VENDA DIRETA CO + NE + NO | H4: =_xlfn.XLOOKUP($N4,'Base de Grupos'!$A:$A,'Base de Grupos'!$J:$J) -> 1000105900 | I4: =_xlfn.XLOOKUP($N4,'Base de Grupos'!$A:$A,'Base de Grupos'!$K:$K) -> REGIONAL VENDA DIRETA CO + NE + NO | J4: =_xlfn.XLOOKUP($N4,'Base de Grupos'!$A:$A,'Base de Grupos'!$L:$L) -> 1000150135 | K4: =_xlfn.XLOOKUP($N4,'Base de Grupos'!$A:$A,'Base de Grupos'!$M:$M) -> HELDER DA SILVA BRUNKOW | L4: =IF(N4<>N3,1,"") | M4: =_xlfn.XLOOKUP($N4,'Base de Grupos'!$A:$A,'Base de Grupos'!$C:$C) -> AP | N4: 1324 | O4: VENDA INTERNA AP | P4: BISCOITO | Q4: 0 | R4: 404.38861 | S4: 505.48576 | T4: =_xlfn.XLOOKUP($N4,'Calculo Leads'!$A$97:$A$134,'Calculo Leads'!G$97:G$134)*_xlfn.XLOOKUP($P4,'Base Grupo de Produtos'!$E$2:$E$18,'Base Grupo de Produtos'!$F$2:$F$18) -> 50 | U4: =_xlfn.XLOOKUP($N4,'Calculo Leads'!$A$97:$A$134,'Calculo Leads'!H$97:H$134)*_xlfn.XLOOKUP($P4,'Base Grupo de Produtos'!$E$2:$E$18,'Base Grupo de Produtos'!$F$2:$F$18) -> 50 | V4: =_xlfn.XLOOKUP($N4,'Calculo Leads'!$A$97:$A$134,'Calculo Leads'!I$97:I$134)*_xlfn.XLOOKUP($P4,'Base Grupo de Produtos'!$E$2:$E$18,'Base Grupo de Produtos'!$F$2:$F$18) -> 50 | W4: =_xlfn.XLOOKUP($N4,'Calculo Leads'!$A$97:$A$134,'Calculo Leads'!J$97:J$134)*_xlfn.XLOOKUP($P4,'Base Grupo de Produtos'!$E$2:$E$18,'Base Grupo de Produtos'!$F$2:$F$18) -> 50 | X4: =_xlfn.XLOOKUP($N4,'Calculo Leads'!$A$97:$A$134,'Calculo Leads'!K$97:K$134)*_xlfn.XLOOKUP($P4,'Base Grupo de Produtos'!$E$2:$E$18,'Base Grupo de Produtos'!$F$2:$F$18) -> 55 | Y4: =_xlfn.XLOOKUP($N4,'Calculo Leads'!$A$97:$A$134,'Calculo Leads'!L$97:L$134)*_xlfn.XLOOKUP($P4,'Base Grupo de Produtos'!$E$2:$E$18,'Base Grupo de Produtos'!$F$2:$F$18) -> 55 | Z4: =_xlfn.XLOOKUP($N4,'Calculo Leads'!$A$97:$A$134,'Calculo Leads'!M$97:M$134)*_xlfn.XLOOKUP($P4,'Base Grupo de Produtos'!$E$2:$E$18,'Base Grupo de Produtos'!$F$2:$F$18) -> 55 | AA4: =_xlfn.XLOOKUP($N4,'Calculo Leads'!$A$97:$A$134,'Calculo Leads'!N$97:N$134)*_xlfn.XLOOKUP($P4,'Base Grupo de Produtos'!$E$2:$E$18,'Base Grupo de Produtos'!$F$2:$F$18) -> 55 | AB4: =_xlfn.XLOOKUP($N4,'Calculo Leads'!$A$97:$A$134,'Calculo Leads'!O$97:O$134)*_xlfn.XLOOKUP($P4,'Base Grupo de Produtos'!$E$2:$E$18,'Base Grupo de Produtos'!$F$2:$F$18) -> 55 | AC4: =SUM(T4:AB4) -> 475 | AD4: =IF(AC4=0,0,AC4-AG4) -> 475 | AE4: =IFERROR(_xlfn.XLOOKUP(N4&P4,'Historico Vendas'!G:G,'Historico Vendas'!E:E),0) -> 0 | AF4: =IFERROR((AC4-AE4)/AE4,"") | AG4: =IFERROR(_xlfn.XLOOKUP(N4&P4,'Historico Vendas'!G:G,'Historico Vendas'!F:F),0) -> 0 | AH4: =SUM(Q4:S4) -> 909.87436 | AI4: =AH4-AG4 -> 909.87436 | AJ4: =IFERROR(AG4/AH4,"") -> 0 | AK4: Novos | AL4: =IFERROR(INDEX('Balizador da Meta'!$D$3:$F$23,MATCH(Faturamento!$P4,'Balizador da Meta'!$C$3:$C$23,0),MATCH(Faturamento!AK4,'Balizador da Meta'!$D$2:$F$2,0)),"") -> 0.2
A5: =IF(L5=1,"SIM","NÃO") -> NÃO | B5: =_xlfn.XLOOKUP($N5,'Base de Grupos'!$A:$A,'Base de Grupos'!$D:$D) -> 1000065763 | C5: =_xlfn.XLOOKUP($N5,'Base de Grupos'!$A:$A,'Base de Grupos'!$E:$E) -> CANAL VENDA INTERNA | D5: =_xlfn.XLOOKUP($N5,'Base de Grupos'!$A:$A,'Base de Grupos'!$F:$F) -> 1000065763 | E5: =_xlfn.XLOOKUP($N5,'Base de Grupos'!$A:$A,'Base de Grupos'!$G:$G) -> CANAL VENDA INTERNA | F5: =_xlfn.XLOOKUP($N5,'Base de Grupos'!$A:$A,'Base de Grupos'!$H:$H) -> 1000105900 | G5: =_xlfn.XLOOKUP($N5,'Base de Grupos'!$A:$A,'Base de Grupos'!$I:$I) -> REGIONAL VENDA DIRETA CO + NE + NO | H5: =_xlfn.XLOOKUP($N5,'Base de Grupos'!$A:$A,'Base de Grupos'!$J:$J) -> 1000105900 | I5: =_xlfn.XLOOKUP($N5,'Base de Grupos'!$A:$A,'Base de Grupos'!$K:$K) -> REGIONAL VENDA DIRETA CO + NE + NO | J5: =_xlfn.XLOOKUP($N5,'Base de Grupos'!$A:$A,'Base de Grupos'!$L:$L) -> 1000150135 | K5: =_xlfn.XLOOKUP($N5,'Base de Grupos'!$A:$A,'Base de Grupos'!$M:$M) -> HELDER DA SILVA BRUNKOW | L5: =IF(N5<>N4,1,"") | M5: =_xlfn.XLOOKUP($N5,'Base de Grupos'!$A:$A,'Base de Grupos'!$C:$C) -> AP | N5: 1324 | O5: VENDA INTERNA AP | P5: CHOCOLATES | Q5: 0 | R5: 2462.0565 | S5: 2872.3992 | T5: =_xlfn.XLOOKUP($N5,'Calculo Leads'!$A$97:$A$134,'Calculo Leads'!G$97:G$134)*_xlfn.XLOOKUP($P5,'Base Grupo de Produtos'!$E$2:$E$18,'Base Grupo de Produtos'!$F$2:$F$18) -> 50 | U5: =_xlfn.XLOOKUP($N5,'Calculo Leads'!$A$97:$A$134,'Calculo Leads'!H$97:H$134)*_xlfn.XLOOKUP($P5,'Base Grupo de Produtos'!$E$2:$E$18,'Base Grupo de Produtos'!$F$2:$F$18) -> 50 | V5: =_xlfn.XLOOKUP($N5,'Calculo Leads'!$A$97:$A$134,'Calculo Leads'!I$97:I$134)*_xlfn.XLOOKUP($P5,'Base Grupo de Produtos'!$E$2:$E$18,'Base Grupo de Produtos'!$F$2:$F$18) -> 50 | W5: =_xlfn.XLOOKUP($N5,'Calculo Leads'!$A$97:$A$134,'Calculo Leads'!J$97:J$134)*_xlfn.XLOOKUP($P5,'Base Grupo de Produtos'!$E$2:$E$18,'Base Grupo de Produtos'!$F$2:$F$18) -> 50 | X5: =_xlfn.XLOOKUP($N5,'Calculo Leads'!$A$97:$A$134,'Calculo Leads'!K$97:K$134)*_xlfn.XLOOKUP($P5,'Base Grupo de Produtos'!$E$2:$E$18,'Base Grupo de Produtos'!$F$2:$F$18) -> 55 | Y5: =_xlfn.XLOOKUP($N5,'Calculo Leads'!$A$97:$A$134,'Calculo Leads'!L$97:L$134)*_xlfn.XLOOKUP($P5,'Base Grupo de Produtos'!$E$2:$E$18,'Base Grupo de Produtos'!$F$2:$F$18) -> 55 | Z5: =_xlfn.XLOOKUP($N5,'Calculo Leads'!$A$97:$A$134,'Calculo Leads'!M$97:M$134)*_xlfn.XLOOKUP($P5,'Base Grupo de Produtos'!$E$2:$E$18,'Base Grupo de Produtos'!$F$2:$F$18) -> 55 | AA5: =_xlfn.XLOOKUP($N5,'Calculo Leads'!$A$97:$A$134,'Calculo Leads'!N$97:N$134)*_xlfn.XLOOKUP($P5,'Base Grupo de Produtos'!$E$2:$E$18,'Base Grupo de Produtos'!$F$2:$F$18) -> 55 | AB5: =_xlfn.XLOOKUP($N5,'Calculo Leads'!$A$97:$A$134,'Calculo Leads'!O$97:O$134)*_xlfn.XLOOKUP($P5,'Base Grupo de Produtos'!$E$2:$E$18,'Base Grupo de Produtos'!$F$2:$F$18) -> 55 | AC5: =SUM(T5:AB5) -> 475 | AD5: =IF(AC5=0,0,AC5-AG5) -> 475 | AE5: =IFERROR(_xlfn.XLOOKUP(N5&P5,'Historico Vendas'!G:G,'Historico Vendas'!E:E),0) -> 0 | AF5: =IFERROR((AC5-AE5)/AE5,"") | AG5: =IFERROR(_xlfn.XLOOKUP(N5&P5,'Historico Vendas'!G:G,'Historico Vendas'!F:F),0) -> 0 | AH5: =SUM(Q5:S5) -> 5334.4557 | AI5: =AH5-AG5 -> 5334.4557 | AJ5: =IFERROR(AG5/AH5,"") -> 0 | AK5: Novos | AL5: =IFERROR(INDEX('Balizador da Meta'!$D$3:$F$23,MATCH(Faturamento!$P5,'Balizador da Meta'!$C$3:$C$23,0),MATCH(Faturamento!AK5,'Balizador da Meta'!$D$2:$F$2,0)),"") -> 0.2
A6: =IF(L6=1,"SIM","NÃO") -> NÃO | B6: =_xlfn.XLOOKUP($N6,'Base de Grupos'!$A:$A,'Base de Grupos'!$D:$D) -> 1000065763 | C6: =_xlfn.XLOOKUP($N6,'Base de Grupos'!$A:$A,'Base de Grupos'!$E:$E) -> CANAL VENDA INTERNA | D6: =_xlfn.XLOOKUP($N6,'Base de Grupos'!$A:$A,'Base de Grupos'!$F:$F) -> 1000065763 | E6: =_xlfn.XLOOKUP($N6,'Base de Grupos'!$A:$A,'Base de Grupos'!$G:$G) -> CANAL VENDA INTERNA | F6: =_xlfn.XLOOKUP($N6,'Base de Grupos'!$A:$A,'Base de Grupos'!$H:$H) -> 1000105900 | G6: =_xlfn.XLOOKUP($N6,'Base de Grupos'!$A:$A,'Base de Grupos'!$I:$I) -> REGIONAL VENDA DIRETA CO + NE + NO | H6: =_xlfn.XLOOKUP($N6,'Base de Grupos'!$A:$A,'Base de Grupos'!$J:$J) -> 1000105900 | I6: =_xlfn.XLOOKUP($N6,'Base de Grupos'!$A:$A,'Base de Grupos'!$K:$K) -> REGIONAL VENDA DIRETA CO + NE + NO | J6: =_xlfn.XLOOKUP($N6,'Base de Grupos'!$A:$A,'Base de Grupos'!$L:$L) -> 1000150135 | K6: =_xlfn.XLOOKUP($N6,'Base de Grupos'!$A:$A,'Base de Grupos'!$M:$M) -> HELDER DA SILVA BRUNKOW | L6: =IF(N6<>N5,1,"") | M6: =_xlfn.XLOOKUP($N6,'Base de Grupos'!$A:$A,'Base de Grupos'!$C:$C) -> AP | N6: 1324 | O6: VENDA INTERNA AP | P6: DISNEY | Q6: 0 | R6: 441.51511 | S6: 551.89389 | T6: =_xlfn.XLOOKUP($N6,'Calculo Leads'!$A$97:$A$134,'Calculo Leads'!G$97:G$134)*_xlfn.XLOOKUP($P6,'Base Grupo de Produtos'!$E$2:$E$18,'Base Grupo de Produtos'!$F$2:$F$18) -> 80 | U6: =_xlfn.XLOOKUP($N6,'Calculo Leads'!$A$97:$A$134,'Calculo Leads'!H$97:H$134)*_xlfn.XLOOKUP($P6,'Base Grupo de Produtos'!$E$2:$E$18,'Base Grupo de Produtos'!$F$2:$F$18) -> 80 | V6: =_xlfn.XLOOKUP($N6,'Calculo Leads'!$A$97:$A$134,'Calculo Leads'!I$97:I$134)*_xlfn.XLOOKUP($P6,'Base Grupo de Produtos'!$E$2:$E$18,'Base Grupo de Produtos'!$F$2:$F$18) -> 80 | W6: =_xlfn.XLOOKUP($N6,'Calculo Leads'!$A$97:$A$134,'Calculo Leads'!J$97:J$134)*_xlfn.XLOOKUP($P6,'Base Grupo de Produtos'!$E$2:$E$18,'Base Grupo de Produtos'!$F$2:$F$18) -> 80 | X6: =_xlfn.XLOOKUP($N6,'Calculo Leads'!$A$97:$A$134,'Calculo Leads'!K$97:K$134)*_xlfn.XLOOKUP($P6,'Base Grupo de Produtos'!$E$2:$E$18,'Base Grupo de Produtos'!$F$2:$F$18) -> 88 | Y6: =_xlfn.XLOOKUP($N6,'Calculo Leads'!$A$97:$A$134,'Calculo Leads'!L$97:L$134)*_xlfn.XLOOKUP($P6,'Base Grupo de Produtos'!$E$2:$E$18,'Base Grupo de Produtos'!$F$2:$F$18) -> 88 | Z6: =_xlfn.XLOOKUP($N6,'Calculo Leads'!$A$97:$A$134,'Calculo Leads'!M$97:M$134)*_xlfn.XLOOKUP($P6,'Base Grupo de Produtos'!$E$2:$E$18,'Base Grupo de Produtos'!$F$2:$F$18) -> 88 | AA6: =_xlfn.XLOOKUP($N6,'Calculo Leads'!$A$97:$A$134,'Calculo Leads'!N$97:N$134)*_xlfn.XLOOKUP($P6,'Base Grupo de Produtos'!$E$2:$E$18,'Base Grupo de Produtos'!$F$2:$F$18) -> 88 | AB6: =_xlfn.XLOOKUP($N6,'Calculo Leads'!$A$97:$A$134,'Calculo Leads'!O$97:O$134)*_xlfn.XLOOKUP($P6,'Base Grupo de Produtos'!$E$2:$E$18,'Base Grupo de Produtos'!$F$2:$F$18) -> 88 | AC6: =SUM(T6:AB6) -> 760 | AD6: =IF(AC6=0,0,AC6-AG6) -> 760 | AE6: =IFERROR(_xlfn.XLOOKUP(N6&P6,'Historico Vendas'!G:G,'Historico Vendas'!E:E),0) -> 0 | AF6: =IFERROR((AC6-AE6)/AE6,"") | AG6: =IFERROR(_xlfn.XLOOKUP(N6&P6,'Historico Vendas'!G:G,'Historico Vendas'!F:F),0) -> 0 | AH6: =SUM(Q6:S6) -> 993.409 | AI6: =AH6-AG6 -> 993.409 | AJ6: =IFERROR(AG6/AH6,"") -> 0 | AK6: Novos | AL6: =IFERROR(INDEX('Balizador da Meta'!$D$3:$F$23,MATCH(Faturamento!$P6,'Balizador da Meta'!$C$3:$C$23,0),MATCH(Faturamento!AK6,'Balizador da Meta'!$D$2:$F$2,0)),"") -> 0.15
A7: =IF(L7=1,"SIM","NÃO") -> NÃO | B7: =_xlfn.XLOOKUP($N7,'Base de Grupos'!$A:$A,'Base de Grupos'!$D:$D) -> 1000065763 | C7: =_xlfn.XLOOKUP($N7,'Base de Grupos'!$A:$A,'Base de Grupos'!$E:$E) -> CANAL VENDA INTERNA | D7: =_xlfn.XLOOKUP($N7,'Base de Grupos'!$A:$A,'Base de Grupos'!$F:$F) -> 1000065763 | E7: =_xlfn.XLOOKUP($N7,'Base de Grupos'!$A:$A,'Base de Grupos'!$G:$G) -> CANAL VENDA INTERNA | F7: =_xlfn.XLOOKUP($N7,'Base de Grupos'!$A:$A,'Base de Grupos'!$H:$H) -> 1000105900 | G7: =_xlfn.XLOOKUP($N7,'Base de Grupos'!$A:$A,'Base de Grupos'!$I:$I) -> REGIONAL VENDA DIRETA CO + NE + NO | H7: =_xlfn.XLOOKUP($N7,'Base de Grupos'!$A:$A,'Base de Grupos'!$J:$J) -> 1000105900 | I7: =_xlfn.XLOOKUP($N7,'Base de Grupos'!$A:$A,'Base de Grupos'!$K:$K) -> REGIONAL VENDA DIRETA CO + NE + NO | J7: =_xlfn.XLOOKUP($N7,'Base de Grupos'!$A:$A,'Base de Grupos'!$L:$L) -> 1000150135 | K7: =_xlfn.XLOOKUP($N7,'Base de Grupos'!$A:$A,'Base de Grupos'!$M:$M) -> HELDER DA SILVA BRUNKOW | L7: =IF(N7<>N6,1,"") | M7: =_xlfn.XLOOKUP($N7,'Base de Grupos'!$A:$A,'Base de Grupos'!$C:$C) -> AP | N7: 1324 | O7: VENDA INTERNA AP | P7: DOCES | Q7: 0 | R7: 555.05619 | S7: 555.05619 | T7: =_xlfn.XLOOKUP($N7,'Calculo Leads'!$A$97:$A$134,'Calculo Leads'!G$97:G$134)*_xlfn.XLOOKUP($P7,'Base Grupo de Produtos'!$E$2:$E$18,'Base Grupo de Produtos'!$F$2:$F$18) -> 100 | U7: =_xlfn.XLOOKUP($N7,'Calculo Leads'!$A$97:$A$134,'Calculo Leads'!H$97:H$134)*_xlfn.XLOOKUP($P7,'Base Grupo de Produtos'!$E$2:$E$18,'Base Grupo de Produtos'!$F$2:$F$18) -> 100 | V7: =_xlfn.XLOOKUP($N7,'Calculo Leads'!$A$97:$A$134,'Calculo Leads'!I$97:I$134)*_xlfn.XLOOKUP($P7,'Base Grupo de Produtos'!$E$2:$E$18,'Base Grupo de Produtos'!$F$2:$F$18) -> 100 | W7: =_xlfn.XLOOKUP($N7,'Calculo Leads'!$A$97:$A$134,'Calculo Leads'!J$97:J$134)*_xlfn.XLOOKUP($P7,'Base Grupo de Produtos'!$E$2:$E$18,'Base Grupo de Produtos'!$F$2:$F$18) -> 100 | X7: =_xlfn.XLOOKUP($N7,'Calculo Leads'!$A$97:$A$134,'Calculo Leads'!K$97:K$134)*_xlfn.XLOOKUP($P7,'Base Grupo de Produtos'!$E$2:$E$18,'Base Grupo de Produtos'!$F$2:$F$18) -> 110 | Y7: =_xlfn.XLOOKUP($N7,'Calculo Leads'!$A$97:$A$134,'Calculo Leads'!L$97:L$134)*_xlfn.XLOOKUP($P7,'Base Grupo de Produtos'!$E$2:$E$18,'Base Grupo de Produtos'!$F$2:$F$18) -> 110 | Z7: =_xlfn.XLOOKUP($N7,'Calculo Leads'!$A$97:$A$134,'Calculo Leads'!M$97:M$134)*_xlfn.XLOOKUP($P7,'Base Grupo de Produtos'!$E$2:$E$18,'Base Grupo de Produtos'!$F$2:$F$18) -> 110 | AA7: =_xlfn.XLOOKUP($N7,'Calculo Leads'!$A$97:$A$134,'Calculo Leads'!N$97:N$134)*_xlfn.XLOOKUP($P7,'Base Grupo de Produtos'!$E$2:$E$18,'Base Grupo de Produtos'!$F$2:$F$18) -> 110 | AB7: =_xlfn.XLOOKUP($N7,'Calculo Leads'!$A$97:$A$134,'Calculo Leads'!O$97:O$134)*_xlfn.XLOOKUP($P7,'Base Grupo de Produtos'!$E$2:$E$18,'Base Grupo de Produtos'!$F$2:$F$18) -> 110 | AC7: =SUM(T7:AB7) -> 950 | AD7: =IF(AC7=0,0,AC7-AG7) -> 950 | AE7: =IFERROR(_xlfn.XLOOKUP(N7&P7,'Historico Vendas'!G:G,'Historico Vendas'!E:E),0) -> 0 | AF7: =IFERROR((AC7-AE7)/AE7,"") | AG7: =IFERROR(_xlfn.XLOOKUP(N7&P7,'Historico Vendas'!G:G,'Historico Vendas'!F:F),0) -> 0 | AH7: =SUM(Q7:S7) -> 1110.1124 | AI7: =AH7-AG7 -> 1110.1124 | AJ7: =IFERROR(AG7/AH7,"") -> 0 | AK7: Novos | AL7: =IFERROR(INDEX('Balizador da Meta'!$D$3:$F$23,MATCH(Faturamento!$P7,'Balizador da Meta'!$C$3:$C$23,0),MATCH(Faturamento!AK7,'Balizador da Meta'!$D$2:$F$2,0)),"") -> 0
A8: =IF(L8=1,"SIM","NÃO") -> NÃO | B8: =_xlfn.XLOOKUP($N8,'Base de Grupos'!$A:$A,'Base de Grupos'!$D:$D) -> 1000065763 | C8: =_xlfn.XLOOKUP($N8,'Base de Grupos'!$A:$A,'Base de Grupos'!$E:$E) -> CANAL VENDA INTERNA | D8: =_xlfn.XLOOKUP($N8,'Base de Grupos'!$A:$A,'Base de Grupos'!$F:$F) -> 1000065763 | E8: =_xlfn.XLOOKUP($N8,'Base de Grupos'!$A:$A,'Base de Grupos'!$G:$G) -> CANAL VENDA INTERNA | F8: =_xlfn.XLOOKUP($N8,'Base de Grupos'!$A:$A,'Base de Grupos'!$H:$H) -> 1000105900 | G8: =_xlfn.XLOOKUP($N8,'Base de Grupos'!$A:$A,'Base de Grupos'!$I:$I) -> REGIONAL VENDA DIRETA CO + NE + NO | H8: =_xlfn.XLOOKUP($N8,'Base de Grupos'!$A:$A,'Base de Grupos'!$J:$J) -> 1000105900 | I8: =_xlfn.XLOOKUP($N8,'Base de Grupos'!$A:$A,'Base de Grupos'!$K:$K) -> REGIONAL VENDA DIRETA CO + NE + NO | J8: =_xlfn.XLOOKUP($N8,'Base de Grupos'!$A:$A,'Base de Grupos'!$L:$L) -> 1000150135 | K8: =_xlfn.XLOOKUP($N8,'Base de Grupos'!$A:$A,'Base de Grupos'!$M:$M) -> HELDER DA SILVA BRUNKOW | L8: =IF(N8<>N7,1,"") | M8: =_xlfn.XLOOKUP($N8,'Base de Grupos'!$A:$A,'Base de Grupos'!$C:$C) -> AP | N8: 1324 | O8: VENDA INTERNA AP | P8: GELEIA | Q8: 0 | R8: 124.75667 | S8: 249.51333 | T8: =_xlfn.XLOOKUP($N8,'Calculo Leads'!$A$97:$A$134,'Calculo Leads'!G$97:G$134)*_xlfn.XLOOKUP($P8,'Base Grupo de Produtos'!$E$2:$E$18,'Base Grupo de Produtos'!$F$2:$F$18) -> 20 | U8: =_xlfn.XLOOKUP($N8,'Calculo Leads'!$A$97:$A$134,'Calculo Leads'!H$97:H$134)*_xlfn.XLOOKUP($P8,'Base Grupo de Produtos'!$E$2:$E$18,'Base Grupo de Produtos'!$F$2:$F$18) -> 20 | V8: =_xlfn.XLOOKUP($N8,'Calculo Leads'!$A$97:$A$134,'Calculo Leads'!I$97:I$134)*_xlfn.XLOOKUP($P8,'Base Grupo de Produtos'!$E$2:$E$18,'Base Grupo de Produtos'!$F$2:$F$18) -> 20 | W8: =_xlfn.XLOOKUP($N8,'Calculo Leads'!$A$97:$A$134,'Calculo Leads'!J$97:J$134)*_xlfn.XLOOKUP($P8,'Base Grupo de Produtos'!$E$2:$E$18,'Base Grupo de Produtos'!$F$2:$F$18) -> 20 | X8: =_xlfn.XLOOKUP($N8,'Calculo Leads'!$A$97:$A$134,'Calculo Leads'!K$97:K$134)*_xlfn.XLOOKUP($P8,'Base Grupo de Produtos'!$E$2:$E$18,'Base Grupo de Produtos'!$F$2:$F$18) -> 22 | Y8: =_xlfn.XLOOKUP($N8,'Calculo Leads'!$A$97:$A$134,'Calculo Leads'!L$97:L$134)*_xlfn.XLOOKUP($P8,'Base Grupo de Produtos'!$E$2:$E$18,'Base Grupo de Produtos'!$F$2:$F$18) -> 22 | Z8: =_xlfn.XLOOKUP($N8,'Calculo Leads'!$A$97:$A$134,'Calculo Leads'!M$97:M$134)*_xlfn.XLOOKUP($P8,'Base Grupo de Produtos'!$E$2:$E$18,'Base Grupo de Produtos'!$F$2:$F$18) -> 22 | AA8: =_xlfn.XLOOKUP($N8,'Calculo Leads'!$A$97:$A$134,'Calculo Leads'!N$97:N$134)*_xlfn.XLOOKUP($P8,'Base Grupo de Produtos'!$E$2:$E$18,'Base Grupo de Produtos'!$F$2:$F$18) -> 22 | AB8: =_xlfn.XLOOKUP($N8,'Calculo Leads'!$A$97:$A$134,'Calculo Leads'!O$97:O$134)*_xlfn.XLOOKUP($P8,'Base Grupo de Produtos'!$E$2:$E$18,'Base Grupo de Produtos'!$F$2:$F$18) -> 22 | AC8: =SUM(T8:AB8) -> 190 | AD8: =IF(AC8=0,0,AC8-AG8) -> 190 | AE8: =IFERROR(_xlfn.XLOOKUP(N8&P8,'Historico Vendas'!G:G,'Historico Vendas'!E:E),0) -> 0 | AF8: =IFERROR((AC8-AE8)/AE8,"") | AG8: =IFERROR(_xlfn.XLOOKUP(N8&P8,'Historico Vendas'!G:G,'Historico Vendas'!F:F),0) -> 0 | AH8: =SUM(Q8:S8) -> 374.27 | AI8: =AH8-AG8 -> 374.27 | AJ8: =IFERROR(AG8/AH8,"") -> 0 | AK8: Novos | AL8: =IFERROR(INDEX('Balizador da Meta'!$D$3:$F$23,MATCH(Faturamento!$P8,'Balizador da Meta'!$C$3:$C$23,0),MATCH(Faturamento!AK8,'Balizador da Meta'!$D$2:$F$2,0)),"") -> 0
A9: =IF(L9=1,"SIM","NÃO") -> NÃO | B9: =_xlfn.XLOOKUP($N9,'Base de Grupos'!$A:$A,'Base de Grupos'!$D:$D) -> 1000065763 | C9: =_xlfn.XLOOKUP($N9,'Base de Grupos'!$A:$A,'Base de Grupos'!$E:$E) -> CANAL VENDA INTERNA | D9: =_xlfn.XLOOKUP($N9,'Base de Grupos'!$A:$A,'Base de Grupos'!$F:$F) -> 1000065763 | E9: =_xlfn.XLOOKUP($N9,'Base de Grupos'!$A:$A,'Base de Grupos'!$G:$G) -> CANAL VENDA INTERNA | F9: =_xlfn.XLOOKUP($N9,'Base de Grupos'!$A:$A,'Base de Grupos'!$H:$H) -> 1000105900 | G9: =_xlfn.XLOOKUP($N9,'Base de Grupos'!$A:$A,'Base de Grupos'!$I:$I) -> REGIONAL VENDA DIRETA CO + NE + NO | H9: =_xlfn.XLOOKUP($N9,'Base de Grupos'!$A:$A,'Base de Grupos'!$J:$J) -> 1000105900 | I9: =_xlfn.XLOOKUP($N9,'Base de Grupos'!$A:$A,'Base de Grupos'!$K:$K) -> REGIONAL VENDA DIRETA CO + NE + NO | J9: =_xlfn.XLOOKUP($N9,'Base de Grupos'!$A:$A,'Base de Grupos'!$L:$L) -> 1000150135 | K9: =_xlfn.XLOOKUP($N9,'Base de Grupos'!$A:$A,'Base de Grupos'!$M:$M) -> HELDER DA SILVA BRUNKOW | L9: =IF(N9<>N8,1,"") | M9: =_xlfn.XLOOKUP($N9,'Base de Grupos'!$A:$A,'Base de Grupos'!$C:$C) -> AP | N9: 1324 | O9: VENDA INTERNA AP | P9: GRANOLA | Q9: 0 | R9: 315.15 | S9: 420.2 | T9: =_xlfn.XLOOKUP($N9,'Calculo Leads'!$A$97:$A$134,'Calculo Leads'!G$97:G$134)*_xlfn.XLOOKUP($P9,'Base Grupo de Produtos'!$E$2:$E$18,'Base Grupo de Produtos'!$F$2:$F$18) -> 20 | U9: =_xlfn.XLOOKUP($N9,'Calculo Leads'!$A$97:$A$134,'Calculo Leads'!H$97:H$134)*_xlfn.XLOOKUP($P9,'Base Grupo de Produtos'!$E$2:$E$18,'Base Grupo de Produtos'!$F$2:$F$18) -> 20 | V9: =_xlfn.XLOOKUP($N9,'Calculo Leads'!$A$97:$A$134,'Calculo Leads'!I$97:I$134)*_xlfn.XLOOKUP($P9,'Base Grupo de Produtos'!$E$2:$E$18,'Base Grupo de Produtos'!$F$2:$F$18) -> 20 | W9: =_xlfn.XLOOKUP($N9,'Calculo Leads'!$A$97:$A$134,'Calculo Leads'!J$97:J$134)*_xlfn.XLOOKUP($P9,'Base Grupo de Produtos'!$E$2:$E$18,'Base Grupo de Produtos'!$F$2:$F$18) -> 20 | X9: =_xlfn.XLOOKUP($N9,'Calculo Leads'!$A$97:$A$134,'Calculo Leads'!K$97:K$134)*_xlfn.XLOOKUP($P9,'Base Grupo de Produtos'!$E$2:$E$18,'Base Grupo de Produtos'!$F$2:$F$18) -> 22 | Y9: =_xlfn.XLOOKUP($N9,'Calculo Leads'!$A$97:$A$134,'Calculo Leads'!L$97:L$134)*_xlfn.XLOOKUP($P9,'Base Grupo de Produtos'!$E$2:$E$18,'Base Grupo de Produtos'!$F$2:$F$18) -> 22 | Z9: =_xlfn.XLOOKUP($N9,'Calculo Leads'!$A$97:$A$134,'Calculo Leads'!M$97:M$134)*_xlfn.XLOOKUP($P9,'Base Grupo de Produtos'!$E$2:$E$18,'Base Grupo de Produtos'!$F$2:$F$18) -> 22 | AA9: =_xlfn.XLOOKUP($N9,'Calculo Leads'!$A$97:$A$134,'Calculo Leads'!N$97:N$134)*_xlfn.XLOOKUP($P9,'Base Grupo de Produtos'!$E$2:$E$18,'Base Grupo de Produtos'!$F$2:$F$18) -> 22 | AB9: =_xlfn.XLOOKUP($N9,'Calculo Leads'!$A$97:$A$134,'Calculo Leads'!O$97:O$134)*_xlfn.XLOOKUP($P9,'Base Grupo de Produtos'!$E$2:$E$18,'Base Grupo de Produtos'!$F$2:$F$18) -> 22 | AC9: =SUM(T9:AB9) -> 190 | AD9: =IF(AC9=0,0,AC9-AG9) -> 190 | AE9: =IFERROR(_xlfn.XLOOKUP(N9&P9,'Historico Vendas'!G:G,'Historico Vendas'!E:E),0) -> 0 | AF9: =IFERROR((AC9-AE9)/AE9,"") | AG9: =IFERROR(_xlfn.XLOOKUP(N9&P9,'Historico Vendas'!G:G,'Historico Vendas'!F:F),0) -> 0 | AH9: =SUM(Q9:S9) -> 735.35 | AI9: =AH9-AG9 -> 735.35 | AJ9: =IFERROR(AG9/AH9,"") -> 0 | AK9: Novos | AL9: =IFERROR(INDEX('Balizador da Meta'!$D$3:$F$23,MATCH(Faturamento!$P9,'Balizador da Meta'!$C$3:$C$23,0),MATCH(Faturamento!AK9,'Balizador da Meta'!$D$2:$F$2,0)),"") -> 0
A10: =IF(L10=1,"SIM","NÃO") -> NÃO | B10: =_xlfn.XLOOKUP($N10,'Base de Grupos'!$A:$A,'Base de Grupos'!$D:$D) -> 1000065763 | C10: =_xlfn.XLOOKUP($N10,'Base de Grupos'!$A:$A,'Base de Grupos'!$E:$E) -> CANAL VENDA INTERNA | D10: =_xlfn.XLOOKUP($N10,'Base de Grupos'!$A:$A,'Base de Grupos'!$F:$F) -> 1000065763 | E10: =_xlfn.XLOOKUP($N10,'Base de Grupos'!$A:$A,'Base de Grupos'!$G:$G) -> CANAL VENDA INTERNA | F10: =_xlfn.XLOOKUP($N10,'Base de Grupos'!$A:$A,'Base de Grupos'!$H:$H) -> 1000105900 | G10: =_xlfn.XLOOKUP($N10,'Base de Grupos'!$A:$A,'Base de Grupos'!$I:$I) -> REGIONAL VENDA DIRETA CO + NE + NO | H10: =_xlfn.XLOOKUP($N10,'Base de Grupos'!$A:$A,'Base de Grupos'!$J:$J) -> 1000105900 | I10: =_xlfn.XLOOKUP($N10,'Base de Grupos'!$A:$A,'Base de Grupos'!$K:$K) -> REGIONAL VENDA DIRETA CO + NE + NO | J10: =_xlfn.XLOOKUP($N10,'Base de Grupos'!$A:$A,'Base de Grupos'!$L:$L) -> 1000150135 | K10: =_xlfn.XLOOKUP($N10,'Base de Grupos'!$A:$A,'Base de Grupos'!$M:$M) -> HELDER DA SILVA BRUNKOW | L10: =IF(N10<>N9,1,"") | M10: =_xlfn.XLOOKUP($N10,'Base de Grupos'!$A:$A,'Base de Grupos'!$C:$C) -> AP | N10: 1324 | O10: VENDA INTERNA AP | P10: KIDS | Q10: 0 | R10: 165.49714 | S10: 165.49714 | T10: =_xlfn.XLOOKUP($N10,'Calculo Leads'!$A$97:$A$134,'Calculo Leads'!G$97:G$134)*_xlfn.XLOOKUP($P10,'Base Grupo de Produtos'!$E$2:$E$18,'Base Grupo de Produtos'!$F$2:$F$18) -> 20 | U10: =_xlfn.XLOOKUP($N10,'Calculo Leads'!$A$97:$A$134,'Calculo Leads'!H$97:H$134)*_xlfn.XLOOKUP($P10,'Base Grupo de Produtos'!$E$2:$E$18,'Base Grupo de Produtos'!$F$2:$F$18) -> 20 | V10: =_xlfn.XLOOKUP($N10,'Calculo Leads'!$A$97:$A$134,'Calculo Leads'!I$97:I$134)*_xlfn.XLOOKUP($P10,'Base Grupo de Produtos'!$E$2:$E$18,'Base Grupo de Produtos'!$F$2:$F$18) -> 20 | W10: =_xlfn.XLOOKUP($N10,'Calculo Leads'!$A$97:$A$134,'Calculo Leads'!J$97:J$134)*_xlfn.XLOOKUP($P10,'Base Grupo de Produtos'!$E$2:$E$18,'Base Grupo de Produtos'!$F$2:$F$18) -> 20 | X10: =_xlfn.XLOOKUP($N10,'Calculo Leads'!$A$97:$A$134,'Calculo Leads'!K$97:K$134)*_xlfn.XLOOKUP($P10,'Base Grupo de Produtos'!$E$2:$E$18,'Base Grupo de Produtos'!$F$2:$F$18) -> 22 | Y10: =_xlfn.XLOOKUP($N10,'Calculo Leads'!$A$97:$A$134,'Calculo Leads'!L$97:L$134)*_xlfn.XLOOKUP($P10,'Base Grupo de Produtos'!$E$2:$E$18,'Base Grupo de Produtos'!$F$2:$F$18) -> 22 | Z10: =_xlfn.XLOOKUP($N10,'Calculo Leads'!$A$97:$A$134,'Calculo Leads'!M$97:M$134)*_xlfn.XLOOKUP($P10,'Base Grupo de Produtos'!$E$2:$E$18,'Base Grupo de Produtos'!$F$2:$F$18) -> 22 | AA10: =_xlfn.XLOOKUP($N10,'Calculo Leads'!$A$97:$A$134,'Calculo Leads'!N$97:N$134)*_xlfn.XLOOKUP($P10,'Base Grupo de Produtos'!$E$2:$E$18,'Base Grupo de Produtos'!$F$2:$F$18) -> 22 | AB10: =_xlfn.XLOOKUP($N10,'Calculo Leads'!$A$97:$A$134,'Calculo Leads'!O$97:O$134)*_xlfn.XLOOKUP($P10,'Base Grupo de Produtos'!$E$2:$E$18,'Base Grupo de Produtos'!$F$2:$F$18) -> 22 | AC10: =SUM(T10:AB10) -> 190 | AD10: =IF(AC10=0,0,AC10-AG10) -> 190 | AE10: =IFERROR(_xlfn.XLOOKUP(N10&P10,'Historico Vendas'!G:G,'Historico Vendas'!E:E),0) -> 0 | AF10: =IFERROR((AC10-AE10)/AE10,"") | AG10: =IFERROR(_xlfn.XLOOKUP(N10&P10,'Historico Vendas'!G:G,'Historico Vendas'!F:F),0) -> 0 | AH10: =SUM(Q10:S10) -> 330.99429 | AI10: =AH10-AG10 -> 330.99429 | AJ10: =IFERROR(AG10/AH10,"") -> 0 | AK10: Novos | AL10: =IFERROR(INDEX('Balizador da Meta'!$D$3:$F$23,MATCH(Faturamento!$P10,'Balizador da Meta'!$C$3:$C$23,0),MATCH(Faturamento!AK10,'Balizador da Meta'!$D$2:$F$2,0)),"") -> 0
A11: =IF(L11=1,"SIM","NÃO") -> NÃO | B11: =_xlfn.XLOOKUP($N11,'Base de Grupos'!$A:$A,'Base de Grupos'!$D:$D) -> 1000065763 | C11: =_xlfn.XLOOKUP($N11,'Base de Grupos'!$A:$A,'Base de Grupos'!$E:$E) -> CANAL VENDA INTERNA | D11: =_xlfn.XLOOKUP($N11,'Base de Grupos'!$A:$A,'Base de Grupos'!$F:$F) -> 1000065763 | E11: =_xlfn.XLOOKUP($N11,'Base de Grupos'!$A:$A,'Base de Grupos'!$G:$G) -> CANAL VENDA INTERNA | F11: =_xlfn.XLOOKUP($N11,'Base de Grupos'!$A:$A,'Base de Grupos'!$H:$H) -> 1000105900 | G11: =_xlfn.XLOOKUP($N11,'Base de Grupos'!$A:$A,'Base de Grupos'!$I:$I) -> REGIONAL VENDA DIRETA CO + NE + NO | H11: =_xlfn.XLOOKUP($N11,'Base de Grupos'!$A:$A,'Base de Grupos'!$J:$J) -> 1000105900 | I11: =_xlfn.XLOOKUP($N11,'Base de Grupos'!$A:$A,'Base de Grupos'!$K:$K) -> REGIONAL VENDA DIRETA CO + NE + NO | J11: =_xlfn.XLOOKUP($N11,'Base de Grupos'!$A:$A,'Base de Grupos'!$L:$L) -> 1000150135 | K11: =_xlfn.XLOOKUP($N11,'Base de Grupos'!$A:$A,'Base de Grupos'!$M:$M) -> HELDER DA SILVA BRUNKOW | L11: =IF(N11<>N10,1,"") | M11: =_xlfn.XLOOKUP($N11,'Base de Grupos'!$A:$A,'Base de Grupos'!$C:$C) -> AP | N11: 1324 | O11: VENDA INTERNA AP | P11: LANCHES | Q11: 0 | R11: 89.608571 | S11: 179.21714 | T11: =_xlfn.XLOOKUP($N11,'Calculo Leads'!$A$97:$A$134,'Calculo Leads'!G$97:G$134)*_xlfn.XLOOKUP($P11,'Base Grupo de Produtos'!$E$2:$E$18,'Base Grupo de Produtos'!$F$2:$F$18) -> 30 | U11: =_xlfn.XLOOKUP($N11,'Calculo Leads'!$A$97:$A$134,'Calculo Leads'!H$97:H$134)*_xlfn.XLOOKUP($P11,'Base Grupo de Produtos'!$E$2:$E$18,'Base Grupo de Produtos'!$F$2:$F$18) -> 30 | V11: =_xlfn.XLOOKUP($N11,'Calculo Leads'!$A$97:$A$134,'Calculo Leads'!I$97:I$134)*_xlfn.XLOOKUP($P11,'Base Grupo de Produtos'!$E$2:$E$18,'Base Grupo de Produtos'!$F$2:$F$18) -> 30 | W11: =_xlfn.XLOOKUP($N11,'Calculo Leads'!$A$97:$A$134,'Calculo Leads'!J$97:J$134)*_xlfn.XLOOKUP($P11,'Base Grupo de Produtos'!$E$2:$E$18,'Base Grupo de Produtos'!$F$2:$F$18) -> 30 | X11: =_xlfn.XLOOKUP($N11,'Calculo Leads'!$A$97:$A$134,'Calculo Leads'!K$97:K$134)*_xlfn.XLOOKUP($P11,'Base Grupo de Produtos'!$E$2:$E$18,'Base Grupo de Produtos'!$F$2:$F$18) -> 33 | Y11: =_xlfn.XLOOKUP($N11,'Calculo Leads'!$A$97:$A$134,'Calculo Leads'!L$97:L$134)*_xlfn.XLOOKUP($P11,'Base Grupo de Produtos'!$E$2:$E$18,'Base Grupo de Produtos'!$F$2:$F$18) -> 33 | Z11: =_xlfn.XLOOKUP($N11,'Calculo Leads'!$A$97:$A$134,'Calculo Leads'!M$97:M$134)*_xlfn.XLOOKUP($P11,'Base Grupo de Produtos'!$E$2:$E$18,'Base Grupo de Produtos'!$F$2:$F$18) -> 33 | AA11: =_xlfn.XLOOKUP($N11,'Calculo Leads'!$A$97:$A$134,'Calculo Leads'!N$97:N$134)*_xlfn.XLOOKUP($P11,'Base Grupo de Produtos'!$E$2:$E$18,'Base Grupo de Produtos'!$F$2:$F$18) -> 33 | AB11: =_xlfn.XLOOKUP($N11,'Calculo Leads'!$A$97:$A$134,'Calculo Leads'!O$97:O$134)*_xlfn.XLOOKUP($P11,'Base Grupo de Produtos'!$E$2:$E$18,'Base Grupo de Produtos'!$F$2:$F$18) -> 33 | AC11: =SUM(T11:AB11) -> 285 | AD11: =IF(AC11=0,0,AC11-AG11) -> 285 | AE11: =IFERROR(_xlfn.XLOOKUP(N11&P11,'Historico Vendas'!G:G,'Historico Vendas'!E:E),0) -> 0 | AF11: =IFERROR((AC11-AE11)/AE11,"") | AG11: =IFERROR(_xlfn.XLOOKUP(N11&P11,'Historico Vendas'!G:G,'Historico Vendas'!F:F),0) -> 0 | AH11: =SUM(Q11:S11) -> 268.82571 | AI11: =AH11-AG11 -> 268.82571 | AJ11: =IFERROR(AG11/AH11,"") -> 0 | AK11: Novos | AL11: =IFERROR(INDEX('Balizador da Meta'!$D$3:$F$23,MATCH(Faturamento!$P11,'Balizador da Meta'!$C$3:$C$23,0),MATCH(Faturamento!AK11,'Balizador da Meta'!$D$2:$F$2,0)),"") -> 0.15
A12: =IF(L12=1,"SIM","NÃO") -> NÃO | B12: =_xlfn.XLOOKUP($N12,'Base de Grupos'!$A:$A,'Base de Grupos'!$D:$D) -> 1000065763 | C12: =_xlfn.XLOOKUP($N12,'Base de Grupos'!$A:$A,'Base de Grupos'!$E:$E) -> CANAL VENDA INTERNA | D12: =_xlfn.XLOOKUP($N12,'Base de Grupos'!$A:$A,'Base de Grupos'!$F:$F) -> 1000065763 | E12: =_xlfn.XLOOKUP($N12,'Base de Grupos'!$A:$A,'Base de Grupos'!$G:$G) -> CANAL VENDA INTERNA | F12: =_xlfn.XLOOKUP($N12,'Base de Grupos'!$A:$A,'Base de Grupos'!$H:$H) -> 1000105900 | G12: =_xlfn.XLOOKUP($N12,'Base de Grupos'!$A:$A,'Base de Grupos'!$I:$I) -> REGIONAL VENDA DIRETA CO + NE + NO | H12: =_xlfn.XLOOKUP($N12,'Base de Grupos'!$A:$A,'Base de Grupos'!$J:$J) -> 1000105900 | I12: =_xlfn.XLOOKUP($N12,'Base de Grupos'!$A:$A,'Base de Grupos'!$K:$K) -> REGIONAL VENDA DIRETA CO + NE + NO | J12: =_xlfn.XLOOKUP($N12,'Base de Grupos'!$A:$A,'Base de Grupos'!$L:$L) -> 1000150135 | K12: =_xlfn.XLOOKUP($N12,'Base de Grupos'!$A:$A,'Base de Grupos'!$M:$M) -> HELDER DA SILVA BRUNKOW | L12: =IF(N12<>N11,1,"") | M12: =_xlfn.XLOOKUP($N12,'Base de Grupos'!$A:$A,'Base de Grupos'!$C:$C) -> AP | N12: 1324 | O12: VENDA INTERNA AP | P12: MAIS GRANEL | Q12: 0 | R12: 516.14303 | S12: 602.16687 | T12: =_xlfn.XLOOKUP($N12,'Calculo Leads'!$A$97:$A$134,'Calculo Leads'!G$97:G$134)*_xlfn.XLOOKUP($P12,'Base Grupo de Produtos'!$E$2:$E$18,'Base Grupo de Produtos'!$F$2:$F$18) -> 250 | U12: =_xlfn.XLOOKUP($N12,'Calculo Leads'!$A$97:$A$134,'Calculo Leads'!H$97:H$134)*_xlfn.XLOOKUP($P12,'Base Grupo de Produtos'!$E$2:$E$18,'Base Grupo de Produtos'!$F$2:$F$18) -> 250 | V12: =_xlfn.XLOOKUP($N12,'Calculo Leads'!$A$97:$A$134,'Calculo Leads'!I$97:I$134)*_xlfn.XLOOKUP($P12,'Base Grupo de Produtos'!$E$2:$E$18,'Base Grupo de Produtos'!$F$2:$F$18) -> 250 | W12: =_xlfn.XLOOKUP($N12,'Calculo Leads'!$A$97:$A$134,'Calculo Leads'!J$97:J$134)*_xlfn.XLOOKUP($P12,'Base Grupo de Produtos'!$E$2:$E$18,'Base Grupo de Produtos'!$F$2:$F$18) -> 250 | X12: =_xlfn.XLOOKUP($N12,'Calculo Leads'!$A$97:$A$134,'Calculo Leads'!K$97:K$134)*_xlfn.XLOOKUP($P12,'Base Grupo de Produtos'!$E$2:$E$18,'Base Grupo de Produtos'!$F$2:$F$18) -> 275 | Y12: =_xlfn.XLOOKUP($N12,'Calculo Leads'!$A$97:$A$134,'Calculo Leads'!L$97:L$134)*_xlfn.XLOOKUP($P12,'Base Grupo de Produtos'!$E$2:$E$18,'Base Grupo de Produtos'!$F$2:$F$18) -> 275 | Z12: =_xlfn.XLOOKUP($N12,'Calculo Leads'!$A$97:$A$134,'Calculo Leads'!M$97:M$134)*_xlfn.XLOOKUP($P12,'Base Grupo de Produtos'!$E$2:$E$18,'Base Grupo de Produtos'!$F$2:$F$18) -> 275 | AA12: =_xlfn.XLOOKUP($N12,'Calculo Leads'!$A$97:$A$134,'Calculo Leads'!N$97:N$134)*_xlfn.XLOOKUP($P12,'Base Grupo de Produtos'!$E$2:$E$18,'Base Grupo de Produtos'!$F$2:$F$18) -> 275 | AB12: =_xlfn.XLOOKUP($N12,'Calculo Leads'!$A$97:$A$134,'Calculo Leads'!O$97:O$134)*_xlfn.XLOOKUP($P12,'Base Grupo de Produtos'!$E$2:$E$18,'Base Grupo de Produtos'!$F$2:$F$18) -> 275 | AC12: =SUM(T12:AB12) -> 2375 | AD12: =IF(AC12=0,0,AC12-AG12) -> 2375 | AE12: =IFERROR(_xlfn.XLOOKUP(N12&P12,'Historico Vendas'!G:G,'Historico Vendas'!E:E),0) -> 0 | AF12: =IFERROR((AC12-AE12)/AE12,"") | AG12: =IFERROR(_xlfn.XLOOKUP(N12&P12,'Historico Vendas'!G:G,'Historico Vendas'!F:F),0) -> 0 | AH12: =SUM(Q12:S12) -> 1118.3099 | AI12: =AH12-AG12 -> 1118.3099 | AJ12: =IFERROR(AG12/AH12,"") -> 0 | AK12: Novos | AL12: =IFERROR(INDEX('Balizador da Meta'!$D$3:$F$23,MATCH(Faturamento!$P12,'Balizador da Meta'!$C$3:$C$23,0),MATCH(Faturamento!AK12,'Balizador da Meta'!$D$2:$F$2,0)),"") -> 0
A13: =IF(L13=1,"SIM","NÃO") -> NÃO | B13: =_xlfn.XLOOKUP($N13,'Base de Grupos'!$A:$A,'Base de Grupos'!$D:$D) -> 1000065763 | C13: =_xlfn.XLOOKUP($N13,'Base de Grupos'!$A:$A,'Base de Grupos'!$E:$E) -> CANAL VENDA INTERNA | D13: =_xlfn.XLOOKUP($N13,'Base de Grupos'!$A:$A,'Base de Grupos'!$F:$F) -> 1000065763 | E13: =_xlfn.XLOOKUP($N13,'Base de Grupos'!$A:$A,'Base de Grupos'!$G:$G) -> CANAL VENDA INTERNA | F13: =_xlfn.XLOOKUP($N13,'Base de Grupos'!$A:$A,'Base de Grupos'!$H:$H) -> 1000105900 | G13: =_xlfn.XLOOKUP($N13,'Base de Grupos'!$A:$A,'Base de Grupos'!$I:$I) -> REGIONAL VENDA DIRETA CO + NE + NO | H13: =_xlfn.XLOOKUP($N13,'Base de Grupos'!$A:$A,'Base de Grupos'!$J:$J) -> 1000105900 | I13: =_xlfn.XLOOKUP($N13,'Base de Grupos'!$A:$A,'Base de Grupos'!$K:$K) -> REGIONAL VENDA DIRETA CO + NE + NO | J13: =_xlfn.XLOOKUP($N13,'Base de Grupos'!$A:$A,'Base de Grupos'!$L:$L) -> 1000150135 | K13: =_xlfn.XLOOKUP($N13,'Base de Grupos'!$A:$A,'Base de Grupos'!$M:$M) -> HELDER DA SILVA BRUNKOW | L13: =IF(N13<>N12,1,"") | M13: =_xlfn.XLOOKUP($N13,'Base de Grupos'!$A:$A,'Base de Grupos'!$C:$C) -> AP | N13: 1324 | O13: VENDA INTERNA AP | P13: NATURATTA | Q13: 0 | R13: 627.68571 | S13: 627.68571 | T13: =_xlfn.XLOOKUP($N13,'Calculo Leads'!$A$97:$A$134,'Calculo Leads'!G$97:G$134)*_xlfn.XLOOKUP($P13,'Base Grupo de Produtos'!$E$2:$E$18,'Base Grupo de Produtos'!$F$2:$F$18) -> 50 | U13: =_xlfn.XLOOKUP($N13,'Calculo Leads'!$A$97:$A$134,'Calculo Leads'!H$97:H$134)*_xlfn.XLOOKUP($P13,'Base Grupo de Produtos'!$E$2:$E$18,'Base Grupo de Produtos'!$F$2:$F$18) -> 50 | V13: =_xlfn.XLOOKUP($N13,'Calculo Leads'!$A$97:$A$134,'Calculo Leads'!I$97:I$134)*_xlfn.XLOOKUP($P13,'Base Grupo de Produtos'!$E$2:$E$18,'Base Grupo de Produtos'!$F$2:$F$18) -> 50 | W13: =_xlfn.XLOOKUP($N13,'Calculo Leads'!$A$97:$A$134,'Calculo Leads'!J$97:J$134)*_xlfn.XLOOKUP($P13,'Base Grupo de Produtos'!$E$2:$E$18,'Base Grupo de Produtos'!$F$2:$F$18) -> 50 | X13: =_xlfn.XLOOKUP($N13,'Calculo Leads'!$A$97:$A$134,'Calculo Leads'!K$97:K$134)*_xlfn.XLOOKUP($P13,'Base Grupo de Produtos'!$E$2:$E$18,'Base Grupo de Produtos'!$F$2:$F$18) -> 55 | Y13: =_xlfn.XLOOKUP($N13,'Calculo Leads'!$A$97:$A$134,'Calculo Leads'!L$97:L$134)*_xlfn.XLOOKUP($P13,'Base Grupo de Produtos'!$E$2:$E$18,'Base Grupo de Produtos'!$F$2:$F$18) -> 55 | Z13: =_xlfn.XLOOKUP($N13,'Calculo Leads'!$A$97:$A$134,'Calculo Leads'!M$97:M$134)*_xlfn.XLOOKUP($P13,'Base Grupo de Produtos'!$E$2:$E$18,'Base Grupo de Produtos'!$F$2:$F$18) -> 55 | AA13: =_xlfn.XLOOKUP($N13,'Calculo Leads'!$A$97:$A$134,'Calculo Leads'!N$97:N$134)*_xlfn.XLOOKUP($P13,'Base Grupo de Produtos'!$E$2:$E$18,'Base Grupo de Produtos'!$F$2:$F$18) -> 55 | AB13: =_xlfn.XLOOKUP($N13,'Calculo Leads'!$A$97:$A$134,'Calculo Leads'!O$97:O$134)*_xlfn.XLOOKUP($P13,'Base Grupo de Produtos'!$E$2:$E$18,'Base Grupo de Produtos'!$F$2:$F$18) -> 55 | AC13: =SUM(T13:AB13) -> 475 | AD13: =IF(AC13=0,0,AC13-AG13) -> 475 | AE13: =IFERROR(_xlfn.XLOOKUP(N13&P13,'Historico Vendas'!G:G,'Historico Vendas'!E:E),0) -> 0 | AF13: =IFERROR((AC13-AE13)/AE13,"") | AG13: =IFERROR(_xlfn.XLOOKUP(N13&P13,'Historico Vendas'!G:G,'Historico Vendas'!F:F),0) -> 0 | AH13: =SUM(Q13:S13) -> 1255.3714 | AI13: =AH13-AG13 -> 1255.3714 | AJ13: =IFERROR(AG13/AH13,"") -> 0 | AK13: Novos | AL13: =IFERROR(INDEX('Balizador da Meta'!$D$3:$F$23,MATCH(Faturamento!$P13,'Balizador da Meta'!$C$3:$C$23,0),MATCH(Faturamento!AK13,'Balizador da Meta'!$D$2:$F$2,0)),"") -> 0.25
A14: =IF(L14=1,"SIM","NÃO") -> NÃO | B14: =_xlfn.XLOOKUP($N14,'Base de Grupos'!$A:$A,'Base de Grupos'!$D:$D) -> 1000065763 | C14: =_xlfn.XLOOKUP($N14,'Base de Grupos'!$A:$A,'Base de Grupos'!$E:$E) -> CANAL VENDA INTERNA | D14: =_xlfn.XLOOKUP($N14,'Base de Grupos'!$A:$A,'Base de Grupos'!$F:$F) -> 1000065763 | E14: =_xlfn.XLOOKUP($N14,'Base de Grupos'!$A:$A,'Base de Grupos'!$G:$G) -> CANAL VENDA INTERNA | F14: =_xlfn.XLOOKUP($N14,'Base de Grupos'!$A:$A,'Base de Grupos'!$H:$H) -> 1000105900 | G14: =_xlfn.XLOOKUP($N14,'Base de Grupos'!$A:$A,'Base de Grupos'!$I:$I) -> REGIONAL VENDA DIRETA CO + NE + NO | H14: =_xlfn.XLOOKUP($N14,'Base de Grupos'!$A:$A,'Base de Grupos'!$J:$J) -> 1000105900 | I14: =_xlfn.XLOOKUP($N14,'Base de Grupos'!$A:$A,'Base de Grupos'!$K:$K) -> REGIONAL VENDA DIRETA CO + NE + NO | J14: =_xlfn.XLOOKUP($N14,'Base de Grupos'!$A:$A,'Base de Grupos'!$L:$L) -> 1000150135 | K14: =_xlfn.XLOOKUP($N14,'Base de Grupos'!$A:$A,'Base de Grupos'!$M:$M) -> HELDER DA SILVA BRUNKOW | L14: =IF(N14<>N13,1,"") | M14: =_xlfn.XLOOKUP($N14,'Base de Grupos'!$A:$A,'Base de Grupos'!$C:$C) -> AP | N14: 1324 | O14: VENDA INTERNA AP | P14: REEMBALADOS | Q14: 0 | R14: 119.60089 | S14: 239.20178 | T14: =_xlfn.XLOOKUP($N14,'Calculo Leads'!$A$97:$A$134,'Calculo Leads'!G$97:G$134)*_xlfn.XLOOKUP($P14,'Base Grupo de Produtos'!$E$2:$E$18,'Base Grupo de Produtos'!$F$2:$F$18) -> 50 | U14: =_xlfn.XLOOKUP($N14,'Calculo Leads'!$A$97:$A$134,'Calculo Leads'!H$97:H$134)*_xlfn.XLOOKUP($P14,'Base Grupo de Produtos'!$E$2:$E$18,'Base Grupo de Produtos'!$F$2:$F$18) -> 50 | V14: =_xlfn.XLOOKUP($N14,'Calculo Leads'!$A$97:$A$134,'Calculo Leads'!I$97:I$134)*_xlfn.XLOOKUP($P14,'Base Grupo de Produtos'!$E$2:$E$18,'Base Grupo de Produtos'!$F$2:$F$18) -> 50 | W14: =_xlfn.XLOOKUP($N14,'Calculo Leads'!$A$97:$A$134,'Calculo Leads'!J$97:J$134)*_xlfn.XLOOKUP($P14,'Base Grupo de Produtos'!$E$2:$E$18,'Base Grupo de Produtos'!$F$2:$F$18) -> 50 | X14: =_xlfn.XLOOKUP($N14,'Calculo Leads'!$A$97:$A$134,'Calculo Leads'!K$97:K$134)*_xlfn.XLOOKUP($P14,'Base Grupo de Produtos'!$E$2:$E$18,'Base Grupo de Produtos'!$F$2:$F$18) -> 55 | Y14: =_xlfn.XLOOKUP($N14,'Calculo Leads'!$A$97:$A$134,'Calculo Leads'!L$97:L$134)*_xlfn.XLOOKUP($P14,'Base Grupo de Produtos'!$E$2:$E$18,'Base Grupo de Produtos'!$F$2:$F$18) -> 55 | Z14: =_xlfn.XLOOKUP($N14,'Calculo Leads'!$A$97:$A$134,'Calculo Leads'!M$97:M$134)*_xlfn.XLOOKUP($P14,'Base Grupo de Produtos'!$E$2:$E$18,'Base Grupo de Produtos'!$F$2:$F$18) -> 55 | AA14: =_xlfn.XLOOKUP($N14,'Calculo Leads'!$A$97:$A$134,'Calculo Leads'!N$97:N$134)*_xlfn.XLOOKUP($P14,'Base Grupo de Produtos'!$E$2:$E$18,'Base Grupo de Produtos'!$F$2:$F$18) -> 55 | AB14: =_xlfn.XLOOKUP($N14,'Calculo Leads'!$A$97:$A$134,'Calculo Leads'!O$97:O$134)*_xlfn.XLOOKUP($P14,'Base Grupo de Produtos'!$E$2:$E$18,'Base Grupo de Produtos'!$F$2:$F$18) -> 55 | AC14: =SUM(T14:AB14) -> 475 | AD14: =IF(AC14=0,0,AC14-AG14) -> 475 | AE14: =IFERROR(_xlfn.XLOOKUP(N14&P14,'Historico Vendas'!G:G,'Historico Vendas'!E:E),0) -> 0 | AF14: =IFERROR((AC14-AE14)/AE14,"") | AG14: =IFERROR(_xlfn.XLOOKUP(N14&P14,'Historico Vendas'!G:G,'Historico Vendas'!F:F),0) -> 0 | AH14: =SUM(Q14:S14) -> 358.80267 | AI14: =AH14-AG14 -> 358.80267 | AJ14: =IFERROR(AG14/AH14,"") -> 0 | AK14: Novos | AL14: =IFERROR(INDEX('Balizador da Meta'!$D$3:$F$23,MATCH(Faturamento!$P14,'Balizador da Meta'!$C$3:$C$23,0),MATCH(Faturamento!AK14,'Balizador da Meta'!$D$2:$F$2,0)),"") -> 0
A15: =IF(L15=1,"SIM","NÃO") -> NÃO | B15: =_xlfn.XLOOKUP($N15,'Base de Grupos'!$A:$A,'Base de Grupos'!$D:$D) -> 1000065763 | C15: =_xlfn.XLOOKUP($N15,'Base de Grupos'!$A:$A,'Base de Grupos'!$E:$E) -> CANAL VENDA INTERNA | D15: =_xlfn.XLOOKUP($N15,'Base de Grupos'!$A:$A,'Base de Grupos'!$F:$F) -> 1000065763 | E15: =_xlfn.XLOOKUP($N15,'Base de Grupos'!$A:$A,'Base de Grupos'!$G:$G) -> CANAL VENDA INTERNA | F15: =_xlfn.XLOOKUP($N15,'Base de Grupos'!$A:$A,'Base de Grupos'!$H:$H) -> 1000105900 | G15: =_xlfn.XLOOKUP($N15,'Base de Grupos'!$A:$A,'Base de Grupos'!$I:$I) -> REGIONAL VENDA DIRETA CO + NE + NO | H15: =_xlfn.XLOOKUP($N15,'Base de Grupos'!$A:$A,'Base de Grupos'!$J:$J) -> 1000105900 | I15: =_xlfn.XLOOKUP($N15,'Base de Grupos'!$A:$A,'Base de Grupos'!$K:$K) -> REGIONAL VENDA DIRETA CO + NE + NO | J15: =_xlfn.XLOOKUP($N15,'Base de Grupos'!$A:$A,'Base de Grupos'!$L:$L) -> 1000150135 | K15: =_xlfn.XLOOKUP($N15,'Base de Grupos'!$A:$A,'Base de Grupos'!$M:$M) -> HELDER DA SILVA BRUNKOW | L15: =IF(N15<>N14,1,"") | M15: =_xlfn.XLOOKUP($N15,'Base de Grupos'!$A:$A,'Base de Grupos'!$C:$C) -> AP | N15: 1324 | O15: VENDA INTERNA AP | P15: S GLUTEN | Q15: 0 | R15: 204.3693 | S15: 204.3693 | T15: =_xlfn.XLOOKUP($N15,'Calculo Leads'!$A$97:$A$134,'Calculo Leads'!G$97:G$134)*_xlfn.XLOOKUP($P15,'Base Grupo de Produtos'!$E$2:$E$18,'Base Grupo de Produtos'!$F$2:$F$18) -> 50 | U15: =_xlfn.XLOOKUP($N15,'Calculo Leads'!$A$97:$A$134,'Calculo Leads'!H$97:H$134)*_xlfn.XLOOKUP($P15,'Base Grupo de Produtos'!$E$2:$E$18,'Base Grupo de Produtos'!$F$2:$F$18) -> 50 | V15: =_xlfn.XLOOKUP($N15,'Calculo Leads'!$A$97:$A$134,'Calculo Leads'!I$97:I$134)*_xlfn.XLOOKUP($P15,'Base Grupo de Produtos'!$E$2:$E$18,'Base Grupo de Produtos'!$F$2:$F$18) -> 50 | W15: =_xlfn.XLOOKUP($N15,'Calculo Leads'!$A$97:$A$134,'Calculo Leads'!J$97:J$134)*_xlfn.XLOOKUP($P15,'Base Grupo de Produtos'!$E$2:$E$18,'Base Grupo de Produtos'!$F$2:$F$18) -> 50 | X15: =_xlfn.XLOOKUP($N15,'Calculo Leads'!$A$97:$A$134,'Calculo Leads'!K$97:K$134)*_xlfn.XLOOKUP($P15,'Base Grupo de Produtos'!$E$2:$E$18,'Base Grupo de Produtos'!$F$2:$F$18) -> 55 | Y15: =_xlfn.XLOOKUP($N15,'Calculo Leads'!$A$97:$A$134,'Calculo Leads'!L$97:L$134)*_xlfn.XLOOKUP($P15,'Base Grupo de Produtos'!$E$2:$E$18,'Base Grupo de Produtos'!$F$2:$F$18) -> 55 | Z15: =_xlfn.XLOOKUP($N15,'Calculo Leads'!$A$97:$A$134,'Calculo Leads'!M$97:M$134)*_xlfn.XLOOKUP($P15,'Base Grupo de Produtos'!$E$2:$E$18,'Base Grupo de Produtos'!$F$2:$F$18) -> 55 | AA15: =_xlfn.XLOOKUP($N15,'Calculo Leads'!$A$97:$A$134,'Calculo Leads'!N$97:N$134)*_xlfn.XLOOKUP($P15,'Base Grupo de Produtos'!$E$2:$E$18,'Base Grupo de Produtos'!$F$2:$F$18) -> 55 | AB15: =_xlfn.XLOOKUP($N15,'Calculo Leads'!$A$97:$A$134,'Calculo Leads'!O$97:O$134)*_xlfn.XLOOKUP($P15,'Base Grupo de Produtos'!$E$2:$E$18,'Base Grupo de Produtos'!$F$2:$F$18) -> 55 | AC15: =SUM(T15:AB15) -> 475 | AD15: =IF(AC15=0,0,AC15-AG15) -> 475 | AE15: =IFERROR(_xlfn.XLOOKUP(N15&P15,'Historico Vendas'!G:G,'Historico Vendas'!E:E),0) -> 0 | AF15: =IFERROR((AC15-AE15)/AE15,"") | AG15: =IFERROR(_xlfn.XLOOKUP(N15&P15,'Historico Vendas'!G:G,'Historico Vendas'!F:F),0) -> 0 | AH15: =SUM(Q15:S15) -> 408.7386 | AI15: =AH15-AG15 -> 408.7386 | AJ15: =IFERROR(AG15/AH15,"") -> 0 | AK15: Novos | AL15: =IFERROR(INDEX('Balizador da Meta'!$D$3:$F$23,MATCH(Faturamento!$P15,'Balizador da Meta'!$C$3:$C$23,0),MATCH(Faturamento!AK15,'Balizador da Meta'!$D$2:$F$2,0)),"") -> 0
... A20: =IF(L20=1,"SIM","NÃO") -> NÃO | B20: =_xlfn.XLOOKUP($N20,'Base de Grupos'!$A:$A,'Base de Grupos'!$D:$D) -> 1000065763 | C20: =_xlfn.XLOOKUP($N20,'Base de Grupos'!$A:$A,'Base de Grupos'!$E:$E) -> CANAL VENDA INTERNA | D20: =_xlfn.XLOOKUP($N20,'Base de Grupos'!$A:$A,'Base de Grupos'!$F:$F) -> 1000065763 | E20: =_xlfn.XLOOKUP($N20,'Base de Grupos'!$A:$A,'Base de Grupos'!$G:$G) -> CANAL VENDA INTERNA | F20: =_xlfn.XLOOKUP($N20,'Base de Grupos'!$A:$A,'Base de Grupos'!$H:$H) -> 1000105900 | G20: =_xlfn.XLOOKUP($N20,'Base de Grupos'!$A:$A,'Base de Grupos'!$I:$I) -> REGIONAL VENDA DIRETA CO + NE + NO | H20: =_xlfn.XLOOKUP($N20,'Base de Grupos'!$A:$A,'Base de Grupos'!$J:$J) -> 1000105900 | I20: =_xlfn.XLOOKUP($N20,'Base de Grupos'!$A:$A,'Base de Grupos'!$K:$K) -> REGIONAL VENDA DIRETA CO + NE + NO | J20: =_xlfn.XLOOKUP($N20,'Base de Grupos'!$A:$A,'Base de Grupos'!$L:$L) -> 1000150135 | K20: =_xlfn.XLOOKUP($N20,'Base de Grupos'!$A:$A,'Base de Grupos'!$M:$M) -> HELDER DA SILVA BRUNKOW | L20: =IF(N20<>N19,1,"") | M20: =_xlfn.XLOOKUP($N20,'Base de Grupos'!$A:$A,'Base de Grupos'!$C:$C) -> AP | N20: 1324 | O20: VENDA INTERNA AP | P20: VICCIO | Q20: 0 | R20: 585.9744 | S20: 585.9744 | T20: =_xlfn.XLOOKUP($N20,'Calculo Leads'!$A$97:$A$134,'Calculo Leads'!G$97:G$134)*_xlfn.XLOOKUP($P20,'Base Grupo de Produtos'!$E$2:$E$18,'Base Grupo de Produtos'!$F$2:$F$18) -> 30 | U20: =_xlfn.XLOOKUP($N20,'Calculo Leads'!$A$97:$A$134,'Calculo Leads'!H$97:H$134)*_xlfn.XLOOKUP($P20,'Base Grupo de Produtos'!$E$2:$E$18,'Base Grupo de Produtos'!$F$2:$F$18) -> 30 | V20: =_xlfn.XLOOKUP($N20,'Calculo Leads'!$A$97:$A$134,'Calculo Leads'!I$97:I$134)*_xlfn.XLOOKUP($P20,'Base Grupo de Produtos'!$E$2:$E$18,'Base Grupo de Produtos'!$F$2:$F$18) -> 30 | W20: =_xlfn.XLOOKUP($N20,'Calculo Leads'!$A$97:$A$134,'Calculo Leads'!J$97:J$134)*_xlfn.XLOOKUP($P20,'Base Grupo de Produtos'!$E$2:$E$18,'Base Grupo de Produtos'!$F$2:$F$18) -> 30 | X20: =_xlfn.XLOOKUP($N20,'Calculo Leads'!$A$97:$A$134,'Calculo Leads'!K$97:K$134)*_xlfn.XLOOKUP($P20,'Base Grupo de Produtos'!$E$2:$E$18,'Base Grupo de Produtos'!$F$2:$F$18) -> 33 | Y20: =_xlfn.XLOOKUP($N20,'Calculo Leads'!$A$97:$A$134,'Calculo Leads'!L$97:L$134)*_xlfn.XLOOKUP($P20,'Base Grupo de Produtos'!$E$2:$E$18,'Base Grupo de Produtos'!$F$2:$F$18) -> 33 | Z20: =_xlfn.XLOOKUP($N20,'Calculo Leads'!$A$97:$A$134,'Calculo Leads'!M$97:M$134)*_xlfn.XLOOKUP($P20,'Base Grupo de Produtos'!$E$2:$E$18,'Base Grupo de Produtos'!$F$2:$F$18) -> 33 | AA20: =_xlfn.XLOOKUP($N20,'Calculo Leads'!$A$97:$A$134,'Calculo Leads'!N$97:N$134)*_xlfn.XLOOKUP($P20,'Base Grupo de Produtos'!$E$2:$E$18,'Base Grupo de Produtos'!$F$2:$F$18) -> 33 | AB20: =_xlfn.XLOOKUP($N20,'Calculo Leads'!$A$97:$A$134,'Calculo Leads'!O$97:O$134)*_xlfn.XLOOKUP($P20,'Base Grupo de Produtos'!$E$2:$E$18,'Base Grupo de Produtos'!$F$2:$F$18) -> 33 | AC20: =SUM(T20:AB20) -> 285 | AD20: =IF(AC20=0,0,AC20-AG20) -> 285 | AE20: =IFERROR(_xlfn.XLOOKUP(N20&P20,'Historico Vendas'!G:G,'Historico Vendas'!E:E),0) -> 0 | AF20: =IFERROR((AC20-AE20)/AE20,"") | AG20: =IFERROR(_xlfn.XLOOKUP(N20&P20,'Historico Vendas'!G:G,'Historico Vendas'!F:F),0) -> 0 | AH20: =SUM(Q20:S20) -> 1171.9488 | AI20: =AH20-AG20 -> 1171.9488 | AJ20: =IFERROR(AG20/AH20,"") -> 0 | AK20: Novos | AL20: =IFERROR(INDEX('Balizador da Meta'!$D$3:$F$23,MATCH(Faturamento!$P20,'Balizador da Meta'!$C$3:$C$23,0),MATCH(Faturamento!AK20,'Balizador da Meta'!$D$2:$F$2,0)),"") -> 0.2
A21: =IF(L21=1,"SIM","NÃO") -> SIM | B21: =_xlfn.XLOOKUP($N21,'Base de Grupos'!$A:$A,'Base de Grupos'!$D:$D) -> 1000065763 | C21: =_xlfn.XLOOKUP($N21,'Base de Grupos'!$A:$A,'Base de Grupos'!$E:$E) -> CANAL VENDA INTERNA | D21: =_xlfn.XLOOKUP($N21,'Base de Grupos'!$A:$A,'Base de Grupos'!$F:$F) -> 1000065763 | E21: =_xlfn.XLOOKUP($N21,'Base de Grupos'!$A:$A,'Base de Grupos'!$G:$G) -> CANAL VENDA INTERNA | F21: =_xlfn.XLOOKUP($N21,'Base de Grupos'!$A:$A,'Base de Grupos'!$H:$H) -> 1000105900 | G21: =_xlfn.XLOOKUP($N21,'Base de Grupos'!$A:$A,'Base de Grupos'!$I:$I) -> REGIONAL VENDA DIRETA CO + NE + NO | H21: =_xlfn.XLOOKUP($N21,'Base de Grupos'!$A:$A,'Base de Grupos'!$J:$J) -> 1000105900 | I21: =_xlfn.XLOOKUP($N21,'Base de Grupos'!$A:$A,'Base de Grupos'!$K:$K) -> REGIONAL VENDA DIRETA CO + NE + NO | J21: =_xlfn.XLOOKUP($N21,'Base de Grupos'!$A:$A,'Base de Grupos'!$L:$L) -> 1000150135 | K21: =_xlfn.XLOOKUP($N21,'Base de Grupos'!$A:$A,'Base de Grupos'!$M:$M) -> HELDER DA SILVA BRUNKOW | L21: =IF(N21<>N20,1,"") -> 1 | M21: =_xlfn.XLOOKUP($N21,'Base de Grupos'!$A:$A,'Base de Grupos'!$C:$C) -> RN | N21: 1325 | O21: VENDA INTERNA RN | P21: 1. TOTAL - VENDA INTERNA RN | Q21: =SUM(Q22:Q38) -> 0 | R21: =SUM(R22:R38) -> 10568.294 | S21: =SUM(S22:S38) -> 12029.079 | T21: =SUM(T22:T38) -> 3000 | U21: =SUM(U22:U38) -> 3000 | V21: =SUM(V22:V38) -> 4000 | W21: =SUM(W22:W38) -> 5000 | X21: =SUM(X22:X38) -> 5500 | ... AE21: =SUM(AE22:AE38) -> 0 | AF21: =IFERROR((AC21-AE21)/AE21,"") | AG21: =SUM(AG22:AG38) -> 0 | AH21: =SUM(AH22:AH38) -> 22597.373 | AI21: =SUM(AI22:AI38) -> 22597.373 | AJ21: =IFERROR(AG21/AH21,"") -> 0
A22: =IF(L22=1,"SIM","NÃO") -> NÃO | B22: =_xlfn.XLOOKUP($N22,'Base de Grupos'!$A:$A,'Base de Grupos'!$D:$D) -> 1000065763 | C22: =_xlfn.XLOOKUP($N22,'Base de Grupos'!$A:$A,'Base de Grupos'!$E:$E) -> CANAL VENDA INTERNA | D22: =_xlfn.XLOOKUP($N22,'Base de Grupos'!$A:$A,'Base de Grupos'!$F:$F) -> 1000065763 | E22: =_xlfn.XLOOKUP($N22,'Base de Grupos'!$A:$A,'Base de Grupos'!$G:$G) -> CANAL VENDA INTERNA | F22: =_xlfn.XLOOKUP($N22,'Base de Grupos'!$A:$A,'Base de Grupos'!$H:$H) -> 1000105900 | G22: =_xlfn.XLOOKUP($N22,'Base de Grupos'!$A:$A,'Base de Grupos'!$I:$I) -> REGIONAL VENDA DIRETA CO + NE + NO | H22: =_xlfn.XLOOKUP($N22,'Base de Grupos'!$A:$A,'Base de Grupos'!$J:$J) -> 1000105900 | I22: =_xlfn.XLOOKUP($N22,'Base de Grupos'!$A:$A,'Base de Grupos'!$K:$K) -> REGIONAL VENDA DIRETA CO + NE + NO | J22: =_xlfn.XLOOKUP($N22,'Base de Grupos'!$A:$A,'Base de Grupos'!$L:$L) -> 1000150135 | K22: =_xlfn.XLOOKUP($N22,'Base de Grupos'!$A:$A,'Base de Grupos'!$M:$M) -> HELDER DA SILVA BRUNKOW | L22: =IF(N22<>N21,1,"") | M22: =_xlfn.XLOOKUP($N22,'Base de Grupos'!$A:$A,'Base de Grupos'!$C:$C) -> RN | N22: 1325 | O22: VENDA INTERNA RN | P22: BISCOITO | Q22: 0 | R22: 404.38861 | S22: 505.48576 | T22: =_xlfn.XLOOKUP($N22,'Calculo Leads'!$A$97:$A$134,'Calculo Leads'!G$97:G$134)*_xlfn.XLOOKUP($P22,'Base Grupo de Produtos'!$E$2:$E$18,'Base Grupo de Produtos'!$F$2:$F$18) -> 150 | U22: =_xlfn.XLOOKUP($N22,'Calculo Leads'!$A$97:$A$134,'Calculo Leads'!H$97:H$134)*_xlfn.XLOOKUP($P22,'Base Grupo de Produtos'!$E$2:$E$18,'Base Grupo de Produtos'!$F$2:$F$18) -> 150 | V22: =_xlfn.XLOOKUP($N22,'Calculo Leads'!$A$97:$A$134,'Calculo Leads'!I$97:I$134)*_xlfn.XLOOKUP($P22,'Base Grupo de Produtos'!$E$2:$E$18,'Base Grupo de Produtos'!$F$2:$F$18) -> 200 | W22: =_xlfn.XLOOKUP($N22,'Calculo Leads'!$A$97:$A$134,'Calculo Leads'!J$97:J$134)*_xlfn.XLOOKUP($P22,'Base Grupo de Produtos'!$E$2:$E$18,'Base Grupo de Produtos'!$F$2:$F$18) -> 250 | X22: =_xlfn.XLOOKUP($N22,'Calculo Leads'!$A$97:$A$134,'Calculo Leads'!K$97:K$134)*_xlfn.XLOOKUP($P22,'Base Grupo de Produtos'!$E$2:$E$18,'Base Grupo de Produtos'!$F$2:$F$18) -> 275 | Y22: =_xlfn.XLOOKUP($N22,'Calculo Leads'!$A$97:$A$134,'Calculo Leads'!L$97:L$134)*_xlfn.XLOOKUP($P22,'Base Grupo de Produtos'!$E$2:$E$18,'Base Grupo de Produtos'!$F$2:$F$18) -> 385 | Z22: =_xlfn.XLOOKUP($N22,'Calculo Leads'!$A$97:$A$134,'Calculo Leads'!M$97:M$134)*_xlfn.XLOOKUP($P22,'Base Grupo de Produtos'!$E$2:$E$18,'Base Grupo de Produtos'!$F$2:$F$18) -> 385 | AA22: =_xlfn.XLOOKUP($N22,'Calculo Leads'!$A$97:$A$134,'Calculo Leads'!N$97:N$134)*_xlfn.XLOOKUP($P22,'Base Grupo de Produtos'!$E$2:$E$18,'Base Grupo de Produtos'!$F$2:$F$18) -> 440 | AB22: =_xlfn.XLOOKUP($N22,'Calculo Leads'!$A$97:$A$134,'Calculo Leads'!O$97:O$134)*_xlfn.XLOOKUP($P22,'Base Grupo de Produtos'!$E$2:$E$18,'Base Grupo de Produtos'!$F$2:$F$18) -> 330 | AC22: =SUM(T22:AB22) -> 2565 | AD22: =IF(AC22=0,0,AC22-AG22) -> 2565 | AE22: =IFERROR(_xlfn.XLOOKUP(N22&P22,'Historico Vendas'!G:G,'Historico Vendas'!E:E),0) -> 0 | AF22: =IFERROR((AC22-AE22)/AE22,"") | AG22: =IFERROR(_xlfn.XLOOKUP(N22&P22,'Historico Vendas'!G:G,'Historico Vendas'!F:F),0) -> 0 | AH22: =SUM(Q22:S22) -> 909.87436 | AI22: =AH22-AG22 -> 909.87436 | AJ22: =IFERROR(AG22/AH22,"") -> 0 | AK22: Novos | AL22: =IFERROR(INDEX('Balizador da Meta'!$D$3:$F$23,MATCH(Faturamento!$P22,'Balizador da Meta'!$C$3:$C$23,0),MATCH(Faturamento!AK22,'Balizador da Meta'!$D$2:$F$2,0)),"") -> 0.2
A23: =IF(L23=1,"SIM","NÃO") -> NÃO | B23: =_xlfn.XLOOKUP($N23,'Base de Grupos'!$A:$A,'Base de Grupos'!$D:$D) -> 1000065763 | C23: =_xlfn.XLOOKUP($N23,'Base de Grupos'!$A:$A,'Base de Grupos'!$E:$E) -> CANAL VENDA INTERNA | D23: =_xlfn.XLOOKUP($N23,'Base de Grupos'!$A:$A,'Base de Grupos'!$F:$F) -> 1000065763 | E23: =_xlfn.XLOOKUP($N23,'Base de Grupos'!$A:$A,'Base de Grupos'!$G:$G) -> CANAL VENDA INTERNA | F23: =_xlfn.XLOOKUP($N23,'Base de Grupos'!$A:$A,'Base de Grupos'!$H:$H) -> 1000105900 | G23: =_xlfn.XLOOKUP($N23,'Base de Grupos'!$A:$A,'Base de Grupos'!$I:$I) -> REGIONAL VENDA DIRETA CO + NE + NO | H23: =_xlfn.XLOOKUP($N23,'Base de Grupos'!$A:$A,'Base de Grupos'!$J:$J) -> 1000105900 | I23: =_xlfn.XLOOKUP($N23,'Base de Grupos'!$A:$A,'Base de Grupos'!$K:$K) -> REGIONAL VENDA DIRETA CO + NE + NO | J23: =_xlfn.XLOOKUP($N23,'Base de Grupos'!$A:$A,'Base de Grupos'!$L:$L) -> 1000150135 | K23: =_xlfn.XLOOKUP($N23,'Base de Grupos'!$A:$A,'Base de Grupos'!$M:$M) -> HELDER DA SILVA BRUNKOW | L23: =IF(N23<>N22,1,"") | M23: =_xlfn.XLOOKUP($N23,'Base de Grupos'!$A:$A,'Base de Grupos'!$C:$C) -> RN | N23: 1325 | O23: VENDA INTERNA RN | P23: CHOCOLATES | Q23: 0 | R23: 2462.0565 | S23: 2872.3992 | T23: =_xlfn.XLOOKUP($N23,'Calculo Leads'!$A$97:$A$134,'Calculo Leads'!G$97:G$134)*_xlfn.XLOOKUP($P23,'Base Grupo de Produtos'!$E$2:$E$18,'Base Grupo de Produtos'!$F$2:$F$18) -> 150 | U23: =_xlfn.XLOOKUP($N23,'Calculo Leads'!$A$97:$A$134,'Calculo Leads'!H$97:H$134)*_xlfn.XLOOKUP($P23,'Base Grupo de Produtos'!$E$2:$E$18,'Base Grupo de Produtos'!$F$2:$F$18) -> 150 | V23: =_xlfn.XLOOKUP($N23,'Calculo Leads'!$A$97:$A$134,'Calculo Leads'!I$97:I$134)*_xlfn.XLOOKUP($P23,'Base Grupo de Produtos'!$E$2:$E$18,'Base Grupo de Produtos'!$F$2:$F$18) -> 200 | W23: =_xlfn.XLOOKUP($N23,'Calculo Leads'!$A$97:$A$134,'Calculo Leads'!J$97:J$134)*_xlfn.XLOOKUP($P23,'Base Grupo de Produtos'!$E$2:$E$18,'Base Grupo de Produtos'!$F$2:$F$18) -> 250 | X23: =_xlfn.XLOOKUP($N23,'Calculo Leads'!$A$97:$A$134,'Calculo Leads'!K$97:K$134)*_xlfn.XLOOKUP($P23,'Base Grupo de Produtos'!$E$2:$E$18,'Base Grupo de Produtos'!$F$2:$F$18) -> 275 | Y23: =_xlfn.XLOOKUP($N23,'Calculo Leads'!$A$97:$A$134,'Calculo Leads'!L$97:L$134)*_xlfn.XLOOKUP($P23,'Base Grupo de Produtos'!$E$2:$E$18,'Base Grupo de Produtos'!$F$2:$F$18) -> 385 | Z23: =_xlfn.XLOOKUP($N23,'Calculo Leads'!$A$97:$A$134,'Calculo Leads'!M$97:M$134)*_xlfn.XLOOKUP($P23,'Base Grupo de Produtos'!$E$2:$E$18,'Base Grupo de Produtos'!$F$2:$F$18) -> 385 | AA23: =_xlfn.XLOOKUP($N23,'Calculo Leads'!$A$97:$A$134,'Calculo Leads'!N$97:N$134)*_xlfn.XLOOKUP($P23,'Base Grupo de Produtos'!$E$2:$E$18,'Base Grupo de Produtos'!$F$2:$F$18) -> 440 | AB23: =_xlfn.XLOOKUP($N23,'Calculo Leads'!$A$97:$A$134,'Calculo Leads'!O$97:O$134)*_xlfn.XLOOKUP($P23,'Base Grupo de Produtos'!$E$2:$E$18,'Base Grupo de Produtos'!$F$2:$F$18) -> 330 | AC23: =SUM(T23:AB23) -> 2565 | AD23: =IF(AC23=0,0,AC23-AG23) -> 2565 | AE23: =IFERROR(_xlfn.XLOOKUP(N23&P23,'Historico Vendas'!G:G,'Historico Vendas'!E:E),0) -> 0 | AF23: =IFERROR((AC23-AE23)/AE23,"") | AG23: =IFERROR(_xlfn.XLOOKUP(N23&P23,'Historico Vendas'!G:G,'Historico Vendas'!F:F),0) -> 0 | AH23: =SUM(Q23:S23) -> 5334.4557 | AI23: =AH23-AG23 -> 5334.4557 | AJ23: =IFERROR(AG23/AH23,"") -> 0 | AK23: Novos | AL23: =IFERROR(INDEX('Balizador da Meta'!$D$3:$F$23,MATCH(Faturamento!$P23,'Balizador da Meta'!$C$3:$C$23,0),MATCH(Faturamento!AK23,'Balizador da Meta'!$D$2:$F$2,0)),"") -> 0.2
