Workbook

Sheet Draft
A1: Nome fantasia | B1: CNPJ/CPF | C1: Estado | D1: Vendedor do último pedido | E1: Data do último pedido | F1: Valor do último pedido | G1: Dias sem comprar | H1: Ciclo médio de compra | I1: Situação
A2: BANCA12 ARMAZEM DE PRODUTOS NATURAIS LTDA | B2: 92.916.360/0002-37 | C2: RS | D2: Manu Ditzel | E2: 07/10/2025 | F2: 2075.26 | I2: Ativo
A3: GRAO VIDA | B3: 31.599.810/0001-30 | C3: SP | D3: Larissa Padilha | E3: 06/10/2025 | F3: 3508.11 | G3: 1 | H3: 46.6667 | I3: Ativo
A4: SUPERMERCADOS PAGOTO LTDA | B4: 27.277.961/0001-02 | C4: ES | D4: Larissa Padilha | E4: 06/10/2025 | F4: 1215.8 | G4: 1 | I4: Ativo
A5: GRAO E VIDA | B5: 43.590.125/0001-21 | C5: MG | D5: Larissa Padilha | E5: 06/10/2025 | F5: 3075.94 | G5: 1 | I5: Ativo
A6: LARISSA DA SILVA PADILHA | B6: 42.149.466/0001-01 | C6: SC | D6: Larissa Padilha | E6: 01/10/2025 | F6: 675.8 | G6: 6 | I6: Ativo
A7: 49.844.222 LUIS CARLOS VIEIRA | B7: 49.844.222/0001-80 | C7: SP | D7: Larissa Padilha | E7: 01/10/2025 | F7: 659.66 | G7: 6 | H7: 62.5 | I7: Ativo
A8: MS NUTRICAO | B8: 53.191.899/0001-33 | C8: SC | D8: Julio Gadret | E8: 01/10/2025 | F8: 1076.41 | G8: 6 | H8: 97 | I8: Ativo
A9: VIDA LEVE BARIGUI | B9: 54.423.411/0001-19 | C9: PR | D9: Central - Daiane | E9: 01/10/2025 | F9: 603 | G9: 6 | H9: 64 | I9: Ativo
A10: GAN NUTRICAO | B10: 34.313.930/0001-17 | C10: SC | D10: Julio Gadret | E10: 01/10/2025 | F10: 1593.58 | G10: 6 | I10: Ativo
A11: VALDECI APARECIDO DE NICOLAI | B11: 37.633.350/0001-03 | C11: SP | D11: Larissa Padilha | E11: 01/10/2025 | F11: 1142.96 | G11: 6 | I11: Ativo
A12: MUNDO VERDE VOCE MAIS SAUDAVEL | B12: 28.019.593/0001-57 | C12: SP | D12: Central - Daiane | E12: 30/09/2025 | F12: 1928.84 | G12: 7 | H12: 55 | I12: Ativo
A13: LOJA VIDA LEVE VILA ARENS | B13: 62.004.109/0001-54 | C13: SP | D13: Central - Daiane | E13: 30/09/2025 | F13: 1570.68 | G13: 7 | I13: Ativo
A14: VIDA NATURAL FSA | B14: 62.617.017/0001-40 | C14: BA | D14: Central - Daiane | E14: 30/09/2025 | F14: 1567.26 | G14: 7 | I14: Ativo
A15: VIDA NATURAL | B15: 61.791.187/0001-83 | C15: PA | D15: Central - Daiane | E15: 30/09/2025 | F15: 1567.26 | G15: 7 | I15: Ativo
A16: C.CORREA LTDA | B16: 62.106.171/0001-57 | C16: PR | D16: Central - Daiane | E16: 30/09/2025 | F16: 1618.97 | G16: 7 | I16: Ativo
A17: AVILA SUPLEMENTOS | B17: 16.966.212/0001-68 | C17: SC | D17: Julio Gadret | E17: 29/09/2025 | F17: 678 | G17: 8 | I17: Ativo
A18: Ávila Natural | B18: 76.384.908/0001-08 | C18: SC | D18: Julio Gadret | E18: 29/09/2025 | F18: 658.76 | G18: 8 | I18: Ativo
A19: FRANQUIA FITLAND BLUMENAU | B19: 40.917.018/0001-77 | C19: SC | D19: Julio Gadret | E19: 29/09/2025 | F19: 1347.96 | G19: 8 | H19: 27.5 | I19: Ativo
A20: FIT LAGES COMERCIO DE SUPLEMENTOS E PRODUTOS NATURAIS | B20: 52.607.036/0001-31 | C20: SC | D20: Julio Gadret | E20: 29/09/2025 | F20: 774.24 | G20: 8 | H20: 34 | I20: Ativo
A21: FIT SJB | B21: 43.732.530/0001-37 | C21: SC | D21: Julio Gadret | E21: 29/09/2025 | F21: 1304.15 | G21: 8 | H21: 44.3333 | I21: Ativo
A22: L & M NUTRICAO | B22: 52.261.228/0002-10 | C22: SC | D22: Julio Gadret | E22: 29/09/2025 | F22: 1216.76 | G22: 8 | H22: 51.5 | I22: Ativo
A23: FITLAND BLUMENAU AGUA VERDE | B23: 49.982.339/0001-20 | C23: SC | D23: Julio Gadret | E23: 29/09/2025 | F23: 2074.89 | G23: 8 | H23: 27.5 | I23: Ativo
A24: L.A. PRODUTOS NATURAIS | B24: 56.174.184/0001-60 | C24: SC | D24: Julio Gadret | E24: 29/09/2025 | F24: 1254.11 | G24: 8 | I24: Ativo
A25: MS DISTRIBUIDORA | B25: 37.790.248/0001-03 | C25: PR | D25: Manu Ditzel | E25: 29/09/2025 | F25: 985.5 | G25: 8 | I25: Ativo
A26: MUNDO VERDE | B26: 72.500.887/0001-98 | C26: RJ | D26: Manu Ditzel | E26: 29/09/2025 | F26: 1226.35 | G26: 8 | H26: 96 | I26: Ativo
A27: FIT PEDRA BRANCA | B27: 60.546.169/0001-73 | C27: SC | D27: Julio Gadret | E27: 29/09/2025 | F27: 1016.3 | G27: 8 | H27: 109 | I27: Ativo
A28: CPQ BRASIL S/A - EM RECUPERACAO JUDICIAL | B28: 74.552.068/0001-10 | C28: SP | D28: Larissa Padilha | E28: 29/09/2025 | F28: 2015.52 | G28: 8 | I28: Ativo
A29: HENRI G. VALCARENGHI LTDA | B29: 57.963.322/0001-53 | C29: RS | D29: Central - Daiane | E29: 29/09/2025 | F29: 871.91 | G29: 8 | I29: Ativo
A30: PICADO'S DA TERRA PRODUTOS NATURAIS | B30: 37.680.783/0002-92 | C30: SC | D30: Julio Gadret | E30: 26/09/2025 | F30: 3353.25 | G30: 11 | I30: Ativo
A31: CSJ BRASIL ALIMENTOS LTDA | B31: 58.363.567/0001-02 | C31: SC | D31: Julio Gadret | E31: 26/09/2025 | F31: 2710.89 | G31: 11 | I31: Ativo
A32: ASSOCIACAO DOS FENILCETONURICOS E HOMOCISTINURICOS DO PARANA - AFEH-PR | B32: 72.326.119/0001-60 | C32: PR | D32: Manu Ditzel | E32: 26/09/2025 | F32: 1388.52 | G32: 11 | H32: 133 | I32: Ativo
A33: MARILIA RAFAELA FERREIRA DA LUZ LTDA | B33: 61.746.555/0001-71 | C33: PR | D33: Central - Daiane | E33: 26/09/2025 | F33: 681.47 | G33: 11 | H33: 32 | I33: Ativo
A34: UNIMED JARAGUA DO SUL | B34: 03.855.214/0002-19 | C34: SC | D34: Manu Ditzel | E34: 26/09/2025 | F34: 433.84 | G34: 11 | I34: Ativo
A35: PICADOS DA TERRA | B35: 59.633.825/0001-96 | C35: SC | D35: Julio Gadret | E35: 26/09/2025 | F35: 3353.25 | G35: 11 | I35: Ativo
A36: TUDO EM GRAOS COMERCIO DE ALIMENTOS LTDA | B36: 20.474.456/0001-09 | C36: RS | D36: Central - Daiane | E36: 25/09/2025 | F36: 859.47 | G36: 12 | I36: Ativo
A37: VILLA DOS GRAOS | B37: 31.118.319/0001-40 | C37: SC | D37: Julio Gadret | E37: 25/09/2025 | F37: 2421.99 | G37: 12 | I37: Ativo
A38: EMPORIO POMAR URBANO | B38: 22.332.946/0001-98 | C38: SC | D38: Manu Ditzel | E38: 25/09/2025 | F38: 1354.15 | G38: 12 | H38: 41 | I38: Ativo
A39: VERCATTO BOUTIQUE SÁUDAVEL | B39: 41.711.232/0001-35 | C39: PR | D39: Central - Daiane | E39: 25/09/2025 | F39: 945 | G39: 12 | H39: 22 | I39: Ativo
A40: CAPITAL FITNESS - 2/3 | B40: 43.922.481/0002-86 | C40: TO | D40: Larissa Padilha | E40: 25/09/2025 | F40: 2013.98 | G40: 12 | H40: 94 | I40: Ativo
...

Sheet Base Mercos
C2: Nome fantasia | D2: CNPJ/CPF | E2: Estado | F2: Vendedor do último pedido | G2: Data do último pedido | H2: Valor do último pedido | I2: Dias sem comprar | J2: Ciclo médio de compra | K2: Situação | L2: Coluna1 | M2: status | N2: ULTIMO CONTATO | O2: RESULTADO ATUAL | P2: AÇÃO | Q2: Coluna12 | R2: FOLLOW UP
C3: NATUREZA EM KILO | D3: 00.211.115/0002-06 | E3: PR | F3: Manu Ditzel | G3: 16/09/2025 | H3: 731.55 | I3: 21 | J3: 19 | K3: ATIVO | M3: =IF(OR(J3<=0,J3=""),"","Recompra") -> Recompra | N3: =IFERROR(IF(Tabela1[[#This Row],[Nome fantasia]]="","",_xlfn.XLOOKUP($C3,Log!D:D,Log!B:B,,,-1)),"") -> 46006 | O3: =IFERROR(_xlfn.XLOOKUP($C3,Log!D:D,Log!W:W,,,-1),"") -> EM ATENDIMENTO | P3: =IFERROR(_xlfn.XLOOKUP($C3,Log!D:D,Log!Y:Y,,,-1),"") -> FORÇANDO RECOMPRA | R3: =IFERROR(IF(Tabela1[[#This Row],[Nome fantasia]]="","",_xlfn.XLOOKUP($C3,Log!D:D,Log!X:X,,,-1)),"") -> 46008
C4: EMPORIO GOURMET | D4: * | E4: SC | F4: Manu Ditzel | G4: * | H4: * | I4: * | J4: * | K4: LEAD | M4: =IF(OR(J4<=0,J4=""),"","Recompra") -> Recompra | N4: =IFERROR(IF(Tabela1[[#This Row],[Nome fantasia]]="","",_xlfn.XLOOKUP($C4,Log!D:D,Log!B:B,,,-1)),"") -> 45922 | O4: =IFERROR(_xlfn.XLOOKUP($C4,Log!D:D,Log!W:W,,,-1),"") -> EM ATENDIMENTO | P4: =IFERROR(_xlfn.XLOOKUP($C4,Log!D:D,Log!Y:Y,,,-1),"") -> LIGOU PARA INFORMAÇÔES | R4: =IFERROR(IF(Tabela1[[#This Row],[Nome fantasia]]="","",_xlfn.XLOOKUP($C4,Log!D:D,Log!X:X,,,-1)),"") -> 0
C5: NATHALIA DE JESUS SILVA COSTA LTDA | D5: 59.244.884/0001-72 | E5: SP | F5: Manu Ditzel | G5: 27/08/2025 | H5: 650.3 | I5: 41 | J5: 0 | K5: ATIVO | M5: =IF(OR(J5<=0,J5=""),"","Recompra") | N5: =IFERROR(IF(Tabela1[[#This Row],[Nome fantasia]]="","",_xlfn.XLOOKUP($C5,Log!D:D,Log!B:B,,,-1)),"") -> 45896 | O5: =IFERROR(_xlfn.XLOOKUP($C5,Log!D:D,Log!W:W,,,-1),"") -> EM ATENDIMENTO | P5: =IFERROR(_xlfn.XLOOKUP($C5,Log!D:D,Log!Y:Y,,,-1),"") -> LIGAÇÃO | R5: =IFERROR(IF(Tabela1[[#This Row],[Nome fantasia]]="","",_xlfn.XLOOKUP($C5,Log!D:D,Log!X:X,,,-1)),"") -> 45894
C6: ERICA BALDIN | D6: * | E6: PR | F6: Manu Ditzel | G6: * | H6: * | I6: * | J6: * | K6: LEAD | M6: =IF(OR(J6<=0,J6=""),"","Recompra") -> Recompra | N6: =IFERROR(IF(Tabela1[[#This Row],[Nome fantasia]]="","",_xlfn.XLOOKUP($C6,Log!D:D,Log!B:B,,,-1)),"") -> 45915 | O6: =IFERROR(_xlfn.XLOOKUP($C6,Log!D:D,Log!W:W,,,-1),"") -> ORÇAMENTO | P6: =IFERROR(_xlfn.XLOOKUP($C6,Log!D:D,Log!Y:Y,,,-1),"") -> LICITAÇÃO | R6: =IFERROR(IF(Tabela1[[#This Row],[Nome fantasia]]="","",_xlfn.XLOOKUP($C6,Log!D:D,Log!X:X,,,-1)),"") -> 45916
C7: F & G VITALIDADE NATURAL | D7: 58.319.253/0001-02 | F7: Manu Ditzel | G7: * | H7: * | I7: * | J7: * | K7: LEAD | M7: =IF(OR(J7<=0,J7=""),"","Recompra") -> Recompra | N7: =IFERROR(IF(Tabela1[[#This Row],[Nome fantasia]]="","",_xlfn.XLOOKUP($C7,Log!D:D,Log!B:B,,,-1)),"") -> 45915 | O7: =IFERROR(_xlfn.XLOOKUP($C7,Log!D:D,Log!W:W,,,-1),"") -> ORÇAMENTO | P7: =IFERROR(_xlfn.XLOOKUP($C7,Log!D:D,Log!Y:Y,,,-1),"") -> E-COMMERCE EM ANDAMENTO | R7: =IFERROR(IF(Tabela1[[#This Row],[Nome fantasia]]="","",_xlfn.XLOOKUP($C7,Log!D:D,Log!X:X,,,-1)),"") -> 45916
C8: EMBALEME | D8: 00.458.459/0001-33 | E8: SP | F8: Manu Ditzel | G8: * | H8: * | I8: * | J8: * | K8: LEAD | M8: =IF(OR(J8<=0,J8=""),"","Recompra") -> Recompra | N8: =IFERROR(IF(Tabela1[[#This Row],[Nome fantasia]]="","",_xlfn.XLOOKUP($C8,Log!D:D,Log!B:B,,,-1)),"") -> 45915 | O8: =IFERROR(_xlfn.XLOOKUP($C8,Log!D:D,Log!W:W,,,-1),"") -> EM ATENDIMENTO | P8: =IFERROR(_xlfn.XLOOKUP($C8,Log!D:D,Log!Y:Y,,,-1),"") -> VARIOS ORÇAMENTOS | R8: =IFERROR(IF(Tabela1[[#This Row],[Nome fantasia]]="","",_xlfn.XLOOKUP($C8,Log!D:D,Log!X:X,,,-1)),"") -> 45917
C9: EMBALEME | D9: 00.458.459/0001-33 | E9: SP | F9: Manu Ditzel | G9: * | H9: * | I9: * | J9: * | K9: LEAD | M9: =IF(OR(J9<=0,J9=""),"","Recompra") -> Recompra | N9: =IFERROR(IF(Tabela1[[#This Row],[Nome fantasia]]="","",_xlfn.XLOOKUP($C9,Log!D:D,Log!B:B,,,-1)),"") -> 45915 | O9: =IFERROR(_xlfn.XLOOKUP($C9,Log!D:D,Log!W:W,,,-1),"") -> EM ATENDIMENTO | P9: =IFERROR(_xlfn.XLOOKUP($C9,Log!D:D,Log!Y:Y,,,-1),"") -> VARIOS ORÇAMENTOS | R9: =IFERROR(IF(Tabela1[[#This Row],[Nome fantasia]]="","",_xlfn.XLOOKUP($C9,Log!D:D,Log!X:X,,,-1)),"") -> 45917
C10: CEREALISSIMA MGV | D10: 28.825.262/0001-04 | E10: GO | F10: Helder Brunkow | G10: 17/09/2025 | H10: 1442.87 | I10: 20 | J10: 40 | K10: ATIVO | M10: =IF(OR(J10<=0,J10=""),"","Recompra") -> Recompra | N10: =IFERROR(IF(Tabela1[[#This Row],[Nome fantasia]]="","",_xlfn.XLOOKUP($C10,Log!D:D,Log!B:B,,,-1)),"") -> 45877 | O10: =IFERROR(_xlfn.XLOOKUP($C10,Log!D:D,Log!W:W,,,-1),"") -> VENDA | P10: =IFERROR(_xlfn.XLOOKUP($C10,Log!D:D,Log!Y:Y,,,-1),"") -> RECOMPRA | R10: =IFERROR(IF(Tabela1[[#This Row],[Nome fantasia]]="","",_xlfn.XLOOKUP($C10,Log!D:D,Log!X:X,,,-1)),"") -> 45940
C11: ASSOCIACAO DE PAIS E AMIGOS DOS EXCEPCIONAIS DE S PAULO | D11: 60.502.242/0001-05 | E11: SP | F11: Helder Brunkow | G11: 08/08/2025 | H11: 2040.89 | I11: 60 | J11: 91 | K11: ATIVO | M11: =IF(OR(J11<=0,J11=""),"","Recompra") -> Recompra | N11: =IFERROR(IF(Tabela1[[#This Row],[Nome fantasia]]="","",_xlfn.XLOOKUP($C11,Log!D:D,Log!B:B,,,-1)),"") -> 45877 | O11: =IFERROR(_xlfn.XLOOKUP($C11,Log!D:D,Log!W:W,,,-1),"") -> VENDA | P11: =IFERROR(_xlfn.XLOOKUP($C11,Log!D:D,Log!Y:Y,,,-1),"") -> RECOMPRA | R11: =IFERROR(IF(Tabela1[[#This Row],[Nome fantasia]]="","",_xlfn.XLOOKUP($C11,Log!D:D,Log!X:X,,,-1)),"") -> 45940
C12: NOSSO GREEN MARKET | D12: 52.916.686/0001-69 | E12: PE | F12: Helder Brunkow | G12: 08/08/2025 | H12: 1009.9 | I12: 60 | J12: 59 | K12: ATIVO | M12: =IF(OR(J12<=0,J12=""),"","Recompra") -> Recompra | N12: =IFERROR(IF(Tabela1[[#This Row],[Nome fantasia]]="","",_xlfn.XLOOKUP($C12,Log!D:D,Log!B:B,,,-1)),"") -> 45877 | O12: =IFERROR(_xlfn.XLOOKUP($C12,Log!D:D,Log!W:W,,,-1),"") -> VENDA | P12: =IFERROR(_xlfn.XLOOKUP($C12,Log!D:D,Log!Y:Y,,,-1),"") -> RECOMPRA | R12: =IFERROR(IF(Tabela1[[#This Row],[Nome fantasia]]="","",_xlfn.XLOOKUP($C12,Log!D:D,Log!X:X,,,-1)),"") -> 45940
C13: PORTONUTRY ALIMENTACAO SAUDAVEL | D13: 61.668.179/0001-44 | E13: BA | F13: Larissa Padilha | G13: 07/08/2025 | H13: 1021.87 | I13: 61 | J13: 0 | K13: ATIVO | M13: =IF(OR(J13<=0,J13=""),"","Recompra") | N13: =IFERROR(IF(Tabela1[[#This Row],[Nome fantasia]]="","",_xlfn.XLOOKUP($C13,Log!D:D,Log!B:B,,,-1)),"") -> 45876 | O13: =IFERROR(_xlfn.XLOOKUP($C13,Log!D:D,Log!W:W,,,-1),"") -> VENDA | P13: =IFERROR(_xlfn.XLOOKUP($C13,Log!D:D,Log!Y:Y,,,-1),"") -> RECOMPRA | R13: =IFERROR(IF(Tabela1[[#This Row],[Nome fantasia]]="","",_xlfn.XLOOKUP($C13,Log!D:D,Log!X:X,,,-1)),"") -> 45939
C14: EMPORIO MULTI ARMAZEM | D14: 59.182.148/0001-37 | E14: DF | F14: Larissa Padilha | G14: 07/08/2025 | H14: 1215.54 | I14: 61 | J14: 0 | K14: ATIVO | M14: =IF(OR(J14<=0,J14=""),"","Recompra") | N14: =IFERROR(IF(Tabela1[[#This Row],[Nome fantasia]]="","",_xlfn.XLOOKUP($C14,Log!D:D,Log!B:B,,,-1)),"") -> 45876 | O14: =IFERROR(_xlfn.XLOOKUP($C14,Log!D:D,Log!W:W,,,-1),"") -> VENDA | P14: =IFERROR(_xlfn.XLOOKUP($C14,Log!D:D,Log!Y:Y,,,-1),"") -> RECOMPRA | R14: =IFERROR(IF(Tabela1[[#This Row],[Nome fantasia]]="","",_xlfn.XLOOKUP($C14,Log!D:D,Log!X:X,,,-1)),"") -> 45939
C15: DIVINA TERRA | D15: 42.415.997/0001-90 | E15: PR | F15: Central - Daiane | G15: 06/08/2025 | H15: 1036.87 | I15: 62 | J15: 0 | K15: ATIVO | M15: =IF(OR(J15<=0,J15=""),"","Recompra") | N15: =IFERROR(IF(Tabela1[[#This Row],[Nome fantasia]]="","",_xlfn.XLOOKUP($C15,Log!D:D,Log!B:B,,,-1)),"") -> 45875 | O15: =IFERROR(_xlfn.XLOOKUP($C15,Log!D:D,Log!W:W,,,-1),"") -> VENDA | P15: =IFERROR(_xlfn.XLOOKUP($C15,Log!D:D,Log!Y:Y,,,-1),"") -> RECOMPRA | R15: =IFERROR(IF(Tabela1[[#This Row],[Nome fantasia]]="","",_xlfn.XLOOKUP($C15,Log!D:D,Log!X:X,,,-1)),"") -> 45938
C16: MUNDO FIT | D16: 29.402.498/0001-09 | E16: MG | F16: Helder Brunkow | G16: 06/08/2025 | H16: 1745.52 | I16: 62 | J16: 0 | K16: ATIVO | M16: =IF(OR(J16<=0,J16=""),"","Recompra") | N16: =IFERROR(IF(Tabela1[[#This Row],[Nome fantasia]]="","",_xlfn.XLOOKUP($C16,Log!D:D,Log!B:B,,,-1)),"") -> 45875 | O16: =IFERROR(_xlfn.XLOOKUP($C16,Log!D:D,Log!W:W,,,-1),"") -> VENDA | P16: =IFERROR(_xlfn.XLOOKUP($C16,Log!D:D,Log!Y:Y,,,-1),"") -> RECOMPRA | R16: =IFERROR(IF(Tabela1[[#This Row],[Nome fantasia]]="","",_xlfn.XLOOKUP($C16,Log!D:D,Log!X:X,,,-1)),"") -> 45938
C17: SUPERMERCADO PEDROSA | D17: 11.322.507/0001-88 | E17: PE | F17: Helder Brunkow | G17: 06/08/2025 | H17: 4108.73 | I17: 62 | J17: 0 | K17: ATIVO | M17: =IF(OR(J17<=0,J17=""),"","Recompra") | N17: =IFERROR(IF(Tabela1[[#This Row],[Nome fantasia]]="","",_xlfn.XLOOKUP($C17,Log!D:D,Log!B:B,,,-1)),"") -> 45875 | O17: =IFERROR(_xlfn.XLOOKUP($C17,Log!D:D,Log!W:W,,,-1),"") -> VENDA | P17: =IFERROR(_xlfn.XLOOKUP($C17,Log!D:D,Log!Y:Y,,,-1),"") -> RECOMPRA | R17: =IFERROR(IF(Tabela1[[#This Row],[Nome fantasia]]="","",_xlfn.XLOOKUP($C17,Log!D:D,Log!X:X,,,-1)),"") -> 45938
C18: CARIMBO ACAI E BEBIDAS DO NORTE | D18: 26.176.117/0001-14 | E18: MG | F18: Helder Brunkow | G18: 06/08/2025 | H18: 658.55 | I18: 62 | J18: 0 | K18: ATIVO | M18: =IF(OR(J18<=0,J18=""),"","Recompra") | N18: =IFERROR(IF(Tabela1[[#This Row],[Nome fantasia]]="","",_xlfn.XLOOKUP($C18,Log!D:D,Log!B:B,,,-1)),"") -> 45875 | O18: =IFERROR(_xlfn.XLOOKUP($C18,Log!D:D,Log!W:W,,,-1),"") -> SUPORTE | P18: =IFERROR(_xlfn.XLOOKUP($C18,Log!D:D,Log!Y:Y,,,-1),"") -> ENTREGA | R18: =IFERROR(IF(Tabela1[[#This Row],[Nome fantasia]]="","",_xlfn.XLOOKUP($C18,Log!D:D,Log!X:X,,,-1)),"") -> 0
C19: SWEET AND FIT ATELIER | D19: 37.370.567/0001-60 | E19: SP | F19: Manu Ditzel | G19: 17/09/2025 | H19: 3231.74 | I19: 20 | J19: 32 | K19: ATIVO | M19: =IF(OR(J19<=0,J19=""),"","Recompra") -> Recompra | N19: =IFERROR(IF(Tabela1[[#This Row],[Nome fantasia]]="","",_xlfn.XLOOKUP($C19,Log!D:D,Log!B:B,,,-1)),"") -> 45917 | O19: =IFERROR(_xlfn.XLOOKUP($C19,Log!D:D,Log!W:W,,,-1),"") -> ORÇAMENTO | P19: =IFERROR(_xlfn.XLOOKUP($C19,Log!D:D,Log!Y:Y,,,-1),"") -> ORÇAMENTO | R19: =IFERROR(IF(Tabela1[[#This Row],[Nome fantasia]]="","",_xlfn.XLOOKUP($C19,Log!D:D,Log!X:X,,,-1)),"") -> 45918
C20: SHOPPING NATURAL | D20: 15.428.647/0001-96 | E20: MT | F20: Manu Ditzel | G20: 28/08/2025 | H20: 998.4 | I20: 40 | J20: 60.5 | K20: ATIVO | M20: =IF(OR(J20<=0,J20=""),"","Recompra") -> Recompra | N20: =IFERROR(IF(Tabela1[[#This Row],[Nome fantasia]]="","",_xlfn.XLOOKUP($C20,Log!D:D,Log!B:B,,,-1)),"") -> 45897 | O20: =IFERROR(_xlfn.XLOOKUP($C20,Log!D:D,Log!W:W,,,-1),"") -> FOLLOW UP | P20: =IFERROR(_xlfn.XLOOKUP($C20,Log!D:D,Log!Y:Y,,,-1),"") -> ENTREGA | R20: =IFERROR(IF(Tabela1[[#This Row],[Nome fantasia]]="","",_xlfn.XLOOKUP($C20,Log!D:D,Log!X:X,,,-1)),"") -> 45919
C21: RAIZES E SABORES | D21: 35.031.254/0001-51 | E21: SP | F21: Manu Ditzel | G21: 26/08/2025 | H21: 936.23 | I21: 42 | J21: 21 | K21: ATIVO | M21: =IF(OR(J21<=0,J21=""),"","Recompra") -> Recompra | N21: =IFERROR(IF(Tabela1[[#This Row],[Nome fantasia]]="","",_xlfn.XLOOKUP($C21,Log!D:D,Log!B:B,,,-1)),"") -> 45895 | O21: =IFERROR(_xlfn.XLOOKUP($C21,Log!D:D,Log!W:W,,,-1),"") -> FOLLOW UP | P21: =IFERROR(_xlfn.XLOOKUP($C21,Log!D:D,Log!Y:Y,,,-1),"") -> ENTREGA | R21: =IFERROR(IF(Tabela1[[#This Row],[Nome fantasia]]="","",_xlfn.XLOOKUP($C21,Log!D:D,Log!X:X,,,-1)),"") -> 45919
C22: 49.844.222 LUIS CARLOS VIEIRA | D22: 49.844.222/0001-80 | E22: SP | F22: Helder Brunkow | G22: 01/10/2025 | H22: 659.66 | I22: 6 | J22: 62.5 | K22: ATIVO | M22: =IF(OR(J22<=0,J22=""),"","Recompra") -> Recompra | N22: =IFERROR(IF(Tabela1[[#This Row],[Nome fantasia]]="","",_xlfn.XLOOKUP($C22,Log!D:D,Log!B:B,,,-1)),"") -> 45873 | O22: =IFERROR(_xlfn.XLOOKUP($C22,Log!D:D,Log!W:W,,,-1),"") -> VENDA | P22: =IFERROR(_xlfn.XLOOKUP($C22,Log!D:D,Log!Y:Y,,,-1),"") -> RECOMPRA | R22: =IFERROR(IF(Tabela1[[#This Row],[Nome fantasia]]="","",_xlfn.XLOOKUP($C22,Log!D:D,Log!X:X,,,-1)),"") -> 45936
C23: CB CURITIBA COMERCIO DE ALIMENTOS | D23: 23.502.037/0001-13 | E23: PR | F23: Manu Ditzel | G23: * | H23: * | I23: * | J23: * | K23: LEAD | M23: =IF(OR(J23<=0,J23=""),"","Recompra") -> Recompra | N23: =IFERROR(IF(Tabela1[[#This Row],[Nome fantasia]]="","",_xlfn.XLOOKUP($C23,Log!D:D,Log!B:B,,,-1)),"") -> 45917 | O23: =IFERROR(_xlfn.XLOOKUP($C23,Log!D:D,Log!W:W,,,-1),"") -> EM ATENDIMENTO | P23: =IFERROR(_xlfn.XLOOKUP($C23,Log!D:D,Log!Y:Y,,,-1),"") -> TRANFERIDO ATENDIMENTO | R23: =IFERROR(IF(Tabela1[[#This Row],[Nome fantasia]]="","",_xlfn.XLOOKUP($C23,Log!D:D,Log!X:X,,,-1)),"") -> 45919
C24: RAYNARA PAULINA ROCHA FRANCO - JUSTGO | D24: 61.819.408/0001-84 | E24: MG | F24: Helder Brunkow | G24: 31/07/2025 | H24: 747.14 | I24: 68 | J24: 0 | K24: ATIVO | M24: =IF(OR(J24<=0,J24=""),"","Recompra") | N24: =IFERROR(IF(Tabela1[[#This Row],[Nome fantasia]]="","",_xlfn.XLOOKUP($C24,Log!D:D,Log!B:B,,,-1)),"") -> 45869 | O24: =IFERROR(_xlfn.XLOOKUP($C24,Log!D:D,Log!W:W,,,-1),"") -> SUPORTE | P24: =IFERROR(_xlfn.XLOOKUP($C24,Log!D:D,Log!Y:Y,,,-1),"") -> RASTREIO | R24: =IFERROR(IF(Tabela1[[#This Row],[Nome fantasia]]="","",_xlfn.XLOOKUP($C24,Log!D:D,Log!X:X,,,-1)),"") -> 0
C25: VIDA LEVE BARIGUI | D25: 54.423.411/0001-19 | E25: PR | F25: Manu Ditzel | G25: 01/10/2025 | H25: 603 | I25: 6 | J25: 64 | K25: ATIVO | M25: =IF(OR(J25<=0,J25=""),"","Recompra") -> Recompra | N25: =IFERROR(IF(Tabela1[[#This Row],[Nome fantasia]]="","",_xlfn.XLOOKUP($C25,Log!D:D,Log!B:B,,,-1)),"") -> 45918 | O25: =IFERROR(_xlfn.XLOOKUP($C25,Log!D:D,Log!W:W,,,-1),"") -> EM ATENDIMENTO | P25: =IFERROR(_xlfn.XLOOKUP($C25,Log!D:D,Log!Y:Y,,,-1),"") -> MENSAGEM | R25: =IFERROR(IF(Tabela1[[#This Row],[Nome fantasia]]="","",_xlfn.XLOOKUP($C25,Log!D:D,Log!X:X,,,-1)),"") -> 45922
C26: VIPI SUPERMERCADOS E BONNO ATACADO E VAREJO | D26: 78.516.440/0006-06 | E26: PR | F26: Manu Ditzel | G26: 07/08/2025 | H26: 1033.22 | I26: 61 | J26: 59 | K26: ATIVO | M26: =IF(OR(J26<=0,J26=""),"","Recompra") -> Recompra | N26: =IFERROR(IF(Tabela1[[#This Row],[Nome fantasia]]="","",_xlfn.XLOOKUP($C26,Log!D:D,Log!B:B,,,-1)),"") -> 45918 | O26: =IFERROR(_xlfn.XLOOKUP($C26,Log!D:D,Log!W:W,,,-1),"") -> EM ATENDIMENTO | P26: =IFERROR(_xlfn.XLOOKUP($C26,Log!D:D,Log!Y:Y,,,-1),"") -> AGUARDANDO CLIENTE | R26: =IFERROR(IF(Tabela1[[#This Row],[Nome fantasia]]="","",_xlfn.XLOOKUP($C26,Log!D:D,Log!X:X,,,-1)),"") -> 45922
C27: MAIS NATURAL COMERCIO DE PRODUTOS NATURAIS | D27: 17.880.439/0002-30 | E27: RS | F27: Manu Ditzel | G27: 05/08/2025 | H27: 1547.8 | I27: 63 | J27: 65.5 | K27: ATIVO | M27: =IF(OR(J27<=0,J27=""),"","Recompra") -> Recompra | N27: =IFERROR(IF(Tabela1[[#This Row],[Nome fantasia]]="","",_xlfn.XLOOKUP($C27,Log!D:D,Log!B:B,,,-1)),"") -> 45918 | O27: =IFERROR(_xlfn.XLOOKUP($C27,Log!D:D,Log!W:W,,,-1),"") -> EM ATENDIMENTO | P27: =IFERROR(_xlfn.XLOOKUP($C27,Log!D:D,Log!Y:Y,,,-1),"") -> MENSAGEM | R27: =IFERROR(IF(Tabela1[[#This Row],[Nome fantasia]]="","",_xlfn.XLOOKUP($C27,Log!D:D,Log!X:X,,,-1)),"") -> 45922
C28: NICE STORE PRESENTES | D28: 32.940.804/0001-67 | E28: SC | F28: Manu Ditzel | G28: 05/08/2025 | H28: 667.16 | I28: 63 | J28: 18 | K28: ATIVO | M28: =IF(OR(J28<=0,J28=""),"","Recompra") -> Recompra | N28: =IFERROR(IF(Tabela1[[#This Row],[Nome fantasia]]="","",_xlfn.XLOOKUP($C28,Log!D:D,Log!B:B,,,-1)),"") -> 45994 | O28: =IFERROR(_xlfn.XLOOKUP($C28,Log!D:D,Log!W:W,,,-1),"") -> VENDA | P28: =IFERROR(_xlfn.XLOOKUP($C28,Log!D:D,Log!Y:Y,,,-1),"") -> VENDA FINALIZADA | R28: =IFERROR(IF(Tabela1[[#This Row],[Nome fantasia]]="","",_xlfn.XLOOKUP($C28,Log!D:D,Log!X:X,,,-1)),"") -> 46057
C29: BATEL GOURMET HORTIFRUTI E EMPORIO | D29: 30.289.781/0001-47 | E29: PR | F29: Manu Ditzel | G29: 31/07/2025 | H29: 944.22 | I29: 68 | J29: 35.3333 | K29: ATIVO | M29: =IF(OR(J29<=0,J29=""),"","Recompra") -> Recompra | N29: =IFERROR(IF(Tabela1[[#This Row],[Nome fantasia]]="","",_xlfn.XLOOKUP($C29,Log!D:D,Log!B:B,,,-1)),"") -> 46001 | O29: =IFERROR(_xlfn.XLOOKUP($C29,Log!D:D,Log!W:W,,,-1),"") -> EM ATENDIMENTO | P29: =IFERROR(_xlfn.XLOOKUP($C29,Log!D:D,Log!Y:Y,,,-1),"") -> NÃO ATENDEU, MANDEI MENSAGEM | R29: =IFERROR(IF(Tabela1[[#This Row],[Nome fantasia]]="","",_xlfn.XLOOKUP($C29,Log!D:D,Log!X:X,,,-1)),"") -> 46003
C30: MAGOGA HORTIFRUTI LTDA | D30: 54.211.982/0001-90 | E30: SP | F30: Helder Brunkow | G30: 22/09/2025 | H30: 1879.39 | I30: 15 | J30: 34.2 | K30: ATIVO | M30: =IF(OR(J30<=0,J30=""),"","Recompra") -> Recompra | N30: =IFERROR(IF(Tabela1[[#This Row],[Nome fantasia]]="","",_xlfn.XLOOKUP($C30,Log!D:D,Log!B:B,,,-1)),"") -> 45863 | O30: =IFERROR(_xlfn.XLOOKUP($C30,Log!D:D,Log!W:W,,,-1),"") -> FOLLOW UP | P30: =IFERROR(_xlfn.XLOOKUP($C30,Log!D:D,Log!Y:Y,,,-1),"") -> MENSAGEM | R30: =IFERROR(IF(Tabela1[[#This Row],[Nome fantasia]]="","",_xlfn.XLOOKUP($C30,Log!D:D,Log!X:X,,,-1)),"") -> 45916
C31: FAZENDINHA SALU.D LTDA | D31: 45.100.604/0001-48 | E31: SC | F31: Manu Ditzel | G31: 30/07/2025 | H31: 671.86 | I31: 69 | J31: 0 | K31: ATIVO | M31: =IF(OR(J31<=0,J31=""),"","Recompra") | N31: =IFERROR(IF(Tabela1[[#This Row],[Nome fantasia]]="","",_xlfn.XLOOKUP($C31,Log!D:D,Log!B:B,,,-1)),"") -> 45918 | O31: =IFERROR(_xlfn.XLOOKUP($C31,Log!D:D,Log!W:W,,,-1),"") -> EM ATENDIMENTO | P31: =IFERROR(_xlfn.XLOOKUP($C31,Log!D:D,Log!Y:Y,,,-1),"") -> AINDA TEM ESTOQUE | R31: =IFERROR(IF(Tabela1[[#This Row],[Nome fantasia]]="","",_xlfn.XLOOKUP($C31,Log!D:D,Log!X:X,,,-1)),"") -> 45922
C32: RIKATI PRODUTOS NATURAIS | D32: 59.876.252/0001-21 | E32: SC | F32: Manu Ditzel | G32: 25/07/2025 | H32: 1253.13 | I32: 74 | J32: 0 | K32: ATIVO | M32: =IF(OR(J32<=0,J32=""),"","Recompra") | N32: =IFERROR(IF(Tabela1[[#This Row],[Nome fantasia]]="","",_xlfn.XLOOKUP($C32,Log!D:D,Log!B:B,,,-1)),"") -> 45994 | O32: =IFERROR(_xlfn.XLOOKUP($C32,Log!D:D,Log!W:W,,,-1),"") -> EM ATENDIMENTO | P32: =IFERROR(_xlfn.XLOOKUP($C32,Log!D:D,Log!Y:Y,,,-1),"") -> MENSAGEM PARA NOVO RELACIOMENTO | R32: =IFERROR(IF(Tabela1[[#This Row],[Nome fantasia]]="","",_xlfn.XLOOKUP($C32,Log!D:D,Log!X:X,,,-1)),"") -> 45996
C33: KF - COMPRAS ANDRE | D33: * | E33: PR | F33: Manu Ditzel | G33: * | H33: * | I33: * | J33: * | K33: LEAD | M33: =IF(OR(J33<=0,J33=""),"","Recompra") -> Recompra | N33: =IFERROR(IF(Tabela1[[#This Row],[Nome fantasia]]="","",_xlfn.XLOOKUP($C33,Log!D:D,Log!B:B,,,-1)),"") -> 45918 | O33: =IFERROR(_xlfn.XLOOKUP($C33,Log!D:D,Log!W:W,,,-1),"") -> FOLLOW UP 7 | P33: =IFERROR(_xlfn.XLOOKUP($C33,Log!D:D,Log!Y:Y,,,-1),"") -> NÃO TIVE MAIS RETORNO | R33: =IFERROR(IF(Tabela1[[#This Row],[Nome fantasia]]="","",_xlfn.XLOOKUP($C33,Log!D:D,Log!X:X,,,-1)),"") -> 45922
C34: MACHADAO ATACADISTA | D34: 03.790.904/0004-07 | E34: MT | F34: Helder Brunkow | G34: 14/07/2025 | H34: 1452.42 | I34: 85 | J34: 53 | K34: ATIVO | M34: =IF(OR(J34<=0,J34=""),"","Recompra") -> Recompra | N34: =IFERROR(IF(Tabela1[[#This Row],[Nome fantasia]]="","",_xlfn.XLOOKUP($C34,Log!D:D,Log!B:B,,,-1)),"") -> 45852 | O34: =IFERROR(_xlfn.XLOOKUP($C34,Log!D:D,Log!W:W,,,-1),"") -> VENDA | P34: =IFERROR(_xlfn.XLOOKUP($C34,Log!D:D,Log!Y:Y,,,-1),"") -> RECOMPRA | R34: =IFERROR(IF(Tabela1[[#This Row],[Nome fantasia]]="","",_xlfn.XLOOKUP($C34,Log!D:D,Log!X:X,,,-1)),"") -> 45923
C35: MACHADAO ATACADISTA | D35: 03.790.904/0005-80 | E35: MT | F35: Helder Brunkow | G35: 14/07/2025 | H35: 4460.93 | I35: 85 | J35: 53 | K35: ATIVO | M35: =IF(OR(J35<=0,J35=""),"","Recompra") -> Recompra | N35: =IFERROR(IF(Tabela1[[#This Row],[Nome fantasia]]="","",_xlfn.XLOOKUP($C35,Log!D:D,Log!B:B,,,-1)),"") -> 45852 | O35: =IFERROR(_xlfn.XLOOKUP($C35,Log!D:D,Log!W:W,,,-1),"") -> VENDA | P35: =IFERROR(_xlfn.XLOOKUP($C35,Log!D:D,Log!Y:Y,,,-1),"") -> RECOMPRA | R35: =IFERROR(IF(Tabela1[[#This Row],[Nome fantasia]]="","",_xlfn.XLOOKUP($C35,Log!D:D,Log!X:X,,,-1)),"") -> 45923
C36: MACHADAO ATACADISTA | D36: 13.338.712/0002-48 | E36: MT | F36: Helder Brunkow | G36: 14/07/2025 | H36: 1453.67 | I36: 85 | J36: 53 | K36: ATIVO | M36: =IF(OR(J36<=0,J36=""),"","Recompra") -> Recompra | N36: =IFERROR(IF(Tabela1[[#This Row],[Nome fantasia]]="","",_xlfn.XLOOKUP($C36,Log!D:D,Log!B:B,,,-1)),"") -> 45852 | O36: =IFERROR(_xlfn.XLOOKUP($C36,Log!D:D,Log!W:W,,,-1),"") -> VENDA | P36: =IFERROR(_xlfn.XLOOKUP($C36,Log!D:D,Log!Y:Y,,,-1),"") -> RECOMPRA | R36: =IFERROR(IF(Tabela1[[#This Row],[Nome fantasia]]="","",_xlfn.XLOOKUP($C36,Log!D:D,Log!X:X,,,-1)),"") -> 45923
C37: MACHADAO ATACADISTA | D37: 13.338.712/0004-00 | E37: MT | F37: Helder Brunkow | G37: 14/07/2025 | H37: 1392.8 | I37: 85 | J37: 53 | K37: ATIVO | M37: =IF(OR(J37<=0,J37=""),"","Recompra") -> Recompra | N37: =IFERROR(IF(Tabela1[[#This Row],[Nome fantasia]]="","",_xlfn.XLOOKUP($C37,Log!D:D,Log!B:B,,,-1)),"") -> 45852 | O37: =IFERROR(_xlfn.XLOOKUP($C37,Log!D:D,Log!W:W,,,-1),"") -> VENDA | P37: =IFERROR(_xlfn.XLOOKUP($C37,Log!D:D,Log!Y:Y,,,-1),"") -> RECOMPRA | R37: =IFERROR(IF(Tabela1[[#This Row],[Nome fantasia]]="","",_xlfn.XLOOKUP($C37,Log!D:D,Log!X:X,,,-1)),"") -> 45923
C38: NATURE PRODUTOS NATURAIS | D38: 46.814.160/0001-75 | E38: PA | F38: Helder Brunkow | G38: 11/07/2025 | H38: 7216.91 | I38: 88 | J38: 102 | K38: INATIVO RECENTE | M38: =IF(OR(J38<=0,J38=""),"","Recompra") -> Recompra | N38: =IFERROR(IF(Tabela1[[#This Row],[Nome fantasia]]="","",_xlfn.XLOOKUP($C38,Log!D:D,Log!B:B,,,-1)),"") -> 45849 | O38: =IFERROR(_xlfn.XLOOKUP($C38,Log!D:D,Log!W:W,,,-1),"") -> EM ATENDIMENTO | P38: =IFERROR(_xlfn.XLOOKUP($C38,Log!D:D,Log!Y:Y,,,-1),"") -> 0 | R38: =IFERROR(IF(Tabela1[[#This Row],[Nome fantasia]]="","",_xlfn.XLOOKUP($C38,Log!D:D,Log!X:X,,,-1)),"") -> 45853
C39: SUPERMERCADO SERVE BEM | D39: 02.672.868/0001-63 | E39: MG | F39: Helder Brunkow | G39: 18/09/2025 | H39: 1542.37 | I39: 19 | J39: 80 | K39: INATIVO RECENTE | M39: =IF(OR(J39<=0,J39=""),"","Recompra") -> Recompra | N39: =IFERROR(IF(Tabela1[[#This Row],[Nome fantasia]]="","",_xlfn.XLOOKUP($C39,Log!D:D,Log!B:B,,,-1)),"") -> 45838 | O39: =IFERROR(_xlfn.XLOOKUP($C39,Log!D:D,Log!W:W,,,-1),"") -> SUPORTE | P39: =IFERROR(_xlfn.XLOOKUP($C39,Log!D:D,Log!Y:Y,,,-1),"") -> ESTOQUE | R39: =IFERROR(IF(Tabela1[[#This Row],[Nome fantasia]]="","",_xlfn.XLOOKUP($C39,Log!D:D,Log!X:X,,,-1)),"") -> 45919
C40: GRANO DI FELICITÁ | D40: 50.853.004/0001-90 | E40: PR | F40: Manu Ditzel | G40: * | H40: * | I40: * | J40: * | K40: LEAD | M40: =IF(OR(J40<=0,J40=""),"","Recompra") -> Recompra | N40: =IFERROR(IF(Tabela1[[#This Row],[Nome fantasia]]="","",_xlfn.XLOOKUP($C40,Log!D:D,Log!B:B,,,-1)),"") -> 45915 | O40: =IFERROR(_xlfn.XLOOKUP($C40,Log!D:D,Log!W:W,,,-1),"") -> FOLLOW UP 7 | P40: =IFERROR(_xlfn.XLOOKUP($C40,Log!D:D,Log!Y:Y,,,-1),"") -> LIGAÇÃO | R40: =IFERROR(IF(Tabela1[[#This Row],[Nome fantasia]]="","",_xlfn.XLOOKUP($C40,Log!D:D,Log!X:X,,,-1)),"") -> 45924
C41: KLOSTERMANN SUPLEMENTOS | D41: 56.157.640/0001-64 | E41: SC | F41: Central - Daiane | G41: 24/06/2025 | H41: 2350.33 | I41: 105 | J41: 0 | K41: INATIVO RECENTE | M41: =IF(OR(J41<=0,J41=""),"","Recompra") | N41: =IFERROR(IF(Tabela1[[#This Row],[Nome fantasia]]="","",_xlfn.XLOOKUP($C41,Log!D:D,Log!B:B,,,-1)),"") -> 45832 | O41: =IFERROR(_xlfn.XLOOKUP($C41,Log!D:D,Log!W:W,,,-1),"") -> VENDA | P41: =IFERROR(_xlfn.XLOOKUP($C41,Log!D:D,Log!Y:Y,,,-1),"") -> Cliente precisa com urgencia do pedido, pois sumiu o pedido dele do sistema | R41: =IFERROR(IF(Tabela1[[#This Row],[Nome fantasia]]="","",_xlfn.XLOOKUP($C41,Log!D:D,Log!X:X,,,-1)),"") -> 0
...

Sheet Log
B2: DATA | D2: NOME FANTASIA | E2: CNPJ/CPF | F2: UF | G2: VENDEDOR DO ULTIMO PEDIDO | H2: DATA DE ULTIMO | I2: VALOR DE PEDIDO | J2: DIAS SEM COMPRAR | K2: CICLO MÉDIO DE COMPRA | L2: SITUAÇÃO | M2: Coluna1 | N2: STATUS | O2: ULTIMO CONTATO | P2: RESULTADO ATUAL | Q2: AÇÃO | R2: WHATSAPP | S2: LIGAÇÃO | T2: LIGAÇÃO ATENDIDA | U2: TIPO AÇÃO | V2: TIPO DO CONTATO | W2: RESULTADO | X2: FOLLOW-UP | Y2: AÇÃO | Z2: MERCOS ATUALIZADO | AA2: EXACTSALES ATUALIZADO | AB2: NOTA DO DIA / AÇÃO
B3: 45910 | D3: ALICE NO PAIS DOS GRAOS COMERCIO DE ALIMENTOS | E3: 41.626.544/0001-40 | F3: RS | G3: Larissa Padilha | H3: 10/09/2025 | I3: 2088.7 | J3: 1 | K3: 17.5 | L3: ATIVO | R3: SIM | S3: SIM | T3: NÃO | U3: ATIVO | V3: ATENDIMENTO CLIENTES ATIVOS | W3: VENDA | X3: =IFERROR(IF(W3="","",WORKDAY.INTL(B3,_xlfn.XLOOKUP(W3,Regras!$F$2:$F$11,Regras!$G$2:$G$11))),"") -> 45973 | Y3: RECOMPRA | Z3: SIM
B4: 45905 | D4: INTENSE CACAU | E4: 12.886.112/0001-70 | F4: PR | G4: Manu Ditzel | H4: 05/09/2025 | I4: 795.71 | J4: 6 | K4: 134 | L4: ATIVO | R4: SIM | S4: SIM | T4: SIM | U4: ATIVO | V4: ATENDIMENTO CLIENTES INATIVOS | W4: VENDA | X4: =IFERROR(IF(W4="","",WORKDAY.INTL(B4,_xlfn.XLOOKUP(W4,Regras!$F$2:$F$11,Regras!$G$2:$G$11))),"") -> 45968 | Y4: RECOMPRA | Z4: SIM
B5: 45905 | D5: ITALO ZILMER BEDERODE LTDA | E5: 53.754.257/0001-03 | F5: RS | G5: Manu Ditzel | H5: 05/09/2025 | I5: 1560.86 | J5: 6 | K5: * | L5: ATIVO | R5: SIM | S5: SIM | T5: SIM | U5: ATIVO | V5: PROSPECÇÃO NOVOS CLIENTES | W5: VENDA | X5: =IFERROR(IF(W5="","",WORKDAY.INTL(B5,_xlfn.XLOOKUP(W5,Regras!$F$2:$F$11,Regras!$G$2:$G$11))),"") -> 45968 | Y5: RECOMPRA | Z5: SIM
B6: 45905 | D6: SOLAR PORTO DE GALINHAS | E6: 08.895.369/0001-11 | F6: PE | G6: Manu Ditzel | H6: 05/09/2025 | I6: 5970 | J6: 6 | K6: 33.5 | L6: ATIVO | R6: SIM | S6: SIM | T6: NÃO | U6: ATIVO | V6: ATENDIMENTO CLIENTES ATIVOS | W6: VENDA | X6: =IFERROR(IF(W6="","",WORKDAY.INTL(B6,_xlfn.XLOOKUP(W6,Regras!$F$2:$F$11,Regras!$G$2:$G$11))),"") -> 45968 | Y6: RECOMPRA | Z6: SIM
B7: 45904 | D7: 50.342.650 PRISCILA LILIANE ROSSETO | E7: 50.342.650/0001-93 | F7: SP | G7: Manu Ditzel | H7: 04/09/2025 | I7: 769.47 | J7: 7 | K7: 30 | L7: ATIVO | R7: SIM | S7: SIM | T7: SIM | U7: ATIVO | V7: ATENDIMENTO CLIENTES ATIVOS | W7: VENDA | X7: =IFERROR(IF(W7="","",WORKDAY.INTL(B7,_xlfn.XLOOKUP(W7,Regras!$F$2:$F$11,Regras!$G$2:$G$11))),"") -> 45967 | Y7: RECOMPRA | Z7: SIM
B8: 45904 | D8: A CEREALISSIMA | E8: 15.265.760/0001-06 | F8: GO | G8: Central - Daiane | H8: 04/09/2025 | I8: 5983.46 | J8: 7 | K8: 20 | L8: ATIVO | R8: SIM | S8: SIM | T8: SIM | U8: ATIVO | V8: ATENDIMENTO CLIENTES ATIVOS | W8: VENDA | X8: =IFERROR(IF(W8="","",WORKDAY.INTL(B8,_xlfn.XLOOKUP(W8,Regras!$F$2:$F$11,Regras!$G$2:$G$11))),"") -> 45967 | Y8: RECOMPRA | Z8: SIM
B9: 45904 | D9: ARMAZÉM ESTIVA | E9: 38.614.942/0001-32 | F9: RJ | G9: Manu Ditzel | H9: 04/09/2025 | I9: 2873.11 | J9: 7 | K9: 90 | L9: ATIVO | R9: SIM | S9: SIM | T9: SIM | U9: ATIVO | V9: ATENDIMENTO CLIENTES ATIVOS | W9: VENDA | X9: =IFERROR(IF(W9="","",WORKDAY.INTL(B9,_xlfn.XLOOKUP(W9,Regras!$F$2:$F$11,Regras!$G$2:$G$11))),"") -> 45967 | Y9: RECOMPRA | Z9: SIM
B10: 45904 | D10: BIO MUNDO GURUPI | E10: 55.861.609/0001-47 | F10: TO | G10: Central - Daiane | H10: 04/09/2025 | I10: 675.96 | J10: 7 | K10: * | L10: ATIVO | R10: SIM | S10: SIM | T10: SIM | U10: ATIVO | V10: PROSPECÇÃO NOVOS CLIENTES | W10: VENDA | X10: =IFERROR(IF(W10="","",WORKDAY.INTL(B10,_xlfn.XLOOKUP(W10,Regras!$F$2:$F$11,Regras!$G$2:$G$11))),"") -> 45967 | Y10: RECOMPRA | Z10: SIM
B11: 45904 | D11: LAURA ISABEL RICARDO OCHOA | E11: 52.655.585/0001-81 | F11: BA | G11: Larissa Padilha | H11: 04/09/2025 | I11: 704.66 | J11: 7 | K11: * | L11: ATIVO | R11: SIM | S11: SIM | T11: NÃO | U11: ATIVO | V11: PROSPECÇÃO NOVOS CLIENTES | W11: VENDA | X11: =IFERROR(IF(W11="","",WORKDAY.INTL(B11,_xlfn.XLOOKUP(W11,Regras!$F$2:$F$11,Regras!$G$2:$G$11))),"") -> 45967 | Y11: RECOMPRA | Z11: SIM
B12: 45904 | D12: MINHA QUITANDINHA - AGUA VERDE - BLUMENAU | E12: 54.729.143/0001-68 | F12: SC | G12: Central - Daiane | H12: 04/09/2025 | I12: 775.04 | J12: 7 | K12: * | L12: ATIVO | R12: SIM | S12: SIM | T12: NÃO | U12: ATIVO | V12: PROSPECÇÃO NOVOS CLIENTES | W12: VENDA | X12: =IFERROR(IF(W12="","",WORKDAY.INTL(B12,_xlfn.XLOOKUP(W12,Regras!$F$2:$F$11,Regras!$G$2:$G$11))),"") -> 45967 | Y12: RECOMPRA | Z12: SIM
B13: 45904 | D13: PUDIMZERA | E13: 22.180.402/0001-58 | F13: SP | G13: Manu Ditzel | H13: 04/09/2025 | I13: 397.4 | J13: 7 | K13: 10.5 | L13: ATIVO | R13: SIM | S13: SIM | T13: NÃO | U13: ATIVO | V13: ATENDIMENTO CLIENTES ATIVOS | W13: VENDA | X13: =IFERROR(IF(W13="","",WORKDAY.INTL(B13,_xlfn.XLOOKUP(W13,Regras!$F$2:$F$11,Regras!$G$2:$G$11))),"") -> 45967 | Y13: RECOMPRA | Z13: SIM
B14: 45903 | D14: NATU & FIT | E14: 28.088.475/0001-09 | F14: ES | G14: Helder Brunkow | H14: 03/09/2025 | I14: 1572.57 | J14: 8 | K14: 53.5 | L14: ATIVO | R14: SIM | S14: SIM | T14: NÃO | U14: RECEPTIVO | V14: ATENDIMENTO CLIENTES ATIVOS | W14: VENDA | X14: =IFERROR(IF(W14="","",WORKDAY.INTL(B14,_xlfn.XLOOKUP(W14,Regras!$F$2:$F$11,Regras!$G$2:$G$11))),"") -> 45966 | Y14: RECOMPRA | Z14: SIM
B15: 45903 | D15: REDE NOVO TEMPO DE COMUNICACAO | E15: 01.385.423/0001-30 | F15: SP | G15: Manu Ditzel | H15: 03/09/2025 | I15: 1873.36 | J15: 8 | K15: 22 | L15: ATIVO | R15: SIM | S15: SIM | T15: NÃO | U15: ATIVO | V15: ATENDIMENTO CLIENTES ATIVOS | W15: VENDA | X15: =IFERROR(IF(W15="","",WORKDAY.INTL(B15,_xlfn.XLOOKUP(W15,Regras!$F$2:$F$11,Regras!$G$2:$G$11))),"") -> 45966 | Y15: RECOMPRA | Z15: SIM
B16: 45902 | D16: EMPORIO TRIBO VERDE | E16: 48.391.847/0001-70 | F16: GO | G16: Manu Ditzel | H16: 02/09/2025 | I16: 2021.53 | J16: 9 | K16: * | L16: ATIVO | R16: SIM | S16: SIM | T16: SIM | U16: ATIVO | V16: PROSPECÇÃO NOVOS CLIENTES | W16: VENDA | X16: =IFERROR(IF(W16="","",WORKDAY.INTL(B16,_xlfn.XLOOKUP(W16,Regras!$F$2:$F$11,Regras!$G$2:$G$11))),"") -> 45965 | Y16: RECOMPRA | Z16: SIM
B17: 45902 | D17: HERTZ NUTRITION | E17: 17.039.758/0001-36 | F17: RS | G17: Manu Ditzel | H17: 02/09/2025 | I17: 1387.75 | J17: 9 | K17: * | L17: ATIVO | R17: SIM | S17: SIM | T17: NÃO | U17: ATIVO | V17: PROSPECÇÃO NOVOS CLIENTES | W17: VENDA | X17: =IFERROR(IF(W17="","",WORKDAY.INTL(B17,_xlfn.XLOOKUP(W17,Regras!$F$2:$F$11,Regras!$G$2:$G$11))),"") -> 45965 | Y17: RECOMPRA | Z17: SIM
B18: 45902 | D18: KUWADA COMPANIA LTDA | E18: 18.997.672/0001-89 | F18: MT | G18: Manu Ditzel | H18: 02/09/2025 | I18: 1216.68 | J18: 9 | K18: 61 | L18: ATIVO | R18: SIM | S18: SIM | T18: SIM | U18: ATIVO | V18: ATENDIMENTO CLIENTES ATIVOS | W18: VENDA | X18: =IFERROR(IF(W18="","",WORKDAY.INTL(B18,_xlfn.XLOOKUP(W18,Regras!$F$2:$F$11,Regras!$G$2:$G$11))),"") -> 45965 | Y18: RECOMPRA | Z18: SIM
B19: 45901 | D19: PROSAUDE - NOVO PROGRESSO | E19: 22.081.589/0001-32 | F19: PA | G19: Larissa Padilha | H19: 01/09/2025 | I19: 858.48 | J19: 10 | K19: 153 | L19: ATIVO | R19: SIM | S19: SIM | T19: SIM | U19: ATIVO | V19: ATENDIMENTO CLIENTES INATIVOS | W19: VENDA | X19: =IFERROR(IF(W19="","",WORKDAY.INTL(B19,_xlfn.XLOOKUP(W19,Regras!$F$2:$F$11,Regras!$G$2:$G$11))),"") -> 45964 | Y19: RECOMPRA | Z19: SIM
B20: 45898 | D20: KLOSTERMANN NUTRICAO | E20: 58.072.623/0001-50 | F20: SC | G20: Larissa Padilha | H20: 29/08/2025 | I20: 906.11 | J20: 13 | K20: 56.5 | L20: ATIVO | R20: SIM | S20: SIM | T20: SIM | U20: ATIVO | V20: ATENDIMENTO CLIENTES INATIVOS | W20: VENDA | X20: =IFERROR(IF(W20="","",WORKDAY.INTL(B20,_xlfn.XLOOKUP(W20,Regras!$F$2:$F$11,Regras!$G$2:$G$11))),"") -> 45961 | Y20: RECOMPRA | Z20: SIM
B21: 45898 | D21: MERCADO FERREIRA | E21: 14.419.497/0001-91 | F21: SC | G21: Manu Ditzel | H21: 29/08/2025 | I21: 1267.11 | J21: 13 | K21: 58 | L21: ATIVO | R21: SIM | S21: SIM | T21: SIM | U21: ATIVO | V21: ATENDIMENTO CLIENTES INATIVOS | W21: VENDA | X21: =IFERROR(IF(W21="","",WORKDAY.INTL(B21,_xlfn.XLOOKUP(W21,Regras!$F$2:$F$11,Regras!$G$2:$G$11))),"") -> 45961 | Y21: RECOMPRA | Z21: SIM
B22: 45898 | D22: TEMPEROS & MEL | E22: 22.105.950/0001-13 | F22: DF | G22: Manu Ditzel | H22: 29/08/2025 | I22: 1715.21 | J22: 13 | K22: 88 | L22: ATIVO | R22: SIM | S22: SIM | T22: SIM | U22: ATIVO | V22: ATENDIMENTO CLIENTES ATIVOS | W22: VENDA | X22: =IFERROR(IF(W22="","",WORKDAY.INTL(B22,_xlfn.XLOOKUP(W22,Regras!$F$2:$F$11,Regras!$G$2:$G$11))),"") -> 45961 | Y22: RECOMPRA | Z22: SIM
B23: 45898 | D23: VIDA LEVE - CHAPADAO | E23: 61.327.765/0001-25 | F23: GO | G23: Manu Ditzel | H23: 29/08/2025 | I23: 3767.53 | J23: 13 | K23: * | L23: ATIVO | R23: SIM | S23: SIM | T23: NÃO | U23: ATIVO | V23: PROSPECÇÃO NOVOS CLIENTES | W23: VENDA | X23: =IFERROR(IF(W23="","",WORKDAY.INTL(B23,_xlfn.XLOOKUP(W23,Regras!$F$2:$F$11,Regras!$G$2:$G$11))),"") -> 45961 | Y23: RECOMPRA | Z23: SIM
B24: 45898 | D24: VIDA LEVE CANOAS | E24: 60.821.190/0001-30 | F24: RS | G24: Manu Ditzel | H24: 29/08/2025 | I24: 2969.26 | J24: 13 | K24: * | L24: ATIVO | R24: SIM | S24: SIM | T24: NÃO | U24: ATIVO | V24: PROSPECÇÃO NOVOS CLIENTES | W24: VENDA | X24: =IFERROR(IF(W24="","",WORKDAY.INTL(B24,_xlfn.XLOOKUP(W24,Regras!$F$2:$F$11,Regras!$G$2:$G$11))),"") -> 45961 | Y24: RECOMPRA | Z24: SIM
B25: 45897 | D25: DESTAQUE SHAPE | E25: 59.794.577/0001-65 | F25: SC | G25: Larissa Padilha | H25: 28/08/2025 | I25: 876.13 | J25: 14 | K25: 63 | L25: ATIVO | R25: SIM | S25: SIM | T25: NÃO | U25: ATIVO | V25: ATENDIMENTO CLIENTES INATIVOS | W25: VENDA | X25: =IFERROR(IF(W25="","",WORKDAY.INTL(B25,_xlfn.XLOOKUP(W25,Regras!$F$2:$F$11,Regras!$G$2:$G$11))),"") -> 45960 | Y25: RECOMPRA | Z25: SIM
B26: 45897 | D26: EMPORIO GAMBOA - ESPECIARIAS E PRODUTOS NATURAIS | E26: 23.143.632/0001-00 | F26: PE | G26: Larissa Padilha | H26: 28/08/2025 | I26: 1570.64 | J26: 14 | K26: * | L26: ATIVO | R26: SIM | S26: SIM | T26: NÃO | U26: RECEPTIVO | V26: PROSPECÇÃO NOVOS CLIENTES | W26: VENDA | X26: =IFERROR(IF(W26="","",WORKDAY.INTL(B26,_xlfn.XLOOKUP(W26,Regras!$F$2:$F$11,Regras!$G$2:$G$11))),"") -> 45960 | Y26: RECOMPRA | Z26: SIM
B27: 45897 | D27: NATURALIS PRODUTOS NATURAIS | E27: 31.545.180/0001-10 | F27: SC | G27: Manu Ditzel | H27: 28/08/2025 | I27: 5094 | J27: 14 | K27: 62.5 | L27: ATIVO | R27: SIM | S27: SIM | T27: NÃO | U27: ATIVO | V27: ATENDIMENTO CLIENTES INATIVOS | W27: VENDA | X27: =IFERROR(IF(W27="","",WORKDAY.INTL(B27,_xlfn.XLOOKUP(W27,Regras!$F$2:$F$11,Regras!$G$2:$G$11))),"") -> 45960 | Y27: RECOMPRA | Z27: SIM
B28: 45897 | D28: NATUREZA EM KILO | E28: 00.211.115/0002-06 | F28: PR | G28: Manu Ditzel | H28: 28/08/2025 | I28: 904.49 | J28: 14 | K28: * | L28: ATIVO | R28: SIM | S28: SIM | T28: SIM | U28: ATIVO | V28: PROSPECÇÃO NOVOS CLIENTES | W28: VENDA | X28: =IFERROR(IF(W28="","",WORKDAY.INTL(B28,_xlfn.XLOOKUP(W28,Regras!$F$2:$F$11,Regras!$G$2:$G$11))),"") -> 45960 | Y28: PRIMEIRO PEDIDO | Z28: SIM
B29: 45897 | D29: SHOPPING NATURAL | E29: 15.428.647/0001-96 | F29: MT | G29: Manu Ditzel | H29: 28/08/2025 | I29: 998.4 | J29: 14 | K29: 60.5 | L29: ATIVO | R29: SIM | S29: SIM | T29: NÃO | U29: ATIVO | V29: ATENDIMENTO CLIENTES INATIVOS | W29: VENDA | X29: =IFERROR(IF(W29="","",WORKDAY.INTL(B29,_xlfn.XLOOKUP(W29,Regras!$F$2:$F$11,Regras!$G$2:$G$11))),"") -> 45960 | Y29: RECOMPRA | Z29: SIM
B30: 45897 | D30: TROPICAL SUPERMERCADOS | E30: 23.014.826/0001-05 | F30: MT | G30: Manu Ditzel | H30: 28/08/2025 | I30: 8406.63 | J30: 14 | K30: 33 | L30: ATIVO | R30: SIM | S30: SIM | T30: SIM | U30: ATIVO | V30: ATENDIMENTO CLIENTES INATIVOS | W30: VENDA | X30: =IFERROR(IF(W30="","",WORKDAY.INTL(B30,_xlfn.XLOOKUP(W30,Regras!$F$2:$F$11,Regras!$G$2:$G$11))),"") -> 45960 | Y30: RECOMPRA | Z30: SIM
B31: 45897 | D31: SHOPPING NATURAL | E31: 15.428.647/0001-96 | F31: MT | G31: Manu Ditzel | H31: 28/08/2025 | I31: 998.4 | J31: 14 | K31: 60.5 | L31: ATIVO | R31: SIM | S31: NÃO | T31: NÃO | U31: ATIVO | V31: PÓS VENDA / RELACIONAMENTO | W31: FOLLOW UP | X31: 45919 | Y31: ENTREGA | Z31: SIM | AB31: QUESTIONANDO SE CHEGOU TUDO CERTO
B32: 45897 | D32: NATUREZA EM KILO | E32: 00.211.115/0002-06 | F32: PR | G32: Manu Ditzel | H32: 28/08/2025 | I32: 904.49 | J32: 14 | K32: * | L32: ATIVO | R32: SIM | S32: NÃO | T32: NÃO | U32: RECEPTIVO | V32: ATENDIMENTO CLIENTES ATIVOS | W32: VENDA | Y32: RECOMPRA | Z32: SIM | AB32: RECOMPRA/ CLIENTE DE VISITA
B33: 45896 | D33: CASA HIRATA - SUPERMERCADO | E33: 55.615.538/0002-83 | F33: SP | G33: Manu Ditzel | H33: 27/08/2025 | I33: 2571.82 | J33: 15 | K33: 91 | L33: ATIVO | R33: SIM | S33: SIM | T33: SIM | U33: RECEPTIVO | V33: ATENDIMENTO CLIENTES INATIVOS | W33: VENDA | X33: =IFERROR(IF(W33="","",WORKDAY.INTL(B33,_xlfn.XLOOKUP(W33,Regras!$F$2:$F$11,Regras!$G$2:$G$11))),"") -> 45959 | Y33: RECOMPRA | Z33: SIM
B34: 45896 | D34: CONTORNO ARMAZEM | E34: 29.466.137/0001-18 | F34: SP | G34: Manu Ditzel | H34: 27/08/2025 | I34: 901.53 | J34: 15 | K34: * | L34: ATIVO | R34: SIM | S34: SIM | T34: SIM | U34: ATIVO | V34: PROSPECÇÃO NOVOS CLIENTES | W34: VENDA | X34: =IFERROR(IF(W34="","",WORKDAY.INTL(B34,_xlfn.XLOOKUP(W34,Regras!$F$2:$F$11,Regras!$G$2:$G$11))),"") -> 45959 | Y34: RECOMPRA | Z34: SIM
B35: 45896 | D35: MINI MERCADO FAMILIA | E35: 35.743.795/0001-02 | F35: SC | G35: Manu Ditzel | H35: 27/08/2025 | I35: 2161.62 | J35: 15 | K35: * | L35: ATIVO | R35: SIM | S35: SIM | T35: NÃO | U35: RECEPTIVO | V35: PROSPECÇÃO NOVOS CLIENTES | W35: VENDA | X35: =IFERROR(IF(W35="","",WORKDAY.INTL(B35,_xlfn.XLOOKUP(W35,Regras!$F$2:$F$11,Regras!$G$2:$G$11))),"") -> 45959 | Y35: RECOMPRA | Z35: SIM
B36: 45896 | D36: NATHALIA DE JESUS SILVA COSTA LTDA | E36: 59.244.884/0001-72 | F36: SP | G36: Manu Ditzel | H36: 27/08/2025 | I36: 650.3 | J36: 15 | K36: * | L36: ATIVO | R36: SIM | S36: NÃO | T36: NÃO | U36: ATIVO | V36: PROSPECÇÃO NOVOS CLIENTES | W36: VENDA | X36: =IFERROR(IF(W36="","",WORKDAY.INTL(B36,_xlfn.XLOOKUP(W36,Regras!$F$2:$F$11,Regras!$G$2:$G$11))),"") -> 45959 | Y36: PRIMEIRA COMPRA | Z36: SIM
B37: 45896 | D37: SAFITA DOCES | E37: 43.023.380/0001-92 | F37: RJ | G37: Manu Ditzel | H37: 27/08/2025 | I37: 1490.4 | J37: 15 | K37: 72 | L37: ATIVO | R37: SIM | S37: SIM | T37: SIM | U37: RECEPTIVO | V37: ATENDIMENTO CLIENTES INATIVOS | W37: VENDA | X37: =IFERROR(IF(W37="","",WORKDAY.INTL(B37,_xlfn.XLOOKUP(W37,Regras!$F$2:$F$11,Regras!$G$2:$G$11))),"") -> 45959 | Y37: RECOMPRA | Z37: SIM
B38: 45896 | D38: SUPERMERCADO MERCOCENTRO | E38: 05.382.867/0001-72 | F38: SC | G38: Manu Ditzel | H38: 27/08/2025 | I38: 1148.79 | J38: 15 | K38: 21.5 | L38: ATIVO | R38: SIM | S38: SIM | T38: SIM | U38: RECEPTIVO | V38: ATENDIMENTO CLIENTES ATIVOS | W38: VENDA | X38: =IFERROR(IF(W38="","",WORKDAY.INTL(B38,_xlfn.XLOOKUP(W38,Regras!$F$2:$F$11,Regras!$G$2:$G$11))),"") -> 45959 | Y38: RECOMPRA | Z38: SIM
B39: 45896 | D39: WOLFI MACHINES | E39: 61.932.319/0001-40 | F39: RS | G39: Manu Ditzel | H39: 27/08/2025 | I39: 1199 | J39: 15 | K39: * | L39: ATIVO | R39: SIM | S39: SIM | T39: NÃO | U39: RECEPTIVO | V39: PROSPECÇÃO NOVOS CLIENTES | W39: VENDA | X39: =IFERROR(IF(W39="","",WORKDAY.INTL(B39,_xlfn.XLOOKUP(W39,Regras!$F$2:$F$11,Regras!$G$2:$G$11))),"") -> 45959 | Y39: RECOMPRA | Z39: SIM
B40: 45896 | D40: CASA HIRATA - SUPERMERCADO | E40: 55.615.538/0002-83 | F40: SP | G40: Manu Ditzel | H40: 27/08/2025 | I40: 2571.82 | J40: 15 | K40: 91 | L40: ATIVO | R40: SIM | S40: NÃO | T40: NÃO | U40: ATIVO | V40: PÓS VENDA / RELACIONAMENTO | W40: FOLLOW UP | X40: 45919 | Y40: RECOMPRA | Z40: SIM | AB40: VERIFICAR SE ESTA PRECISANDO DE PRODUTOS
B41: 45896 | D41: SAFITA DOCES | E41: 43.023.380/0001-92 | F41: RJ | G41: Manu Ditzel | H41: 27/08/2025 | I41: 1490.4 | J41: 15 | K41: 72 | L41: ATIVO | R41: SIM | S41: NÃO | T41: NÃO | U41: ATIVO | V41: PÓS VENDA / RELACIONAMENTO | W41: FOLLOW UP | X41: 45919 | Y41: ENTREGA | Z41: SIM | AB41: VERIFICANDO SE CHEGOU TUDO CERTO
...

Sheet Planilha1
A1: VIDA LEVE - SÃO JOSE DO RIO PRETO
A2: PADOCA DA BAXA
A3: LAKOSKI MERCEARIA SEM GLUTEN
A4: 48.097.578 SALAH UD DIN ALE CHARKIE
A5: MINI MERCADO FAMILIA
A6: EMPORIO VIDA E SAUDE
A7: FORCE SUPLEMENTOS
A8: NATURALIS PRODUTOS NATURAIS
A9: MERCADO FERREIRA
A10: ITALO ZILMER BEDERODE LTDA
A11: NATURVIDA
A12: NATURVIDA
... A14: RADISSON HOTEL CURITIBA

Sheet CARTEIRA
A1: BASE TOTAL | B1: NOVOS CLIENTES 30 DIAS | C1: CLIENTES ATIVOS | D1: CLIENTES INATIVOS RECENTE | E1: CLIENTES INATIVO ANTIGO | G1: POSITIVAÇÃO ATIVA | H1: POSITIVAÇAO PASSIVA | I1: TOTAL
B2: Puxar direto do Mercos / exact

Sheet Base Novos Clientes
C2: NOME FANTASIA | D2: CNPJ | E2: UF | F2: VENDEDOR | G2: R$ - ULTIMO PEDIDO | H2: DIAS SEM COMPRAR | I2: CICLO MÉDIO | J2: DATA ULTIMA VENDA | K2: STATUS | L2: SITUAÇÃO ATUAL | M2: ULTIMO CONTATO | N2: RESULTADO ATUAL | O2: AÇÃO | P2: Coluna1 | Q2: FOLLOW UP | R2: NÃO ATENDE | S2: RECUSOU LIGAÇÃO | T2: NÃO RESPONDE
K3: =IF(J3="","NOVO",_xlfn.XLOOKUP(TODAY()-J3,Regras!$C$3:$C$10,Regras!$D$3:$D$10,,1)) -> NOVO | L3: =IF(OR(I3<=0,I3=""),"","Recompra") | M3: =IFERROR(IF(Tabela13[[#This Row],[NOME FANTASIA]]="","",_xlfn.XLOOKUP($C3,Log!D:D,Log!B:B,,,-1)),"") | N3: =IFERROR(_xlfn.XLOOKUP($C3,Log!D:D,Log!W:W,,,-1),"") | O3: =IFERROR(_xlfn.XLOOKUP($C3,Log!D:D,Log!Y:Y,,,-1),"") -> 0 | Q3: =IFERROR(IF(Tabela13[[#This Row],[NOME FANTASIA]]="","",_xlfn.XLOOKUP($C3,Log!D:D,Log!X:X,,,-1)),"") | R3: =COUNTIFS(Log!$D:$D,'Base Novos Clientes'!$C3,Log!$W:$W,'Base Novos Clientes'!R$2) -> 0 | S3: =COUNTIFS(Log!$D:$D,'Base Novos Clientes'!$C3,Log!$W:$W,'Base Novos Clientes'!S$2) -> 0 | T3: =COUNTIFS(Log!$D:$D,'Base Novos Clientes'!$C3,Log!$W:$W,'Base Novos Clientes'!T$2) -> 0
K4: =IF(J4="","NOVO",_xlfn.XLOOKUP(TODAY()-J4,Regras!$C$3:$C$10,Regras!$D$3:$D$10,,1)) -> NOVO | L4: =IF(OR(I4<=0,I4=""),"","Recompra") | M4: =IFERROR(IF(Tabela13[[#This Row],[NOME FANTASIA]]="","",_xlfn.XLOOKUP($C4,Log!D:D,Log!B:B,,,-1)),"") | N4: =IFERROR(_xlfn.XLOOKUP($C4,Log!D:D,Log!W:W,,,-1),"") | O4: =IFERROR(_xlfn.XLOOKUP($C4,Log!D:D,Log!Y:Y,,,-1),"") -> 0 | Q4: =IFERROR(IF(Tabela13[[#This Row],[NOME FANTASIA]]="","",_xlfn.XLOOKUP($C4,Log!D:D,Log!X:X,,,-1)),"") | R4: =COUNTIFS(Log!$D:$D,'Base Novos Clientes'!$C4,Log!$W:$W,'Base Novos Clientes'!R$2) -> 0 | S4: =COUNTIFS(Log!$D:$D,'Base Novos Clientes'!$C4,Log!$W:$W,'Base Novos Clientes'!S$2) -> 0 | T4: =COUNTIFS(Log!$D:$D,'Base Novos Clientes'!$C4,Log!$W:$W,'Base Novos Clientes'!T$2) -> 0
K5: =IF(J5="","NOVO",_xlfn.XLOOKUP(TODAY()-J5,Regras!$C$3:$C$10,Regras!$D$3:$D$10,,1)) -> NOVO | L5: =IF(OR(I5<=0,I5=""),"","Recompra") | M5: =IFERROR(IF(Tabela13[[#This Row],[NOME FANTASIA]]="","",_xlfn.XLOOKUP($C5,Log!D:D,Log!B:B,,,-1)),"") | N5: =IFERROR(_xlfn.XLOOKUP($C5,Log!D:D,Log!W:W,,,-1),"") | O5: =IFERROR(_xlfn.XLOOKUP($C5,Log!D:D,Log!Y:Y,,,-1),"") -> 0 | Q5: =IFERROR(IF(Tabela13[[#This Row],[NOME FANTASIA]]="","",_xlfn.XLOOKUP($C5,Log!D:D,Log!X:X,,,-1)),"") | R5: =COUNTIFS(Log!$D:$D,'Base Novos Clientes'!$C5,Log!$W:$W,'Base Novos Clientes'!R$2) -> 0 | S5: =COUNTIFS(Log!$D:$D,'Base Novos Clientes'!$C5,Log!$W:$W,'Base Novos Clientes'!S$2) -> 0 | T5: =COUNTIFS(Log!$D:$D,'Base Novos Clientes'!$C5,Log!$W:$W,'Base Novos Clientes'!T$2) -> 0
K6: =IF(J6="","NOVO",_xlfn.XLOOKUP(TODAY()-J6,Regras!$C$3:$C$10,Regras!$D$3:$D$10,,1)) -> NOVO | L6: =IF(OR(I6<=0,I6=""),"","Recompra") | M6: =IFERROR(IF(Tabela13[[#This Row],[NOME FANTASIA]]="","",_xlfn.XLOOKUP($C6,Log!D:D,Log!B:B,,,-1)),"") | N6: =IFERROR(_xlfn.XLOOKUP($C6,Log!D:D,Log!W:W,,,-1),"") | O6: =IFERROR(_xlfn.XLOOKUP($C6,Log!D:D,Log!Y:Y,,,-1),"") -> 0 | Q6: =IFERROR(IF(Tabela13[[#This Row],[NOME FANTASIA]]="","",_xlfn.XLOOKUP($C6,Log!D:D,Log!X:X,,,-1)),"") | R6: =COUNTIFS(Log!$D:$D,'Base Novos Clientes'!$C6,Log!$W:$W,'Base Novos Clientes'!R$2) -> 0 | S6: =COUNTIFS(Log!$D:$D,'Base Novos Clientes'!$C6,Log!$W:$W,'Base Novos Clientes'!S$2) -> 0 | T6: =COUNTIFS(Log!$D:$D,'Base Novos Clientes'!$C6,Log!$W:$W,'Base Novos Clientes'!T$2) -> 0
K7: =IF(J7="","NOVO",_xlfn.XLOOKUP(TODAY()-J7,Regras!$C$3:$C$10,Regras!$D$3:$D$10,,1)) -> NOVO | L7: =IF(OR(I7<=0,I7=""),"","Recompra") | M7: =IFERROR(IF(Tabela13[[#This Row],[NOME FANTASIA]]="","",_xlfn.XLOOKUP($C7,Log!D:D,Log!B:B,,,-1)),"") | N7: =IFERROR(_xlfn.XLOOKUP($C7,Log!D:D,Log!W:W,,,-1),"") | O7: =IFERROR(_xlfn.XLOOKUP($C7,Log!D:D,Log!Y:Y,,,-1),"") -> 0 | Q7: =IFERROR(IF(Tabela13[[#This Row],[NOME FANTASIA]]="","",_xlfn.XLOOKUP($C7,Log!D:D,Log!X:X,,,-1)),"") | R7: =COUNTIFS(Log!$D:$D,'Base Novos Clientes'!$C7,Log!$W:$W,'Base Novos Clientes'!R$2) -> 0 | S7: =COUNTIFS(Log!$D:$D,'Base Novos Clientes'!$C7,Log!$W:$W,'Base Novos Clientes'!S$2) -> 0 | T7: =COUNTIFS(Log!$D:$D,'Base Novos Clientes'!$C7,Log!$W:$W,'Base Novos Clientes'!T$2) -> 0
K8: =IF(J8="","NOVO",_xlfn.XLOOKUP(TODAY()-J8,Regras!$C$3:$C$10,Regras!$D$3:$D$10,,1)) -> NOVO | L8: =IF(OR(I8<=0,I8=""),"","Recompra") | M8: =IFERROR(IF(Tabela13[[#This Row],[NOME FANTASIA]]="","",_xlfn.XLOOKUP($C8,Log!D:D,Log!B:B,,,-1)),"") | N8: =IFERROR(_xlfn.XLOOKUP($C8,Log!D:D,Log!W:W,,,-1),"") | O8: =IFERROR(_xlfn.XLOOKUP($C8,Log!D:D,Log!Y:Y,,,-1),"") -> 0 | Q8: =IFERROR(IF(Tabela13[[#This Row],[NOME FANTASIA]]="","",_xlfn.XLOOKUP($C8,Log!D:D,Log!X:X,,,-1)),"") | R8: =COUNTIFS(Log!$D:$D,'Base Novos Clientes'!$C8,Log!$W:$W,'Base Novos Clientes'!R$2) -> 0 | S8: =COUNTIFS(Log!$D:$D,'Base Novos Clientes'!$C8,Log!$W:$W,'Base Novos Clientes'!S$2) -> 0 | T8: =COUNTIFS(Log!$D:$D,'Base Novos Clientes'!$C8,Log!$W:$W,'Base Novos Clientes'!T$2) -> 0
K9: =IF(J9="","NOVO",_xlfn.XLOOKUP(TODAY()-J9,Regras!$C$3:$C$10,Regras!$D$3:$D$10,,1)) -> NOVO | L9: =IF(OR(I9<=0,I9=""),"","Recompra") | M9: =IFERROR(IF(Tabela13[[#This Row],[NOME FANTASIA]]="","",_xlfn.XLOOKUP($C9,Log!D:D,Log!B:B,,,-1)),"") | N9: =IFERROR(_xlfn.XLOOKUP($C9,Log!D:D,Log!W:W,,,-1),"") | O9: =IFERROR(_xlfn.XLOOKUP($C9,Log!D:D,Log!Y:Y,,,-1),"") -> 0 | Q9: =IFERROR(IF(Tabela13[[#This Row],[NOME FANTASIA]]="","",_xlfn.XLOOKUP($C9,Log!D:D,Log!X:X,,,-1)),"") | R9: =COUNTIFS(Log!$D:$D,'Base Novos Clientes'!$C9,Log!$W:$W,'Base Novos Clientes'!R$2) -> 0 | S9: =COUNTIFS(Log!$D:$D,'Base Novos Clientes'!$C9,Log!$W:$W,'Base Novos Clientes'!S$2) -> 0 | T9: =COUNTIFS(Log!$D:$D,'Base Novos Clientes'!$C9,Log!$W:$W,'Base Novos Clientes'!T$2) -> 0
K10: =IF(J10="","NOVO",_xlfn.XLOOKUP(TODAY()-J10,Regras!$C$3:$C$10,Regras!$D$3:$D$10,,1)) -> NOVO | L10: =IF(OR(I10<=0,I10=""),"","Recompra") | M10: =IFERROR(IF(Tabela13[[#This Row],[NOME FANTASIA]]="","",_xlfn.XLOOKUP($C10,Log!D:D,Log!B:B,,,-1)),"") | N10: =IFERROR(_xlfn.XLOOKUP($C10,Log!D:D,Log!W:W,,,-1),"") | O10: =IFERROR(_xlfn.XLOOKUP($C10,Log!D:D,Log!Y:Y,,,-1),"") -> 0 | Q10: =IFERROR(IF(Tabela13[[#This Row],[NOME FANTASIA]]="","",_xlfn.XLOOKUP($C10,Log!D:D,Log!X:X,,,-1)),"") | R10: =COUNTIFS(Log!$D:$D,'Base Novos Clientes'!$C10,Log!$W:$W,'Base Novos Clientes'!R$2) -> 0 | S10: =COUNTIFS(Log!$D:$D,'Base Novos Clientes'!$C10,Log!$W:$W,'Base Novos Clientes'!S$2) -> 0 | T10: =COUNTIFS(Log!$D:$D,'Base Novos Clientes'!$C10,Log!$W:$W,'Base Novos Clientes'!T$2) -> 0
K11: =IF(J11="","NOVO",_xlfn.XLOOKUP(TODAY()-J11,Regras!$C$3:$C$10,Regras!$D$3:$D$10,,1)) -> NOVO | L11: =IF(OR(I11<=0,I11=""),"","Recompra") | M11: =IFERROR(IF(Tabela13[[#This Row],[NOME FANTASIA]]="","",_xlfn.XLOOKUP($C11,Log!D:D,Log!B:B,,,-1)),"") | N11: =IFERROR(_xlfn.XLOOKUP($C11,Log!D:D,Log!W:W,,,-1),"") | O11: =IFERROR(_xlfn.XLOOKUP($C11,Log!D:D,Log!Y:Y,,,-1),"") -> 0 | Q11: =IFERROR(IF(Tabela13[[#This Row],[NOME FANTASIA]]="","",_xlfn.XLOOKUP($C11,Log!D:D,Log!X:X,,,-1)),"") | R11: =COUNTIFS(Log!$D:$D,'Base Novos Clientes'!$C11,Log!$W:$W,'Base Novos Clientes'!R$2) -> 0 | S11: =COUNTIFS(Log!$D:$D,'Base Novos Clientes'!$C11,Log!$W:$W,'Base Novos Clientes'!S$2) -> 0 | T11: =COUNTIFS(Log!$D:$D,'Base Novos Clientes'!$C11,Log!$W:$W,'Base Novos Clientes'!T$2) -> 0
K12: =IF(J12="","NOVO",_xlfn.XLOOKUP(TODAY()-J12,Regras!$C$3:$C$10,Regras!$D$3:$D$10,,1)) -> NOVO | L12: =IF(OR(I12<=0,I12=""),"","Recompra") | M12: =IFERROR(IF(Tabela13[[#This Row],[NOME FANTASIA]]="","",_xlfn.XLOOKUP($C12,Log!D:D,Log!B:B,,,-1)),"") | N12: =IFERROR(_xlfn.XLOOKUP($C12,Log!D:D,Log!W:W,,,-1),"") | O12: =IFERROR(_xlfn.XLOOKUP($C12,Log!D:D,Log!Y:Y,,,-1),"") -> 0 | Q12: =IFERROR(IF(Tabela13[[#This Row],[NOME FANTASIA]]="","",_xlfn.XLOOKUP($C12,Log!D:D,Log!X:X,,,-1)),"") | R12: =COUNTIFS(Log!$D:$D,'Base Novos Clientes'!$C12,Log!$W:$W,'Base Novos Clientes'!R$2) -> 0 | S12: =COUNTIFS(Log!$D:$D,'Base Novos Clientes'!$C12,Log!$W:$W,'Base Novos Clientes'!S$2) -> 0 | T12: =COUNTIFS(Log!$D:$D,'Base Novos Clientes'!$C12,Log!$W:$W,'Base Novos Clientes'!T$2) -> 0
K13: =IF(J13="","NOVO",_xlfn.XLOOKUP(TODAY()-J13,Regras!$C$3:$C$10,Regras!$D$3:$D$10,,1)) -> NOVO | L13: =IF(OR(I13<=0,I13=""),"","Recompra") | M13: =IFERROR(IF(Tabela13[[#This Row],[NOME FANTASIA]]="","",_xlfn.XLOOKUP($C13,Log!D:D,Log!B:B,,,-1)),"") | N13: =IFERROR(_xlfn.XLOOKUP($C13,Log!D:D,Log!W:W,,,-1),"") | O13: =IFERROR(_xlfn.XLOOKUP($C13,Log!D:D,Log!Y:Y,,,-1),"") -> 0 | Q13: =IFERROR(IF(Tabela13[[#This Row],[NOME FANTASIA]]="","",_xlfn.XLOOKUP($C13,Log!D:D,Log!X:X,,,-1)),"") | R13: =COUNTIFS(Log!$D:$D,'Base Novos Clientes'!$C13,Log!$W:$W,'Base Novos Clientes'!R$2) -> 0 | S13: =COUNTIFS(Log!$D:$D,'Base Novos Clientes'!$C13,Log!$W:$W,'Base Novos Clientes'!S$2) -> 0 | T13: =COUNTIFS(Log!$D:$D,'Base Novos Clientes'!$C13,Log!$W:$W,'Base Novos Clientes'!T$2) -> 0
K14: =IF(J14="","NOVO",_xlfn.XLOOKUP(TODAY()-J14,Regras!$C$3:$C$10,Regras!$D$3:$D$10,,1)) -> NOVO | L14: =IF(OR(I14<=0,I14=""),"","Recompra") | M14: =IFERROR(IF(Tabela13[[#This Row],[NOME FANTASIA]]="","",_xlfn.XLOOKUP($C14,Log!D:D,Log!B:B,,,-1)),"") | N14: =IFERROR(_xlfn.XLOOKUP($C14,Log!D:D,Log!W:W,,,-1),"") | O14: =IFERROR(_xlfn.XLOOKUP($C14,Log!D:D,Log!Y:Y,,,-1),"") -> 0 | Q14: =IFERROR(IF(Tabela13[[#This Row],[NOME FANTASIA]]="","",_xlfn.XLOOKUP($C14,Log!D:D,Log!X:X,,,-1)),"") | R14: =COUNTIFS(Log!$D:$D,'Base Novos Clientes'!$C14,Log!$W:$W,'Base Novos Clientes'!R$2) -> 0 | S14: =COUNTIFS(Log!$D:$D,'Base Novos Clientes'!$C14,Log!$W:$W,'Base Novos Clientes'!S$2) -> 0 | T14: =COUNTIFS(Log!$D:$D,'Base Novos Clientes'!$C14,Log!$W:$W,'Base Novos Clientes'!T$2) -> 0
... K400: =IF(J400="","NOVO",_xlfn.XLOOKUP(TODAY()-J400,Regras!$C$3:$C$10,Regras!$D$3:$D$10,,1)) -> NOVO | L400: =IF(OR(I400<=0,I400=""),"","Recompra") | M400: =IFERROR(IF(Tabela13[[#This Row],[NOME FANTASIA]]="","",_xlfn.XLOOKUP($C400,Log!D:D,Log!B:B,,,-1)),"") | N400: =IFERROR(_xlfn.XLOOKUP($C400,Log!D:D,Log!W:W,,,-1),"") | O400: =IFERROR(_xlfn.XLOOKUP($C400,Log!D:D,Log!Y:Y,,,-1),"") -> 0 | Q400: =IFERROR(IF(Tabela13[[#This Row],[NOME FANTASIA]]="","",_xlfn.XLOOKUP($C400,Log!D:D,Log!X:X,,,-1)),"") | R400: =COUNTIFS(Log!$D:$D,'Base Novos Clientes'!$C400,Log!$W:$W,'Base Novos Clientes'!R$2) -> 0 | S400: =COUNTIFS(Log!$D:$D,'Base Novos Clientes'!$C400,Log!$W:$W,'Base Novos Clientes'!S$2) -> 0 | T400: =COUNTIFS(Log!$D:$D,'Base Novos Clientes'!$C400,Log!$W:$W,'Base Novos Clientes'!T$2) -> 0

Sheet Dash
C2: VENDEDOR | F2: PERIODO
C3: Manu Ditzel | F3: 46006 | G3: 46006
F4: ,
C5: TIPO DO CONTATO | D5: TOTAL | F5: CONTATOS REALIZADOS | K5: FUNIL DE VENDA | P5: RELACIONAMENTO | S5: NÃO VENDA
F6: CONTATO WHATSAPP | G6: LIGAÇÃO REALIZADAS | H6: LIGAÇÕES ATENDIDAS | I6: LIGAÇÕES NÃO ATENDIDAS | K6: EM ATENDIMENTO | L6: ORÇAMENTO | M6: CADASTRO | N6: VENDA | P6: FOLLOW UP | Q6: SUPORTE | S6: CLIENTE INATIVO | T6: PERDA / NÃO VENDA
C7: PROSPECÇÃO NOVOS CLIENTES | D7: =IF($C$3=Regras!$K$3,COUNTIFS(Log!$B:$B,">="&$F$3,Log!$B:$B,"<="&$G$3,Log!$V:$V,$C7),COUNTIFS(Log!$B:$B,">="&$F$3,Log!$B:$B,"<="&$G$3,Log!$G:$G,$C$3,Log!$V:$V,$C7)) -> 4 | F7: =IF($C$3=Regras!$K$3,COUNTIFS(Log!$B:$B,">="&$F$3,Log!$B:$B,"<="&$G$3,Log!$R:$R,"SIM",Log!$V:$V,$C7),COUNTIFS(Log!$B:$B,">="&$F$3,Log!$B:$B,"<="&$G$3,Log!$G:$G,$C$3,Log!$R:$R,"SIM",Log!$V:$V,$C7)) -> 4 | G7: =IF($C$3=Regras!$K$3,COUNTIFS(Log!$B:$B,">="&$F$3,Log!$B:$B,"<="&$G$3,Log!$S:$S,"SIM",Log!$V:$V,$C7),COUNTIFS(Log!$B:$B,">="&$F$3,Log!$B:$B,"<="&$G$3,Log!$G:$G,$C$3,Log!$S:$S,"SIM",Log!$V:$V,$C7)) -> 0 | H7: =IF($C$3=Regras!$K$3,COUNTIFS(Log!$B:$B,">="&$F$3,Log!$B:$B,"<="&$G$3,Log!$S:$S,"SIM",Log!$T:$T,"SIM",Log!$V:$V,$C7),COUNTIFS(Log!$B:$B,">="&$F$3,Log!$B:$B,"<="&$G$3,Log!$G:$G,$C$3,Log!$S:$S,"SIM",Log!$T:$T,"SIM",Log!$V:$V,$C7)) -> 0 | I7: =IF($C$3=Regras!$K$3,COUNTIFS(Log!$B:$B,">="&$F$3,Log!$B:$B,"<="&$G$3,Log!$S:$S,"SIM",Log!$T:$T,"NÃO",Log!$V:$V,$C7),COUNTIFS(Log!$B:$B,">="&$F$3,Log!$B:$B,"<="&$G$3,Log!$G:$G,$C$3,Log!$S:$S,"SIM",Log!$T:$T,"NÃO",Log!$V:$V,$C7)) -> 0 | K7: =IF($C$3=Regras!$K$3,COUNTIFS(Log!$B:$B,">="&$F$3,Log!$B:$B,"<="&$G$3,Log!$V:$V,$C7,Log!$W:$W,K$6),COUNTIFS(Log!$B:$B,">="&$F$3,Log!$B:$B,"<="&$G$3,Log!$G:$G,$C$3,Log!$V:$V,$C7,Log!$W:$W,K$6)) -> 1 | L7: =IF($C$3=Regras!$K$3,COUNTIFS(Log!$B:$B,">="&$F$3,Log!$B:$B,"<="&$G$3,Log!$V:$V,$C7,Log!$W:$W,L$6),COUNTIFS(Log!$B:$B,">="&$F$3,Log!$B:$B,"<="&$G$3,Log!$G:$G,$C$3,Log!$V:$V,$C7,Log!$W:$W,L$6)) -> 0 | M7: =IF($C$3=Regras!$K$3,COUNTIFS(Log!$B:$B,">="&$F$3,Log!$B:$B,"<="&$G$3,Log!$V:$V,$C7,Log!$W:$W,M$6),COUNTIFS(Log!$B:$B,">="&$F$3,Log!$B:$B,"<="&$G$3,Log!$G:$G,$C$3,Log!$V:$V,$C7,Log!$W:$W,M$6)) -> 0 | N7: =IF($C$3=Regras!$K$3,COUNTIFS(Log!$B:$B,">="&$F$3,Log!$B:$B,"<="&$G$3,Log!$V:$V,$C7,Log!$W:$W,N$6),COUNTIFS(Log!$B:$B,">="&$F$3,Log!$B:$B,"<="&$G$3,Log!$G:$G,$C$3,Log!$V:$V,$C7,Log!$W:$W,N$6)) -> 2 | P7: =IF($C$3=Regras!$K$3,COUNTIFS(Log!$B:$B,">="&$F$3,Log!$B:$B,"<="&$G$3,Log!$V:$V,$C7,Log!$W:$W,P$6&" 15")+ COUNTIFS(Log!$B:$B,">="&$F$3,Log!$B:$B,"<="&$G$3,Log!$V:$V,$C7,Log!$W:$W,P$6&" 7"), COUNTIFS(Log!$B:$B,">="&$F$3,Log!$B:$B,"<="&$G$3,Log!$G:$G,$C$3,Log!$V:$V,$C7,Log!$W:$W,P$6&" 7")+ COUNTIFS(Log!$B:$B,">="&$F$3,Log!$B:$B,"<="&$G$3,Log!$G:$G,$C$3,Log!$V:$V,$C7,Log!$W:$W,P$6&" 15")) -> 1 | Q7: =IF($C$3=Regras!$K$3,COUNTIFS(Log!$B:$B,">="&$F$3,Log!$B:$B,"<="&$G$3,Log!$V:$V,$C7,Log!$W:$W,Q$6),COUNTIFS(Log!$B:$B,">="&$F$3,Log!$B:$B,"<="&$G$3,Log!$G:$G,$C$3,Log!$V:$V,$C7,Log!$W:$W,Q$6)) -> 0 | S7: =IF($C$3=Regras!$K$3,COUNTIFS(Log!$B:$B,">="&$F$3,Log!$B:$B,"<="&$G$3,Log!$V:$V,$C7,Log!$W:$W,S$6),COUNTIFS(Log!$B:$B,">="&$F$3,Log!$B:$B,"<="&$G$3,Log!$G:$G,$C$3,Log!$V:$V,$C7,Log!$W:$W,S$6)) -> 0 | T7: =IF($C$3=Regras!$K$3,COUNTIFS(Log!$B:$B,">="&$F$3,Log!$B:$B,"<="&$G$3,Log!$V:$V,$C7,Log!$W:$W,T$6),COUNTIFS(Log!$B:$B,">="&$F$3,Log!$B:$B,"<="&$G$3,Log!$G:$G,$C$3,Log!$V:$V,$C7,Log!$W:$W,T$6)) -> 0
