Workbook

Sheet Carteira
A1: CÓD. GRUPO CHAVE | B1: 06 NOME GRUPO CHAVE | C1: CÓD. 01 | D1: 01 CANAL | E1: CÓD. 02 | F1: 02 TIPO DE CLIENTE | G1: CÓD. 03 | H1: 03 MACRORREGIÃO DO CLIENTE | I1: CÓD. 04 | J1: 04 MICRORREGIÃO DO CLIENTE | K1: CÓD. 07 | L1: 07 STATUS CLIENTE | M1: CÓD. ZP | N1: ZP - GERENTE NACIONAL | O1: CÓD. ZS | P1: ZS - SUPERVISOR | Q1: CÓD. ZR | R1: ZR - REPRESENTANTE | S1: CÓD. ZX | T1: ZX - VENDEDOR EXTERNO | U1: CÓD. ZV | V1: ZV - VENDEDOR INTERNO
A2: 1000189750 | B2: 06 - INTERNA - BIO MUNDO | C2: 1000184670 | D2: 01 - CANAL VENDA INTERNA | E2: 1000186197 | F2: 02 - INTERNA - CANAL VERDE | G2: 1000198600 | H2: 03 - NACIONAL | I2: 1000198601 | J2: 04 - NACIONAL | M2: 1000136585 | N2: DAIANE STAVICKI | O2: 1000186511 | P2: ZS - NAO APLICAVEL | Q2: 1000186510 | R2: ZR - NAO APLICAVEL | S2: 1000186514 | T2: ZX - NAO APLICAVEL | U2: 1000186513 | V2: ZV - NAO APLICAVEL
A3: 1000189751 | B3: 06 - INTERNA - CIA DA SAUDE | C3: 1000184670 | D3: 01 - CANAL VENDA INTERNA | E3: 1000186197 | F3: 02 - INTERNA - CANAL VERDE | G3: 1000198600 | H3: 03 - NACIONAL | I3: 1000198601 | J3: 04 - NACIONAL | M3: 1000136585 | N3: DAIANE STAVICKI | O3: 1000186511 | P3: ZS - NAO APLICAVEL | Q3: 1000196454 | R3: LG REPRESENTACOES LTDA - EPP | S3: 1000186514 | T3: ZX - NAO APLICAVEL | U3: 1000186513 | V3: ZV - NAO APLICAVEL
A4: 1000189753 | B4: 06 - INTERNA - DIVINA TERRA | C4: 1000184670 | D4: 01 - CANAL VENDA INTERNA | E4: 1000186197 | F4: 02 - INTERNA - CANAL VERDE | G4: 1000198600 | H4: 03 - NACIONAL | I4: 1000198601 | J4: 04 - NACIONAL | M4: 1000136585 | N4: DAIANE STAVICKI | O4: 1000186511 | P4: ZS - NAO APLICAVEL | Q4: 1000186510 | R4: ZR - NAO APLICAVEL | S4: 1000186514 | T4: ZX - NAO APLICAVEL | U4: 1000186513 | V4: ZV - NAO APLICAVEL
A5: 1000189756 | B5: 06 - INTERNA - FITLAND | C5: 1000184670 | D5: 01 - CANAL VENDA INTERNA | E5: 1000186197 | F5: 02 - INTERNA - CANAL VERDE | G5: 1000198600 | H5: 03 - NACIONAL | I5: 1000198601 | J5: 04 - NACIONAL | M5: 1000136585 | N5: DAIANE STAVICKI | O5: 1000186511 | P5: ZS - NAO APLICAVEL | Q5: 1000196454 | R5: LG REPRESENTACOES LTDA - EPP | S5: 1000186514 | T5: ZX - NAO APLICAVEL | U5: 1000186513 | V5: ZV - NAO APLICAVEL
A6: 1000190599 | B6: 06 - INTERNA - JARDIM DAS ERVAS | C6: 1000184670 | D6: 01 - CANAL VENDA INTERNA | E6: 1000186197 | F6: 02 - INTERNA - CANAL VERDE | G6: 1000198600 | H6: 03 - NACIONAL | I6: 1000198601 | J6: 04 - NACIONAL | M6: 1000136585 | N6: DAIANE STAVICKI | O6: 1000186511 | P6: ZS - NAO APLICAVEL | Q6: 1000186510 | R6: ZR - NAO APLICAVEL | S6: 1000186514 | T6: ZX - NAO APLICAVEL | U6: 1000186513 | V6: ZV - NAO APLICAVEL
A7: 1000189757 | B7: 06 - INTERNA - LIGEIRINHO | C7: 1000184670 | D7: 01 - CANAL VENDA INTERNA | E7: 1000186197 | F7: 02 - INTERNA - CANAL VERDE | G7: 1000198600 | H7: 03 - NACIONAL | I7: 1000198601 | J7: 04 - NACIONAL | M7: 1000136585 | N7: DAIANE STAVICKI | O7: 1000186511 | P7: ZS - NAO APLICAVEL | Q7: 1000161699 | R7: 42.149.466 LARISSA DA SILVA PADILHA - ME | S7: 1000186514 | T7: ZX - NAO APLICAVEL | U7: 1000186513 | V7: ZV - NAO APLICAVEL
A8: 1000190613 | B8: 06 - INTERNA - MAIS NATURAL | C8: 1000184670 | D8: 01 - CANAL VENDA INTERNA | E8: 1000186197 | F8: 02 - INTERNA - CANAL VERDE | G8: 1000198600 | H8: 03 - NACIONAL | I8: 1000198601 | J8: 04 - NACIONAL | M8: 1000136585 | N8: DAIANE STAVICKI | O8: 1000186511 | P8: ZS - NAO APLICAVEL | Q8: 1000186510 | R8: ZR - NAO APLICAVEL | S8: 1000186514 | T8: ZX - NAO APLICAVEL | U8: 1000186513 | V8: ZV - NAO APLICAVEL
A9: 1000189760 | B9: 06 - INTERNA - MUNDO VERDE | C9: 1000184670 | D9: 01 - CANAL VENDA INTERNA | E9: 1000186197 | F9: 02 - INTERNA - CANAL VERDE | G9: 1000198600 | H9: 03 - NACIONAL | I9: 1000198601 | J9: 04 - NACIONAL | M9: 1000136585 | N9: DAIANE STAVICKI | O9: 1000186511 | P9: ZS - NAO APLICAVEL | Q9: 1000186510 | R9: ZR - NAO APLICAVEL | S9: 1000186514 | T9: ZX - NAO APLICAVEL | U9: 1000186513 | V9: ZV - NAO APLICAVEL
A10: 1000189761 | B10: 06 - INTERNA - NATURVIDA | C10: 1000184670 | D10: 01 - CANAL VENDA INTERNA | E10: 1000186197 | F10: 02 - INTERNA - CANAL VERDE | G10: 1000198600 | H10: 03 - NACIONAL | I10: 1000198601 | J10: 04 - NACIONAL | M10: 1000136585 | N10: DAIANE STAVICKI | O10: 1000186511 | P10: ZS - NAO APLICAVEL | Q10: 1000186510 | R10: ZR - NAO APLICAVEL | S10: 1000186514 | T10: ZX - NAO APLICAVEL | U10: 1000176426 | V10: HEMANUELE ROSA DITZEL
A11: 1000190614 | B11: 06 - INTERNA - TUDO EM GRAOS / VGA | C11: 1000184670 | D11: 01 - CANAL VENDA INTERNA | E11: 1000186197 | F11: 02 - INTERNA - CANAL VERDE | G11: 1000198600 | H11: 03 - NACIONAL | I11: 1000198601 | J11: 04 - NACIONAL | M11: 1000136585 | N11: DAIANE STAVICKI | O11: 1000186511 | P11: ZS - NAO APLICAVEL | Q11: 1000186510 | R11: ZR - NAO APLICAVEL | S11: 1000186514 | T11: ZX - NAO APLICAVEL | U11: 1000186513 | V11: ZV - NAO APLICAVEL
A12: 1000190600 | B12: 06 - INTERNA - VIDA LEVE | C12: 1000184670 | D12: 01 - CANAL VENDA INTERNA | E12: 1000186197 | F12: 02 - INTERNA - CANAL VERDE | G12: 1000198600 | H12: 03 - NACIONAL | I12: 1000198601 | J12: 04 - NACIONAL | M12: 1000136585 | N12: DAIANE STAVICKI | O12: 1000186511 | P12: ZS - NAO APLICAVEL | Q12: 1000186510 | R12: ZR - NAO APLICAVEL | S12: 1000186514 | T12: ZX - NAO APLICAVEL | U12: 1000186513 | V12: ZV - NAO APLICAVEL
A13: 1000189749 | B13: 06 - INTERNA - ARMAZEM FIT STORE | C13: 1000184670 | D13: 01 - CANAL VENDA INTERNA | E13: 1000186197 | F13: 02 - INTERNA - CANAL VERDE | G13: 1000185288 | H13: 03 - SUL | I13: 1000189807 | J13: 04 - SC LITORAL | M13: 1000136585 | N13: DAIANE STAVICKI | O13: 1000186511 | P13: ZS - NAO APLICAVEL | Q13: 1000186510 | R13: ZR - NAO APLICAVEL | S13: 1000186514 | T13: ZX - NAO APLICAVEL | U13: 1000186513 | V13: ZV - NAO APLICAVEL
... A20: 1000195872 | B20: 06 - INTERNA - PROSAUDE | C20: 1000184670 | D20: 01 - CANAL VENDA INTERNA | E20: 1000186197 | F20: 02 - INTERNA - CANAL VERDE | G20: 1000184758 | H20: 03 - NORTE + MA | I20: 1000189786 | J20: 04 - PA INTERIOR | M20: 1000136585 | N20: DAIANE STAVICKI | O20: 1000186511 | P20: ZS - NAO APLICAVEL | Q20: 1000186510 | R20: ZR - NAO APLICAVEL | S20: 1000186514 | T20: ZX - NAO APLICAVEL | U20: 1000186513 | V20: ZV - NAO APLICAVEL
A21: 1000189270 | B21: 06 - SEM GRUPO | C21: 1000184670 | D21: 01 - CANAL VENDA INTERNA | E21: 1000186197 | F21: 02 - INTERNA - CANAL VERDE | G21: 1000184756 | H21: 03 - CENTRO OESTE | I21: 1000189773 | J21: 04 - DF GERAL | M21: 1000136585 | N21: DAIANE STAVICKI | O21: 1000186511 | P21: ZS - NAO APLICAVEL | Q21: 1000186510 | R21: ZR - NAO APLICAVEL | S21: 1000186514 | T21: ZX - NAO APLICAVEL | U21: 1000176426 | V21: HEMANUELE ROSA DITZEL
A22: 1000189270 | B22: 06 - SEM GRUPO | C22: 1000184670 | D22: 01 - CANAL VENDA INTERNA | E22: 1000186197 | F22: 02 - INTERNA - CANAL VERDE | G22: 1000184756 | H22: 03 - CENTRO OESTE | I22: 1000189775 | J22: 04 - GO GERAL | M22: 1000136585 | N22: DAIANE STAVICKI | O22: 1000186511 | P22: ZS - NAO APLICAVEL | Q22: 1000186510 | R22: ZR - NAO APLICAVEL | S22: 1000186514 | T22: ZX - NAO APLICAVEL | U22: 1000176426 | V22: HEMANUELE ROSA DITZEL
A23: 1000189270 | B23: 06 - SEM GRUPO | C23: 1000184670 | D23: 01 - CANAL VENDA INTERNA | E23: 1000186197 | F23: 02 - INTERNA - CANAL VERDE | G23: 1000184756 | H23: 03 - CENTRO OESTE | I23: 1000189783 | J23: 04 - MS GERAL | M23: 1000136585 | N23: DAIANE STAVICKI | O23: 1000186511 | P23: ZS - NAO APLICAVEL | Q23: 1000186510 | R23: ZR - NAO APLICAVEL | S23: 1000186514 | T23: ZX - NAO APLICAVEL | U23: 1000176426 | V23: HEMANUELE ROSA DITZEL
A24: 1000189270 | B24: 06 - SEM GRUPO | C24: 1000184670 | D24: 01 - CANAL VENDA INTERNA | E24: 1000186197 | F24: 02 - INTERNA - CANAL VERDE | G24: 1000184756 | H24: 03 - CENTRO OESTE | I24: 1000189784 | J24: 04 - MT GERAL | M24: 1000136585 | N24: DAIANE STAVICKI | O24: 1000186511 | P24: ZS - NAO APLICAVEL | Q24: 1000186510 | R24: ZR - NAO APLICAVEL | S24: 1000186514 | T24: ZX - NAO APLICAVEL | U24: 1000176426 | V24: HEMANUELE ROSA DITZEL
A25: 1000189270 | B25: 06 - SEM GRUPO | C25: 1000184670 | D25: 01 - CANAL VENDA INTERNA | E25: 1000186197 | F25: 02 - INTERNA - CANAL VERDE | G25: 1000184756 | H25: 03 - CENTRO OESTE | I25: 1000189824 | J25: 04 - TO GERAL | M25: 1000136585 | N25: DAIANE STAVICKI | O25: 1000186511 | P25: ZS - NAO APLICAVEL | Q25: 1000186510 | R25: ZR - NAO APLICAVEL | S25: 1000186514 | T25: ZX - NAO APLICAVEL | U25: 1000176426 | V25: HEMANUELE ROSA DITZEL
A26: 1000189270 | B26: 06 - SEM GRUPO | C26: 1000184670 | D26: 01 - CANAL VENDA INTERNA | E26: 1000186197 | F26: 02 - INTERNA - CANAL VERDE | G26: 1000184757 | H26: 03 - NORDESTE (SEM MA) | I26: 1000189765 | J26: 04 - AL GERAL | M26: 1000136585 | N26: DAIANE STAVICKI | O26: 1000186511 | P26: ZS - NAO APLICAVEL | Q26: 1000186510 | R26: ZR - NAO APLICAVEL | S26: 1000186514 | T26: ZX - NAO APLICAVEL | U26: 1000176426 | V26: HEMANUELE ROSA DITZEL
A27: 1000189270 | B27: 06 - SEM GRUPO | C27: 1000184670 | D27: 01 - CANAL VENDA INTERNA | E27: 1000186197 | F27: 02 - INTERNA - CANAL VERDE | G27: 1000184757 | H27: 03 - NORDESTE (SEM MA) | I27: 1000189768 | J27: 04 - BA CAPITAL | M27: 1000136585 | N27: DAIANE STAVICKI | O27: 1000186511 | P27: ZS - NAO APLICAVEL | Q27: 1000186510 | R27: ZR - NAO APLICAVEL | S27: 1000186514 | T27: ZX - NAO APLICAVEL | U27: 1000176426 | V27: HEMANUELE ROSA DITZEL
A28: 1000189270 | B28: 06 - SEM GRUPO | C28: 1000184670 | D28: 01 - CANAL VENDA INTERNA | E28: 1000186197 | F28: 02 - INTERNA - CANAL VERDE | G28: 1000184757 | H28: 03 - NORDESTE (SEM MA) | I28: 1000189769 | J28: 04 - BA OESTE | M28: 1000136585 | N28: DAIANE STAVICKI | O28: 1000186511 | P28: ZS - NAO APLICAVEL | Q28: 1000186510 | R28: ZR - NAO APLICAVEL | S28: 1000186514 | T28: ZX - NAO APLICAVEL | U28: 1000176426 | V28: HEMANUELE ROSA DITZEL
A29: 1000189270 | B29: 06 - SEM GRUPO | C29: 1000184670 | D29: 01 - CANAL VENDA INTERNA | E29: 1000186197 | F29: 02 - INTERNA - CANAL VERDE | G29: 1000184757 | H29: 03 - NORDESTE (SEM MA) | I29: 1000189770 | J29: 04 - BA SUL | M29: 1000136585 | N29: DAIANE STAVICKI | O29: 1000186511 | P29: ZS - NAO APLICAVEL | Q29: 1000186510 | R29: ZR - NAO APLICAVEL | S29: 1000186514 | T29: ZX - NAO APLICAVEL | U29: 1000176426 | V29: HEMANUELE ROSA DITZEL
A30: 1000189270 | B30: 06 - SEM GRUPO | C30: 1000184670 | D30: 01 - CANAL VENDA INTERNA | E30: 1000186197 | F30: 02 - INTERNA - CANAL VERDE | G30: 1000184757 | H30: 03 - NORDESTE (SEM MA) | I30: 1000189771 | J30: 04 - BA VALE DO SAO FRANCISCO/NORTE | M30: 1000136585 | N30: DAIANE STAVICKI | O30: 1000186511 | P30: ZS - NAO APLICAVEL | Q30: 1000186510 | R30: ZR - NAO APLICAVEL | S30: 1000186514 | T30: ZX - NAO APLICAVEL | U30: 1000176426 | V30: HEMANUELE ROSA DITZEL
A31: 1000189270 | B31: 06 - SEM GRUPO | C31: 1000184670 | D31: 01 - CANAL VENDA INTERNA | E31: 1000186197 | F31: 02 - INTERNA - CANAL VERDE | G31: 1000184757 | H31: 03 - NORDESTE (SEM MA) | I31: 1000189772 | J31: 04 - CE GERAL | M31: 1000136585 | N31: DAIANE STAVICKI | O31: 1000186511 | P31: ZS - NAO APLICAVEL | Q31: 1000186510 | R31: ZR - NAO APLICAVEL | S31: 1000186514 | T31: ZX - NAO APLICAVEL | U31: 1000176426 | V31: HEMANUELE ROSA DITZEL
A32: 1000189270 | B32: 06 - SEM GRUPO | C32: 1000184670 | D32: 01 - CANAL VENDA INTERNA | E32: 1000186197 | F32: 02 - INTERNA - CANAL VERDE | G32: 1000184757 | H32: 03 - NORDESTE (SEM MA) | I32: 1000189787 | J32: 04 - PB CAPITAL | M32: 1000136585 | N32: DAIANE STAVICKI | O32: 1000186511 | P32: ZS - NAO APLICAVEL | Q32: 1000186510 | R32: ZR - NAO APLICAVEL | S32: 1000186514 | T32: ZX - NAO APLICAVEL | U32: 1000176426 | V32: HEMANUELE ROSA DITZEL
... A81: 1000189270 | B81: 06 - SEM GRUPO | C81: 1000184670 | D81: 01 - CANAL VENDA INTERNA | E81: 1000186197 | F81: 02 - INTERNA - CANAL VERDE | G81: 1000185288 | H81: 03 - SUL | I81: 1000189810 | J81: 04 - SC SUL | M81: 1000136585 | N81: DAIANE STAVICKI | O81: 1000186511 | P81: ZS - NAO APLICAVEL | Q81: 1000186510 | R81: ZR - NAO APLICAVEL | S81: 1000186514 | T81: ZX - NAO APLICAVEL | U81: 1000176426 | V81: HEMANUELE ROSA DITZEL

Sheet Historico - FAT
A1: CÓD. 01 | B1: 01 CANAL | C1: CÓD. 02 | D1: 02 TIPO DE CLIENTE | E1: CÓD. 03 | F1: 03 MACRORREGIÃO DO CLIENTE | G1: CÓD. 04 | H1: 04 MICRORREGIÃO DO CLIENTE | I1: CÓD. GRUPO CHAVE | J1: 06 NOME GRUPO CHAVE | K1: GRUPO DE PRODUTO | L1: 45292 | M1: 45323 | N1: 45352 | O1: 45383 | P1: 45413 | Q1: 45444 | R1: 45474 | S1: 45505 | T1: 45536 | U1: 45566 | V1: 45597 | W1: 45627 | X1: 45658 | Y1: 45689 | Z1: 45717 | AA1: 45748 | AB1: 45778 | AC1: 45809 | AD1: 45839 | AE1: 45870 | AF1: 45901 | AG1: 45931 | AH1: 45962 | AI1: 45992 | AK1: MÉDIA VENDA 2024 | AL1: MÉDIA VENDA 12 MESES | AM1: MÉDIA 6 MESES | AN1: MÉDIA YTD | AO1: TOTAL YTD
A2: 1000184670 | B2: 01 - CANAL VENDA INTERNA | C2: 1000186197 | D2: 02 - INTERNA - CANAL VERDE | E2: 1000185288 | F2: 03 - SUL | G2: 1000189807 | H2: 04 - SC LITORAL | I2: 1000189749 | J2: 06 - INTERNA - ARMAZEM FIT STORE | K2: 01. TOTAL | L2: 0 | M2: 0 | N2: 0 | O2: 0 | P2: 0 | Q2: 0 | R2: 0 | S2: 0 | T2: 0 | U2: 0 | V2: 0 | W2: 0 | X2: 0 | Y2: 0 | Z2: 0 | AA2: 0 | AB2: 0 | AC2: 0 | AD2: 0 | AE2: 0 | AF2: 0 | AG2: 0 | AK2: =AVERAGE(L2:W2) -> 0 | AL2: =AVERAGE(V2:AG2) -> 0 | AM2: =AVERAGE(AB2:AG2) -> 0 | AN2: =AVERAGE(X2:AI2) -> 0 | AO2: =SUM(X2:AI2) -> 0
A3: 1000184670 | B3: 01 - CANAL VENDA INTERNA | C3: 1000186197 | D3: 02 - INTERNA - CANAL VERDE | E3: 1000185288 | F3: 03 - SUL | G3: 1000189807 | H3: 04 - SC LITORAL | I3: 1000189749 | J3: 06 - INTERNA - ARMAZEM FIT STORE | K3: BISCOITO | L3: 0 | M3: 0 | N3: 0 | O3: 0 | P3: 0 | Q3: 0 | R3: 0 | S3: 0 | T3: 0 | U3: 0 | V3: 0 | W3: 0 | X3: 0 | Y3: 0 | Z3: 0 | AA3: 0 | AB3: 0 | AC3: 0 | AD3: 0 | AE3: 0 | AF3: 0 | AG3: 0 | AK3: =AVERAGE(L3:W3) -> 0 | AL3: =AVERAGE(V3:AG3) -> 0 | AM3: =AVERAGE(AB3:AG3) -> 0 | AN3: =AVERAGE(X3:AI3) -> 0 | AO3: =SUM(X3:AI3) -> 0
A4: 1000184670 | B4: 01 - CANAL VENDA INTERNA | C4: 1000186197 | D4: 02 - INTERNA - CANAL VERDE | E4: 1000185288 | F4: 03 - SUL | G4: 1000189807 | H4: 04 - SC LITORAL | I4: 1000189749 | J4: 06 - INTERNA - ARMAZEM FIT STORE | K4: CHOCOLATES | L4: 0 | M4: 0 | N4: 0 | O4: 0 | P4: 0 | Q4: 0 | R4: 0 | S4: 0 | T4: 0 | U4: 0 | V4: 0 | W4: 0 | X4: 0 | Y4: 0 | Z4: 0 | AA4: 0 | AB4: 0 | AC4: 0 | AD4: 0 | AE4: 0 | AF4: 0 | AG4: 0 | AK4: =AVERAGE(L4:W4) -> 0 | AL4: =AVERAGE(V4:AG4) -> 0 | AM4: =AVERAGE(AB4:AG4) -> 0 | AN4: =AVERAGE(X4:AI4) -> 0 | AO4: =SUM(X4:AI4) -> 0
A5: 1000184670 | B5: 01 - CANAL VENDA INTERNA | C5: 1000186197 | D5: 02 - INTERNA - CANAL VERDE | E5: 1000185288 | F5: 03 - SUL | G5: 1000189807 | H5: 04 - SC LITORAL | I5: 1000189749 | J5: 06 - INTERNA - ARMAZEM FIT STORE | K5: DISNEY | L5: 0 | M5: 0 | N5: 0 | O5: 0 | P5: 0 | Q5: 0 | R5: 0 | S5: 0 | T5: 0 | U5: 0 | V5: 0 | W5: 0 | X5: 0 | Y5: 0 | Z5: 0 | AA5: 0 | AB5: 0 | AC5: 0 | AD5: 0 | AE5: 0 | AF5: 0 | AG5: 0 | AK5: =AVERAGE(L5:W5) -> 0 | AL5: =AVERAGE(V5:AG5) -> 0 | AM5: =AVERAGE(AB5:AG5) -> 0 | AN5: =AVERAGE(X5:AI5) -> 0 | AO5: =SUM(X5:AI5) -> 0
A6: 1000184670 | B6: 01 - CANAL VENDA INTERNA | C6: 1000186197 | D6: 02 - INTERNA - CANAL VERDE | E6: 1000185288 | F6: 03 - SUL | G6: 1000189807 | H6: 04 - SC LITORAL | I6: 1000189749 | J6: 06 - INTERNA - ARMAZEM FIT STORE | K6: DOCES | L6: 0 | M6: 0 | N6: 0 | O6: 0 | P6: 0 | Q6: 0 | R6: 0 | S6: 0 | T6: 0 | U6: 0 | V6: 0 | W6: 0 | X6: 0 | Y6: 0 | Z6: 0 | AA6: 0 | AB6: 0 | AC6: 0 | AD6: 0 | AE6: 0 | AF6: 0 | AG6: 0 | AK6: =AVERAGE(L6:W6) -> 0 | AL6: =AVERAGE(V6:AG6) -> 0 | AM6: =AVERAGE(AB6:AG6) -> 0 | AN6: =AVERAGE(X6:AI6) -> 0 | AO6: =SUM(X6:AI6) -> 0
A7: 1000184670 | B7: 01 - CANAL VENDA INTERNA | C7: 1000186197 | D7: 02 - INTERNA - CANAL VERDE | E7: 1000185288 | F7: 03 - SUL | G7: 1000189807 | H7: 04 - SC LITORAL | I7: 1000189749 | J7: 06 - INTERNA - ARMAZEM FIT STORE | K7: FOOD SERVICE | L7: 0 | M7: 0 | N7: 0 | O7: 0 | P7: 0 | Q7: 0 | R7: 0 | S7: 0 | T7: 0 | U7: 0 | V7: 0 | W7: 0 | X7: 0 | Y7: 0 | Z7: 0 | AA7: 0 | AB7: 0 | AC7: 0 | AD7: 0 | AE7: 0 | AF7: 0 | AG7: 0 | AK7: =AVERAGE(L7:W7) -> 0 | AL7: =AVERAGE(V7:AG7) -> 0 | AM7: =AVERAGE(AB7:AG7) -> 0 | AN7: =AVERAGE(X7:AI7) -> 0 | AO7: =SUM(X7:AI7) -> 0
A8: 1000184670 | B8: 01 - CANAL VENDA INTERNA | C8: 1000186197 | D8: 02 - INTERNA - CANAL VERDE | E8: 1000185288 | F8: 03 - SUL | G8: 1000189807 | H8: 04 - SC LITORAL | I8: 1000189749 | J8: 06 - INTERNA - ARMAZEM FIT STORE | K8: GELEIA | L8: 0 | M8: 0 | N8: 0 | O8: 0 | P8: 0 | Q8: 0 | R8: 0 | S8: 0 | T8: 0 | U8: 0 | V8: 0 | W8: 0 | X8: 0 | Y8: 0 | Z8: 0 | AA8: 0 | AB8: 0 | AC8: 0 | AD8: 0 | AE8: 0 | AF8: 0 | AG8: 0 | AK8: =AVERAGE(L8:W8) -> 0 | AL8: =AVERAGE(V8:AG8) -> 0 | AM8: =AVERAGE(AB8:AG8) -> 0 | AN8: =AVERAGE(X8:AI8) -> 0 | AO8: =SUM(X8:AI8) -> 0
A9: 1000184670 | B9: 01 - CANAL VENDA INTERNA | C9: 1000186197 | D9: 02 - INTERNA - CANAL VERDE | E9: 1000185288 | F9: 03 - SUL | G9: 1000189807 | H9: 04 - SC LITORAL | I9: 1000189749 | J9: 06 - INTERNA - ARMAZEM FIT STORE | K9: GRANOLA | L9: 0 | M9: 0 | N9: 0 | O9: 0 | P9: 0 | Q9: 0 | R9: 0 | S9: 0 | T9: 0 | U9: 0 | V9: 0 | W9: 0 | X9: 0 | Y9: 0 | Z9: 0 | AA9: 0 | AB9: 0 | AC9: 0 | AD9: 0 | AE9: 0 | AF9: 0 | AG9: 0 | AK9: =AVERAGE(L9:W9) -> 0 | AL9: =AVERAGE(V9:AG9) -> 0 | AM9: =AVERAGE(AB9:AG9) -> 0 | AN9: =AVERAGE(X9:AI9) -> 0 | AO9: =SUM(X9:AI9) -> 0
A10: 1000184670 | B10: 01 - CANAL VENDA INTERNA | C10: 1000186197 | D10: 02 - INTERNA - CANAL VERDE | E10: 1000185288 | F10: 03 - SUL | G10: 1000189807 | H10: 04 - SC LITORAL | I10: 1000189749 | J10: 06 - INTERNA - ARMAZEM FIT STORE | K10: KIDS | L10: 0 | M10: 0 | N10: 0 | O10: 0 | P10: 0 | Q10: 0 | R10: 0 | S10: 0 | T10: 0 | U10: 0 | V10: 0 | W10: 0 | X10: 0 | Y10: 0 | Z10: 0 | AA10: 0 | AB10: 0 | AC10: 0 | AD10: 0 | AE10: 0 | AF10: 0 | AG10: 0 | AK10: =AVERAGE(L10:W10) -> 0 | AL10: =AVERAGE(V10:AG10) -> 0 | AM10: =AVERAGE(AB10:AG10) -> 0 | AN10: =AVERAGE(X10:AI10) -> 0 | AO10: =SUM(X10:AI10) -> 0
A11: 1000184670 | B11: 01 - CANAL VENDA INTERNA | C11: 1000186197 | D11: 02 - INTERNA - CANAL VERDE | E11: 1000185288 | F11: 03 - SUL | G11: 1000189807 | H11: 04 - SC LITORAL | I11: 1000189749 | J11: 06 - INTERNA - ARMAZEM FIT STORE | K11: LANCHES | L11: 0 | M11: 0 | N11: 0 | O11: 0 | P11: 0 | Q11: 0 | R11: 0 | S11: 0 | T11: 0 | U11: 0 | V11: 0 | W11: 0 | X11: 0 | Y11: 0 | Z11: 0 | AA11: 0 | AB11: 0 | AC11: 0 | AD11: 0 | AE11: 0 | AF11: 0 | AG11: 0 | AK11: =AVERAGE(L11:W11) -> 0 | AL11: =AVERAGE(V11:AG11) -> 0 | AM11: =AVERAGE(AB11:AG11) -> 0 | AN11: =AVERAGE(X11:AI11) -> 0 | AO11: =SUM(X11:AI11) -> 0
A12: 1000184670 | B12: 01 - CANAL VENDA INTERNA | C12: 1000186197 | D12: 02 - INTERNA - CANAL VERDE | E12: 1000185288 | F12: 03 - SUL | G12: 1000189807 | H12: 04 - SC LITORAL | I12: 1000189749 | J12: 06 - INTERNA - ARMAZEM FIT STORE | K12: MAIS GRANEL | L12: 0 | M12: 0 | N12: 0 | O12: 0 | P12: 0 | Q12: 0 | R12: 0 | S12: 0 | T12: 0 | U12: 0 | V12: 0 | W12: 0 | X12: 0 | Y12: 0 | Z12: 0 | AA12: 0 | AB12: 0 | AC12: 0 | AD12: 0 | AE12: 0 | AF12: 0 | AG12: 0 | AK12: =AVERAGE(L12:W12) -> 0 | AL12: =AVERAGE(V12:AG12) -> 0 | AM12: =AVERAGE(AB12:AG12) -> 0 | AN12: =AVERAGE(X12:AI12) -> 0 | AO12: =SUM(X12:AI12) -> 0
A13: 1000184670 | B13: 01 - CANAL VENDA INTERNA | C13: 1000186197 | D13: 02 - INTERNA - CANAL VERDE | E13: 1000185288 | F13: 03 - SUL | G13: 1000189807 | H13: 04 - SC LITORAL | I13: 1000189749 | J13: 06 - INTERNA - ARMAZEM FIT STORE | K13: NATURATTA | L13: 0 | M13: 0 | N13: 0 | O13: 0 | P13: 0 | Q13: 0 | R13: 0 | S13: 0 | T13: 0 | U13: 0 | V13: 0 | W13: 0 | X13: 0 | Y13: 0 | Z13: 0 | AA13: 0 | AB13: 0 | AC13: 0 | AD13: 0 | AE13: 0 | AF13: 0 | AG13: 0 | AK13: =AVERAGE(L13:W13) -> 0 | AL13: =AVERAGE(V13:AG13) -> 0 | AM13: =AVERAGE(AB13:AG13) -> 0 | AN13: =AVERAGE(X13:AI13) -> 0 | AO13: =SUM(X13:AI13) -> 0
... A362: 1000184670 | B362: 01 - CANAL VENDA INTERNA | C362: 1000186197 | D362: 02 - INTERNA - CANAL VERDE | E362: 1000198600 | F362: 03 - NACIONAL | G362: 1000198601 | H362: 04 - NACIONAL | I362: 1000190600 | J362: 06 - INTERNA - VIDA LEVE | K362: VICCIO | L362: 0 | M362: 0 | N362: 0 | O362: 0 | P362: 0 | Q362: 0 | R362: 0 | S362: 0 | T362: 0 | U362: 0 | V362: 0 | W362: 0 | X362: 0 | Y362: 0 | Z362: 0 | AA362: 0 | AB362: 0 | AC362: 0 | AD362: 0 | AE362: 0 | AF362: 252.42 | AG362: 306.87 | AK362: =AVERAGE(L362:W362) -> 0 | AL362: =AVERAGE(V362:AG362) -> 46.6075 | AM362: =AVERAGE(AB362:AG362) -> 93.215 | AN362: =AVERAGE(X362:AI362) -> 55.929 | AO362: =SUM(X362:AI362) -> 559.29
A363: 1000184670 | B363: 01 - CANAL VENDA INTERNA | E363: 1000184758 | F363: 03 - NORTE + MA | G363: 1000189764 | H363: 04 - AC GERAL | I363: 1000189270 | J363: 06 - SEM GRUPO | K363: 01. TOTAL | L363: 0 | M363: 0 | N363: 0 | O363: 0 | P363: 0 | Q363: 0 | R363: 0 | S363: 0 | T363: 0 | U363: 0 | V363: 0 | W363: 0 | X363: 0 | Y363: 0 | Z363: 0 | AA363: 0 | AB363: 0 | AC363: 0 | AD363: 0 | AE363: 0 | AF363: 0 | AG363: 0 | AK363: =AVERAGE(L363:W363) -> 0 | AL363: =AVERAGE(V363:AG363) -> 0 | AM363: =AVERAGE(AB363:AG363) -> 0 | AN363: =AVERAGE(X363:AI363) -> 0 | AO363: =SUM(X363:AI363) -> 0
A364: 1000184670 | B364: 01 - CANAL VENDA INTERNA | E364: 1000184758 | F364: 03 - NORTE + MA | G364: 1000189764 | H364: 04 - AC GERAL | I364: 1000189270 | J364: 06 - SEM GRUPO | K364: BISCOITO | L364: 0 | M364: 0 | N364: 0 | O364: 0 | P364: 0 | Q364: 0 | R364: 0 | S364: 0 | T364: 0 | U364: 0 | V364: 0 | W364: 0 | X364: 0 | Y364: 0 | Z364: 0 | AA364: 0 | AB364: 0 | AC364: 0 | AD364: 0 | AE364: 0 | AF364: 0 | AG364: 0 | AK364: =AVERAGE(L364:W364) -> 0 | AL364: =AVERAGE(V364:AG364) -> 0 | AM364: =AVERAGE(AB364:AG364) -> 0 | AN364: =AVERAGE(X364:AI364) -> 0 | AO364: =SUM(X364:AI364) -> 0
A365: 1000184670 | B365: 01 - CANAL VENDA INTERNA | E365: 1000184758 | F365: 03 - NORTE + MA | G365: 1000189764 | H365: 04 - AC GERAL | I365: 1000189270 | J365: 06 - SEM GRUPO | K365: CHOCOLATES | L365: 0 | M365: 0 | N365: 0 | O365: 0 | P365: 0 | Q365: 0 | R365: 0 | S365: 0 | T365: 0 | U365: 0 | V365: 0 | W365: 0 | X365: 0 | Y365: 0 | Z365: 0 | AA365: 0 | AB365: 0 | AC365: 0 | AD365: 0 | AE365: 0 | AF365: 0 | AG365: 0 | AK365: =AVERAGE(L365:W365) -> 0 | AL365: =AVERAGE(V365:AG365) -> 0 | AM365: =AVERAGE(AB365:AG365) -> 0 | AN365: =AVERAGE(X365:AI365) -> 0 | AO365: =SUM(X365:AI365) -> 0
A366: 1000184670 | B366: 01 - CANAL VENDA INTERNA | E366: 1000184758 | F366: 03 - NORTE + MA | G366: 1000189764 | H366: 04 - AC GERAL | I366: 1000189270 | J366: 06 - SEM GRUPO | K366: DISNEY | L366: 0 | M366: 0 | N366: 0 | O366: 0 | P366: 0 | Q366: 0 | R366: 0 | S366: 0 | T366: 0 | U366: 0 | V366: 0 | W366: 0 | X366: 0 | Y366: 0 | Z366: 0 | AA366: 0 | AB366: 0 | AC366: 0 | AD366: 0 | AE366: 0 | AF366: 0 | AG366: 0 | AK366: =AVERAGE(L366:W366) -> 0 | AL366: =AVERAGE(V366:AG366) -> 0 | AM366: =AVERAGE(AB366:AG366) -> 0 | AN366: =AVERAGE(X366:AI366) -> 0 | AO366: =SUM(X366:AI366) -> 0
A367: 1000184670 | B367: 01 - CANAL VENDA INTERNA | E367: 1000184758 | F367: 03 - NORTE + MA | G367: 1000189764 | H367: 04 - AC GERAL | I367: 1000189270 | J367: 06 - SEM GRUPO | K367: DOCES | L367: 0 | M367: 0 | N367: 0 | O367: 0 | P367: 0 | Q367: 0 | R367: 0 | S367: 0 | T367: 0 | U367: 0 | V367: 0 | W367: 0 | X367: 0 | Y367: 0 | Z367: 0 | AA367: 0 | AB367: 0 | AC367: 0 | AD367: 0 | AE367: 0 | AF367: 0 | AG367: 0 | AK367: =AVERAGE(L367:W367) -> 0 | AL367: =AVERAGE(V367:AG367) -> 0 | AM367: =AVERAGE(AB367:AG367) -> 0 | AN367: =AVERAGE(X367:AI367) -> 0 | AO367: =SUM(X367:AI367) -> 0
A368: 1000184670 | B368: 01 - CANAL VENDA INTERNA | E368: 1000184758 | F368: 03 - NORTE + MA | G368: 1000189764 | H368: 04 - AC GERAL | I368: 1000189270 | J368: 06 - SEM GRUPO | K368: FOOD SERVICE | L368: 0 | M368: 0 | N368: 0 | O368: 0 | P368: 0 | Q368: 0 | R368: 0 | S368: 0 | T368: 0 | U368: 0 | V368: 0 | W368: 0 | X368: 0 | Y368: 0 | Z368: 0 | AA368: 0 | AB368: 0 | AC368: 0 | AD368: 0 | AE368: 0 | AF368: 0 | AG368: 0 | AK368: =AVERAGE(L368:W368) -> 0 | AL368: =AVERAGE(V368:AG368) -> 0 | AM368: =AVERAGE(AB368:AG368) -> 0 | AN368: =AVERAGE(X368:AI368) -> 0 | AO368: =SUM(X368:AI368) -> 0
A369: 1000184670 | B369: 01 - CANAL VENDA INTERNA | E369: 1000184758 | F369: 03 - NORTE + MA | G369: 1000189764 | H369: 04 - AC GERAL | I369: 1000189270 | J369: 06 - SEM GRUPO | K369: GELEIA | L369: 0 | M369: 0 | N369: 0 | O369: 0 | P369: 0 | Q369: 0 | R369: 0 | S369: 0 | T369: 0 | U369: 0 | V369: 0 | W369: 0 | X369: 0 | Y369: 0 | Z369: 0 | AA369: 0 | AB369: 0 | AC369: 0 | AD369: 0 | AE369: 0 | AF369: 0 | AG369: 0 | AK369: =AVERAGE(L369:W369) -> 0 | AL369: =AVERAGE(V369:AG369) -> 0 | AM369: =AVERAGE(AB369:AG369) -> 0 | AN369: =AVERAGE(X369:AI369) -> 0 | AO369: =SUM(X369:AI369) -> 0
A370: 1000184670 | B370: 01 - CANAL VENDA INTERNA | E370: 1000184758 | F370: 03 - NORTE + MA | G370: 1000189764 | H370: 04 - AC GERAL | I370: 1000189270 | J370: 06 - SEM GRUPO | K370: GRANOLA | L370: 0 | M370: 0 | N370: 0 | O370: 0 | P370: 0 | Q370: 0 | R370: 0 | S370: 0 | T370: 0 | U370: 0 | V370: 0 | W370: 0 | X370: 0 | Y370: 0 | Z370: 0 | AA370: 0 | AB370: 0 | AC370: 0 | AD370: 0 | AE370: 0 | AF370: 0 | AG370: 0 | AK370: =AVERAGE(L370:W370) -> 0 | AL370: =AVERAGE(V370:AG370) -> 0 | AM370: =AVERAGE(AB370:AG370) -> 0 | AN370: =AVERAGE(X370:AI370) -> 0 | AO370: =SUM(X370:AI370) -> 0
A371: 1000184670 | B371: 01 - CANAL VENDA INTERNA | E371: 1000184758 | F371: 03 - NORTE + MA | G371: 1000189764 | H371: 04 - AC GERAL | I371: 1000189270 | J371: 06 - SEM GRUPO | K371: KIDS | L371: 0 | M371: 0 | N371: 0 | O371: 0 | P371: 0 | Q371: 0 | R371: 0 | S371: 0 | T371: 0 | U371: 0 | V371: 0 | W371: 0 | X371: 0 | Y371: 0 | Z371: 0 | AA371: 0 | AB371: 0 | AC371: 0 | AD371: 0 | AE371: 0 | AF371: 0 | AG371: 0 | AK371: =AVERAGE(L371:W371) -> 0 | AL371: =AVERAGE(V371:AG371) -> 0 | AM371: =AVERAGE(AB371:AG371) -> 0 | AN371: =AVERAGE(X371:AI371) -> 0 | AO371: =SUM(X371:AI371) -> 0
A372: 1000184670 | B372: 01 - CANAL VENDA INTERNA | E372: 1000184758 | F372: 03 - NORTE + MA | G372: 1000189764 | H372: 04 - AC GERAL | I372: 1000189270 | J372: 06 - SEM GRUPO | K372: LANCHES | L372: 0 | M372: 0 | N372: 0 | O372: 0 | P372: 0 | Q372: 0 | R372: 0 | S372: 0 | T372: 0 | U372: 0 | V372: 0 | W372: 0 | X372: 0 | Y372: 0 | Z372: 0 | AA372: 0 | AB372: 0 | AC372: 0 | AD372: 0 | AE372: 0 | AF372: 0 | AG372: 0 | AK372: =AVERAGE(L372:W372) -> 0 | AL372: =AVERAGE(V372:AG372) -> 0 | AM372: =AVERAGE(AB372:AG372) -> 0 | AN372: =AVERAGE(X372:AI372) -> 0 | AO372: =SUM(X372:AI372) -> 0
A373: 1000184670 | B373: 01 - CANAL VENDA INTERNA | E373: 1000184758 | F373: 03 - NORTE + MA | G373: 1000189764 | H373: 04 - AC GERAL | I373: 1000189270 | J373: 06 - SEM GRUPO | K373: MAIS GRANEL | L373: 0 | M373: 0 | N373: 0 | O373: 0 | P373: 0 | Q373: 0 | R373: 0 | S373: 0 | T373: 0 | U373: 0 | V373: 0 | W373: 0 | X373: 0 | Y373: 0 | Z373: 0 | AA373: 0 | AB373: 0 | AC373: 0 | AD373: 0 | AE373: 0 | AF373: 0 | AG373: 0 | AK373: =AVERAGE(L373:W373) -> 0 | AL373: =AVERAGE(V373:AG373) -> 0 | AM373: =AVERAGE(AB373:AG373) -> 0 | AN373: =AVERAGE(X373:AI373) -> 0 | AO373: =SUM(X373:AI373) -> 0
A374: 1000184670 | B374: 01 - CANAL VENDA INTERNA | E374: 1000184758 | F374: 03 - NORTE + MA | G374: 1000189764 | H374: 04 - AC GERAL | I374: 1000189270 | J374: 06 - SEM GRUPO | K374: NATURATTA | L374: 0 | M374: 0 | N374: 0 | O374: 0 | P374: 0 | Q374: 0 | R374: 0 | S374: 0 | T374: 0 | U374: 0 | V374: 0 | W374: 0 | X374: 0 | Y374: 0 | Z374: 0 | AA374: 0 | AB374: 0 | AC374: 0 | AD374: 0 | AE374: 0 | AF374: 0 | AG374: 0 | AK374: =AVERAGE(L374:W374) -> 0 | AL374: =AVERAGE(V374:AG374) -> 0 | AM374: =AVERAGE(AB374:AG374) -> 0 | AN374: =AVERAGE(X374:AI374) -> 0 | AO374: =SUM(X374:AI374) -> 0
... A1521: 1000184670 | B1521: 01 - CANAL VENDA INTERNA | E1521: 1000184756 | F1521: 03 - CENTRO OESTE | G1521: 1000189824 | H1521: 04 - TO GERAL | I1521: 1000189270 | J1521: 06 - SEM GRUPO | K1521: VICCIO | L1521: 0 | M1521: 0 | N1521: 158.4 | O1521: 979.2 | P1521: 0 | Q1521: 0 | R1521: 0 | S1521: 0 | T1521: 0 | U1521: 0 | V1521: 0 | W1521: 0 | X1521: 0 | Y1521: 0 | Z1521: 108 | AA1521: 0 | AB1521: 0 | AC1521: 0 | AD1521: 0 | AE1521: 0 | AF1521: 0 | AG1521: 0 | AK1521: =AVERAGE(L1521:W1521) -> 94.8 | AL1521: =AVERAGE(V1521:AG1521) -> 9 | AM1521: =AVERAGE(AB1521:AG1521) -> 0 | AN1521: =AVERAGE(X1521:AI1521) -> 10.8 | AO1521: =SUM(X1521:AI1521) -> 108

Sheet Leads
L1: =L2-K2 -> 41 | M1: =M2-L2 -> 40 | N1: =N2-M2 -> 39 | O1: =O2-N2 -> 40 | P1: =P2-O2 -> 39 | Q1: =Q2-P2 -> 39 | R1: =R2-Q2 -> 39 | S1: =S2-R2 -> 39 | ... V1: =V2-U2 -> 39
K2: =SUBTOTAL(9,K4:K674) -> 1634 | L2: =SUBTOTAL(9,L4:L674) -> 1675 | M2: =SUBTOTAL(9,M4:M674) -> 1715 | N2: =SUBTOTAL(9,N4:N674) -> 1754 | O2: =SUBTOTAL(9,O4:O674) -> 1794 | P2: =SUBTOTAL(9,P4:P674) -> 1833 | Q2: =SUBTOTAL(9,Q4:Q674) -> 1872 | R2: =SUBTOTAL(9,R4:R674) -> 1911 | ... V2: =SUBTOTAL(9,V4:V674) -> 2067 | X2: =SUBTOTAL(9,X4:X674) -> 1634
A3: CÓD. 01 | B3: 01 CANAL | C3: CÓD. 02 | D3: 02 TIPO DE CLIENTE | E3: CÓD. 03 | F3: 03 MACRORREGIÃO DO CLIENTE | G3: CÓD. 04 | H3: 04 MICRORREGIÃO DO CLIENTE | I3: CÓD. GRUPO CHAVE | J3: 06 NOME GRUPO CHAVE | K3: JAN | L3: FEV | M3: MAR | N3: ABR | O3: MAI | P3: JUN | Q3: JUL | R3: AGO | S3: SET | T3: OUT | U3: NOV | V3: DEZ | X3: CARTEIRA TOTAL | Y3: TOTAL LOJAS | Z3: CRESCIMENTO MENSAL
A4: 1000184670 | B4: 01 - CANAL VENDA INTERNA | C4: 1000186197 | D4: 02 - INTERNA - CANAL VERDE | E4: 1000198600 | F4: 03 - NACIONAL | G4: 1000198601 | H4: 04 - NACIONAL | I4: 1000189750 | J4: 06 - INTERNA - BIO MUNDO | K4: =X4 -> 13 | L4: =IF(ROUNDUP(K4*(1+$Z4),0)>$Y4,$Y4,ROUNDUP(K4*(1+$Z4),0)) -> 14 | M4: =IF(ROUNDUP(L4*(1+$Z4),0)>$Y4,$Y4,ROUNDUP(L4*(1+$Z4),0)) -> 15 | N4: =IF(ROUNDUP(M4*(1+$Z4),0)>$Y4,$Y4,ROUNDUP(M4*(1+$Z4),0)) -> 16 | O4: =IF(ROUNDUP(N4*(1+$Z4),0)>$Y4,$Y4,ROUNDUP(N4*(1+$Z4),0)) -> 17 | P4: =IF(ROUNDUP(O4*(1+$Z4),0)>$Y4,$Y4,ROUNDUP(O4*(1+$Z4),0)) -> 18 | Q4: =IF(ROUNDUP(P4*(1+$Z4),0)>$Y4,$Y4,ROUNDUP(P4*(1+$Z4),0)) -> 19 | R4: =IF(ROUNDUP(Q4*(1+$Z4),0)>$Y4,$Y4,ROUNDUP(Q4*(1+$Z4),0)) -> 20 | S4: =IF(ROUNDUP(R4*(1+$Z4),0)>$Y4,$Y4,ROUNDUP(R4*(1+$Z4),0)) -> 21 | ... V4: =IF(ROUNDUP(U4*(1+$Z4),0)>$Y4,$Y4,ROUNDUP(U4*(1+$Z4),0)) -> 24 | X4: 13 | Y4: 136 | Z4: 0.03
A5: 1000184670 | B5: 01 - CANAL VENDA INTERNA | C5: 1000186197 | D5: 02 - INTERNA - CANAL VERDE | E5: 1000198600 | F5: 03 - NACIONAL | G5: 1000198601 | H5: 04 - NACIONAL | I5: 1000189751 | J5: 06 - INTERNA - CIA DA SAUDE | K5: =X5 -> 70 | L5: =IF(ROUNDUP(K5*(1+$Z5),0)>$Y5,$Y5,ROUNDUP(K5*(1+$Z5),0)) -> 73 | M5: =IF(ROUNDUP(L5*(1+$Z5),0)>$Y5,$Y5,ROUNDUP(L5*(1+$Z5),0)) -> 76 | N5: =IF(ROUNDUP(M5*(1+$Z5),0)>$Y5,$Y5,ROUNDUP(M5*(1+$Z5),0)) -> 79 | O5: =IF(ROUNDUP(N5*(1+$Z5),0)>$Y5,$Y5,ROUNDUP(N5*(1+$Z5),0)) -> 82 | P5: =IF(ROUNDUP(O5*(1+$Z5),0)>$Y5,$Y5,ROUNDUP(O5*(1+$Z5),0)) -> 85 | Q5: =IF(ROUNDUP(P5*(1+$Z5),0)>$Y5,$Y5,ROUNDUP(P5*(1+$Z5),0)) -> 88 | R5: =IF(ROUNDUP(Q5*(1+$Z5),0)>$Y5,$Y5,ROUNDUP(Q5*(1+$Z5),0)) -> 91 | S5: =IF(ROUNDUP(R5*(1+$Z5),0)>$Y5,$Y5,ROUNDUP(R5*(1+$Z5),0)) -> 94 | ... V5: =IF(ROUNDUP(U5*(1+$Z5),0)>$Y5,$Y5,ROUNDUP(U5*(1+$Z5),0)) -> 103 | X5: 70 | Y5: 150 | Z5: 0.03
A6: 1000184670 | B6: 01 - CANAL VENDA INTERNA | C6: 1000186197 | D6: 02 - INTERNA - CANAL VERDE | E6: 1000198600 | F6: 03 - NACIONAL | G6: 1000198601 | H6: 04 - NACIONAL | I6: 1000189753 | J6: 06 - INTERNA - DIVINA TERRA | K6: =X6 -> 53 | L6: =IF(ROUNDUP(K6*(1+$Z6),0)>$Y6,$Y6,ROUNDUP(K6*(1+$Z6),0)) -> 55 | M6: =IF(ROUNDUP(L6*(1+$Z6),0)>$Y6,$Y6,ROUNDUP(L6*(1+$Z6),0)) -> 57 | N6: =IF(ROUNDUP(M6*(1+$Z6),0)>$Y6,$Y6,ROUNDUP(M6*(1+$Z6),0)) -> 59 | O6: =IF(ROUNDUP(N6*(1+$Z6),0)>$Y6,$Y6,ROUNDUP(N6*(1+$Z6),0)) -> 61 | P6: =IF(ROUNDUP(O6*(1+$Z6),0)>$Y6,$Y6,ROUNDUP(O6*(1+$Z6),0)) -> 63 | Q6: =IF(ROUNDUP(P6*(1+$Z6),0)>$Y6,$Y6,ROUNDUP(P6*(1+$Z6),0)) -> 65 | R6: =IF(ROUNDUP(Q6*(1+$Z6),0)>$Y6,$Y6,ROUNDUP(Q6*(1+$Z6),0)) -> 67 | S6: =IF(ROUNDUP(R6*(1+$Z6),0)>$Y6,$Y6,ROUNDUP(R6*(1+$Z6),0)) -> 69 | ... V6: =IF(ROUNDUP(U6*(1+$Z6),0)>$Y6,$Y6,ROUNDUP(U6*(1+$Z6),0)) -> 75 | X6: 53 | Y6: 76 | Z6: 0.02
A7: 1000184670 | B7: 01 - CANAL VENDA INTERNA | C7: 1000186197 | D7: 02 - INTERNA - CANAL VERDE | E7: 1000198600 | F7: 03 - NACIONAL | G7: 1000198601 | H7: 04 - NACIONAL | I7: 1000189756 | J7: 06 - INTERNA - FITLAND | K7: =X7 -> 58 | L7: =IF(ROUNDUP(K7*(1+$Z7),0)>$Y7,$Y7,ROUNDUP(K7*(1+$Z7),0)) -> 60 | M7: =IF(ROUNDUP(L7*(1+$Z7),0)>$Y7,$Y7,ROUNDUP(L7*(1+$Z7),0)) -> 62 | N7: =IF(ROUNDUP(M7*(1+$Z7),0)>$Y7,$Y7,ROUNDUP(M7*(1+$Z7),0)) -> 64 | O7: =IF(ROUNDUP(N7*(1+$Z7),0)>$Y7,$Y7,ROUNDUP(N7*(1+$Z7),0)) -> 66 | P7: =IF(ROUNDUP(O7*(1+$Z7),0)>$Y7,$Y7,ROUNDUP(O7*(1+$Z7),0)) -> 68 | Q7: =IF(ROUNDUP(P7*(1+$Z7),0)>$Y7,$Y7,ROUNDUP(P7*(1+$Z7),0)) -> 70 | R7: =IF(ROUNDUP(Q7*(1+$Z7),0)>$Y7,$Y7,ROUNDUP(Q7*(1+$Z7),0)) -> 72 | S7: =IF(ROUNDUP(R7*(1+$Z7),0)>$Y7,$Y7,ROUNDUP(R7*(1+$Z7),0)) -> 74 | ... V7: =IF(ROUNDUP(U7*(1+$Z7),0)>$Y7,$Y7,ROUNDUP(U7*(1+$Z7),0)) -> 80 | X7: 58 | Y7: 80 | Z7: 0.02
A8: 1000184670 | B8: 01 - CANAL VENDA INTERNA | C8: 1000186197 | D8: 02 - INTERNA - CANAL VERDE | E8: 1000198600 | F8: 03 - NACIONAL | G8: 1000198601 | H8: 04 - NACIONAL | I8: 1000190599 | J8: 06 - INTERNA - JARDIM DAS ERVAS | K8: =X8 -> 1 | L8: =IF(ROUNDUP(K8*(1+$Z8),0)>$Y8,$Y8,ROUNDUP(K8*(1+$Z8),0)) -> 2 | M8: =IF(ROUNDUP(L8*(1+$Z8),0)>$Y8,$Y8,ROUNDUP(L8*(1+$Z8),0)) -> 3 | N8: =IF(ROUNDUP(M8*(1+$Z8),0)>$Y8,$Y8,ROUNDUP(M8*(1+$Z8),0)) -> 4 | O8: =IF(ROUNDUP(N8*(1+$Z8),0)>$Y8,$Y8,ROUNDUP(N8*(1+$Z8),0)) -> 5 | P8: =IF(ROUNDUP(O8*(1+$Z8),0)>$Y8,$Y8,ROUNDUP(O8*(1+$Z8),0)) -> 6 | Q8: =IF(ROUNDUP(P8*(1+$Z8),0)>$Y8,$Y8,ROUNDUP(P8*(1+$Z8),0)) -> 7 | R8: =IF(ROUNDUP(Q8*(1+$Z8),0)>$Y8,$Y8,ROUNDUP(Q8*(1+$Z8),0)) -> 8 | S8: =IF(ROUNDUP(R8*(1+$Z8),0)>$Y8,$Y8,ROUNDUP(R8*(1+$Z8),0)) -> 9 | ... V8: =IF(ROUNDUP(U8*(1+$Z8),0)>$Y8,$Y8,ROUNDUP(U8*(1+$Z8),0)) -> 12 | X8: 1 | Y8: 22 | Z8: 0.03
A9: 1000184670 | B9: 01 - CANAL VENDA INTERNA | C9: 1000186197 | D9: 02 - INTERNA - CANAL VERDE | E9: 1000198600 | F9: 03 - NACIONAL | G9: 1000198601 | H9: 04 - NACIONAL | I9: 1000189757 | J9: 06 - INTERNA - LIGEIRINHO | K9: =X9 -> 3 | L9: =IF(ROUNDUP(K9*(1+$Z9),0)>$Y9,$Y9,ROUNDUP(K9*(1+$Z9),0)) -> 4 | M9: =IF(ROUNDUP(L9*(1+$Z9),0)>$Y9,$Y9,ROUNDUP(L9*(1+$Z9),0)) -> 4 | N9: =IF(ROUNDUP(M9*(1+$Z9),0)>$Y9,$Y9,ROUNDUP(M9*(1+$Z9),0)) -> 4 | O9: =IF(ROUNDUP(N9*(1+$Z9),0)>$Y9,$Y9,ROUNDUP(N9*(1+$Z9),0)) -> 4 | P9: =IF(ROUNDUP(O9*(1+$Z9),0)>$Y9,$Y9,ROUNDUP(O9*(1+$Z9),0)) -> 4 | Q9: =IF(ROUNDUP(P9*(1+$Z9),0)>$Y9,$Y9,ROUNDUP(P9*(1+$Z9),0)) -> 4 | R9: =IF(ROUNDUP(Q9*(1+$Z9),0)>$Y9,$Y9,ROUNDUP(Q9*(1+$Z9),0)) -> 4 | S9: =IF(ROUNDUP(R9*(1+$Z9),0)>$Y9,$Y9,ROUNDUP(R9*(1+$Z9),0)) -> 4 | ... V9: =IF(ROUNDUP(U9*(1+$Z9),0)>$Y9,$Y9,ROUNDUP(U9*(1+$Z9),0)) -> 4 | X9: 3 | Y9: 4 | Z9: 0.03
A10: 1000184670 | B10: 01 - CANAL VENDA INTERNA | C10: 1000186197 | D10: 02 - INTERNA - CANAL VERDE | E10: 1000198600 | F10: 03 - NACIONAL | G10: 1000198601 | H10: 04 - NACIONAL | I10: 1000190613 | J10: 06 - INTERNA - MAIS NATURAL | K10: =X10 -> 1 | L10: =IF(ROUNDUP(K10*(1+$Z10),0)>$Y10,$Y10,ROUNDUP(K10*(1+$Z10),0)) -> 2 | M10: =IF(ROUNDUP(L10*(1+$Z10),0)>$Y10,$Y10,ROUNDUP(L10*(1+$Z10),0)) -> 3 | N10: =IF(ROUNDUP(M10*(1+$Z10),0)>$Y10,$Y10,ROUNDUP(M10*(1+$Z10),0)) -> 4 | O10: =IF(ROUNDUP(N10*(1+$Z10),0)>$Y10,$Y10,ROUNDUP(N10*(1+$Z10),0)) -> 5 | P10: =IF(ROUNDUP(O10*(1+$Z10),0)>$Y10,$Y10,ROUNDUP(O10*(1+$Z10),0)) -> 5 | Q10: =IF(ROUNDUP(P10*(1+$Z10),0)>$Y10,$Y10,ROUNDUP(P10*(1+$Z10),0)) -> 5 | R10: =IF(ROUNDUP(Q10*(1+$Z10),0)>$Y10,$Y10,ROUNDUP(Q10*(1+$Z10),0)) -> 5 | S10: =IF(ROUNDUP(R10*(1+$Z10),0)>$Y10,$Y10,ROUNDUP(R10*(1+$Z10),0)) -> 5 | ... V10: =IF(ROUNDUP(U10*(1+$Z10),0)>$Y10,$Y10,ROUNDUP(U10*(1+$Z10),0)) -> 5 | X10: 1 | Y10: 5 | Z10: 0.03
A11: 1000184670 | B11: 01 - CANAL VENDA INTERNA | C11: 1000186197 | D11: 02 - INTERNA - CANAL VERDE | E11: 1000198600 | F11: 03 - NACIONAL | G11: 1000198601 | H11: 04 - NACIONAL | I11: 1000189760 | J11: 06 - INTERNA - MUNDO VERDE | K11: =X11 -> 5 | L11: =IF(ROUNDUP(K11*(1+$Z11),0)>$Y11,$Y11,ROUNDUP(K11*(1+$Z11),0)) -> 6 | M11: =IF(ROUNDUP(L11*(1+$Z11),0)>$Y11,$Y11,ROUNDUP(L11*(1+$Z11),0)) -> 7 | N11: =IF(ROUNDUP(M11*(1+$Z11),0)>$Y11,$Y11,ROUNDUP(M11*(1+$Z11),0)) -> 8 | O11: =IF(ROUNDUP(N11*(1+$Z11),0)>$Y11,$Y11,ROUNDUP(N11*(1+$Z11),0)) -> 9 | P11: =IF(ROUNDUP(O11*(1+$Z11),0)>$Y11,$Y11,ROUNDUP(O11*(1+$Z11),0)) -> 10 | Q11: =IF(ROUNDUP(P11*(1+$Z11),0)>$Y11,$Y11,ROUNDUP(P11*(1+$Z11),0)) -> 11 | R11: =IF(ROUNDUP(Q11*(1+$Z11),0)>$Y11,$Y11,ROUNDUP(Q11*(1+$Z11),0)) -> 12 | S11: =IF(ROUNDUP(R11*(1+$Z11),0)>$Y11,$Y11,ROUNDUP(R11*(1+$Z11),0)) -> 13 | ... V11: =IF(ROUNDUP(U11*(1+$Z11),0)>$Y11,$Y11,ROUNDUP(U11*(1+$Z11),0)) -> 16 | X11: 5 | Y11: 171 | Z11: 0.03
A12: 1000184670 | B12: 01 - CANAL VENDA INTERNA | C12: 1000186197 | D12: 02 - INTERNA - CANAL VERDE | E12: 1000198600 | F12: 03 - NACIONAL | G12: 1000198601 | H12: 04 - NACIONAL | I12: 1000189761 | J12: 06 - INTERNA - NATURVIDA | K12: =X12 -> 3 | L12: =IF(ROUNDUP(K12*(1+$Z12),0)>$Y12,$Y12,ROUNDUP(K12*(1+$Z12),0)) -> 3 | M12: =IF(ROUNDUP(L12*(1+$Z12),0)>$Y12,$Y12,ROUNDUP(L12*(1+$Z12),0)) -> 3 | N12: =IF(ROUNDUP(M12*(1+$Z12),0)>$Y12,$Y12,ROUNDUP(M12*(1+$Z12),0)) -> 3 | O12: =IF(ROUNDUP(N12*(1+$Z12),0)>$Y12,$Y12,ROUNDUP(N12*(1+$Z12),0)) -> 3 | P12: =IF(ROUNDUP(O12*(1+$Z12),0)>$Y12,$Y12,ROUNDUP(O12*(1+$Z12),0)) -> 3 | Q12: =IF(ROUNDUP(P12*(1+$Z12),0)>$Y12,$Y12,ROUNDUP(P12*(1+$Z12),0)) -> 3 | R12: =IF(ROUNDUP(Q12*(1+$Z12),0)>$Y12,$Y12,ROUNDUP(Q12*(1+$Z12),0)) -> 3 | S12: =IF(ROUNDUP(R12*(1+$Z12),0)>$Y12,$Y12,ROUNDUP(R12*(1+$Z12),0)) -> 3 | ... V12: =IF(ROUNDUP(U12*(1+$Z12),0)>$Y12,$Y12,ROUNDUP(U12*(1+$Z12),0)) -> 3 | X12: 3 | Y12: 3 | Z12: 0.03
A13: 1000184670 | B13: 01 - CANAL VENDA INTERNA | C13: 1000186197 | D13: 02 - INTERNA - CANAL VERDE | E13: 1000198600 | F13: 03 - NACIONAL | G13: 1000198601 | H13: 04 - NACIONAL | I13: 1000190614 | J13: 06 - INTERNA - TUDO EM GRAOS / VGA | K13: =X13 -> 9 | L13: =IF(ROUNDUP(K13*(1+$Z13),0)>$Y13,$Y13,ROUNDUP(K13*(1+$Z13),0)) -> 10 | M13: =IF(ROUNDUP(L13*(1+$Z13),0)>$Y13,$Y13,ROUNDUP(L13*(1+$Z13),0)) -> 11 | N13: =IF(ROUNDUP(M13*(1+$Z13),0)>$Y13,$Y13,ROUNDUP(M13*(1+$Z13),0)) -> 12 | O13: =IF(ROUNDUP(N13*(1+$Z13),0)>$Y13,$Y13,ROUNDUP(N13*(1+$Z13),0)) -> 13 | P13: =IF(ROUNDUP(O13*(1+$Z13),0)>$Y13,$Y13,ROUNDUP(O13*(1+$Z13),0)) -> 14 | Q13: =IF(ROUNDUP(P13*(1+$Z13),0)>$Y13,$Y13,ROUNDUP(P13*(1+$Z13),0)) -> 15 | R13: =IF(ROUNDUP(Q13*(1+$Z13),0)>$Y13,$Y13,ROUNDUP(Q13*(1+$Z13),0)) -> 16 | S13: =IF(ROUNDUP(R13*(1+$Z13),0)>$Y13,$Y13,ROUNDUP(R13*(1+$Z13),0)) -> 17 | ... V13: =IF(ROUNDUP(U13*(1+$Z13),0)>$Y13,$Y13,ROUNDUP(U13*(1+$Z13),0)) -> 20 | X13: 9 | Y13: 27 | Z13: 0.03
A14: 1000184670 | B14: 01 - CANAL VENDA INTERNA | C14: 1000186197 | D14: 02 - INTERNA - CANAL VERDE | E14: 1000198600 | F14: 03 - NACIONAL | G14: 1000198601 | H14: 04 - NACIONAL | I14: 1000190600 | J14: 06 - INTERNA - VIDA LEVE | K14: =X14 -> 31 | L14: =IF(ROUNDUP(K14*(1+$Z14),0)>$Y14,$Y14,ROUNDUP(K14*(1+$Z14),0)) -> 32 | M14: =IF(ROUNDUP(L14*(1+$Z14),0)>$Y14,$Y14,ROUNDUP(L14*(1+$Z14),0)) -> 33 | N14: =IF(ROUNDUP(M14*(1+$Z14),0)>$Y14,$Y14,ROUNDUP(M14*(1+$Z14),0)) -> 34 | O14: =IF(ROUNDUP(N14*(1+$Z14),0)>$Y14,$Y14,ROUNDUP(N14*(1+$Z14),0)) -> 36 | P14: =IF(ROUNDUP(O14*(1+$Z14),0)>$Y14,$Y14,ROUNDUP(O14*(1+$Z14),0)) -> 38 | Q14: =IF(ROUNDUP(P14*(1+$Z14),0)>$Y14,$Y14,ROUNDUP(P14*(1+$Z14),0)) -> 40 | R14: =IF(ROUNDUP(Q14*(1+$Z14),0)>$Y14,$Y14,ROUNDUP(Q14*(1+$Z14),0)) -> 42 | S14: =IF(ROUNDUP(R14*(1+$Z14),0)>$Y14,$Y14,ROUNDUP(R14*(1+$Z14),0)) -> 44 | ... V14: =IF(ROUNDUP(U14*(1+$Z14),0)>$Y14,$Y14,ROUNDUP(U14*(1+$Z14),0)) -> 50 | X14: 31 | Y14: 77 | Z14: 0.03
A15: 1000184670 | B15: 01 - CANAL VENDA INTERNA | C15: 1000186197 | D15: 02 - INTERNA - CANAL VERDE | E15: 1000185288 | F15: 03 - SUL | G15: 1000189807 | H15: 04 - SC LITORAL | I15: 1000189749 | J15: 06 - INTERNA - ARMAZEM FIT STORE | K15: =X15 -> 5 | L15: =IF(ROUNDUP(K15*(1+$Z15),0)>$Y15,$Y15,ROUNDUP(K15*(1+$Z15),0)) -> 5 | M15: =IF(ROUNDUP(L15*(1+$Z15),0)>$Y15,$Y15,ROUNDUP(L15*(1+$Z15),0)) -> 5 | N15: =IF(ROUNDUP(M15*(1+$Z15),0)>$Y15,$Y15,ROUNDUP(M15*(1+$Z15),0)) -> 5 | O15: =IF(ROUNDUP(N15*(1+$Z15),0)>$Y15,$Y15,ROUNDUP(N15*(1+$Z15),0)) -> 5 | P15: =IF(ROUNDUP(O15*(1+$Z15),0)>$Y15,$Y15,ROUNDUP(O15*(1+$Z15),0)) -> 5 | Q15: =IF(ROUNDUP(P15*(1+$Z15),0)>$Y15,$Y15,ROUNDUP(P15*(1+$Z15),0)) -> 5 | R15: =IF(ROUNDUP(Q15*(1+$Z15),0)>$Y15,$Y15,ROUNDUP(Q15*(1+$Z15),0)) -> 5 | S15: =IF(ROUNDUP(R15*(1+$Z15),0)>$Y15,$Y15,ROUNDUP(R15*(1+$Z15),0)) -> 5 | ... V15: =IF(ROUNDUP(U15*(1+$Z15),0)>$Y15,$Y15,ROUNDUP(U15*(1+$Z15),0)) -> 5 | X15: 5 | Y15: 5 | Z15: 0.03
... A22: 1000184670 | B22: 01 - CANAL VENDA INTERNA | C22: 1000186197 | D22: 02 - INTERNA - CANAL VERDE | E22: 1000184758 | F22: 03 - NORTE + MA | G22: 1000189786 | H22: 04 - PA INTERIOR | I22: 1000195872 | J22: 06 - INTERNA - PROSAUDE | K22: =X22 -> 1 | L22: =IF(ROUNDUP(K22*(1+$Z22),0)>$Y22,$Y22,ROUNDUP(K22*(1+$Z22),0)) -> 1 | M22: =IF(ROUNDUP(L22*(1+$Z22),0)>$Y22,$Y22,ROUNDUP(L22*(1+$Z22),0)) -> 1 | N22: =IF(ROUNDUP(M22*(1+$Z22),0)>$Y22,$Y22,ROUNDUP(M22*(1+$Z22),0)) -> 1 | O22: =IF(ROUNDUP(N22*(1+$Z22),0)>$Y22,$Y22,ROUNDUP(N22*(1+$Z22),0)) -> 1 | P22: =IF(ROUNDUP(O22*(1+$Z22),0)>$Y22,$Y22,ROUNDUP(O22*(1+$Z22),0)) -> 1 | Q22: =IF(ROUNDUP(P22*(1+$Z22),0)>$Y22,$Y22,ROUNDUP(P22*(1+$Z22),0)) -> 1 | R22: =IF(ROUNDUP(Q22*(1+$Z22),0)>$Y22,$Y22,ROUNDUP(Q22*(1+$Z22),0)) -> 1 | S22: =IF(ROUNDUP(R22*(1+$Z22),0)>$Y22,$Y22,ROUNDUP(R22*(1+$Z22),0)) -> 1 | ... V22: =IF(ROUNDUP(U22*(1+$Z22),0)>$Y22,$Y22,ROUNDUP(U22*(1+$Z22),0)) -> 1 | X22: 1 | Y22: 1 | Z22: 0.03
A23: 1000184670 | B23: 01 - CANAL VENDA INTERNA | E23: 1000184756 | F23: 03 - CENTRO OESTE | G23: 1000189773 | H23: 04 - DF GERAL | I23: 1000189270 | J23: 06 - SEM GRUPO | K23: =X23 -> 12 | L23: =ROUNDUP(K23*(1+$Z23),0) -> 12 | M23: =ROUNDUP(L23*(1+$Z23),0) -> 12 | N23: =ROUNDUP(M23*(1+$Z23),0) -> 12 | O23: =ROUNDUP(N23*(1+$Z23),0) -> 12 | P23: =ROUNDUP(O23*(1+$Z23),0) -> 12 | Q23: =ROUNDUP(P23*(1+$Z23),0) -> 12 | R23: =ROUNDUP(Q23*(1+$Z23),0) -> 12 | S23: =ROUNDUP(R23*(1+$Z23),0) -> 12 | ... V23: =ROUNDUP(U23*(1+$Z23),0) -> 12 | X23: 12 | Z23: 0
A24: 1000184670 | B24: 01 - CANAL VENDA INTERNA | E24: 1000184756 | F24: 03 - CENTRO OESTE | G24: 1000189775 | H24: 04 - GO GERAL | I24: 1000189270 | J24: 06 - SEM GRUPO | K24: =X24 -> 53 | L24: =ROUNDUP(K24*(1+$Z24),0) -> 53 | M24: =ROUNDUP(L24*(1+$Z24),0) -> 53 | N24: =ROUNDUP(M24*(1+$Z24),0) -> 53 | O24: =ROUNDUP(N24*(1+$Z24),0) -> 53 | P24: =ROUNDUP(O24*(1+$Z24),0) -> 53 | Q24: =ROUNDUP(P24*(1+$Z24),0) -> 53 | R24: =ROUNDUP(Q24*(1+$Z24),0) -> 53 | S24: =ROUNDUP(R24*(1+$Z24),0) -> 53 | ... V24: =ROUNDUP(U24*(1+$Z24),0) -> 53 | X24: 53 | Z24: 0
A25: 1000184670 | B25: 01 - CANAL VENDA INTERNA | E25: 1000184756 | F25: 03 - CENTRO OESTE | G25: 1000189783 | H25: 04 - MS GERAL | I25: 1000189270 | J25: 06 - SEM GRUPO | K25: =X25 -> 14 | L25: =ROUNDUP(K25*(1+$Z25),0) -> 14 | M25: =ROUNDUP(L25*(1+$Z25),0) -> 14 | N25: =ROUNDUP(M25*(1+$Z25),0) -> 14 | O25: =ROUNDUP(N25*(1+$Z25),0) -> 14 | P25: =ROUNDUP(O25*(1+$Z25),0) -> 14 | Q25: =ROUNDUP(P25*(1+$Z25),0) -> 14 | R25: =ROUNDUP(Q25*(1+$Z25),0) -> 14 | S25: =ROUNDUP(R25*(1+$Z25),0) -> 14 | ... V25: =ROUNDUP(U25*(1+$Z25),0) -> 14 | X25: 14 | Z25: 0
A26: 1000184670 | B26: 01 - CANAL VENDA INTERNA | E26: 1000184756 | F26: 03 - CENTRO OESTE | G26: 1000189784 | H26: 04 - MT GERAL | I26: 1000189270 | J26: 06 - SEM GRUPO | K26: =X26 -> 28 | L26: =ROUNDUP(K26*(1+$Z26),0) -> 28 | M26: =ROUNDUP(L26*(1+$Z26),0) -> 28 | N26: =ROUNDUP(M26*(1+$Z26),0) -> 28 | O26: =ROUNDUP(N26*(1+$Z26),0) -> 28 | P26: =ROUNDUP(O26*(1+$Z26),0) -> 28 | Q26: =ROUNDUP(P26*(1+$Z26),0) -> 28 | R26: =ROUNDUP(Q26*(1+$Z26),0) -> 28 | S26: =ROUNDUP(R26*(1+$Z26),0) -> 28 | ... V26: =ROUNDUP(U26*(1+$Z26),0) -> 28 | X26: 28 | Z26: 0
A27: 1000184670 | B27: 01 - CANAL VENDA INTERNA | E27: 1000184756 | F27: 03 - CENTRO OESTE | G27: 1000189824 | H27: 04 - TO GERAL | I27: 1000189270 | J27: 06 - SEM GRUPO | K27: =X27 -> 10 | L27: =ROUNDUP(K27*(1+$Z27),0) -> 10 | M27: =ROUNDUP(L27*(1+$Z27),0) -> 10 | N27: =ROUNDUP(M27*(1+$Z27),0) -> 10 | O27: =ROUNDUP(N27*(1+$Z27),0) -> 10 | P27: =ROUNDUP(O27*(1+$Z27),0) -> 10 | Q27: =ROUNDUP(P27*(1+$Z27),0) -> 10 | R27: =ROUNDUP(Q27*(1+$Z27),0) -> 10 | S27: =ROUNDUP(R27*(1+$Z27),0) -> 10 | ... V27: =ROUNDUP(U27*(1+$Z27),0) -> 10 | X27: 10 | Z27: 0
A28: 1000184670 | B28: 01 - CANAL VENDA INTERNA | E28: 1000184757 | F28: 03 - NORDESTE (SEM MA) | G28: 1000189765 | H28: 04 - AL GERAL | I28: 1000189270 | J28: 06 - SEM GRUPO | K28: =X28 -> 9 | L28: =ROUNDUP(K28*(1+$Z28),0) -> 9 | M28: =ROUNDUP(L28*(1+$Z28),0) -> 9 | N28: =ROUNDUP(M28*(1+$Z28),0) -> 9 | O28: =ROUNDUP(N28*(1+$Z28),0) -> 9 | P28: =ROUNDUP(O28*(1+$Z28),0) -> 9 | Q28: =ROUNDUP(P28*(1+$Z28),0) -> 9 | R28: =ROUNDUP(Q28*(1+$Z28),0) -> 9 | S28: =ROUNDUP(R28*(1+$Z28),0) -> 9 | ... V28: =ROUNDUP(U28*(1+$Z28),0) -> 9 | X28: 9 | Z28: 0
A29: 1000184670 | B29: 01 - CANAL VENDA INTERNA | E29: 1000184757 | F29: 03 - NORDESTE (SEM MA) | G29: 1000189768 | H29: 04 - BA CAPITAL | I29: 1000189270 | J29: 06 - SEM GRUPO | K29: =X29 -> 12 | L29: =ROUNDUP(K29*(1+$Z29),0) -> 12 | M29: =ROUNDUP(L29*(1+$Z29),0) -> 12 | N29: =ROUNDUP(M29*(1+$Z29),0) -> 12 | O29: =ROUNDUP(N29*(1+$Z29),0) -> 12 | P29: =ROUNDUP(O29*(1+$Z29),0) -> 12 | Q29: =ROUNDUP(P29*(1+$Z29),0) -> 12 | R29: =ROUNDUP(Q29*(1+$Z29),0) -> 12 | S29: =ROUNDUP(R29*(1+$Z29),0) -> 12 | ... V29: =ROUNDUP(U29*(1+$Z29),0) -> 12 | X29: 12 | Z29: 0
A30: 1000184670 | B30: 01 - CANAL VENDA INTERNA | E30: 1000184757 | F30: 03 - NORDESTE (SEM MA) | G30: 1000189769 | H30: 04 - BA OESTE | I30: 1000189270 | J30: 06 - SEM GRUPO | K30: =X30 -> 20 | L30: =ROUNDUP(K30*(1+$Z30),0) -> 20 | M30: =ROUNDUP(L30*(1+$Z30),0) -> 20 | N30: =ROUNDUP(M30*(1+$Z30),0) -> 20 | O30: =ROUNDUP(N30*(1+$Z30),0) -> 20 | P30: =ROUNDUP(O30*(1+$Z30),0) -> 20 | Q30: =ROUNDUP(P30*(1+$Z30),0) -> 20 | R30: =ROUNDUP(Q30*(1+$Z30),0) -> 20 | S30: =ROUNDUP(R30*(1+$Z30),0) -> 20 | ... V30: =ROUNDUP(U30*(1+$Z30),0) -> 20 | X30: 20 | Z30: 0
A31: 1000184670 | B31: 01 - CANAL VENDA INTERNA | E31: 1000184757 | F31: 03 - NORDESTE (SEM MA) | G31: 1000189770 | H31: 04 - BA SUL | I31: 1000189270 | J31: 06 - SEM GRUPO | K31: =X31 -> 21 | L31: =ROUNDUP(K31*(1+$Z31),0) -> 21 | M31: =ROUNDUP(L31*(1+$Z31),0) -> 21 | N31: =ROUNDUP(M31*(1+$Z31),0) -> 21 | O31: =ROUNDUP(N31*(1+$Z31),0) -> 21 | P31: =ROUNDUP(O31*(1+$Z31),0) -> 21 | Q31: =ROUNDUP(P31*(1+$Z31),0) -> 21 | R31: =ROUNDUP(Q31*(1+$Z31),0) -> 21 | S31: =ROUNDUP(R31*(1+$Z31),0) -> 21 | ... V31: =ROUNDUP(U31*(1+$Z31),0) -> 21 | X31: 21 | Z31: 0
A32: 1000184670 | B32: 01 - CANAL VENDA INTERNA | E32: 1000184757 | F32: 03 - NORDESTE (SEM MA) | G32: 1000189771 | H32: 04 - BA VALE DO SAO FRANCISCO/NORTE | I32: 1000189270 | J32: 06 - SEM GRUPO | K32: =X32 -> 9 | L32: =ROUNDUP(K32*(1+$Z32),0) -> 9 | M32: =ROUNDUP(L32*(1+$Z32),0) -> 9 | N32: =ROUNDUP(M32*(1+$Z32),0) -> 9 | O32: =ROUNDUP(N32*(1+$Z32),0) -> 9 | P32: =ROUNDUP(O32*(1+$Z32),0) -> 9 | Q32: =ROUNDUP(P32*(1+$Z32),0) -> 9 | R32: =ROUNDUP(Q32*(1+$Z32),0) -> 9 | S32: =ROUNDUP(R32*(1+$Z32),0) -> 9 | ... V32: =ROUNDUP(U32*(1+$Z32),0) -> 9 | X32: 9 | Z32: 0
A33: 1000184670 | B33: 01 - CANAL VENDA INTERNA | E33: 1000184757 | F33: 03 - NORDESTE (SEM MA) | G33: 1000189772 | H33: 04 - CE GERAL | I33: 1000189270 | J33: 06 - SEM GRUPO | K33: =X33 -> 17 | L33: =ROUNDUP(K33*(1+$Z33),0) -> 17 | M33: =ROUNDUP(L33*(1+$Z33),0) -> 17 | N33: =ROUNDUP(M33*(1+$Z33),0) -> 17 | O33: =ROUNDUP(N33*(1+$Z33),0) -> 17 | P33: =ROUNDUP(O33*(1+$Z33),0) -> 17 | Q33: =ROUNDUP(P33*(1+$Z33),0) -> 17 | R33: =ROUNDUP(Q33*(1+$Z33),0) -> 17 | S33: =ROUNDUP(R33*(1+$Z33),0) -> 17 | ... V33: =ROUNDUP(U33*(1+$Z33),0) -> 17 | X33: 17 | Z33: 0
A34: 1000184670 | B34: 01 - CANAL VENDA INTERNA | E34: 1000184757 | F34: 03 - NORDESTE (SEM MA) | G34: 1000189787 | H34: 04 - PB CAPITAL | I34: 1000189270 | J34: 06 - SEM GRUPO | K34: =X34 -> 5 | L34: =ROUNDUP(K34*(1+$Z34),0) -> 5 | M34: =ROUNDUP(L34*(1+$Z34),0) -> 5 | N34: =ROUNDUP(M34*(1+$Z34),0) -> 5 | O34: =ROUNDUP(N34*(1+$Z34),0) -> 5 | P34: =ROUNDUP(O34*(1+$Z34),0) -> 5 | Q34: =ROUNDUP(P34*(1+$Z34),0) -> 5 | R34: =ROUNDUP(Q34*(1+$Z34),0) -> 5 | S34: =ROUNDUP(R34*(1+$Z34),0) -> 5 | ... V34: =ROUNDUP(U34*(1+$Z34),0) -> 5 | X34: 5 | Z34: 0
... A83: 1000184670 | B83: 01 - CANAL VENDA INTERNA | E83: 1000185288 | F83: 03 - SUL | G83: 1000189810 | H83: 04 - SC SUL | I83: 1000189270 | J83: 06 - SEM GRUPO | K83: =X83 -> 46 | L83: =ROUNDUP(K83*(1+$Z83),0) -> 47 | M83: =ROUNDUP(L83*(1+$Z83),0) -> 48 | N83: =ROUNDUP(M83*(1+$Z83),0) -> 49 | O83: =ROUNDUP(N83*(1+$Z83),0) -> 50 | P83: =ROUNDUP(O83*(1+$Z83),0) -> 51 | Q83: =ROUNDUP(P83*(1+$Z83),0) -> 52 | R83: =ROUNDUP(Q83*(1+$Z83),0) -> 53 | S83: =ROUNDUP(R83*(1+$Z83),0) -> 54 | ... V83: =ROUNDUP(U83*(1+$Z83),0) -> 57 | X83: 46 | Z83: 0.01

Sheet Positivação
L2: =SUBTOTAL(9,L4:L674) -> 385 | M2: =SUBTOTAL(9,M4:M674) -> 401 | N2: =SUBTOTAL(9,N4:N674) -> 409 | O2: =SUBTOTAL(9,O4:O674) -> 417 | P2: =SUBTOTAL(9,P4:P674) -> 428 | Q2: =SUBTOTAL(9,Q4:Q674) -> 437 | R2: =SUBTOTAL(9,R4:R674) -> 453 | S2: =SUBTOTAL(9,S4:S674) -> 462 | ... W2: =SUBTOTAL(9,W4:W674) -> 506 | Y2: =AVERAGEIFS(Y4:Y83,Y4:Y83,">"&0) -> 540.40242 | AD2: =SUM(AD4:AD674) -> 1590
A3: CÓD. 01 | B3: 01 CANAL | C3: CÓD. 02 | D3: 02 TIPO DE CLIENTE | E3: CÓD. 03 | F3: 03 MACRORREGIÃO DO CLIENTE | G3: CÓD. 04 | H3: 04 MICRORREGIÃO DO CLIENTE | I3: CÓD. GRUPO CHAVE | J3: 06 NOME GRUPO CHAVE | L3: JAN | M3: FEV | N3: MAR | O3: ABR | P3: MAI | Q3: JUN | R3: JUL | S3: AGO | T3: SET | U3: OUT | V3: NOV | W3: DEZ | Y3: TICKET MÉDIO REALIZADO | Z3: TICKET MEDIO ESPERADO | AB3: CLASSIFICAÇÃO | AD3: CARTEIRA TOTAL | AE3: TOTAL LOJAS
A4: 1000184670 | B4: 01 - CANAL VENDA INTERNA | C4: 1000186197 | D4: 02 - INTERNA - CANAL VERDE | E4: 1000198600 | F4: 03 - NACIONAL | G4: 1000198601 | H4: 04 - NACIONAL | I4: 1000189750 | J4: 06 - INTERNA - BIO MUNDO | K4: =_xlfn.CONCAT(A4,C4,G4,I4) -> 1000184670100018619710001986011000189750 | L4: =ROUND(SUMIFS(Leads!K:K,Leads!$I:$I,Positivação!$I4,Leads!$G:$G,Positivação!$G4)*_xlfn.XLOOKUP($AB4,'Balizador da Meta'!$F$4:$F$9,'Balizador da Meta'!G$4:G$9),0) -> 4 | M4: =ROUND(SUMIFS(Leads!L:L,Leads!$I:$I,Positivação!$I4,Leads!$G:$G,Positivação!$G4)*_xlfn.XLOOKUP($AB4,'Balizador da Meta'!$F$4:$F$9,'Balizador da Meta'!H$4:H$9),0) -> 4 | N4: =ROUND(SUMIFS(Leads!M:M,Leads!$I:$I,Positivação!$I4,Leads!$G:$G,Positivação!$G4)*_xlfn.XLOOKUP($AB4,'Balizador da Meta'!$F$4:$F$9,'Balizador da Meta'!I$4:I$9),0) -> 5 | O4: =ROUND(SUMIFS(Leads!N:N,Leads!$I:$I,Positivação!$I4,Leads!$G:$G,Positivação!$G4)*_xlfn.XLOOKUP($AB4,'Balizador da Meta'!$F$4:$F$9,'Balizador da Meta'!J$4:J$9),0) -> 5 | P4: =ROUND(SUMIFS(Leads!O:O,Leads!$I:$I,Positivação!$I4,Leads!$G:$G,Positivação!$G4)*_xlfn.XLOOKUP($AB4,'Balizador da Meta'!$F$4:$F$9,'Balizador da Meta'!K$4:K$9),0) -> 5 | Q4: =ROUND(SUMIFS(Leads!P:P,Leads!$I:$I,Positivação!$I4,Leads!$G:$G,Positivação!$G4)*_xlfn.XLOOKUP($AB4,'Balizador da Meta'!$F$4:$F$9,'Balizador da Meta'!L$4:L$9),0) -> 5 | R4: =ROUND(SUMIFS(Leads!Q:Q,Leads!$I:$I,Positivação!$I4,Leads!$G:$G,Positivação!$G4)*_xlfn.XLOOKUP($AB4,'Balizador da Meta'!$F$4:$F$9,'Balizador da Meta'!M$4:M$9),0) -> 6 | S4: =ROUND(SUMIFS(Leads!R:R,Leads!$I:$I,Positivação!$I4,Leads!$G:$G,Positivação!$G4)*_xlfn.XLOOKUP($AB4,'Balizador da Meta'!$F$4:$F$9,'Balizador da Meta'!N$4:N$9),0) -> 6 | T4: =ROUND(SUMIFS(Leads!S:S,Leads!$I:$I,Positivação!$I4,Leads!$G:$G,Positivação!$G4)*_xlfn.XLOOKUP($AB4,'Balizador da Meta'!$F$4:$F$9,'Balizador da Meta'!O$4:O$9),0) -> 6 | U4: =ROUND(SUMIFS(Leads!T:T,Leads!$I:$I,Positivação!$I4,Leads!$G:$G,Positivação!$G4)*_xlfn.XLOOKUP($AB4,'Balizador da Meta'!$F$4:$F$9,'Balizador da Meta'!P$4:P$9),0) -> 7 | V4: =ROUND(SUMIFS(Leads!U:U,Leads!$I:$I,Positivação!$I4,Leads!$G:$G,Positivação!$G4)*_xlfn.XLOOKUP($AB4,'Balizador da Meta'!$F$4:$F$9,'Balizador da Meta'!Q$4:Q$9),0) -> 7 | W4: =ROUND(SUMIFS(Leads!V:V,Leads!$I:$I,Positivação!$I4,Leads!$G:$G,Positivação!$G4)*_xlfn.XLOOKUP($AB4,'Balizador da Meta'!$F$4:$F$9,'Balizador da Meta'!R$4:R$9),0) -> 7 | Y4: =IFERROR(SUMIFS('Historico - FAT'!AO:AO,'Historico - FAT'!I:I,Positivação!I4,'Historico - FAT'!G:G,Positivação!G4)/SUM(L4:T4),0) -> 71.012174 | Z4: 1500 | AB4: EM CRESCIMENTO | AD4: 13 | AE4: 136
A5: 1000184670 | B5: 01 - CANAL VENDA INTERNA | C5: 1000186197 | D5: 02 - INTERNA - CANAL VERDE | E5: 1000198600 | F5: 03 - NACIONAL | G5: 1000198601 | H5: 04 - NACIONAL | I5: 1000189751 | J5: 06 - INTERNA - CIA DA SAUDE | K5: =_xlfn.CONCAT(A5,C5,G5,I5) -> 1000184670100018619710001986011000189751 | L5: =ROUND(SUMIFS(Leads!K:K,Leads!$I:$I,Positivação!$I5,Leads!$G:$G,Positivação!$G5)*_xlfn.XLOOKUP($AB5,'Balizador da Meta'!$F$4:$F$9,'Balizador da Meta'!G$4:G$9),0) -> 35 | M5: =ROUND(SUMIFS(Leads!L:L,Leads!$I:$I,Positivação!$I5,Leads!$G:$G,Positivação!$G5)*_xlfn.XLOOKUP($AB5,'Balizador da Meta'!$F$4:$F$9,'Balizador da Meta'!H$4:H$9),0) -> 37 | N5: =ROUND(SUMIFS(Leads!M:M,Leads!$I:$I,Positivação!$I5,Leads!$G:$G,Positivação!$G5)*_xlfn.XLOOKUP($AB5,'Balizador da Meta'!$F$4:$F$9,'Balizador da Meta'!I$4:I$9),0) -> 38 | O5: =ROUND(SUMIFS(Leads!N:N,Leads!$I:$I,Positivação!$I5,Leads!$G:$G,Positivação!$G5)*_xlfn.XLOOKUP($AB5,'Balizador da Meta'!$F$4:$F$9,'Balizador da Meta'!J$4:J$9),0) -> 40 | P5: =ROUND(SUMIFS(Leads!O:O,Leads!$I:$I,Positivação!$I5,Leads!$G:$G,Positivação!$G5)*_xlfn.XLOOKUP($AB5,'Balizador da Meta'!$F$4:$F$9,'Balizador da Meta'!K$4:K$9),0) -> 41 | Q5: =ROUND(SUMIFS(Leads!P:P,Leads!$I:$I,Positivação!$I5,Leads!$G:$G,Positivação!$G5)*_xlfn.XLOOKUP($AB5,'Balizador da Meta'!$F$4:$F$9,'Balizador da Meta'!L$4:L$9),0) -> 43 | R5: =ROUND(SUMIFS(Leads!Q:Q,Leads!$I:$I,Positivação!$I5,Leads!$G:$G,Positivação!$G5)*_xlfn.XLOOKUP($AB5,'Balizador da Meta'!$F$4:$F$9,'Balizador da Meta'!M$4:M$9),0) -> 44 | S5: =ROUND(SUMIFS(Leads!R:R,Leads!$I:$I,Positivação!$I5,Leads!$G:$G,Positivação!$G5)*_xlfn.XLOOKUP($AB5,'Balizador da Meta'!$F$4:$F$9,'Balizador da Meta'!N$4:N$9),0) -> 46 | T5: =ROUND(SUMIFS(Leads!S:S,Leads!$I:$I,Positivação!$I5,Leads!$G:$G,Positivação!$G5)*_xlfn.XLOOKUP($AB5,'Balizador da Meta'!$F$4:$F$9,'Balizador da Meta'!O$4:O$9),0) -> 47 | U5: =ROUND(SUMIFS(Leads!T:T,Leads!$I:$I,Positivação!$I5,Leads!$G:$G,Positivação!$G5)*_xlfn.XLOOKUP($AB5,'Balizador da Meta'!$F$4:$F$9,'Balizador da Meta'!P$4:P$9),0) -> 49 | V5: =ROUND(SUMIFS(Leads!U:U,Leads!$I:$I,Positivação!$I5,Leads!$G:$G,Positivação!$G5)*_xlfn.XLOOKUP($AB5,'Balizador da Meta'!$F$4:$F$9,'Balizador da Meta'!Q$4:Q$9),0) -> 50 | W5: =ROUND(SUMIFS(Leads!V:V,Leads!$I:$I,Positivação!$I5,Leads!$G:$G,Positivação!$G5)*_xlfn.XLOOKUP($AB5,'Balizador da Meta'!$F$4:$F$9,'Balizador da Meta'!R$4:R$9),0) -> 52 | Y5: =IFERROR(SUMIFS('Historico - FAT'!AO:AO,'Historico - FAT'!I:I,Positivação!I5,'Historico - FAT'!G:G,Positivação!G5)/SUM(L5:T5),0) -> 26.835148 | Z5: 1500 | AB5: MADURO | AD5: 70 | AE5: 150
A6: 1000184670 | B6: 01 - CANAL VENDA INTERNA | C6: 1000186197 | D6: 02 - INTERNA - CANAL VERDE | E6: 1000198600 | F6: 03 - NACIONAL | G6: 1000198601 | H6: 04 - NACIONAL | I6: 1000189753 | J6: 06 - INTERNA - DIVINA TERRA | K6: =_xlfn.CONCAT(A6,C6,G6,I6) -> 1000184670100018619710001986011000189753 | L6: =ROUND(SUMIFS(Leads!K:K,Leads!$I:$I,Positivação!$I6,Leads!$G:$G,Positivação!$G6)*_xlfn.XLOOKUP($AB6,'Balizador da Meta'!$F$4:$F$9,'Balizador da Meta'!G$4:G$9),0) -> 16 | M6: =ROUND(SUMIFS(Leads!L:L,Leads!$I:$I,Positivação!$I6,Leads!$G:$G,Positivação!$G6)*_xlfn.XLOOKUP($AB6,'Balizador da Meta'!$F$4:$F$9,'Balizador da Meta'!H$4:H$9),0) -> 17 | N6: =ROUND(SUMIFS(Leads!M:M,Leads!$I:$I,Positivação!$I6,Leads!$G:$G,Positivação!$G6)*_xlfn.XLOOKUP($AB6,'Balizador da Meta'!$F$4:$F$9,'Balizador da Meta'!I$4:I$9),0) -> 17 | O6: =ROUND(SUMIFS(Leads!N:N,Leads!$I:$I,Positivação!$I6,Leads!$G:$G,Positivação!$G6)*_xlfn.XLOOKUP($AB6,'Balizador da Meta'!$F$4:$F$9,'Balizador da Meta'!J$4:J$9),0) -> 18 | P6: =ROUND(SUMIFS(Leads!O:O,Leads!$I:$I,Positivação!$I6,Leads!$G:$G,Positivação!$G6)*_xlfn.XLOOKUP($AB6,'Balizador da Meta'!$F$4:$F$9,'Balizador da Meta'!K$4:K$9),0) -> 18 | Q6: =ROUND(SUMIFS(Leads!P:P,Leads!$I:$I,Positivação!$I6,Leads!$G:$G,Positivação!$G6)*_xlfn.XLOOKUP($AB6,'Balizador da Meta'!$F$4:$F$9,'Balizador da Meta'!L$4:L$9),0) -> 19 | R6: =ROUND(SUMIFS(Leads!Q:Q,Leads!$I:$I,Positivação!$I6,Leads!$G:$G,Positivação!$G6)*_xlfn.XLOOKUP($AB6,'Balizador da Meta'!$F$4:$F$9,'Balizador da Meta'!M$4:M$9),0) -> 20 | S6: =ROUND(SUMIFS(Leads!R:R,Leads!$I:$I,Positivação!$I6,Leads!$G:$G,Positivação!$G6)*_xlfn.XLOOKUP($AB6,'Balizador da Meta'!$F$4:$F$9,'Balizador da Meta'!N$4:N$9),0) -> 20 | T6: =ROUND(SUMIFS(Leads!S:S,Leads!$I:$I,Positivação!$I6,Leads!$G:$G,Positivação!$G6)*_xlfn.XLOOKUP($AB6,'Balizador da Meta'!$F$4:$F$9,'Balizador da Meta'!O$4:O$9),0) -> 21 | U6: =ROUND(SUMIFS(Leads!T:T,Leads!$I:$I,Positivação!$I6,Leads!$G:$G,Positivação!$G6)*_xlfn.XLOOKUP($AB6,'Balizador da Meta'!$F$4:$F$9,'Balizador da Meta'!P$4:P$9),0) -> 21 | V6: =ROUND(SUMIFS(Leads!U:U,Leads!$I:$I,Positivação!$I6,Leads!$G:$G,Positivação!$G6)*_xlfn.XLOOKUP($AB6,'Balizador da Meta'!$F$4:$F$9,'Balizador da Meta'!Q$4:Q$9),0) -> 22 | W6: =ROUND(SUMIFS(Leads!V:V,Leads!$I:$I,Positivação!$I6,Leads!$G:$G,Positivação!$G6)*_xlfn.XLOOKUP($AB6,'Balizador da Meta'!$F$4:$F$9,'Balizador da Meta'!R$4:R$9),0) -> 23 | Y6: =IFERROR(SUMIFS('Historico - FAT'!AO:AO,'Historico - FAT'!I:I,Positivação!I6,'Historico - FAT'!G:G,Positivação!G6)/SUM(L6:T6),0) -> 50.900361 | Z6: 1500 | AB6: EM CRESCIMENTO | AD6: 53 | AE6: 76
A7: 1000184670 | B7: 01 - CANAL VENDA INTERNA | C7: 1000186197 | D7: 02 - INTERNA - CANAL VERDE | E7: 1000198600 | F7: 03 - NACIONAL | G7: 1000198601 | H7: 04 - NACIONAL | I7: 1000189756 | J7: 06 - INTERNA - FITLAND | K7: =_xlfn.CONCAT(A7,C7,G7,I7) -> 1000184670100018619710001986011000189756 | L7: =ROUND(SUMIFS(Leads!K:K,Leads!$I:$I,Positivação!$I7,Leads!$G:$G,Positivação!$G7)*_xlfn.XLOOKUP($AB7,'Balizador da Meta'!$F$4:$F$9,'Balizador da Meta'!G$4:G$9),0) -> 29 | M7: =ROUND(SUMIFS(Leads!L:L,Leads!$I:$I,Positivação!$I7,Leads!$G:$G,Positivação!$G7)*_xlfn.XLOOKUP($AB7,'Balizador da Meta'!$F$4:$F$9,'Balizador da Meta'!H$4:H$9),0) -> 30 | N7: =ROUND(SUMIFS(Leads!M:M,Leads!$I:$I,Positivação!$I7,Leads!$G:$G,Positivação!$G7)*_xlfn.XLOOKUP($AB7,'Balizador da Meta'!$F$4:$F$9,'Balizador da Meta'!I$4:I$9),0) -> 31 | O7: =ROUND(SUMIFS(Leads!N:N,Leads!$I:$I,Positivação!$I7,Leads!$G:$G,Positivação!$G7)*_xlfn.XLOOKUP($AB7,'Balizador da Meta'!$F$4:$F$9,'Balizador da Meta'!J$4:J$9),0) -> 32 | P7: =ROUND(SUMIFS(Leads!O:O,Leads!$I:$I,Positivação!$I7,Leads!$G:$G,Positivação!$G7)*_xlfn.XLOOKUP($AB7,'Balizador da Meta'!$F$4:$F$9,'Balizador da Meta'!K$4:K$9),0) -> 33 | Q7: =ROUND(SUMIFS(Leads!P:P,Leads!$I:$I,Positivação!$I7,Leads!$G:$G,Positivação!$G7)*_xlfn.XLOOKUP($AB7,'Balizador da Meta'!$F$4:$F$9,'Balizador da Meta'!L$4:L$9),0) -> 34 | R7: =ROUND(SUMIFS(Leads!Q:Q,Leads!$I:$I,Positivação!$I7,Leads!$G:$G,Positivação!$G7)*_xlfn.XLOOKUP($AB7,'Balizador da Meta'!$F$4:$F$9,'Balizador da Meta'!M$4:M$9),0) -> 35 | S7: =ROUND(SUMIFS(Leads!R:R,Leads!$I:$I,Positivação!$I7,Leads!$G:$G,Positivação!$G7)*_xlfn.XLOOKUP($AB7,'Balizador da Meta'!$F$4:$F$9,'Balizador da Meta'!N$4:N$9),0) -> 36 | T7: =ROUND(SUMIFS(Leads!S:S,Leads!$I:$I,Positivação!$I7,Leads!$G:$G,Positivação!$G7)*_xlfn.XLOOKUP($AB7,'Balizador da Meta'!$F$4:$F$9,'Balizador da Meta'!O$4:O$9),0) -> 37 | U7: =ROUND(SUMIFS(Leads!T:T,Leads!$I:$I,Positivação!$I7,Leads!$G:$G,Positivação!$G7)*_xlfn.XLOOKUP($AB7,'Balizador da Meta'!$F$4:$F$9,'Balizador da Meta'!P$4:P$9),0) -> 38 | V7: =ROUND(SUMIFS(Leads!U:U,Leads!$I:$I,Positivação!$I7,Leads!$G:$G,Positivação!$G7)*_xlfn.XLOOKUP($AB7,'Balizador da Meta'!$F$4:$F$9,'Balizador da Meta'!Q$4:Q$9),0) -> 39 | W7: =ROUND(SUMIFS(Leads!V:V,Leads!$I:$I,Positivação!$I7,Leads!$G:$G,Positivação!$G7)*_xlfn.XLOOKUP($AB7,'Balizador da Meta'!$F$4:$F$9,'Balizador da Meta'!R$4:R$9),0) -> 40 | Y7: =IFERROR(SUMIFS('Historico - FAT'!AO:AO,'Historico - FAT'!I:I,Positivação!I7,'Historico - FAT'!G:G,Positivação!G7)/SUM(L7:T7),0) -> 196.44939 | Z7: 1500 | AB7: MADURO | AD7: 58 | AE7: 80
